Workbook

Sheet Summary
A1: AAC Assosa CIL Plant (Ethiopia) Monitoring - Financial Model Summary
A2: Prepared by Smart Innovations GH | USD | Year 0 = Nov 2026 - May 2027, Years 1-5 full operation | Indicative, pre-tax, ex-VAT
A4: Cost base | B4: Value | E4: Note
A5: Concessions (base) | B5: =Inputs!$B$7 -> 8 | E5: Change on Inputs
A6: One-off cost to deliver | B6: =Costs!$D$38 -> 566931.75 | E6: Hardware, installation, services, contingency
A7: Annual operating cost (full year) | B7: =Costs!$D$52 -> 276994.5
A8: Annual operating cost per concession | B8: =Costs!$D$53 -> 34624.313
A9: Annual AAC benefit (full year) | B9: ='AAC Benefits'!$C$14 -> 851614.78 | E9: See AAC Benefits
A10: of which gold from stopped leakage | B10: ='AAC Benefits'!$C$10 -> 550934.78 | E10: Largest single driver
A12: Revenue model comparison | B12: A: Fixed price + service | C12: B: Subscription | D12: C: Gain-share | E12: What it means
A13: Smart Innovations GH 5-yr revenue | B13: ='Revenue Models'!$I$26 -> 2599152.2 | C13: ='Revenue Models'!$I$41 -> 2638303.8 | D13: ='Revenue Models'!$I$57 -> 2805023
A14: Smart Innovations GH NPV | B14: ='Revenue Models'!$I$22 -> 422370.28 | C14: ='Revenue Models'!$I$37 -> 198301.11 | D14: ='Revenue Models'!$I$53 -> 496779.16 | E14: Discounted at the Inputs discount rate
A15: Smart Innovations GH gross margin | B15: ='Revenue Models'!$I$27 -> 0.22237993 | C15: ='Revenue Models'!$I$42 -> 0.23391957 | D15: ='Revenue Models'!$I$58 -> 0.2794523
A16: Smart Innovations GH IRR | B16: ='Revenue Models'!$I$28 -> n/a - costs recovered upfront | C16: ='Revenue Models'!$I$43 -> 0.34488506 | D16: ='Revenue Models'!$I$59 -> n/a - costs recovered upfront | E16: n/a where there is no upfront outlay
A17: Smart Innovations GH payback | B17: ='Revenue Models'!$I$29 -> Year 0 | C17: ='Revenue Models'!$I$44 -> Year 3 | D17: ='Revenue Models'!$I$60 -> Year 0
A18: AAC upfront payment (Year 0 fees) | B18: ='Revenue Models'!$B$21 -> 798687.9 | C18: ='Revenue Models'!$B$36 -> 135103.76 | D18: ='Revenue Models'!$B$52 -> 653587.1 | E18: Cash AAC must find before full go-live
A19: AAC NPV of net benefit | B19: ='Revenue Models'!$I$24 -> 774020.66 | C19: ='Revenue Models'!$I$39 -> 998089.83 | D19: ='Revenue Models'!$I$55 -> 699611.78 | E19: Benefits minus all fees and internal cost
A20: AAC payback | B20: ='Revenue Models'!$I$30 -> Year 2 | C20: ='Revenue Models'!$I$45 -> Year 1 | D20: ='Revenue Models'!$I$61 -> Year 2
A21: AAC return on fees | B21: ='Revenue Models'!$I$31 -> 0.40213883 | C21: ='Revenue Models'!$I$46 -> 0.58687324 | D21: ='Revenue Models'!$I$62 -> 0.34995135
A23: Scenario check (NPV) | B23: Bear | C23: Base | D23: Bull
A24: Smart Innovations GH NPV - Model A | B24: ='Scenario Engine'!$Y$44 -> 365748.51 | C24: ='Scenario Engine'!$B$44 -> 422370.28 | D24: ='Scenario Engine'!$Z$44 -> 467375.59
A25: Smart Innovations GH NPV - Model B | B25: ='Scenario Engine'!$Y$45 -> -260644.52 | C25: ='Scenario Engine'!$B$45 -> 198301.11 | D25: ='Scenario Engine'!$Z$45 -> 561669.13
A26: Smart Innovations GH NPV - Model C | B26: ='Scenario Engine'!$Y$46 -> 150265.85 | C26: ='Scenario Engine'!$B$46 -> 496779.16 | D26: ='Scenario Engine'!$Z$46 -> 1067747
A27: AAC NPV - Model A | B27: ='Scenario Engine'!$Y$47 -> -876706.76 | C27: ='Scenario Engine'!$B$47 -> 774020.66 | D27: ='Scenario Engine'!$Z$47 -> 3562254.7
A28: AAC NPV - Model B | B28: ='Scenario Engine'!$Y$48 -> -250313.73 | C28: ='Scenario Engine'!$B$48 -> 998089.83 | D28: ='Scenario Engine'!$Z$48 -> 3467961.2
A29: AAC NPV - Model C | B29: ='Scenario Engine'!$Y$49 -> -661224.1 | C29: ='Scenario Engine'!$B$49 -> 699611.78 | D29: ='Scenario Engine'!$Z$49 -> 2961883.4
A31: Colour legend
A32: Blue text = hardcoded input you can change
A33: Black text = formula
A34: Green text = link to another sheet
A35: Yellow fill = key assumption to confirm
A37: All unit prices are approximate market estimates, not quotes. Replace the yellow cells on Inputs with AAC data and vendor quotes before using this for a decision.

Sheet Pilot Price
A1: Pilot price - Phase 0 and Phase 1 (2 concessions), fixed price (USD)
A2: Pilot fee is credited in full against the full-rollout fee under any option if AAC proceeds at Gate 2.
A4: Item | B4: Quantity | C4: Unit cost | D4: Total | E4: Note
A5: Pilot concessions | B5: =Inputs!$B$8 -> 2
A6: Excavators | B6: =$B$5*Inputs!$B$9 -> 4
A7: Trucks | B7: =$B$5*Inputs!$B$10 -> 6
A8: Fuel points | B8: =$B$5+1 -> 3
A9: Gateway sites | B9: =MAX(1,ROUND($B$5*Inputs!$B$12,0)) -> 1
A10: Excavator trackers + fuel sensors | B10: =$B$6 -> 4 | C10: =Inputs!$B$16+Inputs!$B$17 -> 850 | D10: =B10*C10 -> 3400
A11: Fuel dispensers + tags | B11: =$B$8 -> 3 | C11: =Inputs!$B$18+Inputs!$B$19*Inputs!$B$20 -> 3650 | D11: =B11*C11 -> 10950
A12: Truck GPS + dashcams | B12: =$B$7 -> 6 | C12: =Inputs!$B$21+Inputs!$B$22 -> 850 | D12: =B12*C12 -> 5100
A13: ANPR + weighbridge link | B13: 1 | C13: =Inputs!$B$23 -> 8000 | D13: =B13*C13 -> 8000
A14: Gateway kits | B14: =$B$9 -> 1 | C14: =Inputs!$B$24 -> 4500 | D14: =B14*C14 -> 4500
A15: Drone kit | B15: 1 | C15: =Inputs!$B$25 -> 15000 | D15: =B15*C15 -> 15000
A16: Rugged phones | B16: =$B$5+Inputs!$B$11 -> 4 | C16: =Inputs!$B$26 -> 400 | D16: =B16*C16 -> 1600
A17: Command centre | B17: 1 | C17: =Inputs!$B$27 -> 5000 | D17: =B17*C17 -> 5000
A18: Landed hardware (+ duty, freight, clearing) | D18: =SUM(D10:D17)*Inputs!$B$30*(1+Inputs!$B$28) -> 72292.5
A19: Installation | B19: =2*$B$6+2*$B$7+$B$8+$B$9 -> 24 | C19: =Inputs!$B$29 -> 80 | D19: =B19*C19 -> 1920
A20: Share of implementation team incurred by end of pilot | B20: 0.6 | C20: =Inputs!$E$44 -> 235800 | D20: =B20*C20*Inputs!$B$50 -> 141480 | E20: Platform is built during the pilot, so most team cost falls here
A21: Geologist baseline, survey, training | B21: =$B$5 -> 2 | C21: =Inputs!$B$46+Inputs!$B$47+Inputs!$B$48 -> 11000 | D21: =B21*C21 -> 22000
A22: Pilot running cost, 3 months | D22: =Inputs!$E$67/4+$B$5*6*Inputs!$B$59+(Inputs!$B$53+Inputs!$B$57)/4+($B$6+$B$7+$B$8)*Inputs!$B$55*3+$B$9*Inputs!$B$56*3 -> 32734 | E22: Support team, 6 drone cycles per concession, cloud, SIM, satellite
A23: Subtotal | D23: =$D$18+$D$19+$D$20+$D$21+$D$22 -> 270426.5
A24: Contingency | D24: =$D$23*Inputs!$B$49 -> 27042.65
A25: Pilot cost | D25: =$D$23+$D$24 -> 297469.15
A26: PILOT FIXED PRICE (cost + Model A implementation margin) | D26: =ROUND($D$25*(1+Inputs!$B$104*Inputs!$B$103),-3) -> 372000
A28: Payment milestones
A29: On contract signature | B29: 0.4 | D29: =B29*$D$26 -> 148800
A30: Gate 1: baseline signed off | B30: 0.3 | D30: =B30*$D$26 -> 111600
A31: Pilot live on 2 concessions | B31: 0.2 | D31: =B31*$D$26 -> 74400
A32: Pilot results report delivered | B32: 0.1 | D32: =B32*$D$26 -> 37200

Sheet Inputs
A1: Inputs and assumptions (USD unless stated)
A2: Blue = editable input. Yellow = key assumption to confirm with AAC or vendor quotes. All prices are approximate market estimates (no live price check was possible) - replace with quotes.
A4: Assumption | B4: Value | C4: Unit | F4: Basis / note
A6: 1. Scale of rollout
A7: Concessions in full rollout | B7: 8 | C7: # | F7: AAC range is 4 to 10; base case assumes 8
A8: Concessions in pilot (information) | B8: 2 | C8: # | F8: From delivery plan
A9: Lent excavators per concession | B9: 2 | C9: # | F9: Assumption - confirm AAC fleet register
A10: Dump trucks per concession | B10: 3 | C10: # | F10: Assumption - confirm with hauliers
A11: Extra rugged phones at plant / AAC | B11: 2 | C11: # | F11: Weighbridge + project owner
A12: Share of concessions needing gateway + satellite | B12: 0.6 | C12: % | F12: Remote pits without reliable 4G
A13: Concessions one drone kit can cover | B13: 6 | C13: # | F13: Above this a second kit is bought
A15: 2. Hardware unit costs (landed cost added below)
A16: Excavator GPS/CAN tracker with tamper alarm + immobiliser | B16: 450 | C16: $/unit | F16: Approx. market price, retrofit telematics unit
A17: Capacitive fuel-level sensor + CAN fuel-rate reader | B17: 400 | C17: $/unit | F17: Approx. price for mining-grade sensor
A18: Smart fuel dispenser (flow meter, RFID controller) | B18: 3500 | C18: $/fuel point | F18: Approx.; one per concession bowser + plant tank
A19: RFID tags / operator cards per fuel point | B19: 15 | C19: #
A20: RFID tag / card | B20: 10 | C20: $/unit | F20: Approx.
A21: Truck GPS tracker | B21: 250 | C21: $/unit | F21: Approx.
A22: AI dashcam (road + driver facing) | B22: 600 | C22: $/unit | F22: Approx.
A23: ANPR camera + weighbridge software link (plant) | B23: 8000 | C23: $ lump | F23: Assumes AAC weighbridge already exists
A24: Gateway kit: 4G/LoRaWAN + licensed VSAT terminal + solar | B24: 4500 | C24: $/kit | F24: Approx.; satellite via a provider licensed in Ethiopia - confirm availability
A25: Drone kit: RTK drone, GNSS base, GCP markers, batteries, laptop | B25: 15000 | C25: $/kit | F25: Approx. enterprise RTK photogrammetry kit; LiDAR option adds ~$20k
A26: Rugged phone / tablet | B26: 400 | C26: $/unit | F26: Approx.
A27: Command centre screen + PC | B27: 5000 | C27: $ lump | F27: Approx.
A28: Import duty, surtax, excise, freight and clearing into Ethiopia | B28: 0.35 | C28: % of HW | F28: Approximate for electronics via Djibouti/Addis; VAT (15%) excluded as recoverable - confirm with clearing agent
A29: Installation labour + travel per device | B29: 80 | C29: $/device | F29: Assumption
A30: Hardware cost multiplier (scenario lever) | B30: 1 | C30: x | F30: 1.00 = base; used in sensitivity
A32: 3. Implementation team (one-off)
A33: Role | B33: Monthly cost | C33: FTE | D33: Months | E33: Total
A34: Programme manager | B34: 4500 | C34: 1 | D34: 8 | E34: =B34*C34*D34 -> 36000
A35: Solution architect / IoT lead | B35: 5500 | C35: 1 | D35: 8 | E35: =B35*C35*D35 -> 44000
A36: Full-stack developers | B36: 3500 | C36: 2 | D36: 5 | E36: =B36*C36*D36 -> 35000
A37: GIS / data engineer | B37: 3500 | C37: 1 | D37: 5 | E37: =B37*C37*D37 -> 17500
A38: Data scientist / ML engineer | B38: 4500 | C38: 0.5 | D38: 6 | E38: =B38*C38*D38 -> 13500
A39: Field installation technicians (Ethiopian) | B39: 900 | C39: 3 | D39: 4 | E39: =B39*C39*D39 -> 10800
A40: Travel Accra-Addis-Assosa, per diem, vehicles | B40: 4000 | C40: 1 | D40: 8 | E40: =B40*C40*D40 -> 32000
A41: Ethiopia partner: coordinator + Amharic translator | B41: 2500 | C41: 1 | D41: 8 | E41: =B41*C41*D41 -> 20000
A42: Site security escorts (Benishangul-Gumuz) | B42: 1500 | C42: 1 | D42: 8 | E42: =B42*C42*D42 -> 12000
A43: Legal, permits and compliance: local counsel, drone import and flight approval (lump sum) | E43: 15000
A44: Total implementation team | E44: =SUM(E34:E43) -> 235800
...

Sheet Costs
A1: Cost build-up - base case (USD)
A2: Green = linked from Inputs. Black = calculation.
A4: Item | B4: Quantity | C4: Unit cost | D4: Total | E4: Note
A6: Quantities
A7: Excavators | B7: =Inputs!$B$7*Inputs!$B$9 -> 16
A8: Dump trucks | B8: =Inputs!$B$7*Inputs!$B$10 -> 24
A9: Fuel points (one per concession + plant) | B9: =Inputs!$B$7+1 -> 9
A10: Gateway sites | B10: =ROUND(Inputs!$B$7*Inputs!$B$12,0) -> 5
A11: Drone kits | B11: =IF(Inputs!$B$7>Inputs!$B$13,2,1) -> 2
A12: Connected devices (excavators + trucks + fuel points) | B12: =Costs!$B$7+Costs!$B$8+Costs!$B$9 -> 49
A13: Rugged phones | B13: =Inputs!$B$7+Inputs!$B$11 -> 10
A15: A. Hardware (one-off)
A16: Excavator trackers | B16: =Costs!$B$7 -> 16 | C16: =Inputs!$B$16 -> 450 | D16: =B16*C16 -> 7200
A17: Excavator fuel sensors | B17: =Costs!$B$7 -> 16 | C17: =Inputs!$B$17 -> 400 | D17: =B17*C17 -> 6400
A18: Smart fuel dispensers | B18: =Costs!$B$9 -> 9 | C18: =Inputs!$B$18 -> 3500 | D18: =B18*C18 -> 31500
A19: RFID tags and operator cards | B19: =Costs!$B$9*Inputs!$B$19 -> 135 | C19: =Inputs!$B$20 -> 10 | D19: =B19*C19 -> 1350
A20: Truck GPS trackers | B20: =Costs!$B$8 -> 24 | C20: =Inputs!$B$21 -> 250 | D20: =B20*C20 -> 6000
A21: AI dashcams | B21: =Costs!$B$8 -> 24 | C21: =Inputs!$B$22 -> 600 | D21: =B21*C21 -> 14400
A22: ANPR + weighbridge link | B22: 1 | C22: =Inputs!$B$23 -> 8000 | D22: =B22*C22 -> 8000
A23: Gateway kits | B23: =Costs!$B$10 -> 5 | C23: =Inputs!$B$24 -> 4500 | D23: =B23*C23 -> 22500
A24: Drone kits | B24: =Costs!$B$11 -> 2 | C24: =Inputs!$B$25 -> 15000 | D24: =B24*C24 -> 30000
A25: Rugged phones | B25: =Costs!$B$13 -> 10 | C25: =Inputs!$B$26 -> 400 | D25: =B25*C25 -> 4000
A26: Command centre | B26: 1 | C26: =Inputs!$B$27 -> 5000 | D26: =B26*C26 -> 5000
A27: Hardware at supplier price | D27: =SUM(D16:D26) -> 136350
A28: Landed hardware (x multiplier, + duty and shipping) | D28: =Costs!$D$27*Inputs!$B$30*(1+Inputs!$B$28) -> 184072.5
A29: Installation (2 devices per excavator and truck, 1 per fuel point and gateway) | B29: =2*Costs!$B$7+2*Costs!$B$8+Costs!$B$9+Costs!$B$10 -> 94 | C29: =Inputs!$B$29 -> 80 | D29: =B29*C29 -> 7520
A31: B. Implementation services (one-off)
A32: Implementation team (Inputs section 3) | D32: =Inputs!$E$44*Inputs!$B$50 -> 235800
A33: Geologist baselines | B33: =Inputs!$B$7 -> 8 | C33: =Inputs!$B$46 -> 7000 | D33: =B33*C33*Inputs!$B$50 -> 56000
A34: Surveys | B34: =Inputs!$B$7 -> 8 | C34: =Inputs!$B$47 -> 2500 | D34: =B34*C34*Inputs!$B$50 -> 20000
A35: Training | B35: =Inputs!$B$7 -> 8 | C35: =Inputs!$B$48 -> 1500 | D35: =B35*C35*Inputs!$B$50 -> 12000
A36: Subtotal before contingency | D36: =Costs!$D$28+Costs!$D$29+Costs!$D$32+Costs!$D$33+Costs!$D$34+Costs!$D$35 -> 515392.5
A37: Contingency | D37: =Costs!$D$36*Inputs!$B$49 -> 51539.25
A38: TOTAL ONE-OFF COST | D38: =Costs!$D$36+Costs!$D$37 -> 566931.75
A40: C. Annual operating cost (full year)
A41: Cloud hosting (fixed) | D41: =Inputs!$B$53 -> 9000
A42: Cloud per device | B42: =Costs!$B$12 -> 49 | C42: =Inputs!$B$54 -> 30 | D42: =B42*C42 -> 1470
A43: SIM data (12 months) | B43: =Costs!$B$12*12 -> 588 | C43: =Inputs!$B$55 -> 6 | D43: =B43*C43 -> 3528
A44: Satellite airtime (12 months) | B44: =Costs!$B$10*12 -> 60 | C44: =Inputs!$B$56 -> 150 | D44: =B44*C44 -> 9000
A45: Software licences | D45: =Inputs!$B$57 -> 6700
...

Sheet AAC Benefits
A1: AAC benefits - full operating year, base case (USD)
A3: Benefit line | B3: Driver | C3: Annual value | D3: How it is calculated
A4: Excavator diesel used (L/yr) | B4: =Costs!$B$7*Inputs!$B$76*Inputs!$B$77 -> 960000 | D4: Excavators x burn x hours
A5: 1. Excavator fuel saving | C5: ='AAC Benefits'!$B$4*Inputs!$B$80*Inputs!$B$79 -> 97920 | D5: Litres x saving % x diesel price
A6: Truck diesel used (L/yr) | B6: =Costs!$B$8*Inputs!$B$78*Inputs!$B$70 -> 432000 | D6: Trucks x L/day x days
A7: 2. Truck fuel saving | C7: ='AAC Benefits'!$B$6*Inputs!$B$81*Inputs!$B$79 -> 18360 | D7: Litres x saving % x diesel price
A8: Tailings feed to plant (t/yr) | B8: =Inputs!$B$7*Inputs!$B$82 -> 400000 | D8: Concessions x feed per concession
A9: Extra gold recovered (oz/yr) | B9: ='AAC Benefits'!$B$8*Inputs!$B$83*Inputs!$B$84*Inputs!$B$85/31.1035 -> 393.52484 | D9: Feed x extra feed % x grade x recovery / 31.1035 g per oz
A10: 3. AAC margin on extra gold from stopped leakage | C10: ='AAC Benefits'!$B$9*Inputs!$B$86*Inputs!$B$87 -> 550934.78 | D10: oz x gold price x AAC margin
A11: 4. Excavator utilisation uplift | C11: =Costs!$B$7*Inputs!$B$77*Inputs!$B$88*Inputs!$B$89 -> 134400 | D11: Excavators x hours x uplift x $/h
A12: 5. Haulage over-claims removed | C12: ='AAC Benefits'!$B$8*Inputs!$B$90*Inputs!$B$91 -> 30000 | D12: Feed t x $/t x over-claim %
A13: 6. Asset theft / insurance avoided | C13: =Costs!$B$7*Inputs!$B$92 -> 20000 | D13: Excavators x $/yr
A14: TOTAL ANNUAL BENEFIT | C14: =SUM(C5:C13) -> 851614.78
A15: Verified savings pool for Model C gain share (lines 1, 2, 3, 5) | C15: ='AAC Benefits'!$C$5+'AAC Benefits'!$C$7+'AAC Benefits'!$C$10+'AAC Benefits'!$C$12 -> 697214.78 | D15: Lines that can be measured and audited from platform data
A17: Gold (line 3) is the largest benefit, so grade, gold price and leakage stopped drive the AAC case - see Sensitivity.

Sheet Revenue Models
A1: Revenue models - 5-year cash flows, base case (USD)
A2: Year 0 = implementation and pilot (Nov 2026 - May 2027). Years 1-5 = full operation. Pre-tax, excluding VAT and levies.
A4: Line | B4: Year 0 | C4: Year 1 | D4: Year 2 | E4: Year 3 | F4: Year 4 | G4: Year 5 | I4: NPV / metric
A5: Discount factor | B5: =1/(1+Inputs!$B$96)^0 -> 1 | C5: =1/(1+Inputs!$B$96)^1 -> 0.84745763 | D5: =1/(1+Inputs!$B$96)^2 -> 0.71818443 | E5: =1/(1+Inputs!$B$96)^3 -> 0.60863087 | F5: =1/(1+Inputs!$B$96)^4 -> 0.51578888 | G5: =1/(1+Inputs!$B$96)^5 -> 0.43710922
A6: Opex / service activity factor | B6: =Inputs!$B$98 -> 0.25 | C6: 1 | D6: 1 | E6: 1 | F6: 1 | G6: 1
A7: AAC benefit factor | B7: =Inputs!$B$99 -> 0.1 | C7: 1 | D7: 1 | E7: 1 | F7: 1 | G7: 1
A8: Subscription billing factor | B8: =Inputs!$B$100 -> 0.1 | C8: 1 | D8: 1 | E8: 1 | F8: 1 | G8: 1
A10: Common: delivery costs to Smart Innovations GH and benefits to AAC
A11: One-off cost (hardware, services, contingency) | B11: =Costs!$D$38 -> 566931.75 | C11: 0 | D11: 0 | E11: 0 | F11: 0 | G11: 0 | I11: =SUMPRODUCT(B11:G11,B5:G5) -> 566931.75
A12: Operating cost | B12: =Costs!$D$52*B6 -> 69248.625 | C12: =Costs!$D$52*C6 -> 276994.5 | D12: =Costs!$D$52*D6 -> 276994.5 | E12: =Costs!$D$52*E6 -> 276994.5 | F12: =Costs!$D$52*F6 -> 276994.5 | G12: =Costs!$D$52*G6 -> 276994.5 | I12: =SUMPRODUCT(B12:G12,B5:G5) -> 935457.8
A13: Total delivery cost | B13: =B11+B12 -> 636180.38 | C13: =C11+C12 -> 276994.5 | D13: =D11+D12 -> 276994.5 | E13: =E11+E12 -> 276994.5 | F13: =F11+F12 -> 276994.5 | G13: =G11+G12 -> 276994.5 | I13: =SUMPRODUCT(B13:G13,B5:G5) -> 1502389.6
A14: AAC benefits | B14: ='AAC Benefits'!$C$14*B7 -> 85161.478 | C14: ='AAC Benefits'!$C$14*C7 -> 851614.78 | D14: ='AAC Benefits'!$C$14*D7 -> 851614.78 | E14: ='AAC Benefits'!$C$14*E7 -> 851614.78 | F14: ='AAC Benefits'!$C$14*F7 -> 851614.78 | G14: ='AAC Benefits'!$C$14*G7 -> 851614.78 | I14: =SUMPRODUCT(B14:G14,B5:G5) -> 2748306.5
A15: of which verified savings pool | B15: ='AAC Benefits'!$C$15*B7 -> 69721.478 | C15: ='AAC Benefits'!$C$15*C7 -> 697214.78 | D15: ='AAC Benefits'!$C$15*D7 -> 697214.78 | E15: ='AAC Benefits'!$C$15*E7 -> 697214.78 | F15: ='AAC Benefits'!$C$15*F7 -> 697214.78 | G15: ='AAC Benefits'!$C$15*G7 -> 697214.78 | I15: =SUMPRODUCT(B15:G15,B5:G5) -> 2250031.3
A16: AAC internal cost | B16: =Inputs!$B$93 -> 12000 | C16: =Inputs!$B$93 -> 12000 | D16: =Inputs!$B$93 -> 12000 | E16: =Inputs!$B$93 -> 12000 | F16: =Inputs!$B$93 -> 12000 | G16: =Inputs!$B$93 -> 12000 | I16: =SUMPRODUCT(B16:G16,B5:G5) -> 49526.052
A18: MODEL A - Fixed-price project + annual managed service
A19: Implementation fee (one-off) | B19: =Costs!$D$38*(1+Inputs!$B$104*Inputs!$B$103) -> 708664.69 | C19: 0 | D19: 0 | E19: 0 | F19: 0 | G19: 0 | I19: =SUMPRODUCT(B19:G19,B5:G5) -> 708664.69
A20: Managed service fee | B20: =Costs!$D$52*(1+Inputs!$B$105*Inputs!$B$103)*B6 -> 90023.213 | C20: =Costs!$D$52*(1+Inputs!$B$105*Inputs!$B$103)*C6 -> 360092.85 | D20: =Costs!$D$52*(1+Inputs!$B$105*Inputs!$B$103)*D6 -> 360092.85 | E20: =Costs!$D$52*(1+Inputs!$B$105*Inputs!$B$103)*E6 -> 360092.85 | F20: =Costs!$D$52*(1+Inputs!$B$105*Inputs!$B$103)*F6 -> 360092.85 | G20: =Costs!$D$52*(1+Inputs!$B$105*Inputs!$B$103)*G6 -> 360092.85 | I20: =SUMPRODUCT(B20:G20,B5:G5) -> 1216095.1
A21: Smart Innovations GH revenue | B21: =B19+B20 -> 798687.9 | C21: =C19+C20 -> 360092.85 | D21: =D19+D20 -> 360092.85 | E21: =E19+E20 -> 360092.85 | F21: =F19+F20 -> 360092.85 | G21: =G19+G20 -> 360092.85 | I21: =SUMPRODUCT(B21:G21,B5:G5) -> 1924759.8
A22: Smart Innovations GH profit (revenue - delivery cost) | B22: =B21-B13 -> 162507.53 | C22: =C21-C13 -> 83098.35 | D22: =D21-D13 -> 83098.35 | E22: =E21-E13 -> 83098.35 | F22: =F21-F13 -> 83098.35 | G22: =G21-G13 -> 83098.35 | I22: =SUMPRODUCT(B22:G22,B5:G5) -> 422370.28
A23: Cumulative profit | B23: =B22 -> 162507.53 | C23: =B23+C22 -> 245605.88 | D23: =C23+D22 -> 328704.23 | E23: =D23+E22 -> 411802.58 | F23: =E23+F22 -> 494900.93 | G23: =F23+G22 -> 577999.28
A24: AAC net benefit (benefits - fees - internal cost) | B24: =B14-B21-B16 -> -725526.42 | C24: =C14-C21-C16 -> 479521.93 | D24: =D14-D21-D16 -> 479521.93 | E24: =E14-E21-E16 -> 479521.93 | F24: =F14-F21-F16 -> 479521.93 | G24: =G14-G21-G16 -> 479521.93 | I24: =SUMPRODUCT(B24:G24,B5:G5) -> 774020.66
A25: AAC cumulative net benefit | B25: =B24 -> -725526.42 | C25: =B25+C24 -> -246004.49 | D25: =C25+D24 -> 233517.44 | E25: =D25+E24 -> 713039.37 | F25: =E25+F24 -> 1192561.3 | G25: =F25+G24 -> 1672083.2
A26: Smart Innovations GH 5-yr revenue | I26: =SUM(B21:G21) -> 2599152.2
A27: Smart Innovations GH gross margin | I27: =IFERROR(SUM(B22:G22)/SUM(B21:G21),0) -> 0.22237993
A28: Smart Innovations GH IRR | I28: =IFERROR(IRR(B22:G22),"n/a - costs recovered upfront") -> n/a - costs recovered upfront
A29: Smart Innovations GH payback | I29: =IF(COUNTIF(B23:G23,"<0")>5,"Beyond Year 5",IF(COUNTIF(B23:G23,"<0")=0,"Year 0","Year "&COUNTIF(B23:G23,"<0"))) -> Year 0
A30: AAC payback | I30: =IF(COUNTIF(B25:G25,"<0")>5,"Beyond Year 5",IF(COUNTIF(B25:G25,"<0")=0,"Year 0","Year "&COUNTIF(B25:G25,"<0"))) -> Year 2
A31: AAC return on fees (NPV net benefit / NPV fees) | I31: =IFERROR(I24/I21,0) -> 0.40213883
A33: MODEL B - Monitoring-as-a-Service subscription (Smart Innovations GH funds hardware)
A34: Onboarding fee | B34: =Costs!$D$38*Inputs!$B$110 -> 85039.762 | C34: 0 | D34: 0 | E34: 0 | F34: 0 | G34: 0 | I34: =SUMPRODUCT(B34:G34,B5:G5) -> 85039.762
A35: Subscription fees | B35: =(Costs!$B$7*Inputs!$B$106+Costs!$B$8*Inputs!$B$107+Inputs!$B$7*Inputs!$B$108+Inputs!$B$109)*12*Inputs!$B$103*B8 -> 50064 | C35: =(Costs!$B$7*Inputs!$B$106+Costs!$B$8*Inputs!$B$107+Inputs!$B$7*Inputs!$B$108+Inputs!$B$109)*12*Inputs!$B$103*C8 -> 500640 | D35: =(Costs!$B$7*Inputs!$B$106+Costs!$B$8*Inputs!$B$107+Inputs!$B$7*Inputs!$B$108+Inputs!$B$109)*12*Inputs!$B$103*D8 -> 500640 | E35: =(Costs!$B$7*Inputs!$B$106+Costs!$B$8*Inputs!$B$107+Inputs!$B$7*Inputs!$B$108+Inputs!$B$109)*12*Inputs!$B$103*E8 -> 500640 | F35: =(Costs!$B$7*Inputs!$B$106+Costs!$B$8*Inputs!$B$107+Inputs!$B$7*Inputs!$B$108+Inputs!$B$109)*12*Inputs!$B$103*F8 -> 500640 | G35: =(Costs!$B$7*Inputs!$B$106+Costs!$B$8*Inputs!$B$107+Inputs!$B$7*Inputs!$B$108+Inputs!$B$109)*12*Inputs!$B$103*G8 -> 500640 | I35: =SUMPRODUCT(B35:G35,B5:G5) -> 1615650.9
A36: Smart Innovations GH revenue | B36: =B34+B35 -> 135103.76 | C36: =C34+C35 -> 500640 | D36: =D34+D35 -> 500640 | E36: =E34+E35 -> 500640 | F36: =F34+F35 -> 500640 | G36: =G34+G35 -> 500640 | I36: =SUMPRODUCT(B36:G36,B5:G5) -> 1700690.7
A37: Smart Innovations GH profit (revenue - delivery cost) | B37: =B36-B13 -> -501076.61 | C37: =C36-C13 -> 223645.5 | D37: =D36-D13 -> 223645.5 | E37: =E36-E13 -> 223645.5 | F37: =F36-F13 -> 223645.5 | G37: =G36-G13 -> 223645.5 | I37: =SUMPRODUCT(B37:G37,B5:G5) -> 198301.11
A38: Cumulative profit | B38: =B37 -> -501076.61 | C38: =B38+C37 -> -277431.11 | D38: =C38+D37 -> -53785.615 | E38: =D38+E37 -> 169859.88 | F38: =E38+F37 -> 393505.38 | G38: =F38+G37 -> 617150.88
A39: AAC net benefit (benefits - fees - internal cost) | B39: =B14-B36-B16 -> -61942.284 | C39: =C14-C36-C16 -> 338974.78 | D39: =D14-D36-D16 -> 338974.78 | E39: =E14-E36-E16 -> 338974.78 | F39: =F14-F36-F16 -> 338974.78 | G39: =G14-G36-G16 -> 338974.78 | I39: =SUMPRODUCT(B39:G39,B5:G5) -> 998089.83
A40: AAC cumulative net benefit | B40: =B39 -> -61942.284 | C40: =B40+C39 -> 277032.5 | D40: =C40+D39 -> 616007.28 | E40: =D40+E39 -> 954982.06 | F40: =E40+F39 -> 1293956.8 | G40: =F40+G39 -> 1632931.6
A41: Smart Innovations GH 5-yr revenue | I41: =SUM(B36:G36) -> 2638303.8
A42: Smart Innovations GH gross margin | I42: =IFERROR(SUM(B37:G37)/SUM(B36:G36),0) -> 0.23391957
A43: Smart Innovations GH IRR | I43: =IFERROR(IRR(B37:G37),"n/a - costs recovered upfront") -> 0.34488506
A44: Smart Innovations GH payback | I44: =IF(COUNTIF(B38:G38,"<0")>5,"Beyond Year 5",IF(COUNTIF(B38:G38,"<0")=0,"Year 0","Year "&COUNTIF(B38:G38,"<0"))) -> Year 3
...

Sheet Scenario Engine
A1: Scenario engine - full model recomputed per column (do not edit; change Inputs or Sensitivity)
A3: Scenario | B3: Base | C3: Concessions in rollout - low | D3: Concessions in rollout - high | E3: Hardware cost multiplier - low | F3: Hardware cost multiplier - high | G3: Implementation services multiplier - low | H3: Implementation services multiplier - high | I3: Annual opex multiplier - low | J3: Annual opex multiplier - high | K3: Diesel price ($/L) - low | L3: Diesel price ($/L) - high | M3: Excavator fuel saving % - low | N3: Excavator fuel saving % - high | O3: Gold price ($/oz) - low | P3: Gold price ($/oz) - high | Q3: Extra feed secured (% of feed) - low | R3: Extra feed secured (% of feed) - high | S3: Tailings grade (g/t) - low | T3: Tailings grade (g/t) - high | U3: Discount rate - low | V3: Discount rate - high | W3: Pricing multiplier (fees / margins) - low | X3: Pricing multiplier (fees / margins) - high | Y3: Bear scenario | Z3: Bull scenario
A4: Concessions in rollout | B4: =Inputs!$B$7 -> 8 | C4: =Sensitivity!$C$5 -> 4 | D4: =Sensitivity!$D$5 -> 10 | E4: =Inputs!$B$7 -> 8 | F4: =Inputs!$B$7 -> 8 | G4: =Inputs!$B$7 -> 8 | H4: =Inputs!$B$7 -> 8 | I4: =Inputs!$B$7 -> 8 | J4: =Inputs!$B$7 -> 8 | K4: =Inputs!$B$7 -> 8 | L4: =Inputs!$B$7 -> 8 | ... X4: =Inputs!$B$7 -> 8 | Y4: =Sensitivity!$E$5 -> 5 | Z4: =Sensitivity!$F$5 -> 10
A5: Hardware cost multiplier | B5: =Inputs!$B$30 -> 1 | C5: =Inputs!$B$30 -> 1 | D5: =Inputs!$B$30 -> 1 | E5: =Sensitivity!$C$6 -> 0.8 | F5: =Sensitivity!$D$6 -> 1.3 | G5: =Inputs!$B$30 -> 1 | H5: =Inputs!$B$30 -> 1 | I5: =Inputs!$B$30 -> 1 | J5: =Inputs!$B$30 -> 1 | K5: =Inputs!$B$30 -> 1 | L5: =Inputs!$B$30 -> 1 | M5: =Inputs!$B$30 -> 1 | N5: =Inputs!$B$30 -> 1 | ... X5: =Inputs!$B$30 -> 1 | Y5: =Sensitivity!$E$6 -> 1.2 | Z5: =Sensitivity!$F$6 -> 0.9
A6: Implementation services multiplier | B6: =Inputs!$B$50 -> 1 | C6: =Inputs!$B$50 -> 1 | D6: =Inputs!$B$50 -> 1 | E6: =Inputs!$B$50 -> 1 | F6: =Inputs!$B$50 -> 1 | G6: =Sensitivity!$C$7 -> 0.85 | H6: =Sensitivity!$D$7 -> 1.25 | I6: =Inputs!$B$50 -> 1 | J6: =Inputs!$B$50 -> 1 | K6: =Inputs!$B$50 -> 1 | L6: =Inputs!$B$50 -> 1 | M6: =Inputs!$B$50 -> 1 | N6: =Inputs!$B$50 -> 1 | O6: =Inputs!$B$50 -> 1 | P6: =Inputs!$B$50 -> 1 | ... X6: =Inputs!$B$50 -> 1 | Y6: =Sensitivity!$E$7 -> 1.15 | Z6: =Sensitivity!$F$7 -> 0.95
A7: Annual opex multiplier | B7: =Inputs!$B$73 -> 1 | C7: =Inputs!$B$73 -> 1 | D7: =Inputs!$B$73 -> 1 | E7: =Inputs!$B$73 -> 1 | F7: =Inputs!$B$73 -> 1 | G7: =Inputs!$B$73 -> 1 | H7: =Inputs!$B$73 -> 1 | I7: =Sensitivity!$C$8 -> 0.85 | J7: =Sensitivity!$D$8 -> 1.25 | K7: =Inputs!$B$73 -> 1 | L7: =Inputs!$B$73 -> 1 | M7: =Inputs!$B$73 -> 1 | N7: =Inputs!$B$73 -> 1 | O7: =Inputs!$B$73 -> 1 | P7: =Inputs!$B$73 -> 1 | Q7: =Inputs!$B$73 -> 1 | R7: =Inputs!$B$73 -> 1 | ... X7: =Inputs!$B$73 -> 1 | Y7: =Sensitivity!$E$8 -> 1.15 | Z7: =Sensitivity!$F$8 -> 0.95
A8: Diesel price ($/L) | B8: =Inputs!$B$79 -> 0.85 | C8: =Inputs!$B$79 -> 0.85 | D8: =Inputs!$B$79 -> 0.85 | E8: =Inputs!$B$79 -> 0.85 | F8: =Inputs!$B$79 -> 0.85 | G8: =Inputs!$B$79 -> 0.85 | H8: =Inputs!$B$79 -> 0.85 | I8: =Inputs!$B$79 -> 0.85 | J8: =Inputs!$B$79 -> 0.85 | K8: =Sensitivity!$C$9 -> 0.65 | L8: =Sensitivity!$D$9 -> 1.1 | M8: =Inputs!$B$79 -> 0.85 | N8: =Inputs!$B$79 -> 0.85 | O8: =Inputs!$B$79 -> 0.85 | P8: =Inputs!$B$79 -> 0.85 | Q8: =Inputs!$B$79 -> 0.85 | R8: =Inputs!$B$79 -> 0.85 | S8: =Inputs!$B$79 -> 0.85 | T8: =Inputs!$B$79 -> 0.85 | ... X8: =Inputs!$B$79 -> 0.85 | Y8: =Sensitivity!$E$9 -> 0.75 | Z8: =Sensitivity!$F$9 -> 1
A9: Excavator fuel saving % | B9: =Inputs!$B$80 -> 0.12 | C9: =Inputs!$B$80 -> 0.12 | D9: =Inputs!$B$80 -> 0.12 | E9: =Inputs!$B$80 -> 0.12 | F9: =Inputs!$B$80 -> 0.12 | G9: =Inputs!$B$80 -> 0.12 | H9: =Inputs!$B$80 -> 0.12 | I9: =Inputs!$B$80 -> 0.12 | ... L9: =Inputs!$B$80 -> 0.12 | M9: =Sensitivity!$C$10 -> 0.06 | N9: =Sensitivity!$D$10 -> 0.18 | O9: =Inputs!$B$80 -> 0.12 | P9: =Inputs!$B$80 -> 0.12 | Q9: =Inputs!$B$80 -> 0.12 | R9: =Inputs!$B$80 -> 0.12 | S9: =Inputs!$B$80 -> 0.12 | T9: =Inputs!$B$80 -> 0.12 | U9: =Inputs!$B$80 -> 0.12 | V9: =Inputs!$B$80 -> 0.12 | ... X9: =Inputs!$B$80 -> 0.12 | Y9: =Sensitivity!$E$10 -> 0.08 | Z9: =Sensitivity!$F$10 -> 0.15
A10: Gold price ($/oz) | B10: =Inputs!$B$86 -> 3500 | C10: =Inputs!$B$86 -> 3500 | D10: =Inputs!$B$86 -> 3500 | E10: =Inputs!$B$86 -> 3500 | F10: =Inputs!$B$86 -> 3500 | G10: =Inputs!$B$86 -> 3500 | H10: =Inputs!$B$86 -> 3500 | I10: =Inputs!$B$86 -> 3500 | ... N10: =Inputs!$B$86 -> 3500 | O10: =Sensitivity!$C$11 -> 2800 | P10: =Sensitivity!$D$11 -> 4200 | Q10: =Inputs!$B$86 -> 3500 | R10: =Inputs!$B$86 -> 3500 | S10: =Inputs!$B$86 -> 3500 | T10: =Inputs!$B$86 -> 3500 | U10: =Inputs!$B$86 -> 3500 | V10: =Inputs!$B$86 -> 3500 | W10: =Inputs!$B$86 -> 3500 | X10: =Inputs!$B$86 -> 3500 | Y10: =Sensitivity!$E$11 -> 3000 | Z10: =Sensitivity!$F$11 -> 4000
A11: Extra feed secured (% of feed) | B11: =Inputs!$B$83 -> 0.03 | C11: =Inputs!$B$83 -> 0.03 | D11: =Inputs!$B$83 -> 0.03 | E11: =Inputs!$B$83 -> 0.03 | F11: =Inputs!$B$83 -> 0.03 | G11: =Inputs!$B$83 -> 0.03 | H11: =Inputs!$B$83 -> 0.03 | I11: =Inputs!$B$83 -> 0.03 | ... P11: =Inputs!$B$83 -> 0.03 | Q11: =Sensitivity!$C$12 -> 0.01 | R11: =Sensitivity!$D$12 -> 0.05 | S11: =Inputs!$B$83 -> 0.03 | T11: =Inputs!$B$83 -> 0.03 | U11: =Inputs!$B$83 -> 0.03 | V11: =Inputs!$B$83 -> 0.03 | W11: =Inputs!$B$83 -> 0.03 | X11: =Inputs!$B$83 -> 0.03 | Y11: =Sensitivity!$E$12 -> 0.015 | Z11: =Sensitivity!$F$12 -> 0.04
A12: Tailings grade (g/t) | B12: =Inputs!$B$84 -> 1.2 | C12: =Inputs!$B$84 -> 1.2 | D12: =Inputs!$B$84 -> 1.2 | E12: =Inputs!$B$84 -> 1.2 | F12: =Inputs!$B$84 -> 1.2 | G12: =Inputs!$B$84 -> 1.2 | H12: =Inputs!$B$84 -> 1.2 | I12: =Inputs!$B$84 -> 1.2 | ... R12: =Inputs!$B$84 -> 1.2 | S12: =Sensitivity!$C$13 -> 0.8 | T12: =Sensitivity!$D$13 -> 1.6 | U12: =Inputs!$B$84 -> 1.2 | V12: =Inputs!$B$84 -> 1.2 | W12: =Inputs!$B$84 -> 1.2 | X12: =Inputs!$B$84 -> 1.2 | Y12: =Sensitivity!$E$13 -> 1 | Z12: =Sensitivity!$F$13 -> 1.4
A13: Discount rate | B13: =Inputs!$B$96 -> 0.18 | C13: =Inputs!$B$96 -> 0.18 | D13: =Inputs!$B$96 -> 0.18 | E13: =Inputs!$B$96 -> 0.18 | F13: =Inputs!$B$96 -> 0.18 | G13: =Inputs!$B$96 -> 0.18 | H13: =Inputs!$B$96 -> 0.18 | I13: =Inputs!$B$96 -> 0.18 | ... T13: =Inputs!$B$96 -> 0.18 | U13: =Sensitivity!$C$14 -> 0.14 | V13: =Sensitivity!$D$14 -> 0.24 | W13: =Inputs!$B$96 -> 0.18 | X13: =Inputs!$B$96 -> 0.18 | Y13: =Sensitivity!$E$14 -> 0.22 | Z13: =Sensitivity!$F$14 -> 0.15
A14: Pricing multiplier (fees / margins) | B14: =Inputs!$B$103 -> 1 | C14: =Inputs!$B$103 -> 1 | D14: =Inputs!$B$103 -> 1 | E14: =Inputs!$B$103 -> 1 | F14: =Inputs!$B$103 -> 1 | G14: =Inputs!$B$103 -> 1 | H14: =Inputs!$B$103 -> 1 | I14: =Inputs!$B$103 -> 1 | ... V14: =Inputs!$B$103 -> 1 | W14: =Sensitivity!$C$15 -> 0.8 | X14: =Sensitivity!$D$15 -> 1.2 | Y14: =Sensitivity!$E$15 -> 1 | Z14: =Sensitivity!$F$15 -> 1
A15: Annuity factor, Years 1-5 | B15: =(1-(1+B13)^-Inputs!$B$97)/B13 -> 3.127171 | C15: =(1-(1+C13)^-Inputs!$B$97)/C13 -> 3.127171 | D15: =(1-(1+D13)^-Inputs!$B$97)/D13 -> 3.127171 | E15: =(1-(1+E13)^-Inputs!$B$97)/E13 -> 3.127171 | F15: =(1-(1+F13)^-Inputs!$B$97)/F13 -> 3.127171 | G15: =(1-(1+G13)^-Inputs!$B$97)/G13 -> 3.127171 | H15: =(1-(1+H13)^-Inputs!$B$97)/H13 -> 3.127171 | I15: =(1-(1+I13)^-Inputs!$B$97)/I13 -> 3.127171 | ... Z15: =(1-(1+Z13)^-Inputs!$B$97)/Z13 -> 3.3521551
A16: Excavators | B16: =B4*Inputs!$B$9 -> 16 | C16: =C4*Inputs!$B$9 -> 8 | D16: =D4*Inputs!$B$9 -> 20 | E16: =E4*Inputs!$B$9 -> 16 | F16: =F4*Inputs!$B$9 -> 16 | G16: =G4*Inputs!$B$9 -> 16 | H16: =H4*Inputs!$B$9 -> 16 | I16: =I4*Inputs!$B$9 -> 16 | ... Z16: =Z4*Inputs!$B$9 -> 20
A17: Trucks | B17: =B4*Inputs!$B$10 -> 24 | C17: =C4*Inputs!$B$10 -> 12 | D17: =D4*Inputs!$B$10 -> 30 | E17: =E4*Inputs!$B$10 -> 24 | F17: =F4*Inputs!$B$10 -> 24 | G17: =G4*Inputs!$B$10 -> 24 | H17: =H4*Inputs!$B$10 -> 24 | I17: =I4*Inputs!$B$10 -> 24 | ... Z17: =Z4*Inputs!$B$10 -> 30
A18: Fuel points | B18: =B4+1 -> 9 | C18: =C4+1 -> 5 | D18: =D4+1 -> 11 | E18: =E4+1 -> 9 | F18: =F4+1 -> 9 | G18: =G4+1 -> 9 | H18: =H4+1 -> 9 | I18: =I4+1 -> 9 | ... Z18: =Z4+1 -> 11
A19: Gateway sites | B19: =ROUND(B4*Inputs!$B$12,0) -> 5 | C19: =ROUND(C4*Inputs!$B$12,0) -> 2 | D19: =ROUND(D4*Inputs!$B$12,0) -> 6 | E19: =ROUND(E4*Inputs!$B$12,0) -> 5 | F19: =ROUND(F4*Inputs!$B$12,0) -> 5 | G19: =ROUND(G4*Inputs!$B$12,0) -> 5 | H19: =ROUND(H4*Inputs!$B$12,0) -> 5 | I19: =ROUND(I4*Inputs!$B$12,0) -> 5 | ... Z19: =ROUND(Z4*Inputs!$B$12,0) -> 6
A20: Drone kits | B20: =IF(B4>Inputs!$B$13,2,1) -> 2 | C20: =IF(C4>Inputs!$B$13,2,1) -> 1 | D20: =IF(D4>Inputs!$B$13,2,1) -> 2 | E20: =IF(E4>Inputs!$B$13,2,1) -> 2 | F20: =IF(F4>Inputs!$B$13,2,1) -> 2 | G20: =IF(G4>Inputs!$B$13,2,1) -> 2 | H20: =IF(H4>Inputs!$B$13,2,1) -> 2 | I20: =IF(I4>Inputs!$B$13,2,1) -> 2 | ... Z20: =IF(Z4>Inputs!$B$13,2,1) -> 2
A21: Connected devices | B21: =B16+B17+B18 -> 49 | C21: =C16+C17+C18 -> 25 | D21: =D16+D17+D18 -> 61 | E21: =E16+E17+E18 -> 49 | F21: =F16+F17+F18 -> 49 | G21: =G16+G17+G18 -> 49 | H21: =H16+H17+H18 -> 49 | I21: =I16+I17+I18 -> 49 | ... Z21: =Z16+Z17+Z18 -> 61
A22: Rugged phones | B22: =B4+Inputs!$B$11 -> 10 | C22: =C4+Inputs!$B$11 -> 6 | D22: =D4+Inputs!$B$11 -> 12 | E22: =E4+Inputs!$B$11 -> 10 | F22: =F4+Inputs!$B$11 -> 10 | G22: =G4+Inputs!$B$11 -> 10 | H22: =H4+Inputs!$B$11 -> 10 | I22: =I4+Inputs!$B$11 -> 10 | ... Z22: =Z4+Inputs!$B$11 -> 12
A23: Hardware at supplier price | B23: =B16*(Inputs!$B$16+Inputs!$B$17)+B18*(Inputs!$B$18+Inputs!$B$19*Inputs!$B$20)+B17*(Inputs!$B$21+Inputs!$B$22)+Inputs!$B$23+B19*Inputs!$B$24+B20*Inputs!$B$25+B22*Inputs!$B$26+Inputs!$B$27 -> 136350 | C23: =C16*(Inputs!$B$16+Inputs!$B$17)+C18*(Inputs!$B$18+Inputs!$B$19*Inputs!$B$20)+C17*(Inputs!$B$21+Inputs!$B$22)+Inputs!$B$23+C19*Inputs!$B$24+C20*Inputs!$B$25+C22*Inputs!$B$26+Inputs!$B$27 -> 74650 | D23: =D16*(Inputs!$B$16+Inputs!$B$17)+D18*(Inputs!$B$18+Inputs!$B$19*Inputs!$B$20)+D17*(Inputs!$B$21+Inputs!$B$22)+Inputs!$B$23+D19*Inputs!$B$24+D20*Inputs!$B$25+D22*Inputs!$B$26+Inputs!$B$27 -> 157450 | E23: =E16*(Inputs!$B$16+Inputs!$B$17)+E18*(Inputs!$B$18+Inputs!$B$19*Inputs!$B$20)+E17*(Inputs!$B$21+Inputs!$B$22)+Inputs!$B$23+E19*Inputs!$B$24+E20*Inputs!$B$25+E22*Inputs!$B$26+Inputs!$B$27 -> 136350 | F23: =F16*(Inputs!$B$16+Inputs!$B$17)+F18*(Inputs!$B$18+Inputs!$B$19*Inputs!$B$20)+F17*(Inputs!$B$21+Inputs!$B$22)+Inputs!$B$23+F19*Inputs!$B$24+F20*Inputs!$B$25+F22*Inputs!$B$26+Inputs!$B$27 -> 136350 | G23: =G16*(Inputs!$B$16+Inputs!$B$17)+G18*(Inputs!$B$18+Inputs!$B$19*Inputs!$B$20)+G17*(Inputs!$B$21+Inputs!$B$22)+Inputs!$B$23+G19*Inputs!$B$24+G20*Inputs!$B$25+G22*Inputs!$B$26+Inputs!$B$27 -> 136350 | H23: =H16*(Inputs!$B$16+Inputs!$B$17)+H18*(Inputs!$B$18+Inputs!$B$19*Inputs!$B$20)+H17*(Inputs!$B$21+Inputs!$B$22)+Inputs!$B$23+H19*Inputs!$B$24+H20*Inputs!$B$25+H22*Inputs!$B$26+Inputs!$B$27 -> 136350 | I23: =I16*(Inputs!$B$16+Inputs!$B$17)+I18*(Inputs!$B$18+Inputs!$B$19*Inputs!$B$20)+I17*(Inputs!$B$21+Inputs!$B$22)+Inputs!$B$23+I19*Inputs!$B$24+I20*Inputs!$B$25+I22*Inputs!$B$26+Inputs!$B$27 -> 136350 | ... Z23: =Z16*(Inputs!$B$16+Inputs!$B$17)+Z18*(Inputs!$B$18+Inputs!$B$19*Inputs!$B$20)+Z17*(Inputs!$B$21+Inputs!$B$22)+Inputs!$B$23+Z19*Inputs!$B$24+Z20*Inputs!$B$25+Z22*Inputs!$B$26+Inputs!$B$27 -> 157450
A24: Landed hardware | B24: =B23*B5*(1+Inputs!$B$28) -> 184072.5 | C24: =C23*C5*(1+Inputs!$B$28) -> 100777.5 | D24: =D23*D5*(1+Inputs!$B$28) -> 212557.5 | E24: =E23*E5*(1+Inputs!$B$28) -> 147258 | F24: =F23*F5*(1+Inputs!$B$28) -> 239294.25 | G24: =G23*G5*(1+Inputs!$B$28) -> 184072.5 | H24: =H23*H5*(1+Inputs!$B$28) -> 184072.5 | I24: =I23*I5*(1+Inputs!$B$28) -> 184072.5 | ... Z24: =Z23*Z5*(1+Inputs!$B$28) -> 191301.75
A25: Installation | B25: =(2*B16+2*B17+B18+B19)*Inputs!$B$29 -> 7520 | C25: =(2*C16+2*C17+C18+C19)*Inputs!$B$29 -> 3760 | D25: =(2*D16+2*D17+D18+D19)*Inputs!$B$29 -> 9360 | E25: =(2*E16+2*E17+E18+E19)*Inputs!$B$29 -> 7520 | F25: =(2*F16+2*F17+F18+F19)*Inputs!$B$29 -> 7520 | G25: =(2*G16+2*G17+G18+G19)*Inputs!$B$29 -> 7520 | H25: =(2*H16+2*H17+H18+H19)*Inputs!$B$29 -> 7520 | I25: =(2*I16+2*I17+I18+I19)*Inputs!$B$29 -> 7520 | ... Z25: =(2*Z16+2*Z17+Z18+Z19)*Inputs!$B$29 -> 9360
A26: Implementation services | B26: =(Inputs!$E$44+B4*(Inputs!$B$46+Inputs!$B$47+Inputs!$B$48))*B6 -> 323800 | C26: =(Inputs!$E$44+C4*(Inputs!$B$46+Inputs!$B$47+Inputs!$B$48))*C6 -> 279800 | D26: =(Inputs!$E$44+D4*(Inputs!$B$46+Inputs!$B$47+Inputs!$B$48))*D6 -> 345800 | E26: =(Inputs!$E$44+E4*(Inputs!$B$46+Inputs!$B$47+Inputs!$B$48))*E6 -> 323800 | F26: =(Inputs!$E$44+F4*(Inputs!$B$46+Inputs!$B$47+Inputs!$B$48))*F6 -> 323800 | G26: =(Inputs!$E$44+G4*(Inputs!$B$46+Inputs!$B$47+Inputs!$B$48))*G6 -> 275230 | H26: =(Inputs!$E$44+H4*(Inputs!$B$46+Inputs!$B$47+Inputs!$B$48))*H6 -> 404750 | I26: =(Inputs!$E$44+I4*(Inputs!$B$46+Inputs!$B$47+Inputs!$B$48))*I6 -> 323800 | ... Z26: =(Inputs!$E$44+Z4*(Inputs!$B$46+Inputs!$B$47+Inputs!$B$48))*Z6 -> 328510
A27: One-off cost | B27: =(B24+B25+B26)*(1+Inputs!$B$49) -> 566931.75 | C27: =(C24+C25+C26)*(1+Inputs!$B$49) -> 422771.25 | D27: =(D24+D25+D26)*(1+Inputs!$B$49) -> 624489.25 | E27: =(E24+E25+E26)*(1+Inputs!$B$49) -> 526435.8 | F27: =(F24+F25+F26)*(1+Inputs!$B$49) -> 627675.68 | G27: =(G24+G25+G26)*(1+Inputs!$B$49) -> 513504.75 | H27: =(H24+H25+H26)*(1+Inputs!$B$49) -> 655976.75 | I27: =(I24+I25+I26)*(1+Inputs!$B$49) -> 566931.75 | ... Z27: =(Z24+Z25+Z26)*(1+Inputs!$B$49) -> 582088.93
A28: Annual opex | B28: =(Inputs!$B$53+B21*Inputs!$B$54+B21*12*Inputs!$B$55+B19*12*Inputs!$B$56+Inputs!$B$57+B4*Inputs!$B$58*Inputs!$B$59+B4*Inputs!$B$60+Inputs!$E$67+B24*Inputs!$B$68+B17*Inputs!$B$69*Inputs!$B$70*Inputs!$B$71)*B7*(1+Inputs!$B$72) -> 276994.5 | C28: =(Inputs!$B$53+C21*Inputs!$B$54+C21*12*Inputs!$B$55+C19*12*Inputs!$B$56+Inputs!$B$57+C4*Inputs!$B$58*Inputs!$B$59+C4*Inputs!$B$60+Inputs!$E$67+C24*Inputs!$B$68+C17*Inputs!$B$69*Inputs!$B$70*Inputs!$B$71)*C7*(1+Inputs!$B$72) -> 193602.2 | D28: =(Inputs!$B$53+D21*Inputs!$B$54+D21*12*Inputs!$B$55+D19*12*Inputs!$B$56+Inputs!$B$57+D4*Inputs!$B$58*Inputs!$B$59+D4*Inputs!$B$60+Inputs!$E$67+D24*Inputs!$B$68+D17*Inputs!$B$69*Inputs!$B$70*Inputs!$B$71)*D7*(1+Inputs!$B$72) -> 316136.77 | E28: =(Inputs!$B$53+E21*Inputs!$B$54+E21*12*Inputs!$B$55+E19*12*Inputs!$B$56+Inputs!$B$57+E4*Inputs!$B$58*Inputs!$B$59+E4*Inputs!$B$60+Inputs!$E$67+E24*Inputs!$B$68+E17*Inputs!$B$69*Inputs!$B$70*Inputs!$B$71)*E7*(1+Inputs!$B$72) -> 272444.23 | F28: =(Inputs!$B$53+F21*Inputs!$B$54+F21*12*Inputs!$B$55+F19*12*Inputs!$B$56+Inputs!$B$57+F4*Inputs!$B$58*Inputs!$B$59+F4*Inputs!$B$60+Inputs!$E$67+F24*Inputs!$B$68+F17*Inputs!$B$69*Inputs!$B$70*Inputs!$B$71)*F7*(1+Inputs!$B$72) -> 283819.91 | G28: =(Inputs!$B$53+G21*Inputs!$B$54+G21*12*Inputs!$B$55+G19*12*Inputs!$B$56+Inputs!$B$57+G4*Inputs!$B$58*Inputs!$B$59+G4*Inputs!$B$60+Inputs!$E$67+G24*Inputs!$B$68+G17*Inputs!$B$69*Inputs!$B$70*Inputs!$B$71)*G7*(1+Inputs!$B$72) -> 276994.5 | H28: =(Inputs!$B$53+H21*Inputs!$B$54+H21*12*Inputs!$B$55+H19*12*Inputs!$B$56+Inputs!$B$57+H4*Inputs!$B$58*Inputs!$B$59+H4*Inputs!$B$60+Inputs!$E$67+H24*Inputs!$B$68+H17*Inputs!$B$69*Inputs!$B$70*Inputs!$B$71)*H7*(1+Inputs!$B$72) -> 276994.5 | I28: =(Inputs!$B$53+I21*Inputs!$B$54+I21*12*Inputs!$B$55+I19*12*Inputs!$B$56+Inputs!$B$57+I4*Inputs!$B$58*Inputs!$B$59+I4*Inputs!$B$60+Inputs!$E$67+I24*Inputs!$B$68+I17*Inputs!$B$69*Inputs!$B$70*Inputs!$B$71)*I7*(1+Inputs!$B$72) -> 235445.33 | ... Z28: =(Inputs!$B$53+Z21*Inputs!$B$54+Z21*12*Inputs!$B$55+Z19*12*Inputs!$B$56+Inputs!$B$57+Z4*Inputs!$B$58*Inputs!$B$59+Z4*Inputs!$B$60+Inputs!$E$67+Z24*Inputs!$B$68+Z17*Inputs!$B$69*Inputs!$B$70*Inputs!$B$71)*Z7*(1+Inputs!$B$72) -> 297834.08
A29: Fuel savings (excavators + trucks) | B29: =(B16*Inputs!$B$76*Inputs!$B$77*B9+B17*Inputs!$B$78*Inputs!$B$70*Inputs!$B$81)*B8 -> 116280 | C29: =(C16*Inputs!$B$76*Inputs!$B$77*C9+C17*Inputs!$B$78*Inputs!$B$70*Inputs!$B$81)*C8 -> 58140 | D29: =(D16*Inputs!$B$76*Inputs!$B$77*D9+D17*Inputs!$B$78*Inputs!$B$70*Inputs!$B$81)*D8 -> 145350 | E29: =(E16*Inputs!$B$76*Inputs!$B$77*E9+E17*Inputs!$B$78*Inputs!$B$70*Inputs!$B$81)*E8 -> 116280 | F29: =(F16*Inputs!$B$76*Inputs!$B$77*F9+F17*Inputs!$B$78*Inputs!$B$70*Inputs!$B$81)*F8 -> 116280 | G29: =(G16*Inputs!$B$76*Inputs!$B$77*G9+G17*Inputs!$B$78*Inputs!$B$70*Inputs!$B$81)*G8 -> 116280 | H29: =(H16*Inputs!$B$76*Inputs!$B$77*H9+H17*Inputs!$B$78*Inputs!$B$70*Inputs!$B$81)*H8 -> 116280 | I29: =(I16*Inputs!$B$76*Inputs!$B$77*I9+I17*Inputs!$B$78*Inputs!$B$70*Inputs!$B$81)*I8 -> 116280 | ... Z29: =(Z16*Inputs!$B$76*Inputs!$B$77*Z9+Z17*Inputs!$B$78*Inputs!$B$70*Inputs!$B$81)*Z8 -> 207000
A30: AAC margin on extra gold | B30: =B4*Inputs!$B$82*B11*B12*Inputs!$B$85/31.1035*B10*Inputs!$B$87 -> 550934.78 | C30: =C4*Inputs!$B$82*C11*C12*Inputs!$B$85/31.1035*C10*Inputs!$B$87 -> 275467.39 | D30: =D4*Inputs!$B$82*D11*D12*Inputs!$B$85/31.1035*D10*Inputs!$B$87 -> 688668.48 | E30: =E4*Inputs!$B$82*E11*E12*Inputs!$B$85/31.1035*E10*Inputs!$B$87 -> 550934.78 | F30: =F4*Inputs!$B$82*F11*F12*Inputs!$B$85/31.1035*F10*Inputs!$B$87 -> 550934.78 | G30: =G4*Inputs!$B$82*G11*G12*Inputs!$B$85/31.1035*G10*Inputs!$B$87 -> 550934.78 | H30: =H4*Inputs!$B$82*H11*H12*Inputs!$B$85/31.1035*H10*Inputs!$B$87 -> 550934.78 | I30: =I4*Inputs!$B$82*I11*I12*Inputs!$B$85/31.1035*I10*Inputs!$B$87 -> 550934.78 | ... Z30: =Z4*Inputs!$B$82*Z11*Z12*Inputs!$B$85/31.1035*Z10*Inputs!$B$87 -> 1224299.5
A31: Utilisation, haulage and theft benefits | B31: =B16*Inputs!$B$77*Inputs!$B$88*Inputs!$B$89+B4*Inputs!$B$82*Inputs!$B$90*Inputs!$B$91+B16*Inputs!$B$92 -> 184400 | C31: =C16*Inputs!$B$77*Inputs!$B$88*Inputs!$B$89+C4*Inputs!$B$82*Inputs!$B$90*Inputs!$B$91+C16*Inputs!$B$92 -> 92200 | D31: =D16*Inputs!$B$77*Inputs!$B$88*Inputs!$B$89+D4*Inputs!$B$82*Inputs!$B$90*Inputs!$B$91+D16*Inputs!$B$92 -> 230500 | E31: =E16*Inputs!$B$77*Inputs!$B$88*Inputs!$B$89+E4*Inputs!$B$82*Inputs!$B$90*Inputs!$B$91+E16*Inputs!$B$92 -> 184400 | F31: =F16*Inputs!$B$77*Inputs!$B$88*Inputs!$B$89+F4*Inputs!$B$82*Inputs!$B$90*Inputs!$B$91+F16*Inputs!$B$92 -> 184400 | G31: =G16*Inputs!$B$77*Inputs!$B$88*Inputs!$B$89+G4*Inputs!$B$82*Inputs!$B$90*Inputs!$B$91+G16*Inputs!$B$92 -> 184400 | H31: =H16*Inputs!$B$77*Inputs!$B$88*Inputs!$B$89+H4*Inputs!$B$82*Inputs!$B$90*Inputs!$B$91+H16*Inputs!$B$92 -> 184400 | I31: =I16*Inputs!$B$77*Inputs!$B$88*Inputs!$B$89+I4*Inputs!$B$82*Inputs!$B$90*Inputs!$B$91+I16*Inputs!$B$92 -> 184400 | ... Z31: =Z16*Inputs!$B$77*Inputs!$B$88*Inputs!$B$89+Z4*Inputs!$B$82*Inputs!$B$90*Inputs!$B$91+Z16*Inputs!$B$92 -> 230500
A32: Annual AAC benefit | B32: =B29+B30+B31 -> 851614.78 | C32: =C29+C30+C31 -> 425807.39 | D32: =D29+D30+D31 -> 1064518.5 | E32: =E29+E30+E31 -> 851614.78 | F32: =F29+F30+F31 -> 851614.78 | G32: =G29+G30+G31 -> 851614.78 | H32: =H29+H30+H31 -> 851614.78 | I32: =I29+I30+I31 -> 851614.78 | ... Z32: =Z29+Z30+Z31 -> 1661799.5
A33: Verified savings pool | B33: =B29+B30+B4*Inputs!$B$82*Inputs!$B$90*Inputs!$B$91 -> 697214.78 | C33: =C29+C30+C4*Inputs!$B$82*Inputs!$B$90*Inputs!$B$91 -> 348607.39 | D33: =D29+D30+D4*Inputs!$B$82*Inputs!$B$90*Inputs!$B$91 -> 871518.48 | E33: =E29+E30+E4*Inputs!$B$82*Inputs!$B$90*Inputs!$B$91 -> 697214.78 | F33: =F29+F30+F4*Inputs!$B$82*Inputs!$B$90*Inputs!$B$91 -> 697214.78 | G33: =G29+G30+G4*Inputs!$B$82*Inputs!$B$90*Inputs!$B$91 -> 697214.78 | H33: =H29+H30+H4*Inputs!$B$82*Inputs!$B$90*Inputs!$B$91 -> 697214.78 | I33: =I29+I30+I4*Inputs!$B$82*Inputs!$B$90*Inputs!$B$91 -> 697214.78 | ... Z33: =Z29+Z30+Z4*Inputs!$B$82*Inputs!$B$90*Inputs!$B$91 -> 1468799.5
A34: PV factor: opex-timed items | B34: =Inputs!$B$98+B15 -> 3.377171 | C34: =Inputs!$B$98+C15 -> 3.377171 | D34: =Inputs!$B$98+D15 -> 3.377171 | E34: =Inputs!$B$98+E15 -> 3.377171 | F34: =Inputs!$B$98+F15 -> 3.377171 | G34: =Inputs!$B$98+G15 -> 3.377171 | H34: =Inputs!$B$98+H15 -> 3.377171 | I34: =Inputs!$B$98+I15 -> 3.377171 | ... Z34: =Inputs!$B$98+Z15 -> 3.6021551
A35: PV factor: benefit-timed items | B35: =Inputs!$B$99+B15 -> 3.227171 | C35: =Inputs!$B$99+C15 -> 3.227171 | D35: =Inputs!$B$99+D15 -> 3.227171 | E35: =Inputs!$B$99+E15 -> 3.227171 | F35: =Inputs!$B$99+F15 -> 3.227171 | G35: =Inputs!$B$99+G15 -> 3.227171 | H35: =Inputs!$B$99+H15 -> 3.227171 | I35: =Inputs!$B$99+I15 -> 3.227171 | ... Z35: =Inputs!$B$99+Z15 -> 3.4521551
A36: PV factor: subscription | B36: =Inputs!$B$100+B15 -> 3.227171 | C36: =Inputs!$B$100+C15 -> 3.227171 | D36: =Inputs!$B$100+D15 -> 3.227171 | E36: =Inputs!$B$100+E15 -> 3.227171 | F36: =Inputs!$B$100+F15 -> 3.227171 | G36: =Inputs!$B$100+G15 -> 3.227171 | H36: =Inputs!$B$100+H15 -> 3.227171 | I36: =Inputs!$B$100+I15 -> 3.227171 | ... Z36: =Inputs!$B$100+Z15 -> 3.4521551
A37: PV of AAC benefits | B37: =B32*B35 -> 2748306.5 | C37: =C32*C35 -> 1374153.3 | D37: =D32*D35 -> 3435383.2 | E37: =E32*E35 -> 2748306.5 | F37: =F32*F35 -> 2748306.5 | G37: =G32*G35 -> 2748306.5 | H37: =H32*H35 -> 2748306.5 | I37: =I32*I35 -> 2748306.5 | ... Z37: =Z32*Z35 -> 5736789.7
A38: PV of AAC internal cost | B38: =Inputs!$B$93*(1+B15) -> 49526.052 | C38: =Inputs!$B$93*(1+C15) -> 49526.052 | D38: =Inputs!$B$93*(1+D15) -> 49526.052 | E38: =Inputs!$B$93*(1+E15) -> 49526.052 | F38: =Inputs!$B$93*(1+F15) -> 49526.052 | G38: =Inputs!$B$93*(1+G15) -> 49526.052 | H38: =Inputs!$B$93*(1+H15) -> 49526.052 | I38: =Inputs!$B$93*(1+I15) -> 49526.052 | ... Z38: =Inputs!$B$93*(1+Z15) -> 52225.861
A39: PV of delivery cost | B39: =B27+B28*B34 -> 1502389.6 | C39: =C27+C28*C34 -> 1076599 | D39: =D27+D28*D34 -> 1692137.2 | E39: =E27+E28*E34 -> 1446526.6 | F39: =F27+F28*F34 -> 1586184 | G39: =G27+G28*G34 -> 1448962.6 | H39: =H27+H28*H34 -> 1591434.6 | I39: =I27+I28*I34 -> 1362070.9 | ... Z39: =Z27+Z28*Z34 -> 1654933.5
A40: Model A: PV of fees to Smart Innovations GH | B40: =B27*(1+Inputs!$B$104*B14)+B28*(1+Inputs!$B$105*B14)*B34 -> 1924759.8 | C40: =C27*(1+Inputs!$B$104*C14)+C28*(1+Inputs!$B$105*C14)*C34 -> 1378440.1 | D40: =D27*(1+Inputs!$B$104*D14)+D28*(1+Inputs!$B$105*D14)*D34 -> 2168553.9 | E40: =E27*(1+Inputs!$B$104*E14)+E28*(1+Inputs!$B$105*E14)*E34 -> 1854162.7 | F40: =F27*(1+Inputs!$B$104*F14)+F28*(1+Inputs!$B$105*F14)*F34 -> 2030655.5 | G40: =G27*(1+Inputs!$B$104*G14)+G28*(1+Inputs!$B$105*G14)*G34 -> 1857976.1 | H40: =H27*(1+Inputs!$B$104*H14)+H28*(1+Inputs!$B$105*H14)*H34 -> 2036066.1 | I40: =I27*(1+Inputs!$B$104*I14)+I28*(1+Inputs!$B$105*I14)*I34 -> 1742345.6 | ... Z40: =Z27*(1+Inputs!$B$104*Z14)+Z28*(1+Inputs!$B$105*Z14)*Z34 -> 2122309.1
A41: Model B: annual subscription | B41: =(B16*Inputs!$B$106+B17*Inputs!$B$107+B4*Inputs!$B$108+Inputs!$B$109)*12*B14 -> 500640 | C41: =(C16*Inputs!$B$106+C17*Inputs!$B$107+C4*Inputs!$B$108+Inputs!$B$109)*12*C14 -> 268320 | D41: =(D16*Inputs!$B$106+D17*Inputs!$B$107+D4*Inputs!$B$108+Inputs!$B$109)*12*D14 -> 616800 | E41: =(E16*Inputs!$B$106+E17*Inputs!$B$107+E4*Inputs!$B$108+Inputs!$B$109)*12*E14 -> 500640 | F41: =(F16*Inputs!$B$106+F17*Inputs!$B$107+F4*Inputs!$B$108+Inputs!$B$109)*12*F14 -> 500640 | G41: =(G16*Inputs!$B$106+G17*Inputs!$B$107+G4*Inputs!$B$108+Inputs!$B$109)*12*G14 -> 500640 | H41: =(H16*Inputs!$B$106+H17*Inputs!$B$107+H4*Inputs!$B$108+Inputs!$B$109)*12*H14 -> 500640 | I41: =(I16*Inputs!$B$106+I17*Inputs!$B$107+I4*Inputs!$B$108+Inputs!$B$109)*12*I14 -> 500640 | ... Z41: =(Z16*Inputs!$B$106+Z17*Inputs!$B$107+Z4*Inputs!$B$108+Inputs!$B$109)*12*Z14 -> 616800
...

Sheet Sensitivity
A1: Sensitivity analysis - NPV over Year 0 to Year 5 (USD)
A2: One driver moves at a time; all others stay at base. Blue low / high values and scenario settings are editable. Results come from the Scenario Engine sheet, which recomputes the full model for each case.
A4: Driver | B4: Base | C4: Low case | D4: High case | E4: Bear scenario | F4: Bull scenario
A5: Concessions in rollout | B5: =Inputs!$B$7 -> 8 | C5: 4 | D5: 10 | E5: 5 | F5: 10
A6: Hardware cost multiplier | B6: =Inputs!$B$30 -> 1 | C6: 0.8 | D6: 1.3 | E6: 1.2 | F6: 0.9
A7: Implementation services multiplier | B7: =Inputs!$B$50 -> 1 | C7: 0.85 | D7: 1.25 | E7: 1.15 | F7: 0.95
A8: Annual opex multiplier | B8: =Inputs!$B$73 -> 1 | C8: 0.85 | D8: 1.25 | E8: 1.15 | F8: 0.95
A9: Diesel price ($/L) | B9: =Inputs!$B$79 -> 0.85 | C9: 0.65 | D9: 1.1 | E9: 0.75 | F9: 1
A10: Excavator fuel saving % | B10: =Inputs!$B$80 -> 0.12 | C10: 0.06 | D10: 0.18 | E10: 0.08 | F10: 0.15
A11: Gold price ($/oz) | B11: =Inputs!$B$86 -> 3500 | C11: 2800 | D11: 4200 | E11: 3000 | F11: 4000
A12: Extra feed secured (% of feed) | B12: =Inputs!$B$83 -> 0.03 | C12: 0.01 | D12: 0.05 | E12: 0.015 | F12: 0.04
A13: Tailings grade (g/t) | B13: =Inputs!$B$84 -> 1.2 | C13: 0.8 | D13: 1.6 | E13: 1 | F13: 1.4
A14: Discount rate | B14: =Inputs!$B$96 -> 0.18 | C14: 0.14 | D14: 0.24 | E14: 0.22 | F14: 0.15
A15: Pricing multiplier (fees / margins) | B15: =Inputs!$B$103 -> 1 | C15: 0.8 | D15: 1.2 | E15: 1 | F15: 1
A17: Base case results
A18: Metric | B18: Model A | C18: Model B | D18: Model C
A19: Smart Innovations GH NPV | B19: ='Scenario Engine'!$B$44 -> 422370.28 | C19: ='Scenario Engine'!$B$45 -> 198301.11 | D19: ='Scenario Engine'!$B$46 -> 496779.16
A20: AAC NPV | B20: ='Scenario Engine'!$B$47 -> 774020.66 | C20: ='Scenario Engine'!$B$48 -> 998089.83 | D20: ='Scenario Engine'!$B$49 -> 699611.78
A21: Check: engine base = Revenue Models NPV (should be 0) | B21: =ROUND(B19-'Revenue Models'!$I$22,0)+ROUND(B20-'Revenue Models'!$I$24,0) -> 0 | C21: =ROUND(C19-'Revenue Models'!$I$37,0)+ROUND(C20-'Revenue Models'!$I$39,0) -> 0 | D21: =ROUND(D19-'Revenue Models'!$I$53,0)+ROUND(D20-'Revenue Models'!$I$55,0) -> 0
A23: Table 1 - Smart Innovations GH NPV by revenue model
A24: Driver | B24: A: low | C24: A: high | D24: A: swing | E24: B: low | F24: B: high | G24: B: swing | H24: C: low | I24: C: high | J24: C: swing
A25: Concessions in rollout | B25: ='Scenario Engine'!$C$44 -> 301841.13 | C25: ='Scenario Engine'!$D$44 -> 476416.69 | D25: =ABS(C25-B25) -> 174575.56 | E25: ='Scenario Engine'!$C$45 -> -147268.77 | F25: ='Scenario Engine'!$D$45 -> 392055.3 | G25: =ABS(F25-E25) -> 539324.07 | H25: ='Scenario Engine'!$C$46 -> 257694.52 | I25: ='Scenario Engine'!$D$46 -> 615890.23 | J25: =ABS(I25-H25) -> 358195.71
A26: Hardware cost multiplier | B26: ='Scenario Engine'!$E$44 -> 407636.18 | C26: ='Scenario Engine'!$F$44 -> 444471.43 | D26: =ABS(C26-B26) -> 36835.254 | E26: ='Scenario Engine'!$E$45 -> 248089.72 | F26: ='Scenario Engine'!$F$45 -> 123618.2 | G26: =ABS(F26-E26) -> 124471.51 | H26: ='Scenario Engine'!$E$46 -> 496010.81 | I26: ='Scenario Engine'!$F$46 -> 497931.69 | J26: =ABS(I26-H26) -> 1920.8809
A27: Implementation services multiplier | B27: ='Scenario Engine'!$G$44 -> 409013.53 | C27: ='Scenario Engine'!$H$44 -> 444631.53 | D27: =ABS(C27-B27) -> 35618 | E27: ='Scenario Engine'!$G$45 -> 243714.06 | F27: ='Scenario Engine'!$H$45 -> 122612.86 | G27: =ABS(F27-E27) -> 121101.2 | H27: ='Scenario Engine'!$G$46 -> 496779.16 | I27: ='Scenario Engine'!$H$46 -> 496779.16 | J27: =ABS(I27-H27) -> 0
A28: Annual opex multiplier | B28: ='Scenario Engine'!$I$44 -> 380274.68 | C28: ='Scenario Engine'!$J$44 -> 492529.61 | D28: =ABS(C28-B28) -> 112254.94 | E28: ='Scenario Engine'!$I$45 -> 338619.78 | F28: ='Scenario Engine'!$J$45 -> -35563.34 | G28: =ABS(F28-E28) -> 374183.12 | H28: ='Scenario Engine'!$I$46 -> 489763.22 | I28: ='Scenario Engine'!$J$46 -> 508472.38 | J28: =ABS(I28-H28) -> 18709.156
A29: Diesel price ($/L) | B29: ='Scenario Engine'!$K$44 -> 422370.28 | C29: ='Scenario Engine'!$L$44 -> 422370.28 | D29: =ABS(C29-B29) -> 0 | E29: ='Scenario Engine'!$K$45 -> 198301.11 | F29: ='Scenario Engine'!$L$45 -> 198301.11 | G29: =ABS(F29-E29) -> 0 | H29: ='Scenario Engine'!$K$46 -> 479120.08 | I29: ='Scenario Engine'!$L$46 -> 518853.01 | J29: =ABS(I29-H29) -> 39732.93
A30: Excavator fuel saving % | B30: ='Scenario Engine'!$M$44 -> 422370.28 | C30: ='Scenario Engine'!$N$44 -> 422370.28 | D30: =ABS(C30-B30) -> 0 | E30: ='Scenario Engine'!$M$45 -> 198301.11 | F30: ='Scenario Engine'!$N$45 -> 198301.11 | G30: =ABS(F30-E30) -> 0 | H30: ='Scenario Engine'!$M$46 -> 465178.7 | I30: ='Scenario Engine'!$N$46 -> 528379.62 | J30: =ABS(I30-H30) -> 63200.917
A31: Gold price ($/oz) | B31: ='Scenario Engine'!$O$44 -> 422370.28 | C31: ='Scenario Engine'!$P$44 -> 422370.28 | D31: =ABS(C31-B31) -> 0 | E31: ='Scenario Engine'!$O$45 -> 198301.11 | F31: ='Scenario Engine'!$P$45 -> 198301.11 | G31: =ABS(F31-E31) -> 0 | H31: ='Scenario Engine'!$O$46 -> 425660.73 | I31: ='Scenario Engine'!$P$46 -> 567897.59 | J31: =ABS(I31-H31) -> 142236.86
A32: Extra feed secured (% of feed) | B32: ='Scenario Engine'!$Q$44 -> 422370.28 | C32: ='Scenario Engine'!$R$44 -> 422370.28 | D32: =ABS(C32-B32) -> 0 | E32: ='Scenario Engine'!$Q$45 -> 198301.11 | F32: ='Scenario Engine'!$R$45 -> 198301.11 | G32: =ABS(F32-E32) -> 0 | H32: ='Scenario Engine'!$Q$46 -> 259717.72 | I32: ='Scenario Engine'!$R$46 -> 733840.59 | J32: =ABS(I32-H32) -> 474122.87
A33: Tailings grade (g/t) | B33: ='Scenario Engine'!$S$44 -> 422370.28 | C33: ='Scenario Engine'!$T$44 -> 422370.28 | D33: =ABS(C33-B33) -> 0 | E33: ='Scenario Engine'!$S$45 -> 198301.11 | F33: ='Scenario Engine'!$T$45 -> 198301.11 | G33: =ABS(F33-E33) -> 0 | H33: ='Scenario Engine'!$S$46 -> 378248.44 | I33: ='Scenario Engine'!$T$46 -> 615309.88 | J33: =ABS(I33-H33) -> 237061.44
A34: Discount rate | B34: ='Scenario Engine'!$U$44 -> 447790.89 | C34: ='Scenario Engine'!$V$44 -> 390644.44 | D34: =ABS(C34-B34) -> 57146.449 | E34: ='Scenario Engine'!$U$45 -> 266716.49 | F34: ='Scenario Engine'!$V$45 -> 112916.25 | G34: =ABS(F34-E34) -> 153800.24 | H34: ='Scenario Engine'!$U$46 -> 543672.91 | I34: ='Scenario Engine'!$V$46 -> 438254.07 | J34: =ABS(I34-H34) -> 105418.85
A35: Pricing multiplier (fees / margins) | B35: ='Scenario Engine'!$W$44 -> 337896.22 | C35: ='Scenario Engine'!$X$44 -> 506844.33 | D35: =ABS(C35-B35) -> 168948.11 | E35: ='Scenario Engine'!$W$45 -> -124829.07 | F35: ='Scenario Engine'!$X$45 -> 521431.29 | G35: =ABS(F35-E35) -> 646260.36 | H35: ='Scenario Engine'!$W$46 -> 397423.33 | I35: ='Scenario Engine'!$X$46 -> 596134.99 | J35: =ABS(I35-H35) -> 198711.66
A37: Table 2 - AAC NPV (net benefit) by revenue model
A38: Driver | B38: A: low | C38: A: high | D38: A: swing | E38: B: low | F38: B: high | G38: B: swing | H38: C: low | I38: C: high | J38: C: swing
A39: Concessions in rollout | B39: ='Scenario Engine'!$C$47 -> -53812.898 | C39: ='Scenario Engine'!$D$47 -> 1217303.3 | D39: =ABS(C39-B39) -> 1271116.2 | E39: ='Scenario Engine'!$C$48 -> 395297.01 | F39: ='Scenario Engine'!$D$48 -> 1301664.7 | G39: =ABS(F39-E39) -> 906367.65 | H39: ='Scenario Engine'!$C$49 -> -9666.286 | I39: ='Scenario Engine'!$D$49 -> 1077829.7 | J39: =ABS(I39-H39) -> 1087496
A40: Hardware cost multiplier | B40: ='Scenario Engine'!$E$47 -> 844617.76 | C40: ='Scenario Engine'!$F$47 -> 668125.02 | D40: =ABS(C40-B40) -> 176492.75 | E40: ='Scenario Engine'!$E$48 -> 1004164.2 | F40: ='Scenario Engine'!$F$48 -> 988978.24 | G40: =ABS(F40-E40) -> 15185.981 | H40: ='Scenario Engine'!$E$49 -> 756243.13 | I40: ='Scenario Engine'!$F$49 -> 614664.76 | J40: =ABS(I40-H40) -> 141578.37
A41: Implementation services multiplier | B41: ='Scenario Engine'!$G$47 -> 840804.41 | C41: ='Scenario Engine'!$H$47 -> 662714.41 | D41: =ABS(C41-B41) -> 178090 | E41: ='Scenario Engine'!$G$48 -> 1006103.9 | F41: ='Scenario Engine'!$H$48 -> 984733.08 | G41: =ABS(F41-E41) -> 21370.8 | H41: ='Scenario Engine'!$G$49 -> 753038.78 | I41: ='Scenario Engine'!$H$49 -> 610566.78 | J41: =ABS(I41-H41) -> 142472
A42: Annual opex multiplier | B42: ='Scenario Engine'!$I$47 -> 956434.94 | C42: ='Scenario Engine'!$J$47 -> 469996.88 | D42: =ABS(C42-B42) -> 486438.06 | E42: ='Scenario Engine'!$I$48 -> 998089.83 | F42: ='Scenario Engine'!$J$48 -> 998089.83 | G42: =ABS(F42-E42) -> 0 | H42: ='Scenario Engine'!$I$49 -> 846946.39 | I42: ='Scenario Engine'!$J$49 -> 454054.11 | J42: =ABS(I42-H42) -> 392892.28
A43: Diesel price ($/L) | B43: ='Scenario Engine'!$K$47 -> 685725.27 | C43: ='Scenario Engine'!$L$47 -> 884389.91 | D43: =ABS(C43-B43) -> 198664.65 | E43: ='Scenario Engine'!$K$48 -> 909794.43 | F43: ='Scenario Engine'!$L$48 -> 1108459.1 | G43: =ABS(F43-E43) -> 198664.65 | H43: ='Scenario Engine'!$K$49 -> 628975.46 | I43: ='Scenario Engine'!$L$49 -> 787907.18 | J43: =ABS(I43-H43) -> 158931.72
A44: Excavator fuel saving % | B44: ='Scenario Engine'!$M$47 -> 616018.37 | C44: ='Scenario Engine'!$N$47 -> 932022.96 | D44: =ABS(C44-B44) -> 316004.59 | E44: ='Scenario Engine'!$M$48 -> 840087.54 | F44: ='Scenario Engine'!$N$48 -> 1156092.1 | G44: =ABS(F44-E44) -> 316004.59 | H44: ='Scenario Engine'!$M$49 -> 573209.95 | I44: ='Scenario Engine'!$N$49 -> 826013.62 | J44: =ABS(I44-H44) -> 252803.67
...
