Workbook

Sheet README
A1: AAC – Assosa CIL Plant Financial Model
A4: PURPOSE
A5: A working financial model for the privately-owned CIL (Carbon-in-Leach) tailings-processing plant near Assosa, Benishangul-Gumuz Region, Western Ethiopia. Built for Accountable Africa Capital (AAC) to stress-test revenue, cost, and the ROI of the IoT/drone monitoring platform under Ethiopia-specific conditions: Birr/USD exchange rate, the National Bank of Ethiopia (NBE) buyer premium, and Assosa-region logistics costs.
A7: HOW TO USE THIS WORKBOOK
A8: 1. Start on the 'Assumptions' tab. Every editable input is BLUE text on a YELLOW cell — change these to your actual data.
A9: 2. 'Monthly Model' shows Year 1 built up month by month from the Assumptions tab.
A10: 3. 'Annual P&L' rolls Year 1 into a 3-year view, applying tonnage growth and cost/FX escalation assumptions.
A11: 4. 'Scenarios' shows Bear / Base / Bull cases driven by gold price, NBE premium, exchange rate and tonnage.
A12: 5. 'Tech ROI' quantifies the financial case for the excavator/fuel/drone/dump-truck monitoring platform itself.
A14: COLOR KEY
A15: Blue text on yellow fill = hardcoded input you should edit.
A16: Black text = formula (do not overwrite).
... A27: This model is a planning and scenario tool, not audited financial guidance. Gold price and FX assumptions should be refreshed regularly given their volatility.

Sheet Assumptions
A1: Assumptions — AAC Assosa CIL Plant
A2: Blue text on yellow = editable input. Black = formula.
A4: PRODUCTION ASSUMPTIONS
A5: Assumption | B5: Value | C5: Unit | D5: Notes / Source
A6: Number of active concessions | B6: 7 | C6: # | D6: Engagement scope is 4-10 concessions; 7 used as base case
A7: Avg tailings processed per concession | B7: 285 | C7: t/month | D7: Illustrative baseline - replace with actual site/geologist data
A8: Total tonnes processed (Month 1, base) | B8: =Assumptions!$B$6*Assumptions!$B$7 -> 1995 | C8: t/month | D8: Formula: concessions x avg tonnes per concession
A9: Average confirmed ore grade | B9: 0.6 | C9: g/t | D9: Geologist baseline; refined by bi-weekly drone volumetrics
A10: CIL recovery rate | B10: 0.87 | C10: % | D10: Typical CIL recovery range 80%-92%
A11: Monthly tonnage growth (Year 1 ramp-up) | B11: 0.015 | C11: %/month | D11: Ramp as concessions onboard and drone survey cadence matures
A12: Annual tonnage growth (Year 2-3) | B12: 0.1 | C12: %/year | D12: Additional concessions onboarded toward the 10-concession ceiling
A14: GOLD PRICE & MARKET ASSUMPTIONS
A15: Assumption | B15: Value | C15: Unit | D15: Notes / Source
A16: International gold price (spot) | B16: 4300 | C16: $/oz | D16: Spot reference, September 2026 - highly volatile; see Scenarios tab
A17: Grams per troy ounce | B17: 31.1035 | C17: g/oz | D17: Constant
A18: Implied international price | B18: =Assumptions!$B$16/Assumptions!$B$17 -> 138.24811 | C18: $/g | D18: Formula
A19: Buyer premium over international price | B19: 0.5 | C19: % | D19: NBE has historically paid ~35%-67% premium vs. international price to formalize ASM supply; NBE reportedly transitioning gold-buying to licensed private banks by end-2026 (IMF-reported) - verify current channel/rate
A20: Realized price to AAC | B20: =Assumptions!$B$18*(1+Assumptions!$B$19) -> 207.37216 | C20: $/g | D20: Formula
A21: USD/ETB exchange rate | B21: 162 | C21: ETB/$ | D21: Spot, September 2026 (~160-164 range per bank quotes); Birr floated July 2024 - high volatility
A22: Annual ETB depreciation vs. USD (illustrative) | B22: 0.08 | C22: %/year | D22: Directional planning assumption only; historical volatility has been materially higher at times
A23: Realized price to AAC (ETB) | B23: =Assumptions!$B$20*Assumptions!$B$21 -> 33594.29 | C23: ETB/g | D23: Formula
A25: COST ASSUMPTIONS
A26: Assumption | B26: Value | C26: Unit | D26: Notes / Source
A27: Feedstock / concession payment | B27: 0.22 | C27: % of gross revenue | D27: Royalty / tolling share paid to concession holders
A28: Reagents & consumables | B28: 9 | C28: $/tonne | D28: Cyanide, lime, carbon; import lead-time premium for landlocked western Ethiopia
A29: Fuel (excavators + plant, monitored) | B29: 5.5 | C29: $/tonne | D29: Diesel; represents the efficient/monitored cost - see Tech ROI tab for unmonitored counterfactual
A30: Haulage/logistics (concession -> plant) | B30: 9 | C30: $/tonne | D30: Remote, border-proximate region premium vs. coastal/urban logistics
A31: Labor (plant + field) | B31: 42000 | C31: $/month | D31: Fixed
A32: Maintenance (excavators, trucks, plant) | B32: 11000 | C32: $/month | D32: Fixed
A33: Compliance & licensing | B33: 5000 | C33: $/month | D33: Ministry of Mines + Benishangul-Gumuz regional mining bureau
A34: Security | B34: 9000 | C34: $/month | D34: Elevated for a border-proximate, contraband-risk region
A35: SG&A / corporate overhead | B35: 16000 | C35: $/month | D35: Fixed
A36: Technology platform - SaaS/monitoring subscription | B36: 6000 | C36: $/month | D36: Telematics + fuel sensors + drone/GIS platform recurring fee
A37: Fixed-cost annual escalator | B37: 0.08 | C37: %/year | D37: Reflects Ethiopia's elevated domestic inflation environment
A39: CAPITAL ASSUMPTIONS (already invested / one-time)
A40: Assumption | B40: Value | C40: Unit | D40: Notes / Source
A41: CIL plant construction & commissioning | B41: 3000000 | C41: $ | D41: One-time
A42: Excavator fleet (loaned to concessions) | B42: 1000000 | C42: $ | D42: One-time
A43: Dump truck fleet | B43: 600000 | C43: $ | D43: One-time
A44: Technology platform implementation | B44: 180000 | C44: $ | D44: One-time: telematics, fuel sensors, geofencing, drones, GIS/dashboard build
...

Sheet Monthly Model
A1: Monthly Model - Year 1 (Assosa CIL Plant)
A3: Metric | B3: Month 1 | C3: Month 2 | D3: Month 3 | E3: Month 4 | F3: Month 5 | G3: Month 6 | H3: Month 7 | I3: Month 8 | J3: Month 9 | K3: Month 10 | L3: Month 11 | M3: Month 12 | N3: Year 1 Total/Avg
A4: Tonnes processed | B4: =Assumptions!$B$8 -> 1995 | C4: =B4*(1+Assumptions!$B$11) -> 2024.925 | D4: =C4*(1+Assumptions!$B$11) -> 2055.2989 | E4: =D4*(1+Assumptions!$B$11) -> 2086.1284 | F4: =E4*(1+Assumptions!$B$11) -> 2117.4203 | G4: =F4*(1+Assumptions!$B$11) -> 2149.1816 | H4: =G4*(1+Assumptions!$B$11) -> 2181.4193 | I4: =H4*(1+Assumptions!$B$11) -> 2214.1406 | J4: =I4*(1+Assumptions!$B$11) -> 2247.3527 | ... M4: =L4*(1+Assumptions!$B$11) -> 2350.0081 | N4: =SUM(B4:M4) -> 26017.217
A5: Ore grade (g/t) | B5: =Assumptions!$B$9 -> 0.6 | C5: =Assumptions!$B$9 -> 0.6 | D5: =Assumptions!$B$9 -> 0.6 | E5: =Assumptions!$B$9 -> 0.6 | F5: =Assumptions!$B$9 -> 0.6 | G5: =Assumptions!$B$9 -> 0.6 | H5: =Assumptions!$B$9 -> 0.6 | I5: =Assumptions!$B$9 -> 0.6 | ... M5: =Assumptions!$B$9 -> 0.6 | N5: =AVERAGE(B5:M5) -> 0.6
A6: CIL recovery rate | B6: =Assumptions!$B$10 -> 0.87 | C6: =Assumptions!$B$10 -> 0.87 | D6: =Assumptions!$B$10 -> 0.87 | E6: =Assumptions!$B$10 -> 0.87 | F6: =Assumptions!$B$10 -> 0.87 | G6: =Assumptions!$B$10 -> 0.87 | H6: =Assumptions!$B$10 -> 0.87 | I6: =Assumptions!$B$10 -> 0.87 | ... M6: =Assumptions!$B$10 -> 0.87 | N6: =AVERAGE(B6:M6) -> 0.87
A7: Grams recovered | B7: =B4*B5*B6 -> 1041.39 | C7: =C4*C5*C6 -> 1057.0108 | D7: =D4*D5*D6 -> 1072.866 | E7: =E4*E5*E6 -> 1088.959 | F7: =F4*F5*F6 -> 1105.2934 | G7: =G4*G5*G6 -> 1121.8728 | H7: =H4*H5*H6 -> 1138.7009 | I7: =I4*I5*I6 -> 1155.7814 | ... M7: =M4*M5*M6 -> 1226.7042 | N7: =SUM(B7:M7) -> 13580.987
A8: International price ($/g) | B8: =Assumptions!$B$18 -> 138.24811 | C8: =Assumptions!$B$18 -> 138.24811 | D8: =Assumptions!$B$18 -> 138.24811 | E8: =Assumptions!$B$18 -> 138.24811 | F8: =Assumptions!$B$18 -> 138.24811 | G8: =Assumptions!$B$18 -> 138.24811 | H8: =Assumptions!$B$18 -> 138.24811 | I8: =Assumptions!$B$18 -> 138.24811 | ... M8: =Assumptions!$B$18 -> 138.24811 | N8: =AVERAGE(B8:M8) -> 138.24811
A9: Realized price to AAC ($/g, incl. premium) | B9: =Assumptions!$B$20 -> 207.37216 | C9: =Assumptions!$B$20 -> 207.37216 | D9: =Assumptions!$B$20 -> 207.37216 | E9: =Assumptions!$B$20 -> 207.37216 | F9: =Assumptions!$B$20 -> 207.37216 | G9: =Assumptions!$B$20 -> 207.37216 | H9: =Assumptions!$B$20 -> 207.37216 | I9: =Assumptions!$B$20 -> 207.37216 | ... M9: =Assumptions!$B$20 -> 207.37216 | N9: =AVERAGE(B9:M9) -> 207.37216
A10: Revenue (USD) | B10: =B7*B9 -> 215955.29 | C10: =C7*C9 -> 219194.62 | D10: =D7*D9 -> 222482.54 | E10: =E7*E9 -> 225819.78 | F10: =F7*F9 -> 229207.08 | G10: =G7*G9 -> 232645.18 | H10: =H7*H9 -> 236134.86 | I10: =I7*I9 -> 239676.88 | ... M10: =M7*M9 -> 254384.31 | N10: =SUM(B10:M10) -> 2816318.7
A11: FX rate (ETB/$) | B11: =Assumptions!$B$21 -> 162 | C11: =Assumptions!$B$21 -> 162 | D11: =Assumptions!$B$21 -> 162 | E11: =Assumptions!$B$21 -> 162 | F11: =Assumptions!$B$21 -> 162 | G11: =Assumptions!$B$21 -> 162 | H11: =Assumptions!$B$21 -> 162 | I11: =Assumptions!$B$21 -> 162 | ... M11: =Assumptions!$B$21 -> 162 | N11: =AVERAGE(B11:M11) -> 162
A12: Revenue (ETB) | B12: =B10*B11 -> 34984758 | C12: =C10*C11 -> 35509529 | D12: =D10*D11 -> 36042172 | E12: =E10*E11 -> 36582805 | F12: =F10*F11 -> 37131547 | G12: =G10*G11 -> 37688520 | H12: =H10*H11 -> 38253848 | I12: =I10*I11 -> 38827655 | ... M12: =M10*M11 -> 41210258 | N12: =SUM(B12:M12) -> 4.5624362e+08
A14: OPERATING COSTS (USD)
A15: Feedstock / concession payment | B15: =B10*Assumptions!$B$27 -> 47510.165 | C15: =C10*Assumptions!$B$27 -> 48222.817 | D15: =D10*Assumptions!$B$27 -> 48946.16 | E15: =E10*Assumptions!$B$27 -> 49680.352 | F15: =F10*Assumptions!$B$27 -> 50425.557 | G15: =G10*Assumptions!$B$27 -> 51181.941 | H15: =H10*Assumptions!$B$27 -> 51949.67 | I15: =I10*Assumptions!$B$27 -> 52728.915 | ... M15: =M10*Assumptions!$B$27 -> 55964.548 | N15: =SUM(B15:M15) -> 619590.1
A16: Reagents & consumables | B16: =B4*Assumptions!$B$28 -> 17955 | C16: =C4*Assumptions!$B$28 -> 18224.325 | D16: =D4*Assumptions!$B$28 -> 18497.69 | E16: =E4*Assumptions!$B$28 -> 18775.155 | F16: =F4*Assumptions!$B$28 -> 19056.783 | G16: =G4*Assumptions!$B$28 -> 19342.634 | H16: =H4*Assumptions!$B$28 -> 19632.774 | I16: =I4*Assumptions!$B$28 -> 19927.265 | ... M16: =M4*Assumptions!$B$28 -> 21150.073 | N16: =SUM(B16:M16) -> 234154.95
A17: Fuel (monitored) | B17: =B4*Assumptions!$B$29 -> 10972.5 | C17: =C4*Assumptions!$B$29 -> 11137.087 | D17: =D4*Assumptions!$B$29 -> 11304.144 | E17: =E4*Assumptions!$B$29 -> 11473.706 | F17: =F4*Assumptions!$B$29 -> 11645.812 | G17: =G4*Assumptions!$B$29 -> 11820.499 | H17: =H4*Assumptions!$B$29 -> 11997.806 | I17: =I4*Assumptions!$B$29 -> 12177.773 | ... M17: =M4*Assumptions!$B$29 -> 12925.045 | N17: =SUM(B17:M17) -> 143094.69
A18: Haulage / logistics | B18: =B4*Assumptions!$B$30 -> 17955 | C18: =C4*Assumptions!$B$30 -> 18224.325 | D18: =D4*Assumptions!$B$30 -> 18497.69 | E18: =E4*Assumptions!$B$30 -> 18775.155 | F18: =F4*Assumptions!$B$30 -> 19056.783 | G18: =G4*Assumptions!$B$30 -> 19342.634 | H18: =H4*Assumptions!$B$30 -> 19632.774 | I18: =I4*Assumptions!$B$30 -> 19927.265 | ... M18: =M4*Assumptions!$B$30 -> 21150.073 | N18: =SUM(B18:M18) -> 234154.95
A19: Labor | B19: =Assumptions!$B$31 -> 42000 | C19: =Assumptions!$B$31 -> 42000 | D19: =Assumptions!$B$31 -> 42000 | E19: =Assumptions!$B$31 -> 42000 | F19: =Assumptions!$B$31 -> 42000 | G19: =Assumptions!$B$31 -> 42000 | H19: =Assumptions!$B$31 -> 42000 | I19: =Assumptions!$B$31 -> 42000 | ... M19: =Assumptions!$B$31 -> 42000 | N19: =SUM(B19:M19) -> 504000
A20: Maintenance | B20: =Assumptions!$B$32 -> 11000 | C20: =Assumptions!$B$32 -> 11000 | D20: =Assumptions!$B$32 -> 11000 | E20: =Assumptions!$B$32 -> 11000 | F20: =Assumptions!$B$32 -> 11000 | G20: =Assumptions!$B$32 -> 11000 | H20: =Assumptions!$B$32 -> 11000 | I20: =Assumptions!$B$32 -> 11000 | ... M20: =Assumptions!$B$32 -> 11000 | N20: =SUM(B20:M20) -> 132000
A21: Compliance & licensing | B21: =Assumptions!$B$33 -> 5000 | C21: =Assumptions!$B$33 -> 5000 | D21: =Assumptions!$B$33 -> 5000 | E21: =Assumptions!$B$33 -> 5000 | F21: =Assumptions!$B$33 -> 5000 | G21: =Assumptions!$B$33 -> 5000 | H21: =Assumptions!$B$33 -> 5000 | I21: =Assumptions!$B$33 -> 5000 | ... M21: =Assumptions!$B$33 -> 5000 | N21: =SUM(B21:M21) -> 60000
A22: Security | B22: =Assumptions!$B$34 -> 9000 | C22: =Assumptions!$B$34 -> 9000 | D22: =Assumptions!$B$34 -> 9000 | E22: =Assumptions!$B$34 -> 9000 | F22: =Assumptions!$B$34 -> 9000 | G22: =Assumptions!$B$34 -> 9000 | H22: =Assumptions!$B$34 -> 9000 | I22: =Assumptions!$B$34 -> 9000 | ... M22: =Assumptions!$B$34 -> 9000 | N22: =SUM(B22:M22) -> 108000
A23: SG&A / overhead | B23: =Assumptions!$B$35 -> 16000 | C23: =Assumptions!$B$35 -> 16000 | D23: =Assumptions!$B$35 -> 16000 | E23: =Assumptions!$B$35 -> 16000 | F23: =Assumptions!$B$35 -> 16000 | G23: =Assumptions!$B$35 -> 16000 | H23: =Assumptions!$B$35 -> 16000 | I23: =Assumptions!$B$35 -> 16000 | ... M23: =Assumptions!$B$35 -> 16000 | N23: =SUM(B23:M23) -> 192000
A24: Technology platform (SaaS) | B24: =Assumptions!$B$36 -> 6000 | C24: =Assumptions!$B$36 -> 6000 | D24: =Assumptions!$B$36 -> 6000 | E24: =Assumptions!$B$36 -> 6000 | F24: =Assumptions!$B$36 -> 6000 | G24: =Assumptions!$B$36 -> 6000 | H24: =Assumptions!$B$36 -> 6000 | I24: =Assumptions!$B$36 -> 6000 | ... M24: =Assumptions!$B$36 -> 6000 | N24: =SUM(B24:M24) -> 72000
A25: Total operating costs | B25: =SUM(B15:B24) -> 183392.66 | C25: =SUM(C15:C24) -> 184808.55 | D25: =SUM(D15:D24) -> 186245.68 | E25: =SUM(E15:E24) -> 187704.37 | F25: =SUM(F15:F24) -> 189184.93 | G25: =SUM(G15:G24) -> 190687.71 | H25: =SUM(H15:H24) -> 192213.02 | I25: =SUM(I15:I24) -> 193761.22 | ... M25: =SUM(M15:M24) -> 200189.74 | N25: =SUM(B25:M25) -> 2298994.7
A27: PROFITABILITY
A28: EBITDA (USD) | B28: =B10-B25 -> 32562.63 | C28: =C10-C25 -> 34386.069 | D28: =D10-D25 -> 36236.86 | E28: =E10-E25 -> 38115.413 | F28: =F10-F25 -> 40022.144 | G28: =G10-G25 -> 41957.476 | H28: =H10-H25 -> 43921.839 | I28: =I10-I25 -> 45915.666 | ... M28: =M10-M25 -> 54194.57 | N28: =SUM(B28:M28) -> 517323.96
A29: EBITDA margin (%) | B29: =IFERROR(B28/B10,0) -> 0.15078412 | C29: =IFERROR(C28/C10,0) -> 0.1568746 | D29: =IFERROR(D28/D10,0) -> 0.16287507 | E29: =IFERROR(E28/E10,0) -> 0.16878687 | F29: =IFERROR(F28/F10,0) -> 0.17461129 | G29: =IFERROR(G28/G10,0) -> 0.18034965 | H29: =IFERROR(H28/H10,0) -> 0.18600319 | I29: =IFERROR(I28/I10,0) -> 0.19157319 | ... M29: =IFERROR(M28/M10,0) -> 0.21304211 | N29: =AVERAGE(B29:M29) -> 0.18268522
A30: EBITDA (ETB) | B30: =B28*B11 -> 5275146 | C30: =C28*C11 -> 5570543.2 | D30: =D28*D11 -> 5870371.3 | E30: =E28*E11 -> 6174696.9 | F30: =F28*F11 -> 6483587.4 | G30: =G28*G11 -> 6797111.2 | H30: =H28*H11 -> 7115337.8 | I30: =I28*I11 -> 7438337.9 | ... M30: =M28*M11 -> 8779520.4 | N30: =SUM(B30:M30) -> 83806481

Sheet Annual PL
A1: Annual P&L - 3 Year View (Assosa CIL Plant)
A3: Metric | B3: Year 1 | C3: Year 2 | D3: Year 3
A4: Tonnes processed (annual) | B4: ='Monthly Model'!N4 -> 26017.217 | C4: =B4*(1+Assumptions!$B$12) -> 28618.938 | D4: =C4*(1+Assumptions!$B$12) -> 31480.832
A5: Revenue per tonne (avg, USD) | B5: ='Monthly Model'!N10/'Monthly Model'!N4 -> 108.24827 | C5: =B5 -> 108.24827 | D5: =B5 -> 108.24827
A6: Revenue (USD) | B6: =B4*B5 -> 2816318.7 | C6: =C4*C5 -> 3097950.5 | D6: =D4*D5 -> 3407745.6
A7: FX rate (ETB/$) | B7: =Assumptions!$B$21 -> 162 | C7: =B7*(1+Assumptions!$B$22) -> 174.96 | D7: =C7*(1+Assumptions!$B$22) -> 188.9568
A8: Revenue (ETB) | B8: =B6*B7 -> 4.5624362e+08 | C8: =C6*C7 -> 5.4201742e+08 | D8: =D6*D7 -> 6.439167e+08
A10: OPERATING COSTS (USD)
A11: Feedstock / concession payment | B11: =B6*Assumptions!$B$27 -> 619590.1 | C11: =C6*Assumptions!$B$27 -> 681549.11 | D11: =D6*Assumptions!$B$27 -> 749704.03
A12: Reagents & consumables | B12: =B4*Assumptions!$B$28 -> 234154.95 | C12: =C4*Assumptions!$B$28 -> 257570.45 | D12: =D4*Assumptions!$B$28 -> 283327.49
A13: Fuel (monitored) | B13: =B4*Assumptions!$B$29 -> 143094.69 | C13: =C4*Assumptions!$B$29 -> 157404.16 | D13: =D4*Assumptions!$B$29 -> 173144.58
A14: Haulage / logistics | B14: =B4*Assumptions!$B$30 -> 234154.95 | C14: =C4*Assumptions!$B$30 -> 257570.45 | D14: =D4*Assumptions!$B$30 -> 283327.49
A15: Fixed costs (labor, maintenance, compliance, security, SG&A, tech SaaS) | B15: =(Assumptions!$B$31+Assumptions!$B$32+Assumptions!$B$33+Assumptions!$B$34+Assumptions!$B$35+Assumptions!$B$36)*12 -> 1068000 | C15: =B15*(1+Assumptions!$B$37) -> 1153440 | D15: =C15*(1+Assumptions!$B$37) -> 1245715.2
A16: Total operating costs | B16: =SUM(B11:B15) -> 2298994.7 | C16: =SUM(C11:C15) -> 2507534.2 | D16: =SUM(D11:D15) -> 2735218.8
A18: PROFITABILITY
A19: EBITDA (USD) | B19: =B6-B16 -> 517323.96 | C19: =C6-C16 -> 590416.35 | D19: =D6-D16 -> 672526.79
A20: EBITDA margin (%) | B20: =IFERROR(B19/B6,0) -> 0.18368801 | C20: =IFERROR(C19/C6,0) -> 0.19058289 | D20: =IFERROR(D19/D6,0) -> 0.19735241
A21: EBITDA (ETB) | B21: =B19*B7 -> 83806481 | C21: =C19*C7 -> 1.0329924e+08 | D21: =D19*D7 -> 1.2707851e+08
A22: Depreciation (straight-line) | B22: =Assumptions!$B$45/Assumptions!$B$46 -> 597500 | C22: =B22 -> 597500 | D22: =B22 -> 597500
A23: EBIT (USD) | B23: =B19-B22 -> -80176.045 | C23: =C19-C22 -> -7083.6492 | D23: =D19-D22 -> 75026.786
A25: Note: excludes taxes, working-capital movements and financing costs (interest, debt repayment) - add per AAC's actual capital structure. FX drift and escalator are directional planning assumptions, not forecasts.

Sheet Scenarios
A1: Scenario Analysis - Bear / Base / Bull (Year 1)
A2: Editable scenario inputs are blue/yellow. Gold-price forecasts for 2026 from bank/analyst commentary range roughly $3,500-$5,400/oz; NBE premium and FX are independently stressed.
A4: Scenario | B4: Bear | C4: Base | D4: Bull
A5: SCENARIO INPUTS
A6: International gold price ($/oz) | B6: 3500 | C6: 4300 | D6: 5200
A7: Buyer/NBE premium (%) | B7: 0.35 | C7: 0.5 | D7: 0.67
A8: USD/ETB exchange rate | B8: 175 | C8: 162 | D8: 155
A9: Tonnes processed per month | B9: 1600 | C9: 1995 | D9: 2450
A11: RESULTING ECONOMICS (Year 1 annualized)
A12: Realized price to AAC ($/g) | B12: =(B6/Assumptions!$B$17)*(1+B7) -> 151.91216 | C12: =(C6/Assumptions!$B$17)*(1+C7) -> 207.37216 | D12: =(D6/Assumptions!$B$17)*(1+D7) -> 279.19687
A13: Grams recovered per month | B13: =B9*Assumptions!$B$9*Assumptions!$B$10 -> 835.2 | C13: =C9*Assumptions!$B$9*Assumptions!$B$10 -> 1041.39 | D13: =D9*Assumptions!$B$9*Assumptions!$B$10 -> 1278.9
A14: Annual revenue (USD) | B14: =B13*12*B12 -> 1522524.5 | C14: =C13*12*C12 -> 2591463.5 | D14: =D13*12*D12 -> 4284778.6
A15: Feedstock / concession payment | B15: =B14*Assumptions!$B$27 -> 334955.38 | C15: =C14*Assumptions!$B$27 -> 570121.98 | D15: =D14*Assumptions!$B$27 -> 942651.29
A16: Reagents & consumables | B16: =B9*12*Assumptions!$B$28 -> 172800 | C16: =C9*12*Assumptions!$B$28 -> 215460 | D16: =D9*12*Assumptions!$B$28 -> 264600
A17: Fuel | B17: =B9*12*Assumptions!$B$29 -> 105600 | C17: =C9*12*Assumptions!$B$29 -> 131670 | D17: =D9*12*Assumptions!$B$29 -> 161700
A18: Haulage / logistics | B18: =B9*12*Assumptions!$B$30 -> 172800 | C18: =C9*12*Assumptions!$B$30 -> 215460 | D18: =D9*12*Assumptions!$B$30 -> 264600
A19: Fixed costs (annual) | B19: =(Assumptions!$B$31+Assumptions!$B$32+Assumptions!$B$33+Assumptions!$B$34+Assumptions!$B$35+Assumptions!$B$36)*12 -> 1068000 | C19: =(Assumptions!$B$31+Assumptions!$B$32+Assumptions!$B$33+Assumptions!$B$34+Assumptions!$B$35+Assumptions!$B$36)*12 -> 1068000 | D19: =(Assumptions!$B$31+Assumptions!$B$32+Assumptions!$B$33+Assumptions!$B$34+Assumptions!$B$35+Assumptions!$B$36)*12 -> 1068000
A20: Total operating costs | B20: =SUM(B15:B19) -> 1854155.4 | C20: =SUM(C15:C19) -> 2200712 | D20: =SUM(D15:D19) -> 2701551.3
A21: EBITDA (USD) | B21: =B14-B20 -> -331630.91 | C21: =C14-C20 -> 390751.56 | D21: =D14-D20 -> 1583227.3
A22: EBITDA margin (%) | B22: =IFERROR(B21/B14,0) -> -0.21781647 | C22: =IFERROR(C21/C14,0) -> 0.15078412 | D22: =IFERROR(D21/D14,0) -> 0.36950038
A23: Annual revenue (ETB) | B23: =B14*B8 -> 2.6644178e+08 | C23: =C14*C8 -> 4.1981709e+08 | D23: =D14*D8 -> 6.6414068e+08

Sheet Tech ROI
A1: Technology Platform ROI - Excavator/Fuel/Drone/Dump-Truck Monitoring
A3: Metric | B3: Value | C3: Notes
A4: 1. FUEL THEFT/LEAKAGE SAVINGS
A5: Annual tonnes processed (Year 1) | B5: ='Annual PL'!B4 -> 26017.217 | C5: Linked from Annual P&L, Year 1
A6: Fuel spend WITH monitoring (modeled/efficient cost) | B6: =B5*Assumptions!$B$29 -> 143094.69 | C6: Formula: tonnes x monitored $/tonne fuel rate from Assumptions
A7: Implied true fuel requirement | B7: =B6*(1-Assumptions!$B$51) -> 138801.85 | C7: Backs out the small residual loss still present even with monitoring
A8: Fuel spend WITHOUT monitoring (counterfactual) | B8: =B7/(1-Assumptions!$B$50) -> 163296.3 | C8: Same true need, but purchased fuel inflated by industry-typical unmonitored theft/leakage rate
A9: Annual fuel savings from monitoring | B9: =B8-B6 -> 20201.604 | C9: Direct, recurring opex reduction
A11: 2. HAULAGE / CUSTODY SHRINKAGE SAVINGS
A12: Annual revenue captured (Year 1, with monitoring) | B12: ='Annual PL'!B6 -> 2816318.7 | C12: Linked from Annual P&L, Year 1
A13: Implied true potential revenue | B13: =B12/(1-Assumptions!$B$53) -> 2844766.3 | C13: Backs out the small residual shrinkage still present even with monitoring
A14: Revenue captured WITHOUT monitoring (counterfactual) | B14: =B13*(1-Assumptions!$B$52) -> 2702528 | C14: Same potential, but more value lost to under-reporting/diversion without GPS/geofence/weighbridge reconciliation
A15: Annual revenue protected by monitoring | B15: =B12-B14 -> 113790.65 | C15: Revenue that would otherwise leak between concession and plant
A17: 3. PLATFORM COST
A18: Technology platform SaaS (annual) | B18: =Assumptions!$B$36*12 -> 72000 | C18: Recurring subscription, already included in Annual P&L opex
A19: Technology platform implementation (one-time) | B19: =Assumptions!$B$44 -> 180000 | C19: One-time build/hardware/integration cost
A21: 4. NET BENEFIT & PAYBACK
A22: Total annual financial benefit | B22: =B9+B15 -> 133992.26 | C22: Fuel savings + revenue protected
A23: Net annual benefit (after recurring SaaS cost) | B23: =B22-B18 -> 61992.256 | C23: Total benefit less the platform's own recurring cost
A24: Net monthly benefit | B24: =B23/12 -> 5166.0214 | C24: For payback calculation
A25: Simple payback period on implementation cost | B25: =IFERROR(B19/B24,0) -> 34.843062 | C25: One-time implementation cost / net monthly benefit
A27: Method: fuel and shrinkage savings are modeled by comparing an unmonitored counterfactual loss rate (industry-typical, see Assumptions tab) against the monitored/residual loss rate the platform is expected to achieve, applied to the same underlying tonnage and revenue base from the Annual P&L tab. Replace the loss-rate assumptions with AAC's own baseline audit data (e.g. a 60-90 day pre-platform reconciliation) as soon as it is available, to tighten this estimate.
