Workbook

Sheet Guide
A1: Cattle Farm Financial Model (Dairy + Beef Cow-Calf)
A2: 8-year projection. All numbers are illustrative placeholders: replace them with local quotes and your own targets.
A4: HOW TO USE
A5: 1 | B5: Go to Assumptions and replace the blue inputs with your prices, herd sizes and costs. Yellow fill marks the biggest drivers.
A6: 2 | B6: Review the Capex sheet: get local quotes for each line. Livestock and infrastructure drive the investment.
A7: 3 | B7: Pick a scenario on the Scenarios sheet (1 Base, 2 Downside, 3 Upside) and edit the lever values to your own risk view.
A8: 4 | B8: Read results on Returns (IRR, NPV, payback, break-even), PnL (profit), CashFlow (loan and cash), and Monthly (Year 1 funding check).
A9: 5 | B9: Watch two warning flags: 'OVER CAPACITY' on the Herd sheet (herd larger than land can carry) and 'SHORTFALL' on Monthly (cash runs out).
A11: COLOUR CODE
A12: Blue text | B12: Input you can change
A13: Black text | B13: Formula
A14: Green text | B14: Link pulled from another sheet
A15: Yellow fill | B15: Key driver or cell you should look at first
A17: SHEETS
A18: Assumptions | B18: Every input: prices, yields, herd rates, costs, financing, tax.
A19: Scenarios | B19: Base / downside / upside levers for prices, feed cost, fertility, yields, mortality.
A20: Capex | B20: Itemised startup investment with depreciation lives.
A21: Herd | B21: Cows, calves, heifer retention, culls, milk litres and land capacity, year by year.
A22: Revenue | B22: Ten revenue streams: raw milk, processed dairy, bull calves, surplus heifers, cull cows, manure, weaners, beef culls, services, other income.
A23: Opex | B23: Feed, health, breeding, labour, overheads, land, contingency.
A24: PnL | B24: Income statement plus dairy and beef gross margins.
A25: CashFlow | B25: Loan schedule, project and equity cash flows, terminal value, DSCR.
A26: Returns | B26: Investment summary, IRR, NPV, payback, key-year KPIs, break-even prices, scenario snapshot, charts.
A27: Monthly | B27: Year 1 monthly cash flow to size the working capital reserve.
A29: KEY MODELLING CHOICES
A30: Herd | B30: Heifers retained in year t enter the cow herd in year t+2. Attrition applies to opening cows. Milk is produced by cows that calve.
A31: Terminal value | B31: Year 8 herd (at a haircut), land if bought and the working capital reserve are added back. Infrastructure resale is ignored. Switch off on Assumptions.
A32: Depreciation | B32: Straight line. Only purchased foundation animals are capitalised; homebred replacements are not.
A33: Tax | B33: Simple: tax on positive profit, no loss carry-forward. Check local farm tax rules.
A34: Inflation | B34: Prices and costs escalate at the rates on Assumptions. Discount rate is nominal.
A35: Not modelled | B35: VAT, exchange-rate moves, land title costs, biogas, feedlot finishing of purchased animals, and drought-year herd losses beyond the downside scenario.
A37: Disclaimer | B37: This is a planning tool, not financial advice. Input values are generic placeholders, not local market data. Validate with a farm advisor, your lender and local extension officers.

Sheet Assumptions
A1: Assumptions (all inputs live here)
A2: Blue = input you can change. Yellow fill = key driver. All amounts are in one currency (label below). Values are indicative placeholders, replace with local quotes.
A4: Assumption | B4: Unit | C4: Value | D4: Note / basis
A5: 1. General and financial
A6: Currency label | B6: text | C6: USD | D6: Labels only. If you switch to local currency, update every price/cost and the rates below.
A7: Projection horizon | B7: years | C7: 8 | D7: Fixed at 8 (model columns). Do not change.
A8: Discount rate (nominal) | B8: % | C8: 0.12 | D8: Cost of capital / hurdle rate. Use local nominal rate if working in local currency.
A9: Income tax rate | B9: % | C9: 0.2 | D9: Placeholder. Check local rules: many countries exempt or reduce tax on farming for several years.
A10: Milk price inflation | B10: % p.a. | C10: 0.05 | D10: Escalates milk price from Year 2.
A11: Animal price inflation | B11: % p.a. | C11: 0.05 | D11: Escalates calf, heifer and cull prices.
A12: Cost inflation | B12: % p.a. | C12: 0.05 | D12: Escalates feed, labour, vet, overheads and other income.
A13: Include terminal value? (1 = yes, 0 = no) | B13: switch | C13: 1 | D13: Herd, land (if bought) and working capital reserve recovered in Year 8. Infrastructure resale ignored (conservative).
A14: Herd terminal value as % of replacement price | B14: % | C14: 0.8 | D14: Discount to reflect age and forced-sale risk.
A15: Land value growth (if bought) | B15: % p.a. | C15: 0.03
A16: Working capital reserve | B16: months of Y1 opex | C16: 4 | D16: Cash held at start to fund feed, wages and vet before revenue builds.
A17: 2. Financing
A18: Loan as % of capex (excl. working capital) | B18: % | C18: 0.4 | D18: Set 0 for all-equity. Loan is drawn in Year 0.
A19: Loan interest rate | B19: % p.a. | C19: 0.14 | D19: Interest on opening balance.
A20: Loan tenor (max 8) | B20: years | C20: 5 | D20: Principal repaid in equal instalments after grace period.
A21: Grace period (principal) | B21: years | C21: 1 | D21: Interest still paid during grace.
A22: 3. Land
A23: Total land available | B23: ha | C23: 150 | D23: Pasture + fodder plots + buildings.
A24: Buy land? (1 = buy, 0 = lease) | B24: switch | C24: 0 | D24: If 1, land price goes into capex and no lease is paid.
A25: Land lease rate | B25: per ha / yr | C25: 25
A26: Land purchase price | B26: per ha | C26: 900
A27: Grazing land per beef cow (incl. followers) | B27: ha / cow | C27: 2.5 | D27: Depends on rainfall and pasture quality: 1-4 ha typical in tropics.
A28: Fodder land per dairy cow (zero/semi-grazing) | B28: ha / cow | C28: 0.4 | D28: Napier, maize silage, hay.
A29: 4. Dairy herd
A30: Dairy cows at start | B30: head | C30: 40 | D30: Crossbred (e.g. Friesian x Zebu) in-calf heifers or cows.
A31: Purchase price per dairy cow | B31: per head | C31: 1200 | D31: Replace with local quote.
A32: Dairy calving rate | B32: % cows / yr | C32: 0.85 | D32: Calves born per cow per year.
A33: Milk per lactation (305 days) | B33: litres / cow | C33: 3500 | D33: About 11.5 L/day average. Indigenous types: 800-1500. Good crossbreds: 3000-5000.
A34: Dairy cull rate | B34: % cows / yr | C34: 0.2 | D34: Sold as cull cows.
A35: Dairy cow mortality | B35: % cows / yr | C35: 0.04
A36: Dairy calf mortality | B36: % born | C36: 0.08 | D36: Birth to sale/weaning.
A37: Female share of calves | B37: % | C37: 0.5 | D37: Applies to both herds.
A38: Dairy heifers retained as replacements | B38: % of heifers | C38: 0.7 | D38: Rest sold. Retained heifers join the milking herd 2 years later.
A39: Dairy bull calf sale price | B39: per head | C39: 120 | D39: Sold at ~3 months.
A40: Surplus dairy heifer sale price | B40: per head | C40: 400 | D40: Sold at ~6 months. Higher if sold in-calf.
A41: Dairy cull cow price | B41: per head | C41: 550
...

Sheet Scenarios
A1: Scenario selector
A2: Choose 1 = Base, 2 = Downside, 3 = Upside. The 'Active' column feeds the whole model.
A3: Active scenario (1 / 2 / 3) | C3: 1 | D3: =CHOOSE($C$3,"Base","Downside","Upside") -> Base
A5: Lever | B5: Applies to | C5: Base | D5: Downside | E5: Upside | F5: Active
A6: Milk price multiplier | B6: Raw and processed milk price | C6: 1 | D6: 0.85 | E6: 1.1 | F6: =CHOOSE($C$3,C6,D6,E6) -> 1
A7: Animal price multiplier | B7: Calves, heifers, cull cows | C7: 1 | D7: 0.85 | E7: 1.1 | F7: =CHOOSE($C$3,C7,D7,E7) -> 1
A8: Feed cost multiplier | B8: All feed lines | C8: 1 | D8: 1.2 | E8: 0.95 | F8: =CHOOSE($C$3,C8,D8,E8) -> 1
A9: Other cost multiplier | B9: Health, labour, overheads | C9: 1 | D9: 1.1 | E9: 1 | F9: =CHOOSE($C$3,C9,D9,E9) -> 1
A10: Calving rate change (points) | B10: Added to both herds' calving rates | C10: 0 | D10: -0.08 | E10: 0.04 | F10: =CHOOSE($C$3,C10,D10,E10) -> 0
A11: Milk yield multiplier | B11: Litres per lactation | C11: 1 | D11: 0.9 | E11: 1.08 | F11: =CHOOSE($C$3,C11,D11,E11) -> 1
A12: Mortality multiplier | B12: Cow and calf mortality | C12: 1 | D12: 1.5 | E12: 0.8 | F12: =CHOOSE($C$3,C12,D12,E12) -> 1
A14: Downside and upside multipliers are illustrative. Replace with values reflecting your own risk view (e.g. a drought year, feed price spike, disease outbreak).

Sheet Capex
A1: Capital expenditure (Year 0 investment)
A2: Quantity x unit cost. Blue = input. Depreciation is straight line over the life shown (0 = not depreciated).
A4: Item | B4: Category | C4: Qty | D4: Unit | E4: Unit cost | F4: Total | G4: Life (yrs) | H4: Salvage % | I4: Annual dep.
A5: Dairy foundation cows (crossbred, in-calf) | B5: Livestock | C5: =Assumptions!$C$30 -> 40 | D5: head | E5: =Assumptions!$C$31 -> 1200 | F5: =C5*E5 -> 48000 | G5: =Assumptions!$C$107 -> 6 | H5: =Assumptions!$C$108 -> 0.45 | I5: =IF(G5>0,F5*(1-H5)/G5,0) -> 4400
A6: Beef foundation cows | B6: Livestock | C6: =Assumptions!$C$43 -> 30 | D6: head | E6: =Assumptions!$C$44 -> 500 | F6: =C6*E6 -> 15000 | G6: =Assumptions!$C$107 -> 6 | H6: =Assumptions!$C$108 -> 0.45 | I6: =IF(G6>0,F6*(1-H6)/G6,0) -> 1375
A7: Replacement dairy heifers bought at start (yearlings) | B7: Livestock | C7: =ROUND(Assumptions!$C$30*Assumptions!$C$102,0) -> 8 | D7: head | E7: =Assumptions!$C$31*Assumptions!$C$103 -> 720 | F7: =C7*E7 -> 5760 | G7: =Assumptions!$C$107 -> 6 | H7: =Assumptions!$C$108 -> 0.45 | I7: =IF(G7>0,F7*(1-H7)/G7,0) -> 528
A8: Replacement beef heifers bought at start (yearlings) | B8: Livestock | C8: =ROUND(Assumptions!$C$43*Assumptions!$C$102,0) -> 6 | D8: head | E8: =Assumptions!$C$44*Assumptions!$C$103 -> 300 | F8: =C8*E8 -> 1800 | G8: =Assumptions!$C$107 -> 6 | H8: =Assumptions!$C$108 -> 0.45 | I8: =IF(G8>0,F8*(1-H8)/G8,0) -> 165
A9: Breeding bulls | B9: Livestock | C9: =Assumptions!$C$45 -> 2 | D9: head | E9: =Assumptions!$C$46 -> 900 | F9: =C9*E9 -> 1800 | G9: 5 | H9: 0.4 | I9: =IF(G9>0,F9*(1-H9)/G9,0) -> 216
A10: Transport, quarantine and disease screening | B10: Livestock | C10: =Assumptions!$C$30+Assumptions!$C$43+Assumptions!$C$45+ROUND(Assumptions!$C$30*Assumptions!$C$102,0)+ROUND(Assumptions!$C$43*Assumptions!$C$102,0) -> 86 | D10: head | E10: 25 | F10: =C10*E10 -> 2150 | G10: 0 | H10: 0 | I10: =IF(G10>0,F10*(1-H10)/G10,0) -> 0
A11: Dairy cow shed | B11: Buildings | C11: =Assumptions!$C$30*Assumptions!$C$100 -> 180 | D11: sq m | E11: 85 | F11: =C11*E11 -> 15300 | G11: 20 | H11: 0 | I11: =IF(G11>0,F11*(1-H11)/G11,0) -> 765
A12: Calf pens and maternity paddock shelter | B12: Buildings | C12: 60 | D12: sq m | E12: 70 | F12: =C12*E12 -> 4200 | G12: 20 | H12: 0 | I12: =IF(G12>0,F12*(1-H12)/G12,0) -> 210
A13: Milking parlour and milk room | B13: Buildings | C13: 30 | D13: sq m | E13: 150 | F13: =C13*E13 -> 4500 | G13: 20 | H13: 0 | I13: =IF(G13>0,F13*(1-H13)/G13,0) -> 225
A14: Feed and hay store | B14: Buildings | C14: 80 | D14: sq m | E14: 45 | F14: =C14*E14 -> 3600 | G14: 20 | H14: 0 | I14: =IF(G14>0,F14*(1-H14)/G14,0) -> 180
A15: Staff house and farm office | B15: Buildings | C15: 1 | D15: lump | E15: 4500 | F15: =C15*E15 -> 4500 | G15: 20 | H15: 0 | I15: =IF(G15>0,F15*(1-H15)/G15,0) -> 225
A16: Concrete yards and drainage | B16: Buildings | C16: 300 | D16: sq m | E16: 18 | F16: =C16*E16 -> 5400 | G16: 15 | H16: 0 | I16: =IF(G16>0,F16*(1-H16)/G16,0) -> 360
A17: Borehole, pump, tank and piping | B17: Water | C17: 1 | D17: lump | E17: 9000 | F17: =C17*E17 -> 9000 | G17: 10 | H17: 0 | I17: =IF(G17>0,F17*(1-H17)/G17,0) -> 900
A18: Troughs and field water points | B18: Water | C18: 12 | D18: no. | E18: 150 | F18: =C18*E18 -> 1800 | G18: 10 | H18: 0 | I18: =IF(G18>0,F18*(1-H18)/G18,0) -> 180
A19: Cattle crush, race and holding pens | B19: Equipment | C19: 1 | D19: lump | E19: 3000 | F19: =C19*E19 -> 3000 | G19: 10 | H19: 0 | I19: =IF(G19>0,F19*(1-H19)/G19,0) -> 300
A20: Dip / spray race or sprayers | B20: Equipment | C20: 1 | D20: lump | E20: 900 | F20: =C20*E20 -> 900 | G20: 8 | H20: 0 | I20: =IF(G20>0,F20*(1-H20)/G20,0) -> 112.5
A21: Milking machine or bucket milking units | B21: Equipment | C21: 1 | D21: lump | E21: 3500 | F21: =C21*E21 -> 3500 | G21: 8 | H21: 0 | I21: =IF(G21>0,F21*(1-H21)/G21,0) -> 437.5
A22: Milk cooling tank (500 L) and cans | B22: Equipment | C22: 1 | D22: lump | E22: 3800 | F22: =C22*E22 -> 3800 | G22: 8 | H22: 0 | I22: =IF(G22>0,F22*(1-H22)/G22,0) -> 475
A23: Chaff cutter / forage chopper | B23: Equipment | C23: 1 | D23: lump | E23: 1500 | F23: =C23*E23 -> 1500 | G23: 8 | H23: 0 | I23: =IF(G23>0,F23*(1-H23)/G23,0) -> 187.5
... A27: Paddock subdivisions and electric fencing | B27: Fencing | C27: 1 | D27: lump | E27: 3500 | F27: =C27*E27 -> 3500 | G27: 8 | H27: 0 | I27: =IF(G27>0,F27*(1-H27)/G27,0) -> 437.5
A28: Land purchase (only if 'buy' switch = 1) | B28: Land | C28: =Assumptions!$C$23*Assumptions!$C$24 -> 0 | D28: ha | E28: =Assumptions!$C$26 -> 900 | F28: =C28*E28 -> 0 | G28: 0 | H28: 0 | I28: =IF(G28>0,F28*(1-H28)/G28,0) -> 0
A29: Pasture improvement / oversowing | B29: Pasture | C29: 30 | D29: ha | E29: 120 | F29: =C29*E29 -> 3600 | G29: 10 | H29: 0 | I29: =IF(G29>0,F29*(1-H29)/G29,0) -> 360
A30: Fodder plots (Napier, legumes) establishment | B30: Pasture | C30: 6 | D30: ha | E30: 700 | F30: =C30*E30 -> 4200 | G30: 8 | H30: 0 | I30: =IF(G30>0,F30*(1-H30)/G30,0) -> 525
A31: Used pick-up truck | B31: Vehicles | C31: 1 | D31: no. | E31: 8000 | F31: =C31*E31 -> 8000 | G31: 8 | H31: 0.2 | I31: =IF(G31>0,F31*(1-H31)/G31,0) -> 800
A32: Motorbikes | B32: Vehicles | C32: 2 | D32: no. | E32: 1500 | F32: =C32*E32 -> 3000 | G32: 5 | H32: 0.1 | I32: =IF(G32>0,F32*(1-H32)/G32,0) -> 540
A33: Trailer for animals and fodder | B33: Vehicles | C33: 1 | D33: no. | E33: 2500 | F33: =C33*E33 -> 2500 | G33: 10 | H33: 0 | I33: =IF(G33>0,F33*(1-H33)/G33,0) -> 250
A34: Registration, licences, legal, health certificates | B34: Pre-operating | C34: 1 | D34: lump | E34: 1500 | F34: =C34*E34 -> 1500 | G34: 5 | H34: 0 | I34: =IF(G34>0,F34*(1-H34)/G34,0) -> 300
A35: Recruitment and training | B35: Pre-operating | C35: 1 | D35: lump | E35: 1000 | F35: =C35*E35 -> 1000 | G35: 3 | H35: 0 | I35: =IF(G35>0,F35*(1-H35)/G35,0) -> 333.33333
A36: Contingency on non-livestock, non-land items | B36: Contingency | C36: 1 | D36: lump | E36: =SUMIFS(F5:F35,B5:B35,"<>Livestock",B5:B35,"<>Land")*Assumptions!$C$101 -> 10310 | F36: =C36*E36 -> 10310 | G36: 15 | H36: 0 | I36: =IF(G36>0,F36*(1-H36)/G36,0) -> 687.33333
A37: TOTAL INITIAL CAPEX | F37: =SUM(F5:F36) -> 187920 | I37: =SUM(I5:I36) -> 16941.333
A39: Summary by category
A40: Category | F40: Amount | G40: % of total
A41: Livestock | F41: =SUMIFS($F$5:$F$36,$B$5:$B$36,A41) -> 74510 | G41: =IF($F$37>0,F41/$F$37,0) -> 0.39649851
A42: Buildings | F42: =SUMIFS($F$5:$F$36,$B$5:$B$36,A42) -> 37500 | G42: =IF($F$37>0,F42/$F$37,0) -> 0.199553
A43: Water | F43: =SUMIFS($F$5:$F$36,$B$5:$B$36,A43) -> 10800 | G43: =IF($F$37>0,F43/$F$37,0) -> 0.057471264
A44: Equipment | F44: =SUMIFS($F$5:$F$36,$B$5:$B$36,A44) -> 16500 | G44: =IF($F$37>0,F44/$F$37,0) -> 0.087803321
A45: Fencing | F45: =SUMIFS($F$5:$F$36,$B$5:$B$36,A45) -> 14500 | G45: =IF($F$37>0,F45/$F$37,0) -> 0.077160494
...

Sheet Herd
A1: Herd dynamics (head)
A2: Heifers retained in year t join the cow herd at the start of year t+2. Attrition (culls + deaths) is applied to opening cows.
A4: Line item | B4: Unit | C4: 0 | D4: 1 | E4: 2 | F4: 3 | G4: 4 | H4: 5 | I4: 6 | J4: 7 | K4: 8
A5: DAIRY HERD
A6: Dairy cows (opening) | B6: head | C6: =Assumptions!$C$30 -> 40 | D6: =C6 -> 40 | E6: =D6*(1-D7)+C13 -> 38.4 | F6: =E6*(1-E7)+D13 -> 40.132 | G6: =F6*(1-F7)+E13 -> 41.0104 | H6: =G6*(1-G7)+F13 -> 42.152032 | I6: =H6*(1-H7)+G13 -> 43.260091 | J6: =I6*(1-I7)+H13 -> 44.414681 | K6: =J6*(1-J7)+I13 -> 45.595444
A7: Attrition rate (cull + mortality) | B7: % | D7: =Assumptions!$C$34+Assumptions!$C$35*Scenarios!$F$12 -> 0.24 | E7: =Assumptions!$C$34+Assumptions!$C$35*Scenarios!$F$12 -> 0.24 | F7: =Assumptions!$C$34+Assumptions!$C$35*Scenarios!$F$12 -> 0.24 | G7: =Assumptions!$C$34+Assumptions!$C$35*Scenarios!$F$12 -> 0.24 | H7: =Assumptions!$C$34+Assumptions!$C$35*Scenarios!$F$12 -> 0.24 | I7: =Assumptions!$C$34+Assumptions!$C$35*Scenarios!$F$12 -> 0.24 | J7: =Assumptions!$C$34+Assumptions!$C$35*Scenarios!$F$12 -> 0.24 | K7: =Assumptions!$C$34+Assumptions!$C$35*Scenarios!$F$12 -> 0.24
A8: Calving rate (scenario-adjusted) | B8: % | D8: =MIN(0.95,MAX(0,Assumptions!$C$32+Scenarios!$F$10)) -> 0.85 | E8: =MIN(0.95,MAX(0,Assumptions!$C$32+Scenarios!$F$10)) -> 0.85 | F8: =MIN(0.95,MAX(0,Assumptions!$C$32+Scenarios!$F$10)) -> 0.85 | G8: =MIN(0.95,MAX(0,Assumptions!$C$32+Scenarios!$F$10)) -> 0.85 | H8: =MIN(0.95,MAX(0,Assumptions!$C$32+Scenarios!$F$10)) -> 0.85 | I8: =MIN(0.95,MAX(0,Assumptions!$C$32+Scenarios!$F$10)) -> 0.85 | J8: =MIN(0.95,MAX(0,Assumptions!$C$32+Scenarios!$F$10)) -> 0.85 | K8: =MIN(0.95,MAX(0,Assumptions!$C$32+Scenarios!$F$10)) -> 0.85
A9: Calves born | B9: head | D9: =D6*D8 -> 34 | E9: =E6*E8 -> 32.64 | F9: =F6*F8 -> 34.1122 | G9: =G6*G8 -> 34.85884 | H9: =H6*H8 -> 35.829228 | I9: =I6*I8 -> 36.771077 | J9: =J6*J8 -> 37.752478 | K9: =K6*K8 -> 38.756128
A10: Calves surviving | B10: head | D10: =D9*(1-Assumptions!$C$36*Scenarios!$F$12) -> 31.28 | E10: =E9*(1-Assumptions!$C$36*Scenarios!$F$12) -> 30.0288 | F10: =F9*(1-Assumptions!$C$36*Scenarios!$F$12) -> 31.383224 | G10: =G9*(1-Assumptions!$C$36*Scenarios!$F$12) -> 32.070133 | H10: =H9*(1-Assumptions!$C$36*Scenarios!$F$12) -> 32.962889 | I10: =I9*(1-Assumptions!$C$36*Scenarios!$F$12) -> 33.829391 | J10: =J9*(1-Assumptions!$C$36*Scenarios!$F$12) -> 34.73228 | K10: =K9*(1-Assumptions!$C$36*Scenarios!$F$12) -> 35.655637
A11: Bull calves (sold) | B11: head | D11: =D10*(1-Assumptions!$C$37) -> 15.64 | E11: =E10*(1-Assumptions!$C$37) -> 15.0144 | F11: =F10*(1-Assumptions!$C$37) -> 15.691612 | G11: =G10*(1-Assumptions!$C$37) -> 16.035066 | H11: =H10*(1-Assumptions!$C$37) -> 16.481445 | I11: =I10*(1-Assumptions!$C$37) -> 16.914696 | J11: =J10*(1-Assumptions!$C$37) -> 17.36614 | K11: =K10*(1-Assumptions!$C$37) -> 17.827819
A12: Heifer calves | B12: head | D12: =D10*Assumptions!$C$37 -> 15.64 | E12: =E10*Assumptions!$C$37 -> 15.0144 | F12: =F10*Assumptions!$C$37 -> 15.691612 | G12: =G10*Assumptions!$C$37 -> 16.035066 | H12: =H10*Assumptions!$C$37 -> 16.481445 | I12: =I10*Assumptions!$C$37 -> 16.914696 | J12: =J10*Assumptions!$C$37 -> 17.36614 | K12: =K10*Assumptions!$C$37 -> 17.827819
A13: Heifers retained (Year 0 = bought at start) | B13: head | C13: =ROUND(Assumptions!$C$30*Assumptions!$C$102,0) -> 8 | D13: =D12*Assumptions!$C$38 -> 10.948 | E13: =E12*Assumptions!$C$38 -> 10.51008 | F13: =F12*Assumptions!$C$38 -> 10.984128 | G13: =G12*Assumptions!$C$38 -> 11.224546 | H13: =H12*Assumptions!$C$38 -> 11.537011 | I13: =I12*Assumptions!$C$38 -> 11.840287 | J13: =J12*Assumptions!$C$38 -> 12.156298 | K13: =K12*Assumptions!$C$38 -> 12.479473
A14: Surplus heifers sold | B14: head | D14: =D12-D13 -> 4.692 | E14: =E12-E13 -> 4.50432 | F14: =F12-F13 -> 4.7074836 | G14: =G12-G13 -> 4.8105199 | H14: =H12-H13 -> 4.9444334 | I14: =I12-I13 -> 5.0744087 | J14: =J12-J13 -> 5.209842 | K14: =K12-K13 -> 5.3483456
A15: Cull cows sold | B15: head | D15: =D6*Assumptions!$C$34 -> 8 | E15: =E6*Assumptions!$C$34 -> 7.68 | F15: =F6*Assumptions!$C$34 -> 8.0264 | G15: =G6*Assumptions!$C$34 -> 8.20208 | H15: =H6*Assumptions!$C$34 -> 8.4304065 | I15: =I6*Assumptions!$C$34 -> 8.6520182 | J15: =J6*Assumptions!$C$34 -> 8.8829361 | K15: =K6*Assumptions!$C$34 -> 9.1190888
A16: Cow deaths | B16: head | D16: =D6*Assumptions!$C$35*Scenarios!$F$12 -> 1.6 | E16: =E6*Assumptions!$C$35*Scenarios!$F$12 -> 1.536 | F16: =F6*Assumptions!$C$35*Scenarios!$F$12 -> 1.60528 | G16: =G6*Assumptions!$C$35*Scenarios!$F$12 -> 1.640416 | H16: =H6*Assumptions!$C$35*Scenarios!$F$12 -> 1.6860813 | I16: =I6*Assumptions!$C$35*Scenarios!$F$12 -> 1.7304036 | J16: =J6*Assumptions!$C$35*Scenarios!$F$12 -> 1.7765872 | K16: =K6*Assumptions!$C$35*Scenarios!$F$12 -> 1.8238178
A17: Heifers in rearing (head-years) | B17: hd-yr | D17: =0.5*D13+C13 -> 13.474 | E17: =0.5*E13+D13 -> 16.20304 | F17: =0.5*F13+E13 -> 16.002144 | G17: =0.5*G13+F13 -> 16.596402 | H17: =0.5*H13+G13 -> 16.993052 | I17: =0.5*I13+H13 -> 17.457155 | J17: =0.5*J13+I13 -> 17.918436 | K17: =0.5*K13+J13 -> 18.396035
A18: Milk produced | B18: litres | D18: =D6*D8*Assumptions!$C$33*Scenarios!$F$11 -> 119000 | E18: =E6*E8*Assumptions!$C$33*Scenarios!$F$11 -> 114240 | F18: =F6*F8*Assumptions!$C$33*Scenarios!$F$11 -> 119392.7 | G18: =G6*G8*Assumptions!$C$33*Scenarios!$F$11 -> 122005.94 | H18: =H6*H8*Assumptions!$C$33*Scenarios!$F$11 -> 125402.3 | I18: =I6*I8*Assumptions!$C$33*Scenarios!$F$11 -> 128698.77 | J18: =J6*J8*Assumptions!$C$33*Scenarios!$F$11 -> 132133.67 | K18: =K6*K8*Assumptions!$C$33*Scenarios!$F$11 -> 135646.45
A19: BEEF HERD
A20: Beef cows (opening) | B20: head | C20: =Assumptions!$C$43 -> 30 | D20: =C20 -> 30 | E20: =D20*(1-D21)+C26 -> 31.5 | F20: =E20*(1-E21)+D26 -> 32.295 | G20: =F20*(1-F21)+E26 -> 33.24675 | H20: =G20*(1-G21)+F26 -> 34.202017 | I20: =H20*(1-H21)+G26 -> 35.189117 | J20: =I20*(1-I21)+H26 -> 36.203921 | K20: =J20*(1-J21)+I26 -> 37.24813
A21: Attrition rate (cull + mortality) | B21: % | D21: =Assumptions!$C$50+Assumptions!$C$51*Scenarios!$F$12 -> 0.15 | E21: =Assumptions!$C$50+Assumptions!$C$51*Scenarios!$F$12 -> 0.15 | F21: =Assumptions!$C$50+Assumptions!$C$51*Scenarios!$F$12 -> 0.15 | G21: =Assumptions!$C$50+Assumptions!$C$51*Scenarios!$F$12 -> 0.15 | H21: =Assumptions!$C$50+Assumptions!$C$51*Scenarios!$F$12 -> 0.15 | I21: =Assumptions!$C$50+Assumptions!$C$51*Scenarios!$F$12 -> 0.15 | J21: =Assumptions!$C$50+Assumptions!$C$51*Scenarios!$F$12 -> 0.15 | K21: =Assumptions!$C$50+Assumptions!$C$51*Scenarios!$F$12 -> 0.15
A22: Calving rate (scenario-adjusted) | B22: % | D22: =MIN(0.95,MAX(0,Assumptions!$C$48+Scenarios!$F$10)) -> 0.8 | E22: =MIN(0.95,MAX(0,Assumptions!$C$48+Scenarios!$F$10)) -> 0.8 | F22: =MIN(0.95,MAX(0,Assumptions!$C$48+Scenarios!$F$10)) -> 0.8 | G22: =MIN(0.95,MAX(0,Assumptions!$C$48+Scenarios!$F$10)) -> 0.8 | H22: =MIN(0.95,MAX(0,Assumptions!$C$48+Scenarios!$F$10)) -> 0.8 | I22: =MIN(0.95,MAX(0,Assumptions!$C$48+Scenarios!$F$10)) -> 0.8 | J22: =MIN(0.95,MAX(0,Assumptions!$C$48+Scenarios!$F$10)) -> 0.8 | K22: =MIN(0.95,MAX(0,Assumptions!$C$48+Scenarios!$F$10)) -> 0.8
A23: Calves born | B23: head | D23: =D20*D22 -> 24 | E23: =E20*E22 -> 25.2 | F23: =F20*F22 -> 25.836 | G23: =G20*G22 -> 26.5974 | H23: =H20*H22 -> 27.361614 | I23: =I20*I22 -> 28.151294 | J23: =J20*J22 -> 28.963136 | K23: =K20*K22 -> 29.798504
A24: Calves surviving to weaning | B24: head | D24: =D23*(1-Assumptions!$C$49*Scenarios!$F$12) -> 22.08 | E24: =E23*(1-Assumptions!$C$49*Scenarios!$F$12) -> 23.184 | F24: =F23*(1-Assumptions!$C$49*Scenarios!$F$12) -> 23.76912 | G24: =G23*(1-Assumptions!$C$49*Scenarios!$F$12) -> 24.469608 | H24: =H23*(1-Assumptions!$C$49*Scenarios!$F$12) -> 25.172685 | I24: =I23*(1-Assumptions!$C$49*Scenarios!$F$12) -> 25.89919 | J24: =J23*(1-Assumptions!$C$49*Scenarios!$F$12) -> 26.646086 | K24: =K23*(1-Assumptions!$C$49*Scenarios!$F$12) -> 27.414624
A25: Heifer calves | B25: head | D25: =D24*Assumptions!$C$37 -> 11.04 | E25: =E24*Assumptions!$C$37 -> 11.592 | F25: =F24*Assumptions!$C$37 -> 11.88456 | G25: =G24*Assumptions!$C$37 -> 12.234804 | H25: =H24*Assumptions!$C$37 -> 12.586342 | I25: =I24*Assumptions!$C$37 -> 12.949595 | J25: =J24*Assumptions!$C$37 -> 13.323043 | K25: =K24*Assumptions!$C$37 -> 13.707312
A26: Heifers retained (Year 0 = bought at start) | B26: head | C26: =ROUND(Assumptions!$C$43*Assumptions!$C$102,0) -> 6 | D26: =D25*Assumptions!$C$52 -> 5.52 | E26: =E25*Assumptions!$C$52 -> 5.796 | F26: =F25*Assumptions!$C$52 -> 5.94228 | G26: =G25*Assumptions!$C$52 -> 6.117402 | H26: =H25*Assumptions!$C$52 -> 6.2931712 | I26: =I25*Assumptions!$C$52 -> 6.4747975 | J26: =J25*Assumptions!$C$52 -> 6.6615214 | K26: =K25*Assumptions!$C$52 -> 6.8536559
A27: Weaners sold (both sexes) | B27: head | D27: =D24-D26 -> 16.56 | E27: =E24-E26 -> 17.388 | F27: =F24-F26 -> 17.82684 | G27: =G24-G26 -> 18.352206 | H27: =H24-H26 -> 18.879514 | I27: =I24-I26 -> 19.424393 | J27: =J24-J26 -> 19.984564 | K27: =K24-K26 -> 20.560968
A28: Cull cows sold | B28: head | D28: =D20*Assumptions!$C$50 -> 3.6 | E28: =E20*Assumptions!$C$50 -> 3.78 | F28: =F20*Assumptions!$C$50 -> 3.8754 | G28: =G20*Assumptions!$C$50 -> 3.98961 | H28: =H20*Assumptions!$C$50 -> 4.1042421 | I28: =I20*Assumptions!$C$50 -> 4.222694 | J28: =J20*Assumptions!$C$50 -> 4.3444705 | K28: =K20*Assumptions!$C$50 -> 4.4697756
A29: Cow deaths | B29: head | D29: =D20*Assumptions!$C$51*Scenarios!$F$12 -> 0.9 | E29: =E20*Assumptions!$C$51*Scenarios!$F$12 -> 0.945 | F29: =F20*Assumptions!$C$51*Scenarios!$F$12 -> 0.96885 | G29: =G20*Assumptions!$C$51*Scenarios!$F$12 -> 0.9974025 | H29: =H20*Assumptions!$C$51*Scenarios!$F$12 -> 1.0260605 | I29: =I20*Assumptions!$C$51*Scenarios!$F$12 -> 1.0556735 | J29: =J20*Assumptions!$C$51*Scenarios!$F$12 -> 1.0861176 | K29: =K20*Assumptions!$C$51*Scenarios!$F$12 -> 1.1174439
A30: Heifers in rearing (head-years) | B30: hd-yr | D30: =0.5*D26+C26 -> 8.76 | E30: =0.5*E26+D26 -> 8.418 | F30: =0.5*F26+E26 -> 8.76714 | G30: =0.5*G26+F26 -> 9.000981 | H30: =0.5*H26+G26 -> 9.2639876 | I30: =0.5*I26+H26 -> 9.53057 | J30: =0.5*J26+I26 -> 9.8055582 | K30: =0.5*K26+J26 -> 10.088349
A31: Weaner live weight sold | B31: kg | D31: =D27*Assumptions!$C$53 -> 2484 | E31: =E27*Assumptions!$C$53 -> 2608.2 | F31: =F27*Assumptions!$C$53 -> 2674.026 | G31: =G27*Assumptions!$C$53 -> 2752.8309 | H31: =H27*Assumptions!$C$53 -> 2831.927 | I31: =I27*Assumptions!$C$53 -> 2913.6589 | J31: =J27*Assumptions!$C$53 -> 2997.6846 | K31: =K27*Assumptions!$C$53 -> 3084.1452
A32: TOTALS AND LAND CAPACITY
A33: Total breeding cows | B33: head | C33: =C6+C20 -> 70 | D33: =D6+D20 -> 70 | E33: =E6+E20 -> 69.9 | F33: =F6+F20 -> 72.427 | G33: =G6+G20 -> 74.25715 | H33: =H6+H20 -> 76.35405 | I33: =I6+I20 -> 78.449208 | J33: =J6+J20 -> 80.618601 | K33: =K6+K20 -> 82.843574
A34: Total heifers in rearing | B34: hd-yr | D34: =D17+D30 -> 22.234 | E34: =E17+E30 -> 24.62104 | F34: =F17+F30 -> 24.769284 | G34: =G17+G30 -> 25.597383 | H34: =H17+H30 -> 26.25704 | I34: =I17+I30 -> 26.987725 | J34: =J17+J30 -> 27.723994 | K34: =K17+K30 -> 28.484384
A35: Animals sold (all classes) | B35: head | D35: =D11+D14+D15+D27+D28 -> 48.492 | E35: =E11+E14+E15+E27+E28 -> 48.36672 | F35: =F11+F14+F15+F27+F28 -> 50.127736 | G35: =G11+G14+G15+G27+G28 -> 51.389482 | H35: =H11+H14+H15+H27+H28 -> 52.84004 | I35: =I11+I14+I15+I27+I28 -> 54.288209 | J35: =J11+J14+J15+J27+J28 -> 55.787953 | K35: =K11+K14+K15+K27+K28 -> 57.325996
A36: Land required | B36: ha | D36: =D20*Assumptions!$C$27+D6*Assumptions!$C$28+D34*Assumptions!$C$27*0.5 -> 118.7925 | E36: =E20*Assumptions!$C$27+E6*Assumptions!$C$28+E34*Assumptions!$C$27*0.5 -> 124.8863 | F36: =F20*Assumptions!$C$27+F6*Assumptions!$C$28+F34*Assumptions!$C$27*0.5 -> 127.75191 | G36: =G20*Assumptions!$C$27+G6*Assumptions!$C$28+G34*Assumptions!$C$27*0.5 -> 131.51776 | H36: =H20*Assumptions!$C$27+H6*Assumptions!$C$28+H34*Assumptions!$C$27*0.5 -> 135.18716 | I36: =I20*Assumptions!$C$27+I6*Assumptions!$C$28+I34*Assumptions!$C$27*0.5 -> 139.01148 | J36: =J20*Assumptions!$C$27+J6*Assumptions!$C$28+J34*Assumptions!$C$27*0.5 -> 142.93067 | K36: =K20*Assumptions!$C$27+K6*Assumptions!$C$28+K34*Assumptions!$C$27*0.5 -> 146.96398
A37: Land available | B37: ha | D37: =Assumptions!$C$23 -> 150 | E37: =Assumptions!$C$23 -> 150 | F37: =Assumptions!$C$23 -> 150 | G37: =Assumptions!$C$23 -> 150 | H37: =Assumptions!$C$23 -> 150 | I37: =Assumptions!$C$23 -> 150 | J37: =Assumptions!$C$23 -> 150 | K37: =Assumptions!$C$23 -> 150
A38: Land utilisation | B38: % | D38: =IF(D37>0,D36/D37,0) -> 0.79195 | E38: =IF(E37>0,E36/E37,0) -> 0.83257533 | F38: =IF(F37>0,F36/F37,0) -> 0.85167937 | G38: =IF(G37>0,G36/G37,0) -> 0.87678509 | H38: =IF(H37>0,H36/H37,0) -> 0.90124771 | I38: =IF(I37>0,I36/I37,0) -> 0.92674323 | J38: =IF(J37>0,J36/J37,0) -> 0.95287111 | K38: =IF(K37>0,K36/K37,0) -> 0.97975988
A39: Capacity check | D39: =IF(D38>1,"OVER CAPACITY","OK") -> OK | E39: =IF(E38>1,"OVER CAPACITY","OK") -> OK | F39: =IF(F38>1,"OVER CAPACITY","OK") -> OK | G39: =IF(G38>1,"OVER CAPACITY","OK") -> OK | H39: =IF(H38>1,"OVER CAPACITY","OK") -> OK | I39: =IF(I38>1,"OVER CAPACITY","OK") -> OK | J39: =IF(J38>1,"OVER CAPACITY","OK") -> OK | K39: =IF(K38>1,"OVER CAPACITY","OK") -> OK

Sheet Revenue
A1: Revenue streams (currency units)
A2: Prices escalate with the inflation inputs and are multiplied by the active scenario levers.
A4: Line item | B4: Unit | C4: 0 | D4: 1 | E4: 2 | F4: 3 | G4: 4 | H4: 5 | I4: 6 | J4: 7 | K4: 8
A5: PRICE INDICES
A6: Milk price index | B6: index | D6: =(1+Assumptions!$C$10)^(D$4-1) -> 1 | E6: =(1+Assumptions!$C$10)^(E$4-1) -> 1.05 | F6: =(1+Assumptions!$C$10)^(F$4-1) -> 1.1025 | G6: =(1+Assumptions!$C$10)^(G$4-1) -> 1.157625 | H6: =(1+Assumptions!$C$10)^(H$4-1) -> 1.2155063 | I6: =(1+Assumptions!$C$10)^(I$4-1) -> 1.2762816 | J6: =(1+Assumptions!$C$10)^(J$4-1) -> 1.3400956 | K6: =(1+Assumptions!$C$10)^(K$4-1) -> 1.4071004
A7: Animal price index | B7: index | D7: =(1+Assumptions!$C$11)^(D$4-1) -> 1 | E7: =(1+Assumptions!$C$11)^(E$4-1) -> 1.05 | F7: =(1+Assumptions!$C$11)^(F$4-1) -> 1.1025 | G7: =(1+Assumptions!$C$11)^(G$4-1) -> 1.157625 | H7: =(1+Assumptions!$C$11)^(H$4-1) -> 1.2155063 | I7: =(1+Assumptions!$C$11)^(I$4-1) -> 1.2762816 | J7: =(1+Assumptions!$C$11)^(J$4-1) -> 1.3400956 | K7: =(1+Assumptions!$C$11)^(K$4-1) -> 1.4071004
A8: General cost / other-income index | B8: index | D8: =(1+Assumptions!$C$12)^(D$4-1) -> 1 | E8: =(1+Assumptions!$C$12)^(E$4-1) -> 1.05 | F8: =(1+Assumptions!$C$12)^(F$4-1) -> 1.1025 | G8: =(1+Assumptions!$C$12)^(G$4-1) -> 1.157625 | H8: =(1+Assumptions!$C$12)^(H$4-1) -> 1.2155063 | I8: =(1+Assumptions!$C$12)^(I$4-1) -> 1.2762816 | J8: =(1+Assumptions!$C$12)^(J$4-1) -> 1.3400956 | K8: =(1+Assumptions!$C$12)^(K$4-1) -> 1.4071004
A9: DAIRY ENTERPRISE
A10: Raw milk sales | D10: =Herd!D18*(1-Assumptions!$C$59)*Assumptions!$C$58*Scenarios!$F$6*D6 -> 64260 | E10: =Herd!E18*(1-Assumptions!$C$59)*Assumptions!$C$58*Scenarios!$F$6*E6 -> 64774.08 | F10: =Herd!F18*(1-Assumptions!$C$59)*Assumptions!$C$58*Scenarios!$F$6*F6 -> 71080.444 | G10: =Herd!G18*(1-Assumptions!$C$59)*Assumptions!$C$58*Scenarios!$F$6*G6 -> 76268.048 | H10: =Herd!H18*(1-Assumptions!$C$59)*Assumptions!$C$58*Scenarios!$F$6*H6 -> 82310.729 | I10: =Herd!I18*(1-Assumptions!$C$59)*Assumptions!$C$58*Scenarios!$F$6*I6 -> 88698.169 | J10: =Herd!J18*(1-Assumptions!$C$59)*Assumptions!$C$58*Scenarios!$F$6*J6 -> 95618.751 | K10: =Herd!K18*(1-Assumptions!$C$59)*Assumptions!$C$58*Scenarios!$F$6*K6 -> 103068.81
A11: Processed dairy products (yoghurt, ghee, cheese) | D11: =Herd!D18*Assumptions!$C$59*Assumptions!$C$58*Assumptions!$C$60*Scenarios!$F$6*D6 -> 15708 | E11: =Herd!E18*Assumptions!$C$59*Assumptions!$C$58*Assumptions!$C$60*Scenarios!$F$6*E6 -> 15833.664 | F11: =Herd!F18*Assumptions!$C$59*Assumptions!$C$58*Assumptions!$C$60*Scenarios!$F$6*F6 -> 17375.22 | G11: =Herd!G18*Assumptions!$C$59*Assumptions!$C$58*Assumptions!$C$60*Scenarios!$F$6*G6 -> 18643.301 | H11: =Herd!H18*Assumptions!$C$59*Assumptions!$C$58*Assumptions!$C$60*Scenarios!$F$6*H6 -> 20120.4 | I11: =Herd!I18*Assumptions!$C$59*Assumptions!$C$58*Assumptions!$C$60*Scenarios!$F$6*I6 -> 21681.775 | J11: =Herd!J18*Assumptions!$C$59*Assumptions!$C$58*Assumptions!$C$60*Scenarios!$F$6*J6 -> 23373.472 | K11: =Herd!K18*Assumptions!$C$59*Assumptions!$C$58*Assumptions!$C$60*Scenarios!$F$6*K6 -> 25194.599
A12: Dairy bull calf sales | D12: =Herd!D11*Assumptions!$C$39*Scenarios!$F$7*D7 -> 1876.8 | E12: =Herd!E11*Assumptions!$C$39*Scenarios!$F$7*E7 -> 1891.8144 | F12: =Herd!F11*Assumptions!$C$39*Scenarios!$F$7*F7 -> 2076.0003 | G12: =Herd!G11*Assumptions!$C$39*Scenarios!$F$7*G7 -> 2227.5112 | H12: =Herd!H11*Assumptions!$C$39*Scenarios!$F$7*H7 -> 2403.9959 | I12: =Herd!I11*Assumptions!$C$39*Scenarios!$F$7*I7 -> 2590.5497 | J12: =Herd!J11*Assumptions!$C$39*Scenarios!$F$7*J7 -> 2792.6746 | K12: =Herd!K11*Assumptions!$C$39*Scenarios!$F$7*K7 -> 3010.2637
A13: Surplus dairy heifer sales | D13: =Herd!D14*Assumptions!$C$40*Scenarios!$F$7*D7 -> 1876.8 | E13: =Herd!E14*Assumptions!$C$40*Scenarios!$F$7*E7 -> 1891.8144 | F13: =Herd!F14*Assumptions!$C$40*Scenarios!$F$7*F7 -> 2076.0003 | G13: =Herd!G14*Assumptions!$C$40*Scenarios!$F$7*G7 -> 2227.5112 | H13: =Herd!H14*Assumptions!$C$40*Scenarios!$F$7*H7 -> 2403.9959 | I13: =Herd!I14*Assumptions!$C$40*Scenarios!$F$7*I7 -> 2590.5497 | J13: =Herd!J14*Assumptions!$C$40*Scenarios!$F$7*J7 -> 2792.6746 | K13: =Herd!K14*Assumptions!$C$40*Scenarios!$F$7*K7 -> 3010.2637
A14: Dairy cull cow sales | D14: =Herd!D15*Assumptions!$C$41*Scenarios!$F$7*D7 -> 4400 | E14: =Herd!E15*Assumptions!$C$41*Scenarios!$F$7*E7 -> 4435.2 | F14: =Herd!F15*Assumptions!$C$41*Scenarios!$F$7*F7 -> 4867.0083 | G14: =Herd!G15*Assumptions!$C$41*Scenarios!$F$7*G7 -> 5222.2131 | H14: =Herd!H15*Assumptions!$C$41*Scenarios!$F$7*H7 -> 5635.9665 | I14: =Herd!I15*Assumptions!$C$41*Scenarios!$F$7*I7 -> 6073.3262 | J14: =Herd!J15*Assumptions!$C$41*Scenarios!$F$7*J7 -> 6547.1912 | K14: =Herd!K15*Assumptions!$C$41*Scenarios!$F$7*K7 -> 7057.3106
A15: Manure sales | D15: =Herd!D6*Assumptions!$C$63*Assumptions!$C$64*D8 -> 960 | E15: =Herd!E6*Assumptions!$C$63*Assumptions!$C$64*E8 -> 967.68 | F15: =Herd!F6*Assumptions!$C$63*Assumptions!$C$64*F8 -> 1061.8927 | G15: =Herd!G6*Assumptions!$C$63*Assumptions!$C$64*G8 -> 1139.3919 | H15: =Herd!H6*Assumptions!$C$63*Assumptions!$C$64*H8 -> 1229.6654 | I15: =Herd!I6*Assumptions!$C$63*Assumptions!$C$64*I8 -> 1325.0894 | J15: =Herd!J6*Assumptions!$C$63*Assumptions!$C$64*J8 -> 1428.4781 | K15: =Herd!K6*Assumptions!$C$63*Assumptions!$C$64*K8 -> 1539.7768
A16: BEEF ENTERPRISE
A17: Beef weaner sales | D17: =Herd!D31*Assumptions!$C$54*Scenarios!$F$7*D7 -> 5961.6 | E17: =Herd!E31*Assumptions!$C$54*Scenarios!$F$7*E7 -> 6572.664 | F17: =Herd!F31*Assumptions!$C$54*Scenarios!$F$7*F7 -> 7075.4728 | G17: =Herd!G31*Assumptions!$C$54*Scenarios!$F$7*G7 -> 7648.1901 | H17: =Herd!H31*Assumptions!$C$54*Scenarios!$F$7*H7 -> 8261.3401 | I17: =Herd!I31*Assumptions!$C$54*Scenarios!$F$7*I7 -> 8924.7579 | J17: =Herd!J31*Assumptions!$C$54*Scenarios!$F$7*J7 -> 9641.2418 | K17: =Herd!K31*Assumptions!$C$54*Scenarios!$F$7*K7 -> 10415.285
A18: Beef cull cow sales | D18: =Herd!D28*Assumptions!$C$55*Assumptions!$C$56*Scenarios!$F$7*D7 -> 2599.2 | E18: =Herd!E28*Assumptions!$C$55*Assumptions!$C$56*Scenarios!$F$7*E7 -> 2865.618 | F18: =Herd!F28*Assumptions!$C$55*Assumptions!$C$56*Scenarios!$F$7*F7 -> 3084.8378 | G18: =Herd!G28*Assumptions!$C$55*Assumptions!$C$56*Scenarios!$F$7*G7 -> 3334.537 | H18: =Herd!H28*Assumptions!$C$55*Assumptions!$C$56*Scenarios!$F$7*H7 -> 3601.8644 | I18: =Herd!I28*Assumptions!$C$55*Assumptions!$C$56*Scenarios!$F$7*I7 -> 3891.1082 | J18: =Herd!J28*Assumptions!$C$55*Assumptions!$C$56*Scenarios!$F$7*J7 -> 4203.4883 | K18: =Herd!K28*Assumptions!$C$55*Assumptions!$C$56*Scenarios!$F$7*K7 -> 4540.9635
A19: OTHER INCOME
A20: AI / bull service income | D20: =Assumptions!$C$65*Assumptions!$C$66*D8 -> 900 | E20: =Assumptions!$C$65*Assumptions!$C$66*E8 -> 945 | F20: =Assumptions!$C$65*Assumptions!$C$66*F8 -> 992.25 | G20: =Assumptions!$C$65*Assumptions!$C$66*G8 -> 1041.8625 | H20: =Assumptions!$C$65*Assumptions!$C$66*H8 -> 1093.9556 | I20: =Assumptions!$C$65*Assumptions!$C$66*I8 -> 1148.6534 | J20: =Assumptions!$C$65*Assumptions!$C$66*J8 -> 1206.0861 | K20: =Assumptions!$C$65*Assumptions!$C$66*K8 -> 1266.3904
A21: Grants and other income | D21: =Assumptions!$C$67*D8 -> 0 | E21: =Assumptions!$C$67*E8 -> 0 | F21: =Assumptions!$C$67*F8 -> 0 | G21: =Assumptions!$C$67*G8 -> 0 | H21: =Assumptions!$C$67*H8 -> 0 | I21: =Assumptions!$C$67*I8 -> 0 | J21: =Assumptions!$C$67*J8 -> 0 | K21: =Assumptions!$C$67*K8 -> 0
A22: TOTALS
A23: TOTAL REVENUE | D23: =D10+D11+D12+D13+D14+D15+D17+D18+D20+D21 -> 98542.4 | E23: =E10+E11+E12+E13+E14+E15+E17+E18+E20+E21 -> 100177.53 | F23: =F10+F11+F12+F13+F14+F15+F17+F18+F20+F21 -> 109689.13 | G23: =G10+G11+G12+G13+G14+G15+G17+G18+G20+G21 -> 117752.57 | H23: =H10+H11+H12+H13+H14+H15+H17+H18+H20+H21 -> 127061.91 | I23: =I10+I11+I12+I13+I14+I15+I17+I18+I20+I21 -> 136923.98 | J23: =J10+J11+J12+J13+J14+J15+J17+J18+J20+J21 -> 147604.06 | K23: =K10+K11+K12+K13+K14+K15+K17+K18+K20+K21 -> 159103.66
A24: Revenue growth | B24: % | E24: =IF(D23>0,E23/D23-1,0) -> 0.016593211 | F24: =IF(E23>0,F23/E23-1,0) -> 0.094947344 | G24: =IF(F23>0,G23/F23-1,0) -> 0.073511756 | H24: =IF(G23>0,H23/G23-1,0) -> 0.079058546 | I24: =IF(H23>0,I23/H23-1,0) -> 0.077616221 | J24: =IF(I23>0,J23/I23-1,0) -> 0.078000072 | K24: =IF(J23>0,K23/J23-1,0) -> 0.077908473
A25: of which dairy enterprise | D25: =D10+D11+D12+D13+D14+D15 -> 89081.6 | E25: =E10+E11+E12+E13+E14+E15 -> 89794.253 | F25: =F10+F11+F12+F13+F14+F15 -> 98536.565 | G25: =G10+G11+G12+G13+G14+G15 -> 105727.98 | H25: =H10+H11+H12+H13+H14+H15 -> 114104.75 | I25: =I10+I11+I12+I13+I14+I15 -> 122959.46 | J25: =J10+J11+J12+J13+J14+J15 -> 132553.24 | K25: =K10+K11+K12+K13+K14+K15 -> 142881.03
A26: of which beef enterprise | D26: =D17+D18 -> 8560.8 | E26: =E17+E18 -> 9438.282 | F26: =F17+F18 -> 10160.311 | G26: =G17+G18 -> 10982.727 | H26: =H17+H18 -> 11863.205 | I26: =I17+I18 -> 12815.866 | J26: =J17+J18 -> 13844.73 | K26: =K17+K18 -> 14956.248
A27: of which other income | D27: =D20+D21 -> 900 | E27: =E20+E21 -> 945 | F27: =F20+F21 -> 992.25 | G27: =G20+G21 -> 1041.8625 | H27: =H20+H21 -> 1093.9556 | I27: =I20+I21 -> 1148.6534 | J27: =J20+J21 -> 1206.0861 | K27: =K20+K21 -> 1266.3904
A28: Milk and dairy products share | B28: % | D28: =IF(D23>0,(D10+D11)/D23,0) -> 0.81150855 | E28: =IF(E23>0,(E10+E11)/E23,0) -> 0.80464891 | F28: =IF(F23>0,(F10+F11)/F23,0) -> 0.80642145 | G28: =IF(G23>0,(G10+G11)/G23,0) -> 0.80602361 | H28: =IF(H23>0,(H10+H11)/H23,0) -> 0.80615132 | I28: =IF(I23>0,(I10+I11)/I23,0) -> 0.80614035 | J28: =IF(J23>0,(J10+J11)/J23,0) -> 0.80615821 | K28: =IF(K23>0,(K10+K11)/K23,0) -> 0.80616252
A29: Animal sales share | B29: % | D29: =IF(D23>0,(D12+D13+D14+D17+D18)/D23,0) -> 0.16961633 | E29: =IF(E23>0,(E12+E13+E14+E17+E18)/E23,0) -> 0.17625819 | F29: =IF(F23>0,(F12+F13+F14+F17+F18)/F23,0) -> 0.1748516 | G29: =IF(G23>0,(G12+G13+G14+G17+G18)/G23,0) -> 0.17545233 | H29: =IF(H23>0,(H12+H13+H14+H17+H18)/H23,0) -> 0.17556136 | I29: =IF(I23>0,(I12+I13+I14+I17+I18)/I23,0) -> 0.17579311 | J29: =IF(J23>0,(J12+J13+J14+J17+J18)/J23,0) -> 0.17599293 | K29: =IF(K23>0,(K12+K13+K14+K17+K18)/K23,0) -> 0.17620013
A30: Manure, services, other share | B30: % | D30: =IF(D23>0,(D15+D20+D21)/D23,0) -> 0.018875124 | E30: =IF(E23>0,(E15+E20+E21)/E23,0) -> 0.019092903 | F30: =IF(F23>0,(F15+F20+F21)/F23,0) -> 0.01872695 | G30: =IF(G23>0,(G15+G20+G21)/G23,0) -> 0.01852405 | H30: =IF(H23>0,(H15+H20+H21)/H23,0) -> 0.018287314 | I30: =IF(I23>0,(I15+I20+I21)/I23,0) -> 0.018066542 | J30: =IF(J23>0,(J15+J20+J21)/J23,0) -> 0.01784886 | K30: =IF(K23>0,(K15+K20+K21)/K23,0) -> 0.017637351

Sheet Opex
A1: Operating costs (currency units)
A2: Feed lines use the feed multiplier; other lines use the other-cost multiplier (Scenarios sheet).
A4: Line item | B4: Unit | C4: 0 | D4: 1 | E4: 2 | F4: 3 | G4: 4 | H4: 5 | I4: 6 | J4: 7 | K4: 8
A5: COST INDEX AND LABOUR SIZING
A6: General cost index | B6: index | D6: =(1+Assumptions!$C$12)^(D$4-1) -> 1 | E6: =(1+Assumptions!$C$12)^(E$4-1) -> 1.05 | F6: =(1+Assumptions!$C$12)^(F$4-1) -> 1.1025 | G6: =(1+Assumptions!$C$12)^(G$4-1) -> 1.157625 | H6: =(1+Assumptions!$C$12)^(H$4-1) -> 1.2155063 | I6: =(1+Assumptions!$C$12)^(I$4-1) -> 1.2762816 | J6: =(1+Assumptions!$C$12)^(J$4-1) -> 1.3400956 | K6: =(1+Assumptions!$C$12)^(K$4-1) -> 1.4071004
A7: Workload units | B7: units | D7: =Herd!D6+Assumptions!$C$87*Herd!D20+Assumptions!$C$88*Herd!D34 -> 55.6702 | E7: =Herd!E6+Assumptions!$C$87*Herd!E20+Assumptions!$C$88*Herd!E34 -> 55.236312 | F7: =Herd!F6+Assumptions!$C$87*Herd!F20+Assumptions!$C$88*Herd!F34 -> 57.251285 | G7: =Herd!G6+Assumptions!$C$87*Herd!G20+Assumptions!$C$88*Herd!G34 -> 58.66364 | H7: =Herd!H6+Assumptions!$C$87*Herd!H20+Assumptions!$C$88*Herd!H34 -> 60.28975 | I7: =Herd!I6+Assumptions!$C$87*Herd!I20+Assumptions!$C$88*Herd!I34 -> 61.913144 | J7: =Herd!J6+Assumptions!$C$87*Herd!J20+Assumptions!$C$88*Herd!J34 -> 63.593055 | K7: =Herd!K6+Assumptions!$C$87*Herd!K20+Assumptions!$C$88*Herd!K34 -> 65.315198
A8: Herdsmen required | B8: people | D8: =MAX(Assumptions!$C$85,ROUNDUP(D7/Assumptions!$C$86,0)) -> 3 | E8: =MAX(Assumptions!$C$85,ROUNDUP(E7/Assumptions!$C$86,0)) -> 3 | F8: =MAX(Assumptions!$C$85,ROUNDUP(F7/Assumptions!$C$86,0)) -> 3 | G8: =MAX(Assumptions!$C$85,ROUNDUP(G7/Assumptions!$C$86,0)) -> 3 | H8: =MAX(Assumptions!$C$85,ROUNDUP(H7/Assumptions!$C$86,0)) -> 4 | I8: =MAX(Assumptions!$C$85,ROUNDUP(I7/Assumptions!$C$86,0)) -> 4 | J8: =MAX(Assumptions!$C$85,ROUNDUP(J7/Assumptions!$C$86,0)) -> 4 | K8: =MAX(Assumptions!$C$85,ROUNDUP(K7/Assumptions!$C$86,0)) -> 4
A9: DAIRY DIRECT COSTS
A10: Concentrate feed | D10: =Herd!D18*Assumptions!$C$69*Assumptions!$C$70*D6*Scenarios!$F$8 -> 16660 | E10: =Herd!E18*Assumptions!$C$69*Assumptions!$C$70*E6*Scenarios!$F$8 -> 16793.28 | F10: =Herd!F18*Assumptions!$C$69*Assumptions!$C$70*F6*Scenarios!$F$8 -> 18428.263 | G10: =Herd!G18*Assumptions!$C$69*Assumptions!$C$70*G6*Scenarios!$F$8 -> 19773.198 | H10: =Herd!H18*Assumptions!$C$69*Assumptions!$C$70*H6*Scenarios!$F$8 -> 21339.819 | I10: =Herd!I18*Assumptions!$C$69*Assumptions!$C$70*I6*Scenarios!$F$8 -> 22995.822 | J10: =Herd!J18*Assumptions!$C$69*Assumptions!$C$70*J6*Scenarios!$F$8 -> 24790.047 | K10: =Herd!K18*Assumptions!$C$69*Assumptions!$C$70*K6*Scenarios!$F$8 -> 26721.544
A11: Forage and minerals (dairy cows) | D11: =Herd!D6*(Assumptions!$C$71+Assumptions!$C$72)*D6*Scenarios!$F$8 -> 7200 | E11: =Herd!E6*(Assumptions!$C$71+Assumptions!$C$72)*E6*Scenarios!$F$8 -> 7257.6 | F11: =Herd!F6*(Assumptions!$C$71+Assumptions!$C$72)*F6*Scenarios!$F$8 -> 7964.1954 | G11: =Herd!G6*(Assumptions!$C$71+Assumptions!$C$72)*G6*Scenarios!$F$8 -> 8545.4396 | H11: =Herd!H6*(Assumptions!$C$71+Assumptions!$C$72)*H6*Scenarios!$F$8 -> 9222.4906 | I11: =Herd!I6*(Assumptions!$C$71+Assumptions!$C$72)*I6*Scenarios!$F$8 -> 9938.1702 | J11: =Herd!J6*(Assumptions!$C$71+Assumptions!$C$72)*J6*Scenarios!$F$8 -> 10713.586 | K11: =Herd!K6*(Assumptions!$C$71+Assumptions!$C$72)*K6*Scenarios!$F$8 -> 11548.326
A12: Dairy heifer rearing | D12: =Herd!D17*Assumptions!$C$75*D6*Scenarios!$F$8 -> 2694.8 | E12: =Herd!E17*Assumptions!$C$75*E6*Scenarios!$F$8 -> 3402.6384 | F12: =Herd!F17*Assumptions!$C$75*F6*Scenarios!$F$8 -> 3528.4728 | G12: =Herd!G17*Assumptions!$C$75*G6*Scenarios!$F$8 -> 3842.4819 | H12: =Herd!H17*Assumptions!$C$75*H6*Scenarios!$F$8 -> 4131.0322 | I12: =Herd!I17*Assumptions!$C$75*I6*Scenarios!$F$8 -> 4456.0489 | J12: =Herd!J17*Assumptions!$C$75*J6*Scenarios!$F$8 -> 4802.4836 | K12: =Herd!K17*Assumptions!$C$75*K6*Scenarios!$F$8 -> 5177.0136
A13: Dairy calf rearing | D13: =Herd!D10*Assumptions!$C$76*D6*Scenarios!$F$8 -> 2189.6 | E13: =Herd!E10*Assumptions!$C$76*E6*Scenarios!$F$8 -> 2207.1168 | F13: =Herd!F10*Assumptions!$C$76*F6*Scenarios!$F$8 -> 2422.0003 | G13: =Herd!G10*Assumptions!$C$76*G6*Scenarios!$F$8 -> 2598.7631 | H13: =Herd!H10*Assumptions!$C$76*H6*Scenarios!$F$8 -> 2804.6619 | I13: =Herd!I10*Assumptions!$C$76*I6*Scenarios!$F$8 -> 3022.308 | J13: =Herd!J10*Assumptions!$C$76*J6*Scenarios!$F$8 -> 3258.1204 | K13: =Herd!K10*Assumptions!$C$76*K6*Scenarios!$F$8 -> 3511.9744
A14: Dairy veterinary and drugs | D14: =Herd!D6*Assumptions!$C$78*D6*Scenarios!$F$9 -> 2200 | E14: =Herd!E6*Assumptions!$C$78*E6*Scenarios!$F$9 -> 2217.6 | F14: =Herd!F6*Assumptions!$C$78*F6*Scenarios!$F$9 -> 2433.5042 | G14: =Herd!G6*Assumptions!$C$78*G6*Scenarios!$F$9 -> 2611.1065 | H14: =Herd!H6*Assumptions!$C$78*H6*Scenarios!$F$9 -> 2817.9832 | I14: =Herd!I6*Assumptions!$C$78*I6*Scenarios!$F$9 -> 3036.6631 | J14: =Herd!J6*Assumptions!$C$78*J6*Scenarios!$F$9 -> 3273.5956 | K14: =Herd!K6*Assumptions!$C$78*K6*Scenarios!$F$9 -> 3528.6553
A15: Artificial insemination | D15: =Herd!D6*Assumptions!$C$80*D6*Scenarios!$F$9 -> 1400 | E15: =Herd!E6*Assumptions!$C$80*E6*Scenarios!$F$9 -> 1411.2 | F15: =Herd!F6*Assumptions!$C$80*F6*Scenarios!$F$9 -> 1548.5936 | G15: =Herd!G6*Assumptions!$C$80*G6*Scenarios!$F$9 -> 1661.6133 | H15: =Herd!H6*Assumptions!$C$80*H6*Scenarios!$F$9 -> 1793.2621 | I15: =Herd!I6*Assumptions!$C$80*I6*Scenarios!$F$9 -> 1932.422 | J15: =Herd!J6*Assumptions!$C$80*J6*Scenarios!$F$9 -> 2083.1972 | K15: =Herd!K6*Assumptions!$C$80*K6*Scenarios!$F$9 -> 2245.5079
A16: Milk processing and packaging | D16: =Herd!D18*Assumptions!$C$59*Assumptions!$C$61*D6*Scenarios!$F$9 -> 3332 | E16: =Herd!E18*Assumptions!$C$59*Assumptions!$C$61*E6*Scenarios!$F$9 -> 3358.656 | F16: =Herd!F18*Assumptions!$C$59*Assumptions!$C$61*F6*Scenarios!$F$9 -> 3685.6526 | G16: =Herd!G18*Assumptions!$C$59*Assumptions!$C$61*G6*Scenarios!$F$9 -> 3954.6395 | H16: =Herd!H18*Assumptions!$C$59*Assumptions!$C$61*H6*Scenarios!$F$9 -> 4267.9637 | I16: =Herd!I18*Assumptions!$C$59*Assumptions!$C$61*I6*Scenarios!$F$9 -> 4599.1643 | J16: =Herd!J18*Assumptions!$C$59*Assumptions!$C$61*J6*Scenarios!$F$9 -> 4958.0093 | K16: =Herd!K18*Assumptions!$C$59*Assumptions!$C$61*K6*Scenarios!$F$9 -> 5344.3088
A17: Milk cooling and transport | D17: =Herd!D18*Assumptions!$C$62*D6*Scenarios!$F$9 -> 3570 | E17: =Herd!E18*Assumptions!$C$62*E6*Scenarios!$F$9 -> 3598.56 | F17: =Herd!F18*Assumptions!$C$62*F6*Scenarios!$F$9 -> 3948.9136 | G17: =Herd!G18*Assumptions!$C$62*G6*Scenarios!$F$9 -> 4237.1138 | H17: =Herd!H18*Assumptions!$C$62*H6*Scenarios!$F$9 -> 4572.8183 | I17: =Herd!I18*Assumptions!$C$62*I6*Scenarios!$F$9 -> 4927.6761 | J17: =Herd!J18*Assumptions!$C$62*J6*Scenarios!$F$9 -> 5312.1528 | K17: =Herd!K18*Assumptions!$C$62*K6*Scenarios!$F$9 -> 5726.0452
A18: BEEF DIRECT COSTS
A19: Beef cow supplementary feed and minerals | D19: =Herd!D20*(Assumptions!$C$73+Assumptions!$C$74)*D6*Scenarios!$F$8 -> 2250 | E19: =Herd!E20*(Assumptions!$C$73+Assumptions!$C$74)*E6*Scenarios!$F$8 -> 2480.625 | F19: =Herd!F20*(Assumptions!$C$73+Assumptions!$C$74)*F6*Scenarios!$F$8 -> 2670.3928 | G19: =Herd!G20*(Assumptions!$C$73+Assumptions!$C$74)*G6*Scenarios!$F$8 -> 2886.5452 | H19: =Herd!H20*(Assumptions!$C$73+Assumptions!$C$74)*H6*Scenarios!$F$8 -> 3117.9575 | I19: =Herd!I20*(Assumptions!$C$73+Assumptions!$C$74)*I6*Scenarios!$F$8 -> 3368.3416 | J19: =Herd!J20*(Assumptions!$C$73+Assumptions!$C$74)*J6*Scenarios!$F$8 -> 3638.7537 | K19: =Herd!K20*(Assumptions!$C$73+Assumptions!$C$74)*K6*Scenarios!$F$8 -> 3930.8895
A20: Beef heifer rearing | D20: =Herd!D30*Assumptions!$C$75*D6*Scenarios!$F$8 -> 1752 | E20: =Herd!E30*Assumptions!$C$75*E6*Scenarios!$F$8 -> 1767.78 | F20: =Herd!F30*Assumptions!$C$75*F6*Scenarios!$F$8 -> 1933.1544 | G20: =Herd!G30*Assumptions!$C$75*G6*Scenarios!$F$8 -> 2083.9521 | H20: =Herd!H30*Assumptions!$C$75*H6*Scenarios!$F$8 -> 2252.087 | I20: =Herd!I30*Assumptions!$C$75*I6*Scenarios!$F$8 -> 2432.7381 | J20: =Herd!J30*Assumptions!$C$75*J6*Scenarios!$F$8 -> 2628.0772 | K20: =Herd!K30*Assumptions!$C$75*K6*Scenarios!$F$8 -> 2839.0641
A21: Beef calf creep feed | D21: =Herd!D24*Assumptions!$C$77*D6*Scenarios!$F$8 -> 552 | E21: =Herd!E24*Assumptions!$C$77*E6*Scenarios!$F$8 -> 608.58 | F21: =Herd!F24*Assumptions!$C$77*F6*Scenarios!$F$8 -> 655.13637 | G21: =Herd!G24*Assumptions!$C$77*G6*Scenarios!$F$8 -> 708.16575 | H21: =Herd!H24*Assumptions!$C$77*H6*Scenarios!$F$8 -> 764.9389 | I21: =Herd!I24*Assumptions!$C$77*I6*Scenarios!$F$8 -> 826.36647 | J21: =Herd!J24*Assumptions!$C$77*J6*Scenarios!$F$8 -> 892.70758 | K21: =Herd!K24*Assumptions!$C$77*K6*Scenarios!$F$8 -> 964.37821
A22: Beef veterinary and drugs | D22: =Herd!D20*Assumptions!$C$79*D6*Scenarios!$F$9 -> 660 | E22: =Herd!E20*Assumptions!$C$79*E6*Scenarios!$F$9 -> 727.65 | F22: =Herd!F20*Assumptions!$C$79*F6*Scenarios!$F$9 -> 783.31523 | G22: =Herd!G20*Assumptions!$C$79*G6*Scenarios!$F$9 -> 846.71992 | H22: =Herd!H20*Assumptions!$C$79*H6*Scenarios!$F$9 -> 914.60085 | I22: =Herd!I20*Assumptions!$C$79*I6*Scenarios!$F$9 -> 988.04686 | J22: =Herd!J20*Assumptions!$C$79*J6*Scenarios!$F$9 -> 1067.3678 | K22: =Herd!K20*Assumptions!$C$79*K6*Scenarios!$F$9 -> 1153.0609
A23: LABOUR
A24: Wages, benefits and casual labour | D24: =((Assumptions!$C$82*Assumptions!$C$83+D8*Assumptions!$C$84)*12*(1+Assumptions!$C$89)+Assumptions!$C$90)*D6*Scenarios!$F$9 -> 15228 | E24: =((Assumptions!$C$82*Assumptions!$C$83+E8*Assumptions!$C$84)*12*(1+Assumptions!$C$89)+Assumptions!$C$90)*E6*Scenarios!$F$9 -> 15989.4 | F24: =((Assumptions!$C$82*Assumptions!$C$83+F8*Assumptions!$C$84)*12*(1+Assumptions!$C$89)+Assumptions!$C$90)*F6*Scenarios!$F$9 -> 16788.87 | G24: =((Assumptions!$C$82*Assumptions!$C$83+G8*Assumptions!$C$84)*12*(1+Assumptions!$C$89)+Assumptions!$C$90)*G6*Scenarios!$F$9 -> 17628.314 | H24: =((Assumptions!$C$82*Assumptions!$C$83+H8*Assumptions!$C$84)*12*(1+Assumptions!$C$89)+Assumptions!$C$90)*H6*Scenarios!$F$9 -> 21397.772 | I24: =((Assumptions!$C$82*Assumptions!$C$83+I8*Assumptions!$C$84)*12*(1+Assumptions!$C$89)+Assumptions!$C$90)*I6*Scenarios!$F$9 -> 22467.661 | J24: =((Assumptions!$C$82*Assumptions!$C$83+J8*Assumptions!$C$84)*12*(1+Assumptions!$C$89)+Assumptions!$C$90)*J6*Scenarios!$F$9 -> 23591.044 | K24: =((Assumptions!$C$82*Assumptions!$C$83+K8*Assumptions!$C$84)*12*(1+Assumptions!$C$89)+Assumptions!$C$90)*K6*Scenarios!$F$9 -> 24770.596
A25: OVERHEADS
A26: Water, power and utilities | D26: =(Assumptions!$C$91+Herd!D6*Assumptions!$C$92)*D6*Scenarios!$F$9 -> 2800 | E26: =(Assumptions!$C$91+Herd!E6*Assumptions!$C$92)*E6*Scenarios!$F$9 -> 2872.8 | F26: =(Assumptions!$C$91+Herd!F6*Assumptions!$C$92)*F6*Scenarios!$F$9 -> 3092.8212 | G26: =(Assumptions!$C$91+Herd!G6*Assumptions!$C$92)*G6*Scenarios!$F$9 -> 3288.1366 | H26: =(Assumptions!$C$91+Herd!H6*Assumptions!$C$92)*H6*Scenarios!$F$9 -> 3508.0499 | I26: =(Assumptions!$C$91+Herd!I6*Assumptions!$C$92)*I6*Scenarios!$F$9 -> 3740.0201 | J26: =(Assumptions!$C$91+Herd!J6*Assumptions!$C$92)*J6*Scenarios!$F$9 -> 3988.9116 | K26: =(Assumptions!$C$91+Herd!K6*Assumptions!$C$92)*K6*Scenarios!$F$9 -> 4254.8153
A27: Fuel and vehicle running | D27: =Assumptions!$C$93*D6*Scenarios!$F$9 -> 1800 | E27: =Assumptions!$C$93*E6*Scenarios!$F$9 -> 1890 | F27: =Assumptions!$C$93*F6*Scenarios!$F$9 -> 1984.5 | G27: =Assumptions!$C$93*G6*Scenarios!$F$9 -> 2083.725 | H27: =Assumptions!$C$93*H6*Scenarios!$F$9 -> 2187.9113 | I27: =Assumptions!$C$93*I6*Scenarios!$F$9 -> 2297.3068 | J27: =Assumptions!$C$93*J6*Scenarios!$F$9 -> 2412.1722 | K27: =Assumptions!$C$93*K6*Scenarios!$F$9 -> 2532.7808
A28: Marketing and haulage | D28: =Herd!D35*Assumptions!$C$94*D6*Scenarios!$F$9 -> 387.936 | E28: =Herd!E35*Assumptions!$C$94*E6*Scenarios!$F$9 -> 406.28045 | F28: =Herd!F35*Assumptions!$C$94*F6*Scenarios!$F$9 -> 442.12663 | G28: =Herd!G35*Assumptions!$C$94*G6*Scenarios!$F$9 -> 475.918 | H28: =Herd!H35*Assumptions!$C$94*H6*Scenarios!$F$9 -> 513.81919 | I28: =Herd!I35*Assumptions!$C$94*I6*Scenarios!$F$9 -> 554.29632 | J28: =Herd!J35*Assumptions!$C$94*J6*Scenarios!$F$9 -> 598.08954 | K28: =Herd!K35*Assumptions!$C$94*K6*Scenarios!$F$9 -> 645.30747
A29: Livestock insurance | D29: =Assumptions!$C$95*Capex!$F$41*Revenue!D7 -> 1862.75 | E29: =Assumptions!$C$95*Capex!$F$41*Revenue!E7 -> 1955.8875 | F29: =Assumptions!$C$95*Capex!$F$41*Revenue!F7 -> 2053.6819 | G29: =Assumptions!$C$95*Capex!$F$41*Revenue!G7 -> 2156.366 | H29: =Assumptions!$C$95*Capex!$F$41*Revenue!H7 -> 2264.1843 | I29: =Assumptions!$C$95*Capex!$F$41*Revenue!I7 -> 2377.3935 | J29: =Assumptions!$C$95*Capex!$F$41*Revenue!J7 -> 2496.2632 | K29: =Assumptions!$C$95*Capex!$F$41*Revenue!K7 -> 2621.0763
A30: Repairs and maintenance | D30: =Assumptions!$C$96*Capex!$F$51*D6*Scenarios!$F$9 -> 2784 | E30: =Assumptions!$C$96*Capex!$F$51*E6*Scenarios!$F$9 -> 2923.2 | F30: =Assumptions!$C$96*Capex!$F$51*F6*Scenarios!$F$9 -> 3069.36 | G30: =Assumptions!$C$96*Capex!$F$51*G6*Scenarios!$F$9 -> 3222.828 | H30: =Assumptions!$C$96*Capex!$F$51*H6*Scenarios!$F$9 -> 3383.9694 | I30: =Assumptions!$C$96*Capex!$F$51*I6*Scenarios!$F$9 -> 3553.1679 | J30: =Assumptions!$C$96*Capex!$F$51*J6*Scenarios!$F$9 -> 3730.8263 | K30: =Assumptions!$C$96*Capex!$F$51*K6*Scenarios!$F$9 -> 3917.3676
A31: Admin, licences, accounting | D31: =Assumptions!$C$97*D6*Scenarios!$F$9 -> 1500 | E31: =Assumptions!$C$97*E6*Scenarios!$F$9 -> 1575 | F31: =Assumptions!$C$97*F6*Scenarios!$F$9 -> 1653.75 | G31: =Assumptions!$C$97*G6*Scenarios!$F$9 -> 1736.4375 | H31: =Assumptions!$C$97*H6*Scenarios!$F$9 -> 1823.2594 | I31: =Assumptions!$C$97*I6*Scenarios!$F$9 -> 1914.4223 | J31: =Assumptions!$C$97*J6*Scenarios!$F$9 -> 2010.1435 | K31: =Assumptions!$C$97*K6*Scenarios!$F$9 -> 2110.6506
A32: Bull replacement provision | D32: =Assumptions!$C$45*Assumptions!$C$46/Assumptions!$C$47*Revenue!D7 -> 450 | E32: =Assumptions!$C$45*Assumptions!$C$46/Assumptions!$C$47*Revenue!E7 -> 472.5 | F32: =Assumptions!$C$45*Assumptions!$C$46/Assumptions!$C$47*Revenue!F7 -> 496.125 | G32: =Assumptions!$C$45*Assumptions!$C$46/Assumptions!$C$47*Revenue!G7 -> 520.93125 | H32: =Assumptions!$C$45*Assumptions!$C$46/Assumptions!$C$47*Revenue!H7 -> 546.97781 | I32: =Assumptions!$C$45*Assumptions!$C$46/Assumptions!$C$47*Revenue!I7 -> 574.3267 | J32: =Assumptions!$C$45*Assumptions!$C$46/Assumptions!$C$47*Revenue!J7 -> 603.04304 | K32: =Assumptions!$C$45*Assumptions!$C$46/Assumptions!$C$47*Revenue!K7 -> 633.19519
A33: LAND
A34: Land lease | D34: =(1-Assumptions!$C$24)*Assumptions!$C$23*Assumptions!$C$25*D6 -> 3750 | E34: =(1-Assumptions!$C$24)*Assumptions!$C$23*Assumptions!$C$25*E6 -> 3937.5 | F34: =(1-Assumptions!$C$24)*Assumptions!$C$23*Assumptions!$C$25*F6 -> 4134.375 | G34: =(1-Assumptions!$C$24)*Assumptions!$C$23*Assumptions!$C$25*G6 -> 4341.0938 | H34: =(1-Assumptions!$C$24)*Assumptions!$C$23*Assumptions!$C$25*H6 -> 4558.1484 | I34: =(1-Assumptions!$C$24)*Assumptions!$C$23*Assumptions!$C$25*I6 -> 4786.0559 | J34: =(1-Assumptions!$C$24)*Assumptions!$C$23*Assumptions!$C$25*J6 -> 5025.3587 | K34: =(1-Assumptions!$C$24)*Assumptions!$C$23*Assumptions!$C$25*K6 -> 5276.6266
A35: CONTINGENCY AND TOTAL
A36: Contingency | D36: =Assumptions!$C$98*(SUM(D10:D22)+D24+SUM(D26:D32)) -> 3563.6543 | E36: =Assumptions!$C$98*(SUM(E10:E22)+E24+SUM(E26:E32)) -> 3695.8177 | F36: =Assumptions!$C$98*(SUM(F10:F22)+F24+SUM(F26:F32)) -> 3979.1415 | G36: =Assumptions!$C$98*(SUM(G10:G22)+G24+SUM(G26:G32)) -> 4243.1197 | H36: =Assumptions!$C$98*(SUM(H10:H22)+H24+SUM(H26:H32)) -> 4681.2779 | I36: =Assumptions!$C$98*(SUM(I10:I22)+I24+SUM(I26:I32)) -> 5000.1181 | J36: =Assumptions!$C$98*(SUM(J10:J22)+J24+SUM(J26:J32)) -> 5342.4295 | K36: =Assumptions!$C$98*(SUM(K10:K22)+K24+SUM(K26:K32)) -> 5708.8279
A37: TOTAL OPERATING COSTS | D37: =SUM(D10:D22)+D24+SUM(D26:D32)+D34+D36 -> 78586.74 | E37: =SUM(E10:E22)+E24+SUM(E26:E32)+E34+E36 -> 81549.672 | F37: =SUM(F10:F22)+F24+SUM(F26:F32)+F34+F36 -> 87696.346 | G37: =SUM(G10:G22)+G24+SUM(G26:G32)+G34+G36 -> 93446.608 | H37: =SUM(H10:H22)+H24+SUM(H26:H32)+H34+H36 -> 102864.98 | I37: =SUM(I10:I22)+I24+SUM(I26:I32)+I34+I36 -> 109788.54 | J37: =SUM(J10:J22)+J24+SUM(J26:J32)+J34+J36 -> 117216.38 | K37: =SUM(K10:K22)+K24+SUM(K26:K32)+K34+K36 -> 125162.01
A38: COST STRUCTURE
A39: Feed and rearing | D39: =D10+D11+D12+D13+D19+D20+D21 -> 33298.4 | E39: =E10+E11+E12+E13+E19+E20+E21 -> 34517.62 | F39: =F10+F11+F12+F13+F19+F20+F21 -> 37601.615 | G39: =G10+G11+G12+G13+G19+G20+G21 -> 40438.545 | H39: =H10+H11+H12+H13+H19+H20+H21 -> 43632.986 | I39: =I10+I11+I12+I13+I19+I20+I21 -> 47039.795 | J39: =J10+J11+J12+J13+J19+J20+J21 -> 50723.775 | K39: =K10+K11+K12+K13+K19+K20+K21 -> 54693.19
A40: Health and breeding | D40: =D14+D15+D22 -> 4260 | E40: =E14+E15+E22 -> 4356.45 | F40: =F14+F15+F22 -> 4765.4129 | G40: =G14+G15+G22 -> 5119.4397 | H40: =H14+H15+H22 -> 5525.8461 | I40: =I14+I15+I22 -> 5957.132 | J40: =J14+J15+J22 -> 6424.1605 | K40: =K14+K15+K22 -> 6927.2241
A41: Labour | D41: =D24 -> 15228 | E41: =E24 -> 15989.4 | F41: =F24 -> 16788.87 | G41: =G24 -> 17628.314 | H41: =H24 -> 21397.772 | I41: =I24 -> 22467.661 | J41: =J24 -> 23591.044 | K41: =K24 -> 24770.596
...

Sheet PnL
A1: Income statement and enterprise margins (currency units)
A2: Depreciation: initial capex per Capex sheet plus expansion capex over its life. Tax is not carried forward on losses (conservative).
A4: Line item | B4: Unit | C4: 0 | D4: 1 | E4: 2 | F4: 3 | G4: 4 | H4: 5 | I4: 6 | J4: 7 | K4: 8
A5: INCOME STATEMENT
A6: Revenue | D6: =Revenue!D23 -> 98542.4 | E6: =Revenue!E23 -> 100177.53 | F6: =Revenue!F23 -> 109689.13 | G6: =Revenue!G23 -> 117752.57 | H6: =Revenue!H23 -> 127061.91 | I6: =Revenue!I23 -> 136923.98 | J6: =Revenue!J23 -> 147604.06 | K6: =Revenue!K23 -> 159103.66
A7: Operating costs | D7: =Opex!D37 -> 78586.74 | E7: =Opex!E37 -> 81549.672 | F7: =Opex!F37 -> 87696.346 | G7: =Opex!G37 -> 93446.608 | H7: =Opex!H37 -> 102864.98 | I7: =Opex!I37 -> 109788.54 | J7: =Opex!J37 -> 117216.38 | K7: =Opex!K37 -> 125162.01
A8: EBITDA | D8: =D6-D7 -> 19955.66 | E8: =E6-E7 -> 18627.863 | F8: =F6-F7 -> 21992.78 | G8: =G6-G7 -> 24305.958 | H8: =H6-H7 -> 24196.929 | I8: =I6-I7 -> 27135.443 | J8: =J6-J7 -> 30387.68 | K8: =K6-K7 -> 33941.653
A9: EBITDA margin | D9: =IF(D6>0,D8/D6,0) -> 0.20250836 | E9: =IF(E6>0,E8/E6,0) -> 0.18594851 | F9: =IF(F6>0,F8/F6,0) -> 0.20050101 | G9: =IF(G6>0,G8/G6,0) -> 0.20641553 | H9: =IF(H6>0,H8/H6,0) -> 0.19043416 | I9: =IF(I6>0,I8/I6,0) -> 0.19817889 | J9: =IF(J6>0,J8/J6,0) -> 0.20587293 | K9: =IF(K6>0,K8/K6,0) -> 0.21333043
A10: Depreciation: initial assets | D10: =SUMPRODUCT(Capex!$I$5:$I$36*(Capex!$G$5:$G$36>=D$4)) -> 16941.333 | E10: =SUMPRODUCT(Capex!$I$5:$I$36*(Capex!$G$5:$G$36>=E$4)) -> 16941.333 | F10: =SUMPRODUCT(Capex!$I$5:$I$36*(Capex!$G$5:$G$36>=F$4)) -> 16941.333 | G10: =SUMPRODUCT(Capex!$I$5:$I$36*(Capex!$G$5:$G$36>=G$4)) -> 16608 | H10: =SUMPRODUCT(Capex!$I$5:$I$36*(Capex!$G$5:$G$36>=H$4)) -> 16608 | I10: =SUMPRODUCT(Capex!$I$5:$I$36*(Capex!$G$5:$G$36>=I$4)) -> 15552 | J10: =SUMPRODUCT(Capex!$I$5:$I$36*(Capex!$G$5:$G$36>=J$4)) -> 8784 | K10: =SUMPRODUCT(Capex!$I$5:$I$36*(Capex!$G$5:$G$36>=K$4)) -> 8784
A11: Depreciation: expansion capex | D11: =SUM(CashFlow!$D$15:D$15)/Assumptions!$C$106 -> 0 | E11: =SUM(CashFlow!$D$15:E$15)/Assumptions!$C$106 -> 12.6 | F11: =SUM(CashFlow!$D$15:F$15)/Assumptions!$C$106 -> 64.1676 | G11: =SUM(CashFlow!$D$15:G$15)/Assumptions!$C$106 -> 96.708439 | H11: =SUM(CashFlow!$D$15:H$15)/Assumptions!$C$106 -> 138.37627 | I11: =SUM(CashFlow!$D$15:I$15)/Assumptions!$C$106 -> 181.45269 | J11: =SUM(CashFlow!$D$15:J$15)/Assumptions!$C$106 -> 228.4349 | K11: =SUM(CashFlow!$D$15:K$15)/Assumptions!$C$106 -> 278.95659
A12: EBIT (operating profit) | D12: =D8-D10-D11 -> 3014.3264 | E12: =E8-E10-E11 -> 1673.9296 | F12: =F8-F10-F11 -> 4987.2792 | G12: =G8-G10-G11 -> 7601.2499 | H12: =H8-H10-H11 -> 7450.5522 | I12: =I8-I10-I11 -> 11401.99 | J12: =J8-J10-J11 -> 21375.245 | K12: =K8-K10-K11 -> 24878.697
A13: Interest expense | D13: =CashFlow!D10 -> 10523.52 | E13: =CashFlow!E10 -> 10523.52 | F13: =CashFlow!F10 -> 7892.64 | G13: =CashFlow!G10 -> 5261.76 | H13: =CashFlow!H10 -> 2630.88 | I13: =CashFlow!I10 -> 0 | J13: =CashFlow!J10 -> 0 | K13: =CashFlow!K10 -> 0
A14: Profit before tax | D14: =D12-D13 -> -7509.1936 | E14: =E12-E13 -> -8849.5904 | F14: =F12-F13 -> -2905.3608 | G14: =G12-G13 -> 2339.4899 | H14: =H12-H13 -> 4819.6722 | I14: =I12-I13 -> 11401.99 | J14: =J12-J13 -> 21375.245 | K14: =K12-K13 -> 24878.697
A15: Income tax | D15: =MAX(0,D14)*Assumptions!$C$9 -> 0 | E15: =MAX(0,E14)*Assumptions!$C$9 -> 0 | F15: =MAX(0,F14)*Assumptions!$C$9 -> 0 | G15: =MAX(0,G14)*Assumptions!$C$9 -> 467.89799 | H15: =MAX(0,H14)*Assumptions!$C$9 -> 963.93445 | I15: =MAX(0,I14)*Assumptions!$C$9 -> 2280.398 | J15: =MAX(0,J14)*Assumptions!$C$9 -> 4275.049 | K15: =MAX(0,K14)*Assumptions!$C$9 -> 4975.7393
