Workbook

Sheet README
A1: CATTLE FARM FINANCIAL MODEL - dairy + beef breeding
A2: 10-year model, live formulas. Start on Assumptions.
A4: PURPOSE | B4: Test whether a mixed dairy and beef-breeding farm makes money, and which levers (breeding strategy, herd size, infrastructure cost, milk price, feed) change the answer.
A5: IMPORTANT | B5: All prices, costs and yields are GENERIC PLACEHOLDERS in USD. Replace them with local quotes (milk buyer, cattle market, feed supplier, equipment suppliers, bank) before relying on any result.
A7: COLOUR CODE | B7: Blue text = input | Black = formula | Green = link from another sheet | Yellow fill = biggest value drivers.
A9: SHEETS
A10: Assumptions | B10: Every input in one place, plus the Base / Downside / Upside selector (cell F5).
A11: Capex | B11: About 35 itemised startup lines (animals, sheds, milking, cooling, borehole, fencing, vehicles) with depreciation lives.
A12: Herd | B12: Cows, calves, heifer replacement (2-year lag), culls, litres of milk, and a land carrying-capacity warning.
A13: Revenue | B13: 13 streams: raw milk, processed dairy, bull calves, cross-bred calves, surplus heifers (ordinary + breeding stock), dairy culls, beef weaners, finished steers, beef culls, manure, breeding services, grants.
A14: Opex | B14: Feed, health & breeding, replacement stock, labour, processing, utilities, overheads, land costs, contingency.
A15: Financials | B15: Income statement, enterprise gross margins, loan schedule, tax with loss carry-forward, terminal value, project and equity cash flows, DSCR.
A16: Returns | B16: Investment, IRR, NPV, payback, break-even milk and weaner price, checks and charts.
A17: Breeding_Economics | B17: Per-cow view: what calves add under different breeding strategies, and how many cows are needed to cover fixed costs.
A18: Monthly_Y1 | B18: Year-1 monthly cash flow and a check that the working capital reserve is enough.
A19: Scenarios | B19: STATIC snapshot comparing strategies (mixed vs dairy-only vs beef-only, breeding upgrade, lean capex, bigger herds).
A21: HOW TO USE | B21: 1) Put local prices and costs into blue cells on Assumptions and Capex. 2) Set the scenario selector. 3) Read Returns and Monthly_Y1. 4) Test the breeding levers: cross-bred share, sexed semen share, breeding-stock share.
A23: LIMITS | B23: No VAT, no currency moves, no multi-year drought beyond the Downside case. Tax is a flat rate on profit with loss carry-forward: check local farm tax rules and exemptions. Herd is modelled in annual steps with fractional animals. Livestock is not depreciated; it is valued at market in the terminal value. Finishing margin is booked in the same year (simplification). No sustaining capex is depreciated.

Sheet Assumptions
A1: ASSUMPTIONS - every input in one place
A2: Blue = input you can change | Black = formula | Green = link from another sheet | Yellow fill = biggest value drivers. ALL FIGURES ARE PLACEHOLDERS: replace with local quotes.
A4: Input | B4: Unit | C4: Base | D4: Downside | E4: Upside | F4: LIVE VALUE | G4: Notes / source
A5: GENERAL & SCENARIO
A6: Scenario selector (1=Base, 2=Downside, 3=Upside) | B6: 1/2/3 | F6: 1 | G6: Switches every 'scenario lever' below (levers = section 2).
A7: Currency label (for headers only) | B7: text | F7: USD | G7: PLACEHOLDER. Type your currency; then replace every price with a local quote.
A8: Dairy enterprise on? (1=yes, 0=no) | B8: 1/0 | F8: 1 | G8: Set 0 for a beef-only farm.
A9: Beef breeding enterprise on? (1=yes, 0=no) | B9: 1/0 | F9: 1 | G9: Set 0 for a dairy-only farm.
A10: Farm area | B10: hectares | F10: 150 | G10: User brief: 150 ha.
A11: Carrying capacity | B11: animal units/ha | F11: 0.8 | G11: PLACEHOLDER. 1 AU = 1 adult cow; young stock = 0.5 AU. Use your local agronomist's figure.
A12: Land purchased? (1=buy, 0=lease) | B12: 1/0 | F12: 0 | G12: Default = leased, so land is an operating cost, not capex.
A13: Land purchase price | B13: per ha | F13: 1500 | G13: PLACEHOLDER. Only used if land is purchased.
A14: Land lease | B14: per ha / yr | F14: 40 | G14: PLACEHOLDER. Only used if land is leased.
A15: Price inflation (all sales prices) | B15: % / yr | F15: 0.03 | G15: PLACEHOLDER
A16: Cost inflation (all costs) | B16: % / yr | F16: 0.04 | G16: PLACEHOLDER. Costs rising faster than prices squeezes margin.
A17: Income tax rate | B17: % | F17: 0.25 | G17: PLACEHOLDER. Check local farm tax rules/exemptions. Loss carry-forward IS modelled.
A18: Hurdle rate / discount rate | B18: % | F18: 0.12 | G18: Return you require to justify the risk.
A19: Include terminal value in Year 10 returns? (1/0) | B19: 1/0 | F19: 1 | G19: Terminal value = herd at market value + net book value of assets.
A20: Working capital reserve | B20: months of Yr-1 opex | F20: 3 | G20: Cash cushion funded at start. Checked on Monthly_Y1 sheet.
A21: 2. SCENARIO LEVERS (blue = Base / Downside / Upside inputs; column F = live value used by the model)
A22: Raw milk farm-gate price | B22: per litre | C22: 0.6 | D22: 0.48 | E22: 0.72 | F22: =CHOOSE($F$6,C22,D22,E22) -> 0.6 | G22: PLACEHOLDER: use your local processor / buyer quote.
A23: Milk yield per cow in milk | B23: litres / day | C23: 10 | D23: 8.5 | E23: 12 | F23: =CHOOSE($F$6,C23,D23,E23) -> 10 | G23: PLACEHOLDER: depends on breed (crossbreds 8-12, Holstein-type 15-25).
A24: Feed cost multiplier | B24: x | C24: 1 | D24: 1.2 | E24: 0.92 | F24: =CHOOSE($F$6,C24,D24,E24) -> 1 | G24: Scales every feed line.
A25: Cattle price multiplier | B25: x | C25: 1 | D25: 0.8 | E25: 1.2 | F25: =CHOOSE($F$6,C25,D25,E25) -> 1 | G25: Scales calves, heifers, weaners, culls, purchased animals.
A26: Dairy calving rate | B26: calves / cow / yr | C26: 0.8 | D26: 0.7 | E26: 0.88 | F26: =CHOOSE($F$6,C26,D26,E26) -> 0.8 | G26: 80-90% is good management.
A27: Beef calving rate | B27: calves / cow / yr | C27: 0.75 | D27: 0.65 | E27: 0.85 | F27: =CHOOSE($F$6,C27,D27,E27) -> 0.75
A28: Adult cow mortality | B28: % / yr | C28: 0.03 | D28: 0.05 | E28: 0.02 | F28: =CHOOSE($F$6,C28,D28,E28) -> 0.03
A29: Calf mortality (birth to weaning) | B29: % | C29: 0.08 | D29: 0.15 | E29: 0.05 | F29: =CHOOSE($F$6,C29,D29,E29) -> 0.08
A30: 3. HERD
A31: Dairy cows at start | B31: head | F31: 40 | G31: User brief: 40.
A32: Dairy herd target size | B32: head | F32: 40 | G32: Herd grows to this using own heifers (then bought heifers). Set higher than start to grow.
A33: Beef cows at start | B33: head | F33: 30 | G33: User brief: 30.
A34: Beef herd target size | B34: head | F34: 30
A35: Dairy cull rate | B35: % / yr | F35: 0.2
A36: Beef cull rate | B36: % / yr | F36: 0.15
A37: Share of calves that are female (normal semen) | B37: % | F37: 0.5
A38: Dairy cows served with SEXED dairy semen | B38: % of non-cross cows | F38: 0 | G38: BREEDING LEVER: more heifer calves for sale/replacement.
A39: Female calves from sexed semen | B39: % | F39: 0.9 | G39: Typical claimed accuracy ~90%.
A40: Dairy cows served with BEEF semen (cross-bred calves) | B40: % of dairy cows | F40: 0 | G40: BREEDING LEVER: cross-bred calves sell for far more than pure dairy bull calves.
A41: Effective heifer share of dairy-bred calves | B41: % | F41: =F37*(1-F38)+F39*F38 -> 0.5 | G41: Calculated.
...

Sheet Capex
A1: CAPEX - initial investment (about 30 itemised lines)
A2: Blue = input. 'Flag' switches a line on/off from the enterprise toggles. Infrastructure lines are scaled by the multiplier on Assumptions. All unit costs are PLACEHOLDERS.
A4: Item | B4: Applies to | C4: Qty | D4: Unit | E4: Unit cost | F4: Flag | G4: Cost mult. | H4: Total cost | I4: Life (yrs) | J4: Annual depreciation | K4: Notes | L4: Group
A5: ANIMALS
A6: Dairy cows / in-calf heifers | B6: Dairy | C6: =Assumptions!$F$31 -> 40 | D6: head | E6: =Assumptions!$F$70 -> 1100 | F6: =Assumptions!$F$8 -> 1 | G6: =1 -> 1 | H6: =C6*E6*F6*G6 -> 44000 | I6: 0 | J6: =IF(I6>0,H6/I6,0) -> 0 | K6: Not depreciated; valued in terminal value | L6: Animals
A7: Beef breeding cows | B7: Beef | C7: =Assumptions!$F$33 -> 30 | D7: head | E7: =Assumptions!$F$71 -> 800 | F7: =Assumptions!$F$9 -> 1 | G7: =1 -> 1 | H7: =C7*E7*F7*G7 -> 24000 | I7: 0 | J7: =IF(I7>0,H7/I7,0) -> 0 | K7: Not depreciated | L7: Animals
A8: Beef bulls | B8: Beef | C8: =ROUNDUP(Assumptions!$F$33/Assumptions!$F$47,0) -> 2 | D8: head | E8: =Assumptions!$F$73 -> 1200 | F8: =Assumptions!$F$9 -> 1 | G8: =1 -> 1 | H8: =C8*E8*F8*G8 -> 2400 | I8: 5 | J8: =IF(I8>0,H8/I8,0) -> 480 | L8: Animals
A9: BUILDINGS & DAIRY EQUIPMENT
A10: Cow shed / feeding & resting area | B10: Dairy | C10: =Assumptions!$F$31*5 -> 200 | D10: m2 | E10: 45 | F10: =Assumptions!$F$8 -> 1 | G10: =Assumptions!$F$98 -> 1 | H10: =C10*E10*F10*G10 -> 9000 | I10: 20 | J10: =IF(I10>0,H10/I10,0) -> 450 | K10: 5 m2 per cow | L10: Infrastructure
A11: Milking parlour building | B11: Dairy | C11: 1 | D11: lot | E11: 5000 | F11: =Assumptions!$F$8 -> 1 | G11: =Assumptions!$F$98 -> 1 | H11: =C11*E11*F11*G11 -> 5000 | I11: 20 | J11: =IF(I11>0,H11/I11,0) -> 250 | L11: Infrastructure
A12: Milking machine units | B12: Dairy | C12: =ROUNDUP(Assumptions!$F$31/12,0) -> 4 | D12: units | E12: 3500 | F12: =Assumptions!$F$8 -> 1 | G12: =Assumptions!$F$98 -> 1 | H12: =C12*E12*F12*G12 -> 14000 | I12: 10 | J12: =IF(I12>0,H12/I12,0) -> 1400 | K12: 1 unit per 12 cows | L12: Infrastructure
A13: Milk cooling tank | B13: Dairy | C13: 1 | D13: unit | E13: 6000 | F13: =Assumptions!$F$8 -> 1 | G13: =Assumptions!$F$98 -> 1 | H13: =C13*E13*F13*G13 -> 6000 | I13: 12 | J13: =IF(I13>0,H13/I13,0) -> 500 | L13: Infrastructure
A14: Generator / solar backup | B14: Shared | C14: 1 | D14: unit | E14: 5000 | F14: =1 -> 1 | G14: =Assumptions!$F$98 -> 1 | H14: =C14*E14*F14*G14 -> 5000 | I14: 10 | J14: =IF(I14>0,H14/I14,0) -> 500 | L14: Infrastructure
A15: Calf pens & housing | B15: Dairy | C15: 1 | D15: lot | E15: 2500 | F15: =Assumptions!$F$8 -> 1 | G15: =Assumptions!$F$98 -> 1 | H15: =C15*E15*F15*G15 -> 2500 | I15: 15 | J15: =IF(I15>0,H15/I15,0) -> 166.66667 | L15: Infrastructure
A16: Milk cans, churns, cleaning kit | B16: Dairy | C16: 1 | D16: lot | E16: 1200 | F16: =Assumptions!$F$8 -> 1 | G16: =Assumptions!$F$98 -> 1 | H16: =C16*E16*F16*G16 -> 1200 | I16: 5 | J16: =IF(I16>0,H16/I16,0) -> 240 | L16: Infrastructure
A17: Dairy processing equipment (pasteuriser, yoghurt/cheese) | B17: Processing | C17: 1 | D17: lot | E17: 7000 | F17: =IF(Assumptions!$F$51>0,1,0) -> 1 | G17: =Assumptions!$F$98 -> 1 | H17: =C17*E17*F17*G17 -> 7000 | I17: 10 | J17: =IF(I17>0,H17/I17,0) -> 700 | K17: Only if processed share > 0 | L17: Infrastructure
A18: FEED, WATER & LAND WORKS
A19: Feed store / hay barn | B19: Shared | C19: 1 | D19: lot | E19: 6000 | F19: =1 -> 1 | G19: =Assumptions!$F$98 -> 1 | H19: =C19*E19*F19*G19 -> 6000 | I19: 20 | J19: =IF(I19>0,H19/I19,0) -> 300 | L19: Infrastructure
A20: Forage chopper / silage equipment | B20: Shared | C20: 1 | D20: unit | E20: 4000 | F20: =1 -> 1 | G20: =Assumptions!$F$98 -> 1 | H20: =C20*E20*F20*G20 -> 4000 | I20: 10 | J20: =IF(I20>0,H20/I20,0) -> 400 | L20: Infrastructure
A21: Borehole, pump & power | B21: Shared | C21: 1 | D21: lot | E21: 10000 | F21: =1 -> 1 | G21: =Assumptions!$F$98 -> 1 | H21: =C21*E21*F21*G21 -> 10000 | I21: 15 | J21: =IF(I21>0,H21/I21,0) -> 666.66667 | L21: Infrastructure
A22: Water tanks & troughs | B22: Shared | C22: 1 | D22: lot | E22: 3000 | F22: =1 -> 1 | G22: =Assumptions!$F$98 -> 1 | H22: =C22*E22*F22*G22 -> 3000 | I22: 10 | J22: =IF(I22>0,H22/I22,0) -> 300 | L22: Infrastructure
A23: Water piping / reticulation | B23: Shared | C23: 1 | D23: lot | E23: 4000 | F23: =1 -> 1 | G23: =Assumptions!$F$98 -> 1 | H23: =C23*E23*F23*G23 -> 4000 | I23: 15 | J23: =IF(I23>0,H23/I23,0) -> 266.66667 | L23: Infrastructure
A24: Perimeter fencing | B24: Shared | C24: =ROUNDUP(4*SQRT(Assumptions!$F$10*10000)/1000,1) -> 4.9 | D24: km | E24: 3000 | F24: =1 -> 1 | G24: =Assumptions!$F$98 -> 1 | H24: =C24*E24*F24*G24 -> 14700 | I24: 15 | J24: =IF(I24>0,H24/I24,0) -> 980 | K24: Square-plot perimeter of farm area | L24: Infrastructure
A25: Paddock subdivision / electric fencing | B25: Shared | C25: 8 | D25: km | E25: 800 | F25: =1 -> 1 | G25: =Assumptions!$F$98 -> 1 | H25: =C25*E25*F25*G25 -> 6400 | I25: 10 | J25: =IF(I25>0,H25/I25,0) -> 640 | L25: Infrastructure
A26: Pasture establishment (improved grass) | B26: Shared | C26: =Assumptions!$F$31*0.25*Assumptions!$F$8+Assumptions!$F$33*0.1*Assumptions!$F$9 -> 13 | D26: ha | E26: 500 | F26: =1 -> 1 | G26: =Assumptions!$F$98 -> 1 | H26: =C26*E26*F26*G26 -> 6500 | I26: 10 | J26: =IF(I26>0,H26/I26,0) -> 650 | L26: Infrastructure
A27: BEEF HANDLING
A28: Cattle crush & handling yard | B28: Shared | C28: 1 | D28: lot | E28: 5000 | F28: =1 -> 1 | G28: =Assumptions!$F$98 -> 1 | H28: =C28*E28*F28*G28 -> 5000 | I28: 15 | J28: =IF(I28>0,H28/I28,0) -> 333.33333 | L28: Infrastructure
A29: Beef shelter / loading ramp | B29: Beef | C29: 1 | D29: lot | E29: 2500 | F29: =Assumptions!$F$9 -> 1 | G29: =Assumptions!$F$98 -> 1 | H29: =C29*E29*F29*G29 -> 2500 | I29: 15 | J29: =IF(I29>0,H29/I29,0) -> 166.66667 | L29: Infrastructure
A30: Livestock weighing scale | B30: Beef | C30: 1 | D30: unit | E30: 1000 | F30: =Assumptions!$F$9 -> 1 | G30: =Assumptions!$F$98 -> 1 | H30: =C30*E30*F30*G30 -> 1000 | I30: 10 | J30: =IF(I30>0,H30/I30,0) -> 100 | L30: Infrastructure
A31: VEHICLES & GENERAL
A32: Tractor | B32: Shared | C32: 1 | D32: unit | E32: 18000 | F32: =1 -> 1 | G32: =Assumptions!$F$98 -> 1 | H32: =C32*E32*F32*G32 -> 18000 | I32: 10 | J32: =IF(I32>0,H32/I32,0) -> 1800 | L32: Infrastructure
A33: Trailer & implements | B33: Shared | C33: 1 | D33: lot | E33: 3000 | F33: =1 -> 1 | G33: =Assumptions!$F$98 -> 1 | H33: =C33*E33*F33*G33 -> 3000 | I33: 8 | J33: =IF(I33>0,H33/I33,0) -> 375 | L33: Infrastructure
A34: Pickup truck | B34: Shared | C34: 1 | D34: unit | E34: 14000 | F34: =1 -> 1 | G34: =Assumptions!$F$98 -> 1 | H34: =C34*E34*F34*G34 -> 14000 | I34: 8 | J34: =IF(I34>0,H34/I34,0) -> 1750 | L34: Infrastructure
A35: Motorbike(s) | B35: Shared | C35: 1 | D35: unit | E35: 1800 | F35: =1 -> 1 | G35: =Assumptions!$F$98 -> 1 | H35: =C35*E35*F35*G35 -> 1800 | I35: 5 | J35: =IF(I35>0,H35/I35,0) -> 360 | L35: Infrastructure
A36: Farm office & worker housing | B36: Shared | C36: 1 | D36: lot | E36: 5000 | F36: =1 -> 1 | G36: =Assumptions!$F$98 -> 1 | H36: =C36*E36*F36*G36 -> 5000 | I36: 20 | J36: =IF(I36>0,H36/I36,0) -> 250 | L36: Infrastructure
A37: Hand tools & miscellaneous | B37: Shared | C37: 1 | D37: lot | E37: 1200 | F37: =1 -> 1 | G37: =Assumptions!$F$98 -> 1 | H37: =C37*E37*F37*G37 -> 1200 | I37: 5 | J37: =IF(I37>0,H37/I37,0) -> 240 | L37: Infrastructure
A38: Licences, registration, vet set-up | B38: Shared | C38: 1 | D38: lot | E38: 1500 | F38: =1 -> 1 | G38: =Assumptions!$F$98 -> 1 | H38: =C38*E38*F38*G38 -> 1500 | I38: 5 | J38: =IF(I38>0,H38/I38,0) -> 300 | L38: Infrastructure
A39: LAND & CONTINGENCY
A40: Land purchase | B40: Land | C40: =Assumptions!$F$10 -> 150 | D40: ha | E40: =Assumptions!$F$13 -> 1500 | F40: =Assumptions!$F$12 -> 0 | G40: =1 -> 1 | H40: =C40*E40*F40*G40 -> 0 | I40: 0 | J40: =IF(I40>0,H40/I40,0) -> 0 | K40: Only if 'Land purchased' = 1 | L40: Land
A41: Contingency on infrastructure | B41: Shared | C41: 1 | D41: lot | E41: =Assumptions!$F$99*SUMIF($L$6:$L$40,"Infrastructure",$H$6:$H$40) -> 12584 | F41: =1 -> 1 | G41: =1 -> 1 | H41: =C41*E41*F41*G41 -> 12584 | I41: 10 | J41: =IF(I41>0,H41/I41,0) -> 1258.4 | L41: Contingency
...

Sheet Herd
A1: HERD MODEL - cows, calves, heifers, culls, litres
A2: Annual model. Own heifers enter the herd 2 years after birth; any shortfall is met by buying heifers. Fractions of animals are allowed.
A3: Line item | B3: Unit | C3: Year 0 | D3: Year 1 | E3: Year 2 | F3: Year 3 | G3: Year 4 | H3: Year 5 | I3: Year 6 | J3: Year 7 | K3: Year 8 | L3: Year 9 | M3: Year 10
A4: Year index | C4: 0 | D4: 1 | E4: 2 | F4: 3 | G4: 4 | H4: 5 | I4: 6 | J4: 7 | K4: 8 | L4: 9 | M4: 10
A6: DAIRY HERD
A7: Opening dairy cows | B7: head | D7: =Assumptions!$F$31*Assumptions!$F$8 -> 40 | E7: =D14 -> 40 | F7: =E14 -> 40 | G7: =F14 -> 40 | H7: =G14 -> 40 | I7: =H14 -> 40 | J7: =I14 -> 40 | K7: =J14 -> 40 | L7: =K14 -> 40 | M7: =L14 -> 40
A8: Cows culled | B8: head | D8: =ROUND(D7*Assumptions!$F$35,0) -> 8 | E8: =ROUND(E7*Assumptions!$F$35,0) -> 8 | F8: =ROUND(F7*Assumptions!$F$35,0) -> 8 | G8: =ROUND(G7*Assumptions!$F$35,0) -> 8 | H8: =ROUND(H7*Assumptions!$F$35,0) -> 8 | I8: =ROUND(I7*Assumptions!$F$35,0) -> 8 | J8: =ROUND(J7*Assumptions!$F$35,0) -> 8 | K8: =ROUND(K7*Assumptions!$F$35,0) -> 8 | ... M8: =ROUND(M7*Assumptions!$F$35,0) -> 8
A9: Cow deaths | B9: head | D9: =ROUND(D7*Assumptions!$F$28,0) -> 1 | E9: =ROUND(E7*Assumptions!$F$28,0) -> 1 | F9: =ROUND(F7*Assumptions!$F$28,0) -> 1 | G9: =ROUND(G7*Assumptions!$F$28,0) -> 1 | H9: =ROUND(H7*Assumptions!$F$28,0) -> 1 | I9: =ROUND(I7*Assumptions!$F$28,0) -> 1 | J9: =ROUND(J7*Assumptions!$F$28,0) -> 1 | K9: =ROUND(K7*Assumptions!$F$28,0) -> 1 | ... M9: =ROUND(M7*Assumptions!$F$28,0) -> 1
A10: Target herd size | B10: head | D10: =Assumptions!$F$32*Assumptions!$F$8 -> 40 | E10: =Assumptions!$F$32*Assumptions!$F$8 -> 40 | F10: =Assumptions!$F$32*Assumptions!$F$8 -> 40 | G10: =Assumptions!$F$32*Assumptions!$F$8 -> 40 | H10: =Assumptions!$F$32*Assumptions!$F$8 -> 40 | I10: =Assumptions!$F$32*Assumptions!$F$8 -> 40 | J10: =Assumptions!$F$32*Assumptions!$F$8 -> 40 | K10: =Assumptions!$F$32*Assumptions!$F$8 -> 40 | ... M10: =Assumptions!$F$32*Assumptions!$F$8 -> 40
A11: Replacements needed to reach target | B11: head | D11: =MAX(0,D10-(D7-D8-D9)) -> 9 | E11: =MAX(0,E10-(E7-E8-E9)) -> 9 | F11: =MAX(0,F10-(F7-F8-F9)) -> 9 | G11: =MAX(0,G10-(G7-G8-G9)) -> 9 | H11: =MAX(0,H10-(H7-H8-H9)) -> 9 | I11: =MAX(0,I10-(I7-I8-I9)) -> 9 | J11: =MAX(0,J10-(J7-J8-J9)) -> 9 | K11: =MAX(0,K10-(K7-K8-K9)) -> 9 | ... M11: =MAX(0,M10-(M7-M8-M9)) -> 9
A12: Own heifers entering herd | B12: head | D12: =MIN(D24,D11) -> 0 | E12: =MIN(E24,E11) -> 0 | F12: =MIN(F24,F11) -> 9 | G12: =MIN(G24,G11) -> 9 | H12: =MIN(H24,H11) -> 9 | I12: =MIN(I24,I11) -> 9 | J12: =MIN(J24,J11) -> 9 | K12: =MIN(K24,K11) -> 9 | ... M12: =MIN(M24,M11) -> 9
A13: Replacement heifers bought in | B13: head | D13: =D11-D12 -> 9 | E13: =E11-E12 -> 9 | F13: =F11-F12 -> 0 | G13: =G11-G12 -> 0 | H13: =H11-H12 -> 0 | I13: =I11-I12 -> 0 | J13: =J11-J12 -> 0 | K13: =K11-K12 -> 0 | ... M13: =M11-M12 -> 0
A14: Closing dairy cows | B14: head | D14: =D7-D8-D9+D12+D13 -> 40 | E14: =E7-E8-E9+E12+E13 -> 40 | F14: =F7-F8-F9+F12+F13 -> 40 | G14: =G7-G8-G9+G12+G13 -> 40 | H14: =H7-H8-H9+H12+H13 -> 40 | I14: =I7-I8-I9+I12+I13 -> 40 | J14: =J7-J8-J9+J12+J13 -> 40 | K14: =K7-K8-K9+K12+K13 -> 40 | ... M14: =M7-M8-M9+M12+M13 -> 40
A15: Average dairy cows | B15: head | D15: =(D7+D14)/2 -> 40 | E15: =(E7+E14)/2 -> 40 | F15: =(F7+F14)/2 -> 40 | G15: =(G7+G14)/2 -> 40 | H15: =(H7+H14)/2 -> 40 | I15: =(I7+I14)/2 -> 40 | J15: =(J7+J14)/2 -> 40 | K15: =(K7+K14)/2 -> 40 | ... M15: =(M7+M14)/2 -> 40
A17: DAIRY CALF CROP
A18: Calves born | B18: head | D18: =D7*Assumptions!$F$26 -> 32 | E18: =E7*Assumptions!$F$26 -> 32 | F18: =F7*Assumptions!$F$26 -> 32 | G18: =G7*Assumptions!$F$26 -> 32 | H18: =H7*Assumptions!$F$26 -> 32 | I18: =I7*Assumptions!$F$26 -> 32 | J18: =J7*Assumptions!$F$26 -> 32 | K18: =K7*Assumptions!$F$26 -> 32 | ... M18: =M7*Assumptions!$F$26 -> 32
A19: of which sired by beef bull (cross-bred) | B19: head | D19: =D18*Assumptions!$F$40 -> 0 | E19: =E18*Assumptions!$F$40 -> 0 | F19: =F18*Assumptions!$F$40 -> 0 | G19: =G18*Assumptions!$F$40 -> 0 | H19: =H18*Assumptions!$F$40 -> 0 | I19: =I18*Assumptions!$F$40 -> 0 | J19: =J18*Assumptions!$F$40 -> 0 | K19: =K18*Assumptions!$F$40 -> 0 | ... M19: =M18*Assumptions!$F$40 -> 0
A20: of which dairy-bred | B20: head | D20: =D18-D19 -> 32 | E20: =E18-E19 -> 32 | F20: =F18-F19 -> 32 | G20: =G18-G19 -> 32 | H20: =H18-H19 -> 32 | I20: =I18-I19 -> 32 | J20: =J18-J19 -> 32 | K20: =K18-K19 -> 32 | ... M20: =M18-M19 -> 32
A21: Heifer calves surviving (dairy-bred) | B21: head | D21: =D20*Assumptions!$F$41*(1-Assumptions!$F$29) -> 14.72 | E21: =E20*Assumptions!$F$41*(1-Assumptions!$F$29) -> 14.72 | F21: =F20*Assumptions!$F$41*(1-Assumptions!$F$29) -> 14.72 | G21: =G20*Assumptions!$F$41*(1-Assumptions!$F$29) -> 14.72 | H21: =H20*Assumptions!$F$41*(1-Assumptions!$F$29) -> 14.72 | I21: =I20*Assumptions!$F$41*(1-Assumptions!$F$29) -> 14.72 | J21: =J20*Assumptions!$F$41*(1-Assumptions!$F$29) -> 14.72 | K21: =K20*Assumptions!$F$41*(1-Assumptions!$F$29) -> 14.72 | ... M21: =M20*Assumptions!$F$41*(1-Assumptions!$F$29) -> 14.72
A22: Bull calves surviving (sold) | B22: head | D22: =D20*(1-Assumptions!$F$41)*(1-Assumptions!$F$29) -> 14.72 | E22: =E20*(1-Assumptions!$F$41)*(1-Assumptions!$F$29) -> 14.72 | F22: =F20*(1-Assumptions!$F$41)*(1-Assumptions!$F$29) -> 14.72 | G22: =G20*(1-Assumptions!$F$41)*(1-Assumptions!$F$29) -> 14.72 | H22: =H20*(1-Assumptions!$F$41)*(1-Assumptions!$F$29) -> 14.72 | I22: =I20*(1-Assumptions!$F$41)*(1-Assumptions!$F$29) -> 14.72 | J22: =J20*(1-Assumptions!$F$41)*(1-Assumptions!$F$29) -> 14.72 | K22: =K20*(1-Assumptions!$F$41)*(1-Assumptions!$F$29) -> 14.72 | ... M22: =M20*(1-Assumptions!$F$41)*(1-Assumptions!$F$29) -> 14.72
A23: Cross-bred calves surviving (sold) | B23: head | D23: =D19*(1-Assumptions!$F$29) -> 0 | E23: =E19*(1-Assumptions!$F$29) -> 0 | F23: =F19*(1-Assumptions!$F$29) -> 0 | G23: =G19*(1-Assumptions!$F$29) -> 0 | H23: =H19*(1-Assumptions!$F$29) -> 0 | I23: =I19*(1-Assumptions!$F$29) -> 0 | J23: =J19*(1-Assumptions!$F$29) -> 0 | K23: =K19*(1-Assumptions!$F$29) -> 0 | ... M23: =M19*(1-Assumptions!$F$29) -> 0
A24: Heifers reaching breeding age (born 2 yrs earlier) | B24: head | D24: =0 -> 0 | E24: =0 -> 0 | F24: =E21 -> 14.72 | G24: =F21 -> 14.72 | H24: =G21 -> 14.72 | I24: =H21 -> 14.72 | J24: =I21 -> 14.72 | K24: =J21 -> 14.72 | L24: =K21 -> 14.72 | M24: =L21 -> 14.72
A25: Surplus heifers sold | B25: head | D25: =D24-D12 -> 0 | E25: =E24-E12 -> 0 | F25: =F24-F12 -> 5.72 | G25: =G24-G12 -> 5.72 | H25: =H24-H12 -> 5.72 | I25: =I24-I12 -> 5.72 | J25: =J24-J12 -> 5.72 | K25: =K24-K12 -> 5.72 | ... M25: =M24-M12 -> 5.72
A26: Young heifers on farm (under 2 yrs) | B26: head | D26: =D21 -> 14.72 | E26: =E21+D21 -> 29.44 | F26: =F21+E21 -> 29.44 | G26: =G21+F21 -> 29.44 | H26: =H21+G21 -> 29.44 | I26: =I21+H21 -> 29.44 | J26: =J21+I21 -> 29.44 | K26: =K21+J21 -> 29.44 | L26: =L21+K21 -> 29.44 | M26: =M21+L21 -> 29.44
A28: MILK PRODUCTION
A29: Total milk produced | B29: litres | D29: =D15*Assumptions!$F$50*Assumptions!$F$23*Assumptions!$F$49 -> 102000 | E29: =E15*Assumptions!$F$50*Assumptions!$F$23*Assumptions!$F$49 -> 102000 | F29: =F15*Assumptions!$F$50*Assumptions!$F$23*Assumptions!$F$49 -> 102000 | G29: =G15*Assumptions!$F$50*Assumptions!$F$23*Assumptions!$F$49 -> 102000 | H29: =H15*Assumptions!$F$50*Assumptions!$F$23*Assumptions!$F$49 -> 102000 | I29: =I15*Assumptions!$F$50*Assumptions!$F$23*Assumptions!$F$49 -> 102000 | J29: =J15*Assumptions!$F$50*Assumptions!$F$23*Assumptions!$F$49 -> 102000 | K29: =K15*Assumptions!$F$50*Assumptions!$F$23*Assumptions!$F$49 -> 102000 | ... M29: =M15*Assumptions!$F$50*Assumptions!$F$23*Assumptions!$F$49 -> 102000
A30: processed on farm | B30: litres | D30: =D29*Assumptions!$F$51 -> 10200 | E30: =E29*Assumptions!$F$51 -> 10200 | F30: =F29*Assumptions!$F$51 -> 10200 | G30: =G29*Assumptions!$F$51 -> 10200 | H30: =H29*Assumptions!$F$51 -> 10200 | I30: =I29*Assumptions!$F$51 -> 10200 | J30: =J29*Assumptions!$F$51 -> 10200 | K30: =K29*Assumptions!$F$51 -> 10200 | ... M30: =M29*Assumptions!$F$51 -> 10200
A31: sold raw | B31: litres | D31: =D29-D30 -> 91800 | E31: =E29-E30 -> 91800 | F31: =F29-F30 -> 91800 | G31: =G29-G30 -> 91800 | H31: =H29-H30 -> 91800 | I31: =I29-I30 -> 91800 | J31: =J29-J30 -> 91800 | K31: =K29-K30 -> 91800 | ... M31: =M29-M30 -> 91800
A33: BEEF BREEDING HERD
A34: Opening beef cows | B34: head | D34: =Assumptions!$F$33*Assumptions!$F$9 -> 30 | E34: =D41 -> 30 | F34: =E41 -> 30 | G34: =F41 -> 30 | H34: =G41 -> 30 | I34: =H41 -> 30 | J34: =I41 -> 30 | K34: =J41 -> 30 | L34: =K41 -> 30 | M34: =L41 -> 30
A35: Cows culled | B35: head | D35: =ROUND(D34*Assumptions!$F$36,0) -> 5 | E35: =ROUND(E34*Assumptions!$F$36,0) -> 5 | F35: =ROUND(F34*Assumptions!$F$36,0) -> 5 | G35: =ROUND(G34*Assumptions!$F$36,0) -> 5 | H35: =ROUND(H34*Assumptions!$F$36,0) -> 5 | I35: =ROUND(I34*Assumptions!$F$36,0) -> 5 | J35: =ROUND(J34*Assumptions!$F$36,0) -> 5 | K35: =ROUND(K34*Assumptions!$F$36,0) -> 5 | ... M35: =ROUND(M34*Assumptions!$F$36,0) -> 5
A36: Cow deaths | B36: head | D36: =ROUND(D34*Assumptions!$F$28,0) -> 1 | E36: =ROUND(E34*Assumptions!$F$28,0) -> 1 | F36: =ROUND(F34*Assumptions!$F$28,0) -> 1 | G36: =ROUND(G34*Assumptions!$F$28,0) -> 1 | H36: =ROUND(H34*Assumptions!$F$28,0) -> 1 | I36: =ROUND(I34*Assumptions!$F$28,0) -> 1 | J36: =ROUND(J34*Assumptions!$F$28,0) -> 1 | K36: =ROUND(K34*Assumptions!$F$28,0) -> 1 | ... M36: =ROUND(M34*Assumptions!$F$28,0) -> 1
A37: Target herd size | B37: head | D37: =Assumptions!$F$34*Assumptions!$F$9 -> 30 | E37: =Assumptions!$F$34*Assumptions!$F$9 -> 30 | F37: =Assumptions!$F$34*Assumptions!$F$9 -> 30 | G37: =Assumptions!$F$34*Assumptions!$F$9 -> 30 | H37: =Assumptions!$F$34*Assumptions!$F$9 -> 30 | I37: =Assumptions!$F$34*Assumptions!$F$9 -> 30 | J37: =Assumptions!$F$34*Assumptions!$F$9 -> 30 | K37: =Assumptions!$F$34*Assumptions!$F$9 -> 30 | ... M37: =Assumptions!$F$34*Assumptions!$F$9 -> 30
A38: Replacements needed to reach target | B38: head | D38: =MAX(0,D37-(D34-D35-D36)) -> 6 | E38: =MAX(0,E37-(E34-E35-E36)) -> 6 | F38: =MAX(0,F37-(F34-F35-F36)) -> 6 | G38: =MAX(0,G37-(G34-G35-G36)) -> 6 | H38: =MAX(0,H37-(H34-H35-H36)) -> 6 | I38: =MAX(0,I37-(I34-I35-I36)) -> 6 | J38: =MAX(0,J37-(J34-J35-J36)) -> 6 | K38: =MAX(0,K37-(K34-K35-K36)) -> 6 | ... M38: =MAX(0,M37-(M34-M35-M36)) -> 6
A39: Own heifers entering herd | B39: head | D39: =MIN(D51,D38) -> 0 | E39: =MIN(E51,E38) -> 0 | F39: =MIN(F51,F38) -> 6 | G39: =MIN(G51,G38) -> 6 | H39: =MIN(H51,H38) -> 6 | I39: =MIN(I51,I38) -> 6 | J39: =MIN(J51,J38) -> 6 | K39: =MIN(K51,K38) -> 6 | ... M39: =MIN(M51,M38) -> 6
A40: Replacement heifers bought in | B40: head | D40: =D38-D39 -> 6 | E40: =E38-E39 -> 6 | F40: =F38-F39 -> 0 | G40: =G38-G39 -> 0 | H40: =H38-H39 -> 0 | I40: =I38-I39 -> 0 | J40: =J38-J39 -> 0 | K40: =K38-K39 -> 0 | ... M40: =M38-M39 -> 0
A41: Closing beef cows | B41: head | D41: =D34-D35-D36+D39+D40 -> 30 | E41: =E34-E35-E36+E39+E40 -> 30 | F41: =F34-F35-F36+F39+F40 -> 30 | G41: =G34-G35-G36+G39+G40 -> 30 | H41: =H34-H35-H36+H39+H40 -> 30 | I41: =I34-I35-I36+I39+I40 -> 30 | J41: =J34-J35-J36+J39+J40 -> 30 | K41: =K34-K35-K36+K39+K40 -> 30 | ... M41: =M34-M35-M36+M39+M40 -> 30
A42: Average beef cows | B42: head | D42: =(D34+D41)/2 -> 30 | E42: =(E34+E41)/2 -> 30 | F42: =(F34+F41)/2 -> 30 | G42: =(G34+G41)/2 -> 30 | H42: =(H34+H41)/2 -> 30 | I42: =(I34+I41)/2 -> 30 | J42: =(J34+J41)/2 -> 30 | K42: =(K34+K41)/2 -> 30 | ... M42: =(M34+M41)/2 -> 30
A44: BEEF CALF CROP
A45: Calves born | B45: head | D45: =D34*Assumptions!$F$27 -> 22.5 | E45: =E34*Assumptions!$F$27 -> 22.5 | F45: =F34*Assumptions!$F$27 -> 22.5 | G45: =G34*Assumptions!$F$27 -> 22.5 | H45: =H34*Assumptions!$F$27 -> 22.5 | I45: =I34*Assumptions!$F$27 -> 22.5 | J45: =J34*Assumptions!$F$27 -> 22.5 | K45: =K34*Assumptions!$F$27 -> 22.5 | ... M45: =M34*Assumptions!$F$27 -> 22.5
...

Sheet Revenue
A1: REVENUE - streams by year
A2: Volume from Herd sheet x price (Year-1 price x price inflation x scenario multiplier).
A3: Line item | B3: Unit | C3: Year 0 | D3: Year 1 | E3: Year 2 | F3: Year 3 | G3: Year 4 | H3: Year 5 | I3: Year 6 | J3: Year 7 | K3: Year 8 | L3: Year 9 | M3: Year 10
A4: Year index | C4: 0 | D4: 1 | E4: 2 | F4: 3 | G4: 4 | H4: 5 | I4: 6 | J4: 7 | K4: 8 | L4: 9 | M4: 10
A6: Price inflation factor | B6: index | D6: =(1+Assumptions!$F$15)^(D$4-1) -> 1 | E6: =(1+Assumptions!$F$15)^(E$4-1) -> 1.03 | F6: =(1+Assumptions!$F$15)^(F$4-1) -> 1.0609 | G6: =(1+Assumptions!$F$15)^(G$4-1) -> 1.092727 | H6: =(1+Assumptions!$F$15)^(H$4-1) -> 1.1255088 | I6: =(1+Assumptions!$F$15)^(I$4-1) -> 1.1592741 | J6: =(1+Assumptions!$F$15)^(J$4-1) -> 1.1940523 | K6: =(1+Assumptions!$F$15)^(K$4-1) -> 1.2298739 | ... M6: =(1+Assumptions!$F$15)^(M$4-1) -> 1.3047732
A7: DAIRY REVENUE
A8: 1. Raw milk sales | B8: money | D8: =Herd!D31*Assumptions!$F$22*D$6 -> 55080 | E8: =Herd!E31*Assumptions!$F$22*E$6 -> 56732.4 | F8: =Herd!F31*Assumptions!$F$22*F$6 -> 58434.372 | G8: =Herd!G31*Assumptions!$F$22*G$6 -> 60187.403 | H8: =Herd!H31*Assumptions!$F$22*H$6 -> 61993.025 | I8: =Herd!I31*Assumptions!$F$22*I$6 -> 63852.816 | J8: =Herd!J31*Assumptions!$F$22*J$6 -> 65768.4 | K8: =Herd!K31*Assumptions!$F$22*K$6 -> 67741.453 | ... M8: =Herd!M31*Assumptions!$F$22*M$6 -> 71866.907
A9: 2. Processed dairy products (yoghurt, cheese...) | B9: money | D9: =Herd!D30*Assumptions!$F$22*Assumptions!$F$52*D$6 -> 12240 | E9: =Herd!E30*Assumptions!$F$22*Assumptions!$F$52*E$6 -> 12607.2 | F9: =Herd!F30*Assumptions!$F$22*Assumptions!$F$52*F$6 -> 12985.416 | G9: =Herd!G30*Assumptions!$F$22*Assumptions!$F$52*G$6 -> 13374.978 | H9: =Herd!H30*Assumptions!$F$22*Assumptions!$F$52*H$6 -> 13776.228 | I9: =Herd!I30*Assumptions!$F$22*Assumptions!$F$52*I$6 -> 14189.515 | J9: =Herd!J30*Assumptions!$F$22*Assumptions!$F$52*J$6 -> 14615.2 | K9: =Herd!K30*Assumptions!$F$22*Assumptions!$F$52*K$6 -> 15053.656 | ... M9: =Herd!M30*Assumptions!$F$22*Assumptions!$F$52*M$6 -> 15970.424
A10: 3. Dairy bull calves | B10: money | D10: =Herd!D22*Assumptions!$F$55*Assumptions!$F$25*D$6 -> 588.8 | E10: =Herd!E22*Assumptions!$F$55*Assumptions!$F$25*E$6 -> 606.464 | F10: =Herd!F22*Assumptions!$F$55*Assumptions!$F$25*F$6 -> 624.65792 | G10: =Herd!G22*Assumptions!$F$55*Assumptions!$F$25*G$6 -> 643.39766 | H10: =Herd!H22*Assumptions!$F$55*Assumptions!$F$25*H$6 -> 662.69959 | I10: =Herd!I22*Assumptions!$F$55*Assumptions!$F$25*I$6 -> 682.58057 | J10: =Herd!J22*Assumptions!$F$55*Assumptions!$F$25*J$6 -> 703.05799 | K10: =Herd!K22*Assumptions!$F$55*Assumptions!$F$25*K$6 -> 724.14973 | ... M10: =Herd!M22*Assumptions!$F$55*Assumptions!$F$25*M$6 -> 768.25045
A11: 4. Beef-cross calves (from beef semen on dairy cows) | B11: money | D11: =Herd!D23*Assumptions!$F$56*Assumptions!$F$25*D$6 -> 0 | E11: =Herd!E23*Assumptions!$F$56*Assumptions!$F$25*E$6 -> 0 | F11: =Herd!F23*Assumptions!$F$56*Assumptions!$F$25*F$6 -> 0 | G11: =Herd!G23*Assumptions!$F$56*Assumptions!$F$25*G$6 -> 0 | H11: =Herd!H23*Assumptions!$F$56*Assumptions!$F$25*H$6 -> 0 | I11: =Herd!I23*Assumptions!$F$56*Assumptions!$F$25*I$6 -> 0 | J11: =Herd!J23*Assumptions!$F$56*Assumptions!$F$25*J$6 -> 0 | K11: =Herd!K23*Assumptions!$F$56*Assumptions!$F$25*K$6 -> 0 | ... M11: =Herd!M23*Assumptions!$F$56*Assumptions!$F$25*M$6 -> 0
A12: 5a. Surplus dairy heifers - ordinary | B12: money | D12: =Herd!D25*(1-Assumptions!$F$42)*Assumptions!$F$57*Assumptions!$F$25*D$6 -> 0 | E12: =Herd!E25*(1-Assumptions!$F$42)*Assumptions!$F$57*Assumptions!$F$25*E$6 -> 0 | F12: =Herd!F25*(1-Assumptions!$F$42)*Assumptions!$F$57*Assumptions!$F$25*F$6 -> 4247.8436 | G12: =Herd!G25*(1-Assumptions!$F$42)*Assumptions!$F$57*Assumptions!$F$25*G$6 -> 4375.2789 | H12: =Herd!H25*(1-Assumptions!$F$42)*Assumptions!$F$57*Assumptions!$F$25*H$6 -> 4506.5373 | I12: =Herd!I25*(1-Assumptions!$F$42)*Assumptions!$F$57*Assumptions!$F$25*I$6 -> 4641.7334 | J12: =Herd!J25*(1-Assumptions!$F$42)*Assumptions!$F$57*Assumptions!$F$25*J$6 -> 4780.9854 | K12: =Herd!K25*(1-Assumptions!$F$42)*Assumptions!$F$57*Assumptions!$F$25*K$6 -> 4924.415 | ... M12: =Herd!M25*(1-Assumptions!$F$42)*Assumptions!$F$57*Assumptions!$F$25*M$6 -> 5224.3118
A13: 5b. Surplus dairy heifers - breeding stock | B13: money | D13: =Herd!D25*Assumptions!$F$42*Assumptions!$F$57*Assumptions!$F$44*Assumptions!$F$25*D$6 -> 0 | E13: =Herd!E25*Assumptions!$F$42*Assumptions!$F$57*Assumptions!$F$44*Assumptions!$F$25*E$6 -> 0 | F13: =Herd!F25*Assumptions!$F$42*Assumptions!$F$57*Assumptions!$F$44*Assumptions!$F$25*F$6 -> 0 | G13: =Herd!G25*Assumptions!$F$42*Assumptions!$F$57*Assumptions!$F$44*Assumptions!$F$25*G$6 -> 0 | H13: =Herd!H25*Assumptions!$F$42*Assumptions!$F$57*Assumptions!$F$44*Assumptions!$F$25*H$6 -> 0 | I13: =Herd!I25*Assumptions!$F$42*Assumptions!$F$57*Assumptions!$F$44*Assumptions!$F$25*I$6 -> 0 | J13: =Herd!J25*Assumptions!$F$42*Assumptions!$F$57*Assumptions!$F$44*Assumptions!$F$25*J$6 -> 0 | K13: =Herd!K25*Assumptions!$F$42*Assumptions!$F$57*Assumptions!$F$44*Assumptions!$F$25*K$6 -> 0 | ... M13: =Herd!M25*Assumptions!$F$42*Assumptions!$F$57*Assumptions!$F$44*Assumptions!$F$25*M$6 -> 0
A14: 6. Dairy cull cows | B14: money | D14: =Herd!D8*Assumptions!$F$63*Assumptions!$F$65*Assumptions!$F$25*D$6 -> 5376 | E14: =Herd!E8*Assumptions!$F$63*Assumptions!$F$65*Assumptions!$F$25*E$6 -> 5537.28 | F14: =Herd!F8*Assumptions!$F$63*Assumptions!$F$65*Assumptions!$F$25*F$6 -> 5703.3984 | G14: =Herd!G8*Assumptions!$F$63*Assumptions!$F$65*Assumptions!$F$25*G$6 -> 5874.5004 | H14: =Herd!H8*Assumptions!$F$63*Assumptions!$F$65*Assumptions!$F$25*H$6 -> 6050.7354 | I14: =Herd!I8*Assumptions!$F$63*Assumptions!$F$65*Assumptions!$F$25*I$6 -> 6232.2574 | J14: =Herd!J8*Assumptions!$F$63*Assumptions!$F$65*Assumptions!$F$25*J$6 -> 6419.2251 | K14: =Herd!K8*Assumptions!$F$63*Assumptions!$F$65*Assumptions!$F$25*K$6 -> 6611.8019 | ... M14: =Herd!M8*Assumptions!$F$63*Assumptions!$F$65*Assumptions!$F$25*M$6 -> 7014.4606
A16: BEEF REVENUE
A17: 7. Beef weaners (steers) | B17: money | D17: =Herd!D49*Assumptions!$F$59*Assumptions!$F$60*Assumptions!$F$25*D$6 -> 4554 | E17: =Herd!E49*Assumptions!$F$59*Assumptions!$F$60*Assumptions!$F$25*E$6 -> 4690.62 | F17: =Herd!F49*Assumptions!$F$59*Assumptions!$F$60*Assumptions!$F$25*F$6 -> 4831.3386 | G17: =Herd!G49*Assumptions!$F$59*Assumptions!$F$60*Assumptions!$F$25*G$6 -> 4976.2788 | H17: =Herd!H49*Assumptions!$F$59*Assumptions!$F$60*Assumptions!$F$25*H$6 -> 5125.5671 | I17: =Herd!I49*Assumptions!$F$59*Assumptions!$F$60*Assumptions!$F$25*I$6 -> 5279.3341 | J17: =Herd!J49*Assumptions!$F$59*Assumptions!$F$60*Assumptions!$F$25*J$6 -> 5437.7142 | K17: =Herd!K49*Assumptions!$F$59*Assumptions!$F$60*Assumptions!$F$25*K$6 -> 5600.8456 | ... M17: =Herd!M49*Assumptions!$F$59*Assumptions!$F$60*Assumptions!$F$25*M$6 -> 5941.9371
A18: 8. Finished steers for slaughter | B18: money | D18: =Herd!D50*Assumptions!$F$61*Assumptions!$F$62*Assumptions!$F$25*D$6 -> 0 | E18: =Herd!E50*Assumptions!$F$61*Assumptions!$F$62*Assumptions!$F$25*E$6 -> 0 | F18: =Herd!F50*Assumptions!$F$61*Assumptions!$F$62*Assumptions!$F$25*F$6 -> 0 | G18: =Herd!G50*Assumptions!$F$61*Assumptions!$F$62*Assumptions!$F$25*G$6 -> 0 | H18: =Herd!H50*Assumptions!$F$61*Assumptions!$F$62*Assumptions!$F$25*H$6 -> 0 | I18: =Herd!I50*Assumptions!$F$61*Assumptions!$F$62*Assumptions!$F$25*I$6 -> 0 | J18: =Herd!J50*Assumptions!$F$61*Assumptions!$F$62*Assumptions!$F$25*J$6 -> 0 | K18: =Herd!K50*Assumptions!$F$61*Assumptions!$F$62*Assumptions!$F$25*K$6 -> 0 | ... M18: =Herd!M50*Assumptions!$F$61*Assumptions!$F$62*Assumptions!$F$25*M$6 -> 0
A19: 9a. Surplus beef heifers - ordinary | B19: money | D19: =Herd!D52*(1-Assumptions!$F$43)*Assumptions!$F$58*Assumptions!$F$25*D$6 -> 0 | E19: =Herd!E52*(1-Assumptions!$F$43)*Assumptions!$F$58*Assumptions!$F$25*E$6 -> 0 | F19: =Herd!F52*(1-Assumptions!$F$43)*Assumptions!$F$58*Assumptions!$F$25*F$6 -> 2768.949 | G19: =Herd!G52*(1-Assumptions!$F$43)*Assumptions!$F$58*Assumptions!$F$25*G$6 -> 2852.0175 | H19: =Herd!H52*(1-Assumptions!$F$43)*Assumptions!$F$58*Assumptions!$F$25*H$6 -> 2937.578 | I19: =Herd!I52*(1-Assumptions!$F$43)*Assumptions!$F$58*Assumptions!$F$25*I$6 -> 3025.7053 | J19: =Herd!J52*(1-Assumptions!$F$43)*Assumptions!$F$58*Assumptions!$F$25*J$6 -> 3116.4765 | K19: =Herd!K52*(1-Assumptions!$F$43)*Assumptions!$F$58*Assumptions!$F$25*K$6 -> 3209.9708 | ... M19: =Herd!M52*(1-Assumptions!$F$43)*Assumptions!$F$58*Assumptions!$F$25*M$6 -> 3405.458
A20: 9b. Surplus beef heifers - breeding stock | B20: money | D20: =Herd!D52*Assumptions!$F$43*Assumptions!$F$58*Assumptions!$F$44*Assumptions!$F$25*D$6 -> 0 | E20: =Herd!E52*Assumptions!$F$43*Assumptions!$F$58*Assumptions!$F$44*Assumptions!$F$25*E$6 -> 0 | F20: =Herd!F52*Assumptions!$F$43*Assumptions!$F$58*Assumptions!$F$44*Assumptions!$F$25*F$6 -> 0 | G20: =Herd!G52*Assumptions!$F$43*Assumptions!$F$58*Assumptions!$F$44*Assumptions!$F$25*G$6 -> 0 | H20: =Herd!H52*Assumptions!$F$43*Assumptions!$F$58*Assumptions!$F$44*Assumptions!$F$25*H$6 -> 0 | I20: =Herd!I52*Assumptions!$F$43*Assumptions!$F$58*Assumptions!$F$44*Assumptions!$F$25*I$6 -> 0 | J20: =Herd!J52*Assumptions!$F$43*Assumptions!$F$58*Assumptions!$F$44*Assumptions!$F$25*J$6 -> 0 | K20: =Herd!K52*Assumptions!$F$43*Assumptions!$F$58*Assumptions!$F$44*Assumptions!$F$25*K$6 -> 0 | ... M20: =Herd!M52*Assumptions!$F$43*Assumptions!$F$58*Assumptions!$F$44*Assumptions!$F$25*M$6 -> 0
A21: 10. Beef cull cows | B21: money | D21: =Herd!D35*Assumptions!$F$64*Assumptions!$F$65*Assumptions!$F$25*D$6 -> 3600 | E21: =Herd!E35*Assumptions!$F$64*Assumptions!$F$65*Assumptions!$F$25*E$6 -> 3708 | F21: =Herd!F35*Assumptions!$F$64*Assumptions!$F$65*Assumptions!$F$25*F$6 -> 3819.24 | G21: =Herd!G35*Assumptions!$F$64*Assumptions!$F$65*Assumptions!$F$25*G$6 -> 3933.8172 | H21: =Herd!H35*Assumptions!$F$64*Assumptions!$F$65*Assumptions!$F$25*H$6 -> 4051.8317 | I21: =Herd!I35*Assumptions!$F$64*Assumptions!$F$65*Assumptions!$F$25*I$6 -> 4173.3867 | J21: =Herd!J35*Assumptions!$F$64*Assumptions!$F$65*Assumptions!$F$25*J$6 -> 4298.5883 | K21: =Herd!K35*Assumptions!$F$64*Assumptions!$F$65*Assumptions!$F$25*K$6 -> 4427.5459 | ... M21: =Herd!M35*Assumptions!$F$64*Assumptions!$F$65*Assumptions!$F$25*M$6 -> 4697.1835
A23: OTHER REVENUE
A24: 11. Manure / slurry | B24: money | D24: =(Herd!D15+Herd!D42)*Assumptions!$F$66*D$6 -> 1750 | E24: =(Herd!E15+Herd!E42)*Assumptions!$F$66*E$6 -> 1802.5 | F24: =(Herd!F15+Herd!F42)*Assumptions!$F$66*F$6 -> 1856.575 | G24: =(Herd!G15+Herd!G42)*Assumptions!$F$66*G$6 -> 1912.2722 | H24: =(Herd!H15+Herd!H42)*Assumptions!$F$66*H$6 -> 1969.6404 | I24: =(Herd!I15+Herd!I42)*Assumptions!$F$66*I$6 -> 2028.7296 | J24: =(Herd!J15+Herd!J42)*Assumptions!$F$66*J$6 -> 2089.5915 | K24: =(Herd!K15+Herd!K42)*Assumptions!$F$66*K$6 -> 2152.2793 | ... M24: =(Herd!M15+Herd!M42)*Assumptions!$F$66*M$6 -> 2283.3531
A25: 12. Breeding services (bull hire / AI for outside cows) | B25: money | D25: =Assumptions!$F$46*Assumptions!$F$67*Assumptions!$F$9*D$6 -> 0 | E25: =Assumptions!$F$46*Assumptions!$F$67*Assumptions!$F$9*E$6 -> 0 | F25: =Assumptions!$F$46*Assumptions!$F$67*Assumptions!$F$9*F$6 -> 0 | G25: =Assumptions!$F$46*Assumptions!$F$67*Assumptions!$F$9*G$6 -> 0 | H25: =Assumptions!$F$46*Assumptions!$F$67*Assumptions!$F$9*H$6 -> 0 | I25: =Assumptions!$F$46*Assumptions!$F$67*Assumptions!$F$9*I$6 -> 0 | J25: =Assumptions!$F$46*Assumptions!$F$67*Assumptions!$F$9*J$6 -> 0 | K25: =Assumptions!$F$46*Assumptions!$F$67*Assumptions!$F$9*K$6 -> 0 | ... M25: =Assumptions!$F$46*Assumptions!$F$67*Assumptions!$F$9*M$6 -> 0
A26: 13. Grants / subsidies | B26: money | D26: =IF(D$4<=Assumptions!$F$69,Assumptions!$F$68,0) -> 0 | E26: =IF(E$4<=Assumptions!$F$69,Assumptions!$F$68,0) -> 0 | F26: =IF(F$4<=Assumptions!$F$69,Assumptions!$F$68,0) -> 0 | G26: =IF(G$4<=Assumptions!$F$69,Assumptions!$F$68,0) -> 0 | H26: =IF(H$4<=Assumptions!$F$69,Assumptions!$F$68,0) -> 0 | I26: =IF(I$4<=Assumptions!$F$69,Assumptions!$F$68,0) -> 0 | J26: =IF(J$4<=Assumptions!$F$69,Assumptions!$F$68,0) -> 0 | K26: =IF(K$4<=Assumptions!$F$69,Assumptions!$F$68,0) -> 0 | ... M26: =IF(M$4<=Assumptions!$F$69,Assumptions!$F$68,0) -> 0
A28: TOTAL REVENUE | B28: money | D28: =D8+D9+D10+D11+D12+D13+D14+D17+D18+D19+D20+D21+D24+D25+D26 -> 83188.8 | E28: =E8+E9+E10+E11+E12+E13+E14+E17+E18+E19+E20+E21+E24+E25+E26 -> 85684.464 | F28: =F8+F9+F10+F11+F12+F13+F14+F17+F18+F19+F20+F21+F24+F25+F26 -> 95271.791 | G28: =G8+G9+G10+G11+G12+G13+G14+G17+G18+G19+G20+G21+G24+G25+G26 -> 98129.944 | H28: =H8+H9+H10+H11+H12+H13+H14+H17+H18+H19+H20+H21+H24+H25+H26 -> 101073.84 | I28: =I8+I9+I10+I11+I12+I13+I14+I17+I18+I19+I20+I21+I24+I25+I26 -> 104106.06 | J28: =J8+J9+J10+J11+J12+J13+J14+J17+J18+J19+J20+J21+J24+J25+J26 -> 107229.24 | K28: =K8+K9+K10+K11+K12+K13+K14+K17+K18+K19+K20+K21+K24+K25+K26 -> 110446.12 | ... M28: =M8+M9+M10+M11+M12+M13+M14+M17+M18+M19+M20+M21+M24+M25+M26 -> 117172.29
A30: SUMMARY BY GROUP (chart data)
A31: Milk (raw + processed) | B31: money | D31: =D8+D9 -> 67320 | E31: =E8+E9 -> 69339.6 | F31: =F8+F9 -> 71419.788 | G31: =G8+G9 -> 73562.382 | H31: =H8+H9 -> 75769.253 | I31: =I8+I9 -> 78042.331 | J31: =J8+J9 -> 80383.601 | K31: =K8+K9 -> 82795.109 | ... M31: =M8+M9 -> 87837.331
A32: Calves (bull + cross-bred) | B32: money | D32: =D10+D11 -> 588.8 | E32: =E10+E11 -> 606.464 | F32: =F10+F11 -> 624.65792 | G32: =G10+G11 -> 643.39766 | H32: =H10+H11 -> 662.69959 | I32: =I10+I11 -> 682.58057 | J32: =J10+J11 -> 703.05799 | K32: =K10+K11 -> 724.14973 | ... M32: =M10+M11 -> 768.25045
A33: Surplus heifers (all) | B33: money | D33: =D12+D13+D19+D20 -> 0 | E33: =E12+E13+E19+E20 -> 0 | F33: =F12+F13+F19+F20 -> 7016.7926 | G33: =G12+G13+G19+G20 -> 7227.2964 | H33: =H12+H13+H19+H20 -> 7444.1153 | I33: =I12+I13+I19+I20 -> 7667.4387 | J33: =J12+J13+J19+J20 -> 7897.4619 | K33: =K12+K13+K19+K20 -> 8134.3857 | ... M33: =M12+M13+M19+M20 -> 8629.7698
A34: Cull cows (all) | B34: money | D34: =D14+D21 -> 8976 | E34: =E14+E21 -> 9245.28 | F34: =F14+F21 -> 9522.6384 | G34: =G14+G21 -> 9808.3176 | H34: =H14+H21 -> 10102.567 | I34: =I14+I21 -> 10405.644 | J34: =J14+J21 -> 10717.813 | K34: =K14+K21 -> 11039.348 | ... M34: =M14+M21 -> 11711.644
A35: Beef weaners & finished steers | B35: money | D35: =D17+D18 -> 4554 | E35: =E17+E18 -> 4690.62 | F35: =F17+F18 -> 4831.3386 | G35: =G17+G18 -> 4976.2788 | H35: =H17+H18 -> 5125.5671 | I35: =I17+I18 -> 5279.3341 | J35: =J17+J18 -> 5437.7142 | K35: =K17+K18 -> 5600.8456 | ... M35: =M17+M18 -> 5941.9371
A36: Manure, services, grants | B36: money | D36: =D24+D25+D26 -> 1750 | E36: =E24+E25+E26 -> 1802.5 | F36: =F24+F25+F26 -> 1856.575 | G36: =G24+G25+G26 -> 1912.2722 | H36: =H24+H25+H26 -> 1969.6404 | I36: =I24+I25+I26 -> 2028.7296 | J36: =J24+J25+J26 -> 2089.5915 | K36: =K24+K25+K26 -> 2152.2793 | ... M36: =M24+M25+M26 -> 2283.3531
A38: Dairy revenue (streams 1-6) | B38: money | D38: =D8+D9+D10+D11+D12+D13+D14 -> 73284.8 | E38: =E8+E9+E10+E11+E12+E13+E14 -> 75483.344 | F38: =F8+F9+F10+F11+F12+F13+F14 -> 81995.688 | G38: =G8+G9+G10+G11+G12+G13+G14 -> 84455.559 | H38: =H8+H9+H10+H11+H12+H13+H14 -> 86989.225 | I38: =I8+I9+I10+I11+I12+I13+I14 -> 89598.902 | J38: =J8+J9+J10+J11+J12+J13+J14 -> 92286.869 | K38: =K8+K9+K10+K11+K12+K13+K14 -> 95055.475 | ... M38: =M8+M9+M10+M11+M12+M13+M14 -> 100844.35
A39: Beef revenue (streams 7-10) | B39: money | D39: =D17+D18+D19+D20+D21 -> 8154 | E39: =E17+E18+E19+E20+E21 -> 8398.62 | F39: =F17+F18+F19+F20+F21 -> 11419.528 | G39: =G17+G18+G19+G20+G21 -> 11762.113 | H39: =H17+H18+H19+H20+H21 -> 12114.977 | I39: =I17+I18+I19+I20+I21 -> 12478.426 | J39: =J17+J18+J19+J20+J21 -> 12852.779 | K39: =K17+K18+K19+K20+K21 -> 13238.362 | ... M39: =M17+M18+M19+M20+M21 -> 14044.579
A40: Dairy share of revenue | B40: % | D40: =IF(D28=0,0,D38/D28) -> 0.88094551 | E40: =IF(E28=0,0,E38/E28) -> 0.88094551 | F40: =IF(F28=0,0,F38/F28) -> 0.86065022 | G40: =IF(G28=0,0,G38/G28) -> 0.86065022 | H40: =IF(H28=0,0,H38/H28) -> 0.86065022 | I40: =IF(I28=0,0,I38/I28) -> 0.86065022 | J40: =IF(J28=0,0,J38/J28) -> 0.86065022 | K40: =IF(K28=0,0,K38/K28) -> 0.86065022 | ... M40: =IF(M28=0,0,M38/M28) -> 0.86065022
A41: Animal sales (calves, heifers, culls, weaners) share of revenue | B41: % | D41: =IF(D28=0,0,(D32+D33+D34+D35)/D28) -> 0.16971996 | E41: =IF(E28=0,0,(E32+E33+E34+E35)/E28) -> 0.16971996 | F41: =IF(F28=0,0,(F32+F33+F34+F35)/F28) -> 0.23087031 | G41: =IF(G28=0,0,(G32+G33+G34+G35)/G28) -> 0.23087031 | H41: =IF(H28=0,0,(H32+H33+H34+H35)/H28) -> 0.23087031 | I41: =IF(I28=0,0,(I32+I33+I34+I35)/I28) -> 0.23087031 | J41: =IF(J28=0,0,(J32+J33+J34+J35)/J28) -> 0.23087031 | K41: =IF(K28=0,0,(K32+K33+K34+K35)/K28) -> 0.23087031 | ... M41: =IF(M28=0,0,(M32+M33+M34+M35)/M28) -> 0.23087031

Sheet Opex
A1: OPERATING COSTS - by year
A2: Year-1 unit costs x cost inflation. Feed lines also x scenario feed multiplier.
A3: Line item | B3: Unit | C3: Year 0 | D3: Year 1 | E3: Year 2 | F3: Year 3 | G3: Year 4 | H3: Year 5 | I3: Year 6 | J3: Year 7 | K3: Year 8 | L3: Year 9 | M3: Year 10
A4: Year index | C4: 0 | D4: 1 | E4: 2 | F4: 3 | G4: 4 | H4: 5 | I4: 6 | J4: 7 | K4: 8 | L4: 9 | M4: 10
A6: Cost inflation factor | B6: index | D6: =(1+Assumptions!$F$16)^(D$4-1) -> 1 | E6: =(1+Assumptions!$F$16)^(E$4-1) -> 1.04 | F6: =(1+Assumptions!$F$16)^(F$4-1) -> 1.0816 | G6: =(1+Assumptions!$F$16)^(G$4-1) -> 1.124864 | H6: =(1+Assumptions!$F$16)^(H$4-1) -> 1.1698586 | I6: =(1+Assumptions!$F$16)^(I$4-1) -> 1.2166529 | J6: =(1+Assumptions!$F$16)^(J$4-1) -> 1.265319 | K6: =(1+Assumptions!$F$16)^(K$4-1) -> 1.3159318 | ... M6: =(1+Assumptions!$F$16)^(M$4-1) -> 1.4233118
A7: FEED
A8: Dairy cow feed | B8: money | D8: =Herd!D15*Assumptions!$F$76*Assumptions!$F$24*D$6 -> 19200 | E8: =Herd!E15*Assumptions!$F$76*Assumptions!$F$24*E$6 -> 19968 | F8: =Herd!F15*Assumptions!$F$76*Assumptions!$F$24*F$6 -> 20766.72 | G8: =Herd!G15*Assumptions!$F$76*Assumptions!$F$24*G$6 -> 21597.389 | H8: =Herd!H15*Assumptions!$F$76*Assumptions!$F$24*H$6 -> 22461.284 | I8: =Herd!I15*Assumptions!$F$76*Assumptions!$F$24*I$6 -> 23359.736 | J8: =Herd!J15*Assumptions!$F$76*Assumptions!$F$24*J$6 -> 24294.125 | K8: =Herd!K15*Assumptions!$F$76*Assumptions!$F$24*K$6 -> 25265.89 | ... M8: =Herd!M15*Assumptions!$F$76*Assumptions!$F$24*M$6 -> 27327.587
A9: Dairy heifer & calf feed | B9: money | D9: =Herd!D26*Assumptions!$F$77*Assumptions!$F$24*D$6 -> 2208 | E9: =Herd!E26*Assumptions!$F$77*Assumptions!$F$24*E$6 -> 4592.64 | F9: =Herd!F26*Assumptions!$F$77*Assumptions!$F$24*F$6 -> 4776.3456 | G9: =Herd!G26*Assumptions!$F$77*Assumptions!$F$24*G$6 -> 4967.3994 | H9: =Herd!H26*Assumptions!$F$77*Assumptions!$F$24*H$6 -> 5166.0954 | I9: =Herd!I26*Assumptions!$F$77*Assumptions!$F$24*I$6 -> 5372.7392 | J9: =Herd!J26*Assumptions!$F$77*Assumptions!$F$24*J$6 -> 5587.6488 | K9: =Herd!K26*Assumptions!$F$77*Assumptions!$F$24*K$6 -> 5811.1547 | ... M9: =Herd!M26*Assumptions!$F$77*Assumptions!$F$24*M$6 -> 6285.345
A10: Beef cow feed | B10: money | D10: =Herd!D42*Assumptions!$F$78*Assumptions!$F$24*D$6 -> 3600 | E10: =Herd!E42*Assumptions!$F$78*Assumptions!$F$24*E$6 -> 3744 | F10: =Herd!F42*Assumptions!$F$78*Assumptions!$F$24*F$6 -> 3893.76 | G10: =Herd!G42*Assumptions!$F$78*Assumptions!$F$24*G$6 -> 4049.5104 | H10: =Herd!H42*Assumptions!$F$78*Assumptions!$F$24*H$6 -> 4211.4908 | I10: =Herd!I42*Assumptions!$F$78*Assumptions!$F$24*I$6 -> 4379.9504 | J10: =Herd!J42*Assumptions!$F$78*Assumptions!$F$24*J$6 -> 4555.1485 | K10: =Herd!K42*Assumptions!$F$78*Assumptions!$F$24*K$6 -> 4737.3544 | ... M10: =Herd!M42*Assumptions!$F$78*Assumptions!$F$24*M$6 -> 5123.9225
A11: Beef heifer & calf feed | B11: money | D11: =Herd!D53*Assumptions!$F$79*Assumptions!$F$24*D$6 -> 931.5 | E11: =Herd!E53*Assumptions!$F$79*Assumptions!$F$24*E$6 -> 1937.52 | F11: =Herd!F53*Assumptions!$F$79*Assumptions!$F$24*F$6 -> 2015.0208 | G11: =Herd!G53*Assumptions!$F$79*Assumptions!$F$24*G$6 -> 2095.6216 | H11: =Herd!H53*Assumptions!$F$79*Assumptions!$F$24*H$6 -> 2179.4465 | I11: =Herd!I53*Assumptions!$F$79*Assumptions!$F$24*I$6 -> 2266.6244 | J11: =Herd!J53*Assumptions!$F$79*Assumptions!$F$24*J$6 -> 2357.2893 | K11: =Herd!K53*Assumptions!$F$79*Assumptions!$F$24*K$6 -> 2451.5809 | ... M11: =Herd!M53*Assumptions!$F$79*Assumptions!$F$24*M$6 -> 2651.6299
A12: Finishing feed (steers) | B12: money | D12: =Herd!D50*Assumptions!$F$80*Assumptions!$F$24*D$6 -> 0 | E12: =Herd!E50*Assumptions!$F$80*Assumptions!$F$24*E$6 -> 0 | F12: =Herd!F50*Assumptions!$F$80*Assumptions!$F$24*F$6 -> 0 | G12: =Herd!G50*Assumptions!$F$80*Assumptions!$F$24*G$6 -> 0 | H12: =Herd!H50*Assumptions!$F$80*Assumptions!$F$24*H$6 -> 0 | I12: =Herd!I50*Assumptions!$F$80*Assumptions!$F$24*I$6 -> 0 | J12: =Herd!J50*Assumptions!$F$80*Assumptions!$F$24*J$6 -> 0 | K12: =Herd!K50*Assumptions!$F$80*Assumptions!$F$24*K$6 -> 0 | ... M12: =Herd!M50*Assumptions!$F$80*Assumptions!$F$24*M$6 -> 0
A13: Pasture upkeep | B13: money | D13: =Assumptions!$F$10*Assumptions!$F$81*D$6 -> 2250 | E13: =Assumptions!$F$10*Assumptions!$F$81*E$6 -> 2340 | F13: =Assumptions!$F$10*Assumptions!$F$81*F$6 -> 2433.6 | G13: =Assumptions!$F$10*Assumptions!$F$81*G$6 -> 2530.944 | H13: =Assumptions!$F$10*Assumptions!$F$81*H$6 -> 2632.1818 | I13: =Assumptions!$F$10*Assumptions!$F$81*I$6 -> 2737.469 | J13: =Assumptions!$F$10*Assumptions!$F$81*J$6 -> 2846.9678 | K13: =Assumptions!$F$10*Assumptions!$F$81*K$6 -> 2960.8465 | ... M13: =Assumptions!$F$10*Assumptions!$F$81*M$6 -> 3202.4516
A14: Total feed | B14: money | D14: =SUM(D8:D13) -> 28189.5 | E14: =SUM(E8:E13) -> 32582.16 | F14: =SUM(F8:F13) -> 33885.446 | G14: =SUM(G8:G13) -> 35240.864 | H14: =SUM(H8:H13) -> 36650.499 | I14: =SUM(I8:I13) -> 38116.519 | J14: =SUM(J8:J13) -> 39641.18 | K14: =SUM(K8:K13) -> 41226.827 | ... M14: =SUM(M8:M13) -> 44590.936
A16: HEALTH, BREEDING & REPLACEMENT STOCK
A17: Veterinary & medicines | B17: money | D17: =(Herd!D15+Herd!D42+Herd!D26+Herd!D53)*Assumptions!$F$82*D$6 -> 2091.54 | E17: =(Herd!E15+Herd!E42+Herd!E26+Herd!E53)*Assumptions!$F$82*E$6 -> 2748.8032 | F17: =(Herd!F15+Herd!F42+Herd!F26+Herd!F53)*Assumptions!$F$82*F$6 -> 2858.7553 | G17: =(Herd!G15+Herd!G42+Herd!G26+Herd!G53)*Assumptions!$F$82*G$6 -> 2973.1055 | H17: =(Herd!H15+Herd!H42+Herd!H26+Herd!H53)*Assumptions!$F$82*H$6 -> 3092.0298 | I17: =(Herd!I15+Herd!I42+Herd!I26+Herd!I53)*Assumptions!$F$82*I$6 -> 3215.711 | J17: =(Herd!J15+Herd!J42+Herd!J26+Herd!J53)*Assumptions!$F$82*J$6 -> 3344.3394 | K17: =(Herd!K15+Herd!K42+Herd!K26+Herd!K53)*Assumptions!$F$82*K$6 -> 3478.113 | ... M17: =(Herd!M15+Herd!M42+Herd!M26+Herd!M53)*Assumptions!$F$82*M$6 -> 3761.927
A18: AI / semen (incl. sexed premium) | B18: money | D18: =Herd!D15*(Assumptions!$F$83+Assumptions!$F$38*Assumptions!$F$84)*D$6 -> 720 | E18: =Herd!E15*(Assumptions!$F$83+Assumptions!$F$38*Assumptions!$F$84)*E$6 -> 748.8 | F18: =Herd!F15*(Assumptions!$F$83+Assumptions!$F$38*Assumptions!$F$84)*F$6 -> 778.752 | G18: =Herd!G15*(Assumptions!$F$83+Assumptions!$F$38*Assumptions!$F$84)*G$6 -> 809.90208 | H18: =Herd!H15*(Assumptions!$F$83+Assumptions!$F$38*Assumptions!$F$84)*H$6 -> 842.29816 | I18: =Herd!I15*(Assumptions!$F$83+Assumptions!$F$38*Assumptions!$F$84)*I$6 -> 875.99009 | J18: =Herd!J15*(Assumptions!$F$83+Assumptions!$F$38*Assumptions!$F$84)*J$6 -> 911.02969 | K18: =Herd!K15*(Assumptions!$F$83+Assumptions!$F$38*Assumptions!$F$84)*K$6 -> 947.47088 | ... M18: =Herd!M15*(Assumptions!$F$83+Assumptions!$F$38*Assumptions!$F$84)*M$6 -> 1024.7845
A19: Bull replacement (annualised) | B19: money | D19: =Herd!D54*Assumptions!$F$73/Assumptions!$F$74*D$6 -> 480 | E19: =Herd!E54*Assumptions!$F$73/Assumptions!$F$74*E$6 -> 499.2 | F19: =Herd!F54*Assumptions!$F$73/Assumptions!$F$74*F$6 -> 519.168 | G19: =Herd!G54*Assumptions!$F$73/Assumptions!$F$74*G$6 -> 539.93472 | H19: =Herd!H54*Assumptions!$F$73/Assumptions!$F$74*H$6 -> 561.53211 | I19: =Herd!I54*Assumptions!$F$73/Assumptions!$F$74*I$6 -> 583.99339 | J19: =Herd!J54*Assumptions!$F$73/Assumptions!$F$74*J$6 -> 607.35313 | K19: =Herd!K54*Assumptions!$F$73/Assumptions!$F$74*K$6 -> 631.64725 | ... M19: =Herd!M54*Assumptions!$F$73/Assumptions!$F$74*M$6 -> 683.18967
A20: Replacement dairy heifers bought | B20: money | D20: =Herd!D13*Assumptions!$F$70*Assumptions!$F$25*Revenue!D6 -> 9900 | E20: =Herd!E13*Assumptions!$F$70*Assumptions!$F$25*Revenue!E6 -> 10197 | F20: =Herd!F13*Assumptions!$F$70*Assumptions!$F$25*Revenue!F6 -> 0 | G20: =Herd!G13*Assumptions!$F$70*Assumptions!$F$25*Revenue!G6 -> 0 | H20: =Herd!H13*Assumptions!$F$70*Assumptions!$F$25*Revenue!H6 -> 0 | I20: =Herd!I13*Assumptions!$F$70*Assumptions!$F$25*Revenue!I6 -> 0 | J20: =Herd!J13*Assumptions!$F$70*Assumptions!$F$25*Revenue!J6 -> 0 | K20: =Herd!K13*Assumptions!$F$70*Assumptions!$F$25*Revenue!K6 -> 0 | ... M20: =Herd!M13*Assumptions!$F$70*Assumptions!$F$25*Revenue!M6 -> 0
A21: Replacement beef heifers bought | B21: money | D21: =Herd!D40*Assumptions!$F$71*Assumptions!$F$25*Revenue!D6 -> 4800 | E21: =Herd!E40*Assumptions!$F$71*Assumptions!$F$25*Revenue!E6 -> 4944 | F21: =Herd!F40*Assumptions!$F$71*Assumptions!$F$25*Revenue!F6 -> 0 | G21: =Herd!G40*Assumptions!$F$71*Assumptions!$F$25*Revenue!G6 -> 0 | H21: =Herd!H40*Assumptions!$F$71*Assumptions!$F$25*Revenue!H6 -> 0 | I21: =Herd!I40*Assumptions!$F$71*Assumptions!$F$25*Revenue!I6 -> 0 | J21: =Herd!J40*Assumptions!$F$71*Assumptions!$F$25*Revenue!J6 -> 0 | K21: =Herd!K40*Assumptions!$F$71*Assumptions!$F$25*Revenue!K6 -> 0 | ... M21: =Herd!M40*Assumptions!$F$71*Assumptions!$F$25*Revenue!M6 -> 0
A22: Total health, breeding & replacements | B22: money | D22: =SUM(D17:D21) -> 17991.54 | E22: =SUM(E17:E21) -> 19137.803 | F22: =SUM(F17:F21) -> 4156.6753 | G22: =SUM(G17:G21) -> 4322.9423 | H22: =SUM(H17:H21) -> 4495.86 | I22: =SUM(I17:I21) -> 4675.6944 | J22: =SUM(J17:J21) -> 4862.7222 | K22: =SUM(K17:K21) -> 5057.2311 | ... M22: =SUM(M17:M21) -> 5469.9012
A24: LABOUR
A25: Farm manager | B25: money | D25: =Assumptions!$F$85*D$6 -> 7000 | E25: =Assumptions!$F$85*E$6 -> 7280 | F25: =Assumptions!$F$85*F$6 -> 7571.2 | G25: =Assumptions!$F$85*G$6 -> 7874.048 | H25: =Assumptions!$F$85*H$6 -> 8189.0099 | I25: =Assumptions!$F$85*I$6 -> 8516.5703 | J25: =Assumptions!$F$85*J$6 -> 8857.2331 | K25: =Assumptions!$F$85*K$6 -> 9211.5225 | ... M25: =Assumptions!$F$85*M$6 -> 9963.1827
A26: Farm workers (milkers, herders) | B26: money | D26: =(Herd!D15/Assumptions!$F$87+Herd!D42/Assumptions!$F$88)*Assumptions!$F$86*D$6 -> 4740 | E26: =(Herd!E15/Assumptions!$F$87+Herd!E42/Assumptions!$F$88)*Assumptions!$F$86*E$6 -> 4929.6 | F26: =(Herd!F15/Assumptions!$F$87+Herd!F42/Assumptions!$F$88)*Assumptions!$F$86*F$6 -> 5126.784 | G26: =(Herd!G15/Assumptions!$F$87+Herd!G42/Assumptions!$F$88)*Assumptions!$F$86*G$6 -> 5331.8554 | H26: =(Herd!H15/Assumptions!$F$87+Herd!H42/Assumptions!$F$88)*Assumptions!$F$86*H$6 -> 5545.1296 | I26: =(Herd!I15/Assumptions!$F$87+Herd!I42/Assumptions!$F$88)*Assumptions!$F$86*I$6 -> 5766.9348 | J26: =(Herd!J15/Assumptions!$F$87+Herd!J42/Assumptions!$F$88)*Assumptions!$F$86*J$6 -> 5997.6121 | K26: =(Herd!K15/Assumptions!$F$87+Herd!K42/Assumptions!$F$88)*Assumptions!$F$86*K$6 -> 6237.5166 | ... M26: =(Herd!M15/Assumptions!$F$87+Herd!M42/Assumptions!$F$88)*Assumptions!$F$86*M$6 -> 6746.498
A27: Total labour | B27: money | D27: =D25+D26 -> 11740 | E27: =E25+E26 -> 12209.6 | F27: =F25+F26 -> 12697.984 | G27: =G25+G26 -> 13205.903 | H27: =H25+H26 -> 13734.139 | I27: =I25+I26 -> 14283.505 | J27: =J25+J26 -> 14854.845 | K27: =K25+K26 -> 15449.039 | ... M27: =M25+M26 -> 16709.681
A29: PROCESSING, UTILITIES & OVERHEADS
A30: Milk processing & packaging | B30: money | D30: =Herd!D30*Assumptions!$F$53*D$6 -> 2040 | E30: =Herd!E30*Assumptions!$F$53*E$6 -> 2121.6 | F30: =Herd!F30*Assumptions!$F$53*F$6 -> 2206.464 | G30: =Herd!G30*Assumptions!$F$53*G$6 -> 2294.7226 | H30: =Herd!H30*Assumptions!$F$53*H$6 -> 2386.5115 | I30: =Herd!I30*Assumptions!$F$53*I$6 -> 2481.9719 | J30: =Herd!J30*Assumptions!$F$53*J$6 -> 2581.2508 | K30: =Herd!K30*Assumptions!$F$53*K$6 -> 2684.5008 | ... M30: =Herd!M30*Assumptions!$F$53*M$6 -> 2903.5561
A31: Electricity, water & cleaning (per cow) | B31: money | D31: =Herd!D15*Assumptions!$F$89*D$6 -> 1400 | E31: =Herd!E15*Assumptions!$F$89*E$6 -> 1456 | F31: =Herd!F15*Assumptions!$F$89*F$6 -> 1514.24 | G31: =Herd!G15*Assumptions!$F$89*G$6 -> 1574.8096 | H31: =Herd!H15*Assumptions!$F$89*H$6 -> 1637.802 | I31: =Herd!I15*Assumptions!$F$89*I$6 -> 1703.3141 | J31: =Herd!J15*Assumptions!$F$89*J$6 -> 1771.4466 | K31: =Herd!K15*Assumptions!$F$89*K$6 -> 1842.3045 | ... M31: =Herd!M15*Assumptions!$F$89*M$6 -> 1992.6365
A32: Vehicle fuel & running costs | B32: money | D32: =Assumptions!$F$90*D$6 -> 1800 | E32: =Assumptions!$F$90*E$6 -> 1872 | F32: =Assumptions!$F$90*F$6 -> 1946.88 | G32: =Assumptions!$F$90*G$6 -> 2024.7552 | H32: =Assumptions!$F$90*H$6 -> 2105.7454 | I32: =Assumptions!$F$90*I$6 -> 2189.9752 | J32: =Assumptions!$F$90*J$6 -> 2277.5742 | K32: =Assumptions!$F$90*K$6 -> 2368.6772 | ... M32: =Assumptions!$F$90*M$6 -> 2561.9613
A33: Insurance | B33: money | D33: =Assumptions!$F$92*Capex!$H$47 -> 2402.84 | E33: =Assumptions!$F$92*Capex!$H$47 -> 2402.84 | F33: =Assumptions!$F$92*Capex!$H$47 -> 2402.84 | G33: =Assumptions!$F$92*Capex!$H$47 -> 2402.84 | H33: =Assumptions!$F$92*Capex!$H$47 -> 2402.84 | I33: =Assumptions!$F$92*Capex!$H$47 -> 2402.84 | J33: =Assumptions!$F$92*Capex!$H$47 -> 2402.84 | K33: =Assumptions!$F$92*Capex!$H$47 -> 2402.84 | ... M33: =Assumptions!$F$92*Capex!$H$47 -> 2402.84
A34: Repairs & maintenance | B34: money | D34: =Assumptions!$F$93*Capex!$H$44*D$6 -> 4719 | E34: =Assumptions!$F$93*Capex!$H$44*E$6 -> 4907.76 | F34: =Assumptions!$F$93*Capex!$H$44*F$6 -> 5104.0704 | G34: =Assumptions!$F$93*Capex!$H$44*G$6 -> 5308.2332 | H34: =Assumptions!$F$93*Capex!$H$44*H$6 -> 5520.5625 | I34: =Assumptions!$F$93*Capex!$H$44*I$6 -> 5741.385 | J34: =Assumptions!$F$93*Capex!$H$44*J$6 -> 5971.0404 | K34: =Assumptions!$F$93*Capex!$H$44*K$6 -> 6209.8821 | ... M34: =Assumptions!$F$93*Capex!$H$44*M$6 -> 6716.6084
A35: Transport & marketing | B35: money | D35: =Assumptions!$F$94*Revenue!D28 -> 1663.776 | E35: =Assumptions!$F$94*Revenue!E28 -> 1713.6893 | F35: =Assumptions!$F$94*Revenue!F28 -> 1905.4358 | G35: =Assumptions!$F$94*Revenue!G28 -> 1962.5989 | H35: =Assumptions!$F$94*Revenue!H28 -> 2021.4769 | I35: =Assumptions!$F$94*Revenue!I28 -> 2082.1212 | J35: =Assumptions!$F$94*Revenue!J28 -> 2144.5848 | K35: =Assumptions!$F$94*Revenue!K28 -> 2208.9223 | ... M35: =Assumptions!$F$94*Revenue!M28 -> 2343.4457
A36: Admin, accounting, licences | B36: money | D36: =Assumptions!$F$95*D$6 -> 2500 | E36: =Assumptions!$F$95*E$6 -> 2600 | F36: =Assumptions!$F$95*F$6 -> 2704 | G36: =Assumptions!$F$95*G$6 -> 2812.16 | H36: =Assumptions!$F$95*H$6 -> 2924.6464 | I36: =Assumptions!$F$95*I$6 -> 3041.6323 | J36: =Assumptions!$F$95*J$6 -> 3163.2975 | K36: =Assumptions!$F$95*K$6 -> 3289.8294 | ... M36: =Assumptions!$F$95*M$6 -> 3558.2795
A37: Total processing & overheads | B37: money | D37: =SUM(D30:D36) -> 16525.616 | E37: =SUM(E30:E36) -> 17073.889 | F37: =SUM(F30:F36) -> 17783.93 | G37: =SUM(G30:G36) -> 18380.119 | H37: =SUM(H30:H36) -> 18999.585 | I37: =SUM(I30:I36) -> 19643.24 | J37: =SUM(J30:J36) -> 20312.034 | K37: =SUM(K30:K36) -> 21006.956 | ... M37: =SUM(M30:M36) -> 22479.328
A39: LAND
A40: Land lease | B40: money | D40: =Assumptions!$F$10*Assumptions!$F$14*(1-Assumptions!$F$12)*D$6 -> 6000 | E40: =Assumptions!$F$10*Assumptions!$F$14*(1-Assumptions!$F$12)*E$6 -> 6240 | F40: =Assumptions!$F$10*Assumptions!$F$14*(1-Assumptions!$F$12)*F$6 -> 6489.6 | G40: =Assumptions!$F$10*Assumptions!$F$14*(1-Assumptions!$F$12)*G$6 -> 6749.184 | H40: =Assumptions!$F$10*Assumptions!$F$14*(1-Assumptions!$F$12)*H$6 -> 7019.1514 | I40: =Assumptions!$F$10*Assumptions!$F$14*(1-Assumptions!$F$12)*I$6 -> 7299.9174 | J40: =Assumptions!$F$10*Assumptions!$F$14*(1-Assumptions!$F$12)*J$6 -> 7591.9141 | K40: =Assumptions!$F$10*Assumptions!$F$14*(1-Assumptions!$F$12)*K$6 -> 7895.5907 | ... M40: =Assumptions!$F$10*Assumptions!$F$14*(1-Assumptions!$F$12)*M$6 -> 8539.8709
A41: Land rates / property tax | B41: money | D41: =Assumptions!$F$10*Assumptions!$F$91*D$6 -> 225 | E41: =Assumptions!$F$10*Assumptions!$F$91*E$6 -> 234 | F41: =Assumptions!$F$10*Assumptions!$F$91*F$6 -> 243.36 | G41: =Assumptions!$F$10*Assumptions!$F$91*G$6 -> 253.0944 | H41: =Assumptions!$F$10*Assumptions!$F$91*H$6 -> 263.21818 | I41: =Assumptions!$F$10*Assumptions!$F$91*I$6 -> 273.7469 | J41: =Assumptions!$F$10*Assumptions!$F$91*J$6 -> 284.69678 | K41: =Assumptions!$F$10*Assumptions!$F$91*K$6 -> 296.08465 | ... M41: =Assumptions!$F$10*Assumptions!$F$91*M$6 -> 320.24516
