Workbook

Sheet 📊 Executive Summary
B2: GHANA CHAMBER OF MINES MEMBER MANAGEMENT & REPORT AGGREGATION SYSTEM SOFTWARE DEVELOPMENT BUDGET
B3: Fiscal Year 2025 – 2027 | Prepared by: IT & Strategy Division | Date: May 2025
B13: Total 3-Year Investment (GHS) | E13: Year 1 (Discovery & Build) | H13: Year 2 (Deploy & Optimize) | K13: Year 3 (Scale & Sustain)
B14: ='💰 Budget Breakdown'!O47 -> 1991150 | E14: ='💰 Budget Breakdown'!C47 -> 706000 | H14: ='💰 Budget Breakdown'!F47 -> 356000 | K14: ='💰 Budget Breakdown'!I47 -> 175000
B17: BUDGET BY PHASE | I17: BUDGET BY COST CATEGORY
B18: Phase | E18: Yr 1 (GHS) | F18: Yr 2 (GHS) | G18: Yr 3 (GHS) | H18: Total (GHS) | I18: Category | L18: Yr 1 | M18: Yr 2 | N18: Yr 3
B19: Phase 1: Discovery & Planning | E19: ='💰 Budget Breakdown'!C10 -> 63000 | F19: ='💰 Budget Breakdown'!F10 -> 0 | G19: ='💰 Budget Breakdown'!I10 -> 0 | H19: =E19+F19+G19 -> 63000 | I19: Personnel & Labour | L19: ='💰 Budget Breakdown'!C48 -> 706000 | M19: ='💰 Budget Breakdown'!F48 -> 356000 | N19: ='💰 Budget Breakdown'!I48 -> 175000
B20: Phase 2: System Architecture & Design | E20: ='💰 Budget Breakdown'!C17 -> 107000 | F20: ='💰 Budget Breakdown'!F17 -> 0 | G20: ='💰 Budget Breakdown'!I17 -> 0 | H20: =E20+F20+G20 -> 107000 | I20: Software & Licences | L20: ='💰 Budget Breakdown'!C49 -> 27000 | M20: ='💰 Budget Breakdown'!F49 -> 0 | N20: ='💰 Budget Breakdown'!I49 -> 0
B21: Phase 3: Core Development | E21: ='💰 Budget Breakdown'!C25 -> 375000 | F21: ='💰 Budget Breakdown'!F25 -> 135000 | G21: ='💰 Budget Breakdown'!I25 -> 0 | H21: =E21+F21+G21 -> 510000 | I21: Infrastructure & Cloud | L21: ='💰 Budget Breakdown'!C50 -> 78000 | M21: ='💰 Budget Breakdown'!F50 -> 152000 | N21: ='💰 Budget Breakdown'!I50 -> 167000
B22: Phase 4: Integration & Testing | E22: ='💰 Budget Breakdown'!C30 -> 63000 | F22: ='💰 Budget Breakdown'!F30 -> 28000 | G22: ='💰 Budget Breakdown'!I30 -> 0 | H22: =E22+F22+G22 -> 91000 | I22: Training & Change Mgmt | L22: ='💰 Budget Breakdown'!C51 -> 176000 | M22: ='💰 Budget Breakdown'!F51 -> 65000 | N22: ='💰 Budget Breakdown'!I51 -> 0
B23: Phase 5: Deployment & Training | E23: ='💰 Budget Breakdown'!C36 -> 98000 | F23: ='💰 Budget Breakdown'!F36 -> 33000 | G23: ='💰 Budget Breakdown'!I36 -> 0 | H23: =E23+F23+G23 -> 131000 | I23: Contingency (15%) | L23: ='💰 Budget Breakdown'!C52 -> 139650 | M23: ='💰 Budget Breakdown'!F52 -> 0 | N23: ='💰 Budget Breakdown'!I52 -> 0
B24: Phase 6: Support & Maintenance | E24: ='💰 Budget Breakdown'!C43 -> 0 | F24: ='💰 Budget Breakdown'!F43 -> 160000 | G24: ='💰 Budget Breakdown'!I43 -> 175000 | H24: =E24+F24+G24 -> 335000 | I24: Other / Miscellaneous | L24: ='💰 Budget Breakdown'!C53 -> 120000 | M24: ='💰 Budget Breakdown'!F53 -> 38500 | N24: ='💰 Budget Breakdown'!I53 -> 0
B25: GRAND TOTAL | E25: =SUM(E19:E24) -> 706000 | F25: =SUM(F19:F24) -> 356000 | G25: =SUM(G19:G24) -> 175000 | H25: =SUM(H19:H24) -> 1237000 | I25: TOTAL | L25: =SUM(L19:L24) -> 1246650 | M25: =SUM(M19:M24) -> 611500 | N25: =SUM(N19:N24) -> 342000
B27: KEY ASSUMPTIONS & NOTES
B28: 1. All figures are in Ghana Cedis (GHS). USD equivalents available on the FX Assumptions tab.
B29: 2. Blue text = user-editable inputs; Black text = calculated values; Green text = cross-sheet links.
B30: 3. Personnel costs assume mixed team (2 senior devs, 3 mid devs, 1 BA, 1 PM, 1 QA, 1 DevOps) for Year 1.
B31: 4. A 15% contingency buffer is included in all years to absorb scope changes and risk events.
B32: 5. Cloud/infrastructure costs are based on AWS GovCloud equivalent pricing, scaled annually.
B33: 6. Training covers GCoM staff (est. 45 users) + member company super-users (est. 120 users).

Sheet 💰 Budget Breakdown
A1: GHANA CHAMBER OF MINES — MEMBER MANAGEMENT SYSTEM | DETAILED BUDGET BREAKDOWN (GHS)
A2: Blue = Input | Black = Formula | Green = Cross-sheet link | Source: GCoM IT Strategy Plan 2025
A3: LINE ITEM / DELIVERABLE | C3: YEAR 1 — FY2025 | F3: YEAR 2 — FY2026 | I3: YEAR 3 — FY2027 | L3: CONTINGENCY (15%) | O3: 3-YEAR TOTAL (GHS)
C4: Labour (GHS) | D4: Non-Labour (GHS) | F4: Labour (GHS) | G4: Non-Labour (GHS) | I4: Labour (GHS) | J4: Non-Labour (GHS) | L4: Labour (GHS) | M4: Non-Labour (GHS)
A5: PHASE 1 — DISCOVERY & PLANNING (Months 1–3)
A6: Requirements gathering & stakeholder workshops | C6: 25000 | D6: 5000 | F6: 0 | G6: 0 | I6: 0 | J6: 0 | L6: =C6*0.15 -> 3750 | M6: =D6*0.15 -> 750 | O6: =C6+D6+F6+G6+I6+J6+L6+M6 -> 34500
A7: Current system audit & gap analysis | C7: 18000 | D7: 3000 | F7: 0 | G7: 0 | I7: 0 | J7: 0 | L7: =C7*0.15 -> 2700 | M7: =D7*0.15 -> 450 | O7: =C7+D7+F7+G7+I7+J7+L7+M7 -> 24150
A8: Feasibility study & vendor evaluation | C8: 12000 | D8: 8000 | F8: 0 | G8: 0 | I8: 0 | J8: 0 | L8: =C8*0.15 -> 1800 | M8: =D8*0.15 -> 1200 | O8: =C8+D8+F8+G8+I8+J8+L8+M8 -> 23000
A9: Project charter & governance setup | C9: 8000 | D9: 2000 | F9: 0 | G9: 0 | I9: 0 | J9: 0 | L9: =C9*0.15 -> 1200 | M9: =D9*0.15 -> 300 | O9: =C9+D9+F9+G9+I9+J9+L9+M9 -> 11500
A10: PHASE 1 SUBTOTAL | C10: =SUM(C6:C9) -> 63000 | D10: =SUM(D6:D9) -> 18000 | F10: =SUM(F6:F9) -> 0 | G10: =SUM(G6:G9) -> 0 | I10: =SUM(I6:I9) -> 0 | J10: =SUM(J6:J9) -> 0 | L10: =SUM(L6:L9) -> 9450 | M10: =SUM(M6:M9) -> 2700 | O10: =SUM(O6:O9) -> 93150
A11: PHASE 2 — SYSTEM ARCHITECTURE & DESIGN (Months 2–5)
A12: System architecture design (cloud-native) | C12: 32000 | D12: 5000 | F12: 0 | G12: 0 | I12: 0 | J12: 0 | L12: =C12*0.15 -> 4800 | M12: =D12*0.15 -> 750 | O12: =C12+D12+F12+G12+I12+J12+L12+M12 -> 42550
A13: Database schema design (member registry + reports) | C13: 22000 | D13: 2000 | F13: 0 | G13: 0 | I13: 0 | J13: 0 | L13: =C13*0.15 -> 3300 | M13: =D13*0.15 -> 300 | O13: =C13+D13+F13+G13+I13+J13+L13+M13 -> 27600
A14: UI/UX wireframes & prototype | C14: 18000 | D14: 12000 | F14: 0 | G14: 0 | I14: 0 | J14: 0 | L14: =C14*0.15 -> 2700 | M14: =D14*0.15 -> 1800 | O14: =C14+D14+F14+G14+I14+J14+L14+M14 -> 34500
A15: API & integration design | C15: 20000 | D15: 3000 | F15: 0 | G15: 0 | I15: 0 | J15: 0 | L15: =C15*0.15 -> 3000 | M15: =D15*0.15 -> 450 | O15: =C15+D15+F15+G15+I15+J15+L15+M15 -> 26450
A16: Security architecture & data governance plan | C16: 15000 | D16: 5000 | F16: 0 | G16: 0 | I16: 0 | J16: 0 | L16: =C16*0.15 -> 2250 | M16: =D16*0.15 -> 750 | O16: =C16+D16+F16+G16+I16+J16+L16+M16 -> 23000
A17: PHASE 2 SUBTOTAL | C17: =SUM(C12:C16) -> 107000 | D17: =SUM(D12:D16) -> 27000 | F17: =SUM(F12:F16) -> 0 | G17: =SUM(G12:G16) -> 0 | I17: =SUM(I12:I16) -> 0 | J17: =SUM(J12:J16) -> 0 | L17: =SUM(L12:L16) -> 16050 | M17: =SUM(M12:M16) -> 4050 | O17: =SUM(O12:O16) -> 154100
A18: PHASE 3 — CORE DEVELOPMENT (Months 4–14)
A19: Member registry & profile management module | C19: 85000 | D19: 15000 | F19: 30000 | G19: 5000 | I19: 0 | J19: 0 | L19: =C19*0.15 -> 12750 | M19: =D19*0.15 -> 2250 | O19: =C19+D19+F19+G19+I19+J19+L19+M19 -> 150000
A20: Member onboarding portal & self-service | C20: 60000 | D20: 10000 | F20: 20000 | G20: 3000 | I20: 0 | J20: 0 | L20: =C20*0.15 -> 9000 | M20: =D20*0.15 -> 1500 | O20: =C20+D20+F20+G20+I20+J20+L20+M20 -> 103500
A21: Subscription & dues management module | C21: 45000 | D21: 8000 | F21: 15000 | G21: 2000 | I21: 0 | J21: 0 | L21: =C21*0.15 -> 6750 | M21: =D21*0.15 -> 1200 | O21: =C21+D21+F21+G21+I21+J21+L21+M21 -> 77950
A22: Report submission & aggregation engine | C22: 90000 | D22: 20000 | F22: 35000 | G22: 8000 | I22: 0 | J22: 0 | L22: =C22*0.15 -> 13500 | M22: =D22*0.15 -> 3000 | O22: =C22+D22+F22+G22+I22+J22+L22+M22 -> 169500
A23: Dashboard & analytics module (BI layer) | C23: 55000 | D23: 25000 | F23: 20000 | G23: 10000 | I23: 0 | J23: 0 | L23: =C23*0.15 -> 8250 | M23: =D23*0.15 -> 3750 | O23: =C23+D23+F23+G23+I23+J23+L23+M23 -> 122000
A24: Document management & compliance tracker | C24: 40000 | D24: 8000 | F24: 15000 | G24: 3000 | I24: 0 | J24: 0 | L24: =C24*0.15 -> 6000 | M24: =D24*0.15 -> 1200 | O24: =C24+D24+F24+G24+I24+J24+L24+M24 -> 73200
A25: PHASE 3 SUBTOTAL | C25: =SUM(C19:C24) -> 375000 | D25: =SUM(D19:D24) -> 86000 | F25: =SUM(F19:F24) -> 135000 | G25: =SUM(G19:G24) -> 31000 | I25: =SUM(I19:I24) -> 0 | J25: =SUM(J19:J24) -> 0 | L25: =SUM(L19:L24) -> 56250 | M25: =SUM(M19:M24) -> 12900 | O25: =SUM(O19:O24) -> 696150
A26: PHASE 4 — INTEGRATION & TESTING (Months 12–16)
A27: System integration testing (SIT) | C27: 28000 | D27: 5000 | F27: 12000 | G27: 2000 | I27: 0 | J27: 0 | L27: =C27*0.15 -> 4200 | M27: =D27*0.15 -> 750 | O27: =C27+D27+F27+G27+I27+J27+L27+M27 -> 51950
A28: User acceptance testing (UAT) with GCoM staff | C28: 20000 | D28: 3000 | F28: 8000 | G28: 1500 | I28: 0 | J28: 0 | L28: =C28*0.15 -> 3000 | M28: =D28*0.15 -> 450 | O28: =C28+D28+F28+G28+I28+J28+L28+M28 -> 35950
A29: Performance & load testing | C29: 15000 | D29: 8000 | F29: 8000 | G29: 4000 | I29: 0 | J29: 0 | L29: =C29*0.15 -> 2250 | M29: =D29*0.15 -> 1200 | O29: =C29+D29+F29+G29+I29+J29+L29+M29 -> 38450
A30: PHASE 4 SUBTOTAL | C30: =SUM(C27:C29) -> 63000 | D30: =SUM(D27:D29) -> 16000 | F30: =SUM(F27:F29) -> 28000 | G30: =SUM(G27:G29) -> 7500 | I30: =SUM(I27:I29) -> 0 | J30: =SUM(J27:J29) -> 0 | L30: =SUM(L27:L29) -> 9450 | M30: =SUM(M27:M29) -> 2400 | O30: =SUM(O27:O29) -> 126350
A31: PHASE 5 — DEPLOYMENT & TRAINING (Months 16–20)
A32: Cloud infrastructure setup & go-live | C32: 20000 | D32: 45000 | F32: 5000 | G32: 15000 | I32: 0 | J32: 0 | L32: =C32*0.15 -> 3000 | M32: =D32*0.15 -> 6750 | O32: =C32+D32+F32+G32+I32+J32+L32+M32 -> 94750
A33: Data migration from legacy systems | C33: 35000 | D33: 10000 | F33: 10000 | G33: 5000 | I33: 0 | J33: 0 | L33: =C33*0.15 -> 5250 | M33: =D33*0.15 -> 1500 | O33: =C33+D33+F33+G33+I33+J33+L33+M33 -> 66750
A34: End-user training — GCoM staff (45 users) | C34: 18000 | D34: 8000 | F34: 8000 | G34: 4000 | I34: 0 | J34: 0 | L34: =C34*0.15 -> 2700 | M34: =D34*0.15 -> 1200 | O34: =C34+D34+F34+G34+I34+J34+L34+M34 -> 41900
A35: Member company super-user training (120 users) | C35: 25000 | D35: 15000 | F35: 10000 | G35: 8000 | I35: 0 | J35: 0 | L35: =C35*0.15 -> 3750 | M35: =D35*0.15 -> 2250 | O35: =C35+D35+F35+G35+I35+J35+L35+M35 -> 64000
A36: PHASE 5 SUBTOTAL | C36: =SUM(C32:C35) -> 98000 | D36: =SUM(D32:D35) -> 78000 | F36: =SUM(F32:F35) -> 33000 | G36: =SUM(G32:G35) -> 32000 | I36: =SUM(I32:I35) -> 0 | J36: =SUM(J32:J35) -> 0 | L36: =SUM(L32:L35) -> 14700 | M36: =SUM(M32:M35) -> 11700 | O36: =SUM(O32:O35) -> 267400
A37: PHASE 6 — ONGOING SUPPORT & MAINTENANCE (Year 2–3, recurring)
A38: Application support & helpdesk | C38: 0 | D38: 0 | F38: 60000 | G38: 12000 | I38: 65000 | J38: 12000 | L38: =C38*0.15 -> 0 | M38: =D38*0.15 -> 0 | O38: =C38+D38+F38+G38+I38+J38+L38+M38 -> 149000
A39: Annual software licence renewals | C39: 0 | D39: 0 | F39: 5000 | G39: 35000 | I39: 5000 | J39: 40000 | L39: =C39*0.15 -> 0 | M39: =D39*0.15 -> 0 | O39: =C39+D39+F39+G39+I39+J39+L39+M39 -> 85000
A40: Cloud hosting & infrastructure (annual) | C40: 0 | D40: 0 | F40: 5000 | G40: 80000 | I40: 5000 | J40: 90000 | L40: =C40*0.15 -> 0 | M40: =D40*0.15 -> 0 | O40: =C40+D40+F40+G40+I40+J40+L40+M40 -> 180000
...

Sheet 👥 Staffing Plan
A1: GHANA CHAMBER OF MINES — SOFTWARE PROJECT STAFFING PLAN & RATE CARD (GHS)
A3: Role | B3: Engagement Type | C3: Monthly Rate (GHS) | D3: Yr1 Months | E3: Yr1 Cost (GHS) | F3: Yr2 Months | G3: Yr2 Cost (GHS) | H3: Yr3 Months | I3: Yr3 Cost (GHS) | J3: Count | K3: FTE Equiv. | L3: Notes
A4: Project Manager | B4: Fixed-term contract | C4: 18000 | D4: 18 | E4: =C4*D4*J4 -> 324000 | F4: 12 | G4: =C4*F4*J4 -> 216000 | H4: 6 | I4: =C4*H4*J4 -> 108000 | J4: 1 | K4: =J4*0.5 -> 0.5 | L4: GCoM-side PM; oversees delivery
A5: Business Analyst | B5: Fixed-term contract | C5: 14000 | D5: 14 | E5: =C5*D5*J5 -> 196000 | F5: 8 | G5: =C5*F5*J5 -> 112000 | H5: 4 | I5: =C5*H5*J5 -> 56000 | J5: 1 | K5: =J5*0.5 -> 0.5 | L5: Requirements, UAT, documentation
A6: Solution Architect | B6: Consultancy | C6: 25000 | D6: 10 | E6: =C6*D6*J6 -> 250000 | F6: 6 | G6: =C6*F6*J6 -> 150000 | H6: 3 | I6: =C6*H6*J6 -> 75000 | J6: 1 | K6: =J6*0.5 -> 0.5 | L6: Cloud-native; AWS or Azure certified
A7: Senior Full-Stack Developer | B7: Fixed-term contract | C7: 22000 | D7: 18 | E7: =C7*D7*J7 -> 792000 | F7: 18 | G7: =C7*F7*J7 -> 792000 | H7: 18 | I7: =C7*H7*J7 -> 792000 | J7: 2 | K7: =J7*0.5 -> 1 | L7: React/Node or Django stack
A8: Mid Full-Stack Developer | B8: Fixed-term contract | C8: 15000 | D8: 16 | E8: =C8*D8*J8 -> 720000 | F8: 16 | G8: =C8*F8*J8 -> 720000 | H8: 16 | I8: =C8*H8*J8 -> 720000 | J8: 3 | K8: =J8*0.5 -> 1.5 | L8: Feature dev & integration
A9: Mobile Developer (iOS/Android) | B9: Fixed-term contract | C9: 18000 | D9: 12 | E9: =C9*D9*J9 -> 216000 | F9: 12 | G9: =C9*F9*J9 -> 216000 | H9: 12 | I9: =C9*H9*J9 -> 216000 | J9: 1 | K9: =J9*0.5 -> 0.5 | L9: Member mobile portal
A10: UI/UX Designer | B10: Consultancy | C10: 12000 | D10: 8 | E10: =C10*D10*J10 -> 96000 | F10: 4 | G10: =C10*F10*J10 -> 48000 | H10: 2 | I10: =C10*H10*J10 -> 24000 | J10: 1 | K10: =J10*0.5 -> 0.5 | L10: Figma; design system ownership
A11: Data Engineer / BI Developer | B11: Fixed-term contract | C11: 18000 | D11: 14 | E11: =C11*D11*J11 -> 252000 | F11: 14 | G11: =C11*F11*J11 -> 252000 | H11: 14 | I11: =C11*H11*J11 -> 252000 | J11: 1 | K11: =J11*0.5 -> 0.5 | L11: Report aggregation & dashboards
A12: QA / Test Engineer | B12: Fixed-term contract | C12: 12000 | D12: 16 | E12: =C12*D12*J12 -> 192000 | F12: 12 | G12: =C12*F12*J12 -> 144000 | H12: 12 | I12: =C12*H12*J12 -> 144000 | J12: 1 | K12: =J12*0.5 -> 0.5 | L12: Automated + manual testing
A13: DevOps / Cloud Engineer | B13: Fixed-term contract | C13: 20000 | D13: 18 | E13: =C13*D13*J13 -> 360000 | F13: 18 | G13: =C13*F13*J13 -> 360000 | H13: 18 | I13: =C13*H13*J13 -> 360000 | J13: 1 | K13: =J13*0.5 -> 0.5 | L13: CI/CD, security, monitoring
A14: Database Administrator | B14: Part-time | C14: 10000 | D14: 12 | E14: =C14*D14*J14 -> 120000 | F14: 12 | G14: =C14*F14*J14 -> 120000 | H14: 12 | I14: =C14*H14*J14 -> 120000 | J14: 1 | K14: =J14*0.5 -> 0.5 | L14: PostgreSQL / MongoDB
A15: Cybersecurity Consultant | B15: Consultancy | C15: 22000 | D15: 6 | E15: =C15*D15*J15 -> 132000 | F15: 4 | G15: =C15*F15*J15 -> 88000 | H15: 2 | I15: =C15*H15*J15 -> 44000 | J15: 1 | K15: =J15*0.5 -> 0.5 | L15: Pen-testing, compliance (ISO 27001)
... A18: Helpdesk / Support Analyst | B18: Permanent hire | C18: 8000 | D18: 0 | E18: =C18*D18*J18 -> 0 | F18: 12 | G18: =C18*F18*J18 -> 192000 | H18: 12 | I18: =C18*H18*J18 -> 192000 | J18: 2 | K18: =J18*0.5 -> 1 | L18: Operational support Year 2+
A19: TOTAL PERSONNEL COST | E19: =SUM(E4:E18) -> 3798000 | G19: =SUM(G4:G18) -> 3484000 | I19: =SUM(I4:I18) -> 3147000

Sheet 📅 Timeline & Milestones
A1: GHANA CHAMBER OF MINES — PROJECT TIMELINE & MILESTONES (36 MONTHS)
A2: PHASE / MILESTONE | H2: YEAR 1 — FY2025 | P2: YEAR 2 — FY2026 | X2: YEAR 3 — FY2027
C3: Due Date | D3: Budget (GHS) | E3: Owner | F3: Status | G3: Risk Level | H3: M1 | I3: M2 | J3: M3 | K3: M4 | L3: M5 | M3: M6 | N3: M7 | O3: M8 | P3: M9 | Q3: M10 | R3: M11 | S3: M12 | T3: M13 | U3: M14 | V3: M15 | W3: M16 | X3: M17 | Y3: M18 | Z3: M19 | AA3: M20 | AB3: M21 | AC3: M22 | AD3: M23 | AE3: M24 | AF3: M25 | AG3: M26 | AH3: M27 | AI3: M28 | AJ3: M29 | AK3: M30 | AL3: M31 | AM3: M32 | AN3: M33 | AO3: M34 | AP3: M35 | AQ3: M36
A4: PHASE 1: DISCOVERY & PLANNING
A5: Kick-off & stakeholder alignment | B5: Aug 2025 | C5: 15000 | D5: PM / BA | E5: Not Started | F5: Low
A6: Requirements & gap analysis complete | B6: Sep 2025 | C6: 28000 | D6: BA | E6: Not Started | F6: Medium
A7: Procurement & vendor selection done | B7: Oct 2025 | C7: 12000 | D7: Procurement | E7: Not Started | F7: Medium
A8: PHASE 2: ARCHITECTURE & DESIGN
A9: System architecture approved | B9: Nov 2025 | C9: 40000 | D9: Architect | E9: Not Started | F9: Medium
A10: UI/UX prototype signed off | B10: Dec 2025 | C10: 30000 | D10: UX / PM | E10: Not Started | F10: Low
A11: PHASE 3: CORE DEVELOPMENT
A12: Member registry module live (Beta) | B12: Feb 2026 | C12: 120000 | D12: Dev Lead | E12: Not Started | F12: High
A13: Report aggregation engine complete | B13: May 2026 | C13: 150000 | D13: Data Eng | E13: Not Started | F13: High
A14: BI dashboard & analytics ready | B14: Jul 2026 | C14: 90000 | D14: Dev Lead | E14: Not Started | F14: Medium
A15: PHASE 4: INTEGRATION & TESTING
A16: SIT & UAT cycles complete | B16: Sep 2026 | C16: 55000 | D16: QA / PM | E16: Not Started | F16: Medium
A17: Security pen-test passed | B17: Oct 2026 | C17: 35000 | D17: CyberSec | E17: Not Started | F17: High
A18: PHASE 5: DEPLOYMENT & TRAINING
A19: Go-live (Production launch) | B19: Jan 2027 | C19: 80000 | D19: DevOps / PM | E19: Not Started | F19: High
A20: All users trained & onboarded | B20: Mar 2027 | C20: 60000 | D20: Change Mgmt | E20: Not Started | F20: Medium
A21: PHASE 6: SUPPORT & MAINTENANCE
A22: Year 2 feature release 1 | B22: Jul 2027 | C22: 85000 | D22: Dev Lead | E22: Not Started | F22: Low
A23: Annual security & compliance review | B23: Jul 2027 | C23: 30000 | D23: CyberSec | E23: Not Started | F23: Medium
A24: Year 3 feature release 2 | B24: Jan 2028 | C24: 95000 | D24: Dev Lead | E24: Not Started | F24: Low
A25: Project closure & handover | B25: Jun 2028 | C25: 20000 | D25: PM | E25: Not Started | F25: Low

Sheet ⚠️ Risk Register
A1: GHANA CHAMBER OF MINES — PROJECT RISK REGISTER
A2: ID | B2: Risk Description | C2: Category | D2: Likelihood (1–5) | E2: Impact (1–5) | F2: Risk Score (L×I) | G2: Mitigation Strategy | H2: Contingency Action | I2: Owner | J2: Budget Impact (GHS)
A3: R01 | B3: Scope creep due to evolving member requirements | C3: Scope | D3: 3 | E3: 4 | F3: =D3*E3 -> 12 | G3: Agile delivery with change control board; fixed sprint scope | H3: Activate contingency budget; defer non-critical features | I3: PM | J3: 85000
A4: R02 | B4: Key developer attrition during build phase | C4: HR / Talent | D4: 2 | E4: 5 | F4: =D4*E4 -> 10 | G4: Competitive market rates; knowledge-transfer protocols | H4: Maintain talent pipeline; use bench contractors | I4: Dev Lead | J4: 120000
A5: R03 | B5: GHS/USD exchange rate volatility (imported tools) | C5: Financial | D5: 4 | E5: 3 | F5: =D5*E5 -> 12 | G5: Hedge with GHS pricing clauses in contracts | H5: Activate FX buffer in contingency fund | I5: Finance | J5: 60000
A6: R04 | B6: Data migration errors from legacy systems | C6: Technical | D6: 3 | E6: 4 | F6: =D6*E6 -> 12 | G6: Parallel-run migration; automated reconciliation scripts | H6: Roll back to legacy; manual data correction sprint | I6: DBA | J6: 50000
A7: R05 | B7: Low user adoption by member companies | C7: Change | D7: 3 | E7: 4 | F7: =D7*E7 -> 12 | G7: Early-adopter pilot; champion network; UX research | H7: Extended training; enhanced helpdesk support | I7: Change Mgmt | J7: 70000
A8: R06 | B8: Cybersecurity breach / data leak | C8: Security | D8: 2 | E8: 5 | F8: =D8*E8 -> 10 | G8: ISO 27001 alignment; penetration testing; MFA enforced | H8: Incident response plan; regulatory notification | I8: CyberSec | J8: 200000
A9: R07 | B9: Cloud provider outage (AWS / GCP) | C9: Infrastructure | D9: 2 | E9: 4 | F9: =D9*E9 -> 8 | G9: Multi-AZ deployment; automated failover | H9: Activate DR site; communicate SLA breach | I9: DevOps | J9: 40000
A10: R08 | B10: Regulatory / legal compliance gaps (PNDCL 153) | C10: Legal | D10: 2 | E10: 4 | F10: =D10*E10 -> 8 | G10: Legal review at each phase; GDPA compliance checklist | H10: Engage legal counsel; architecture rework | I10: Legal / PM | J10: 55000
A11: R09 | B11: Budget overrun beyond 15% contingency | C11: Financial | D11: 2 | E11: 5 | F11: =D11*E11 -> 10 | G11: Monthly burn-rate reviews; earned-value reporting | H11: Seek supplementary board approval | I11: PM / Finance | J11: 150000
A12: R10 | B12: Integration failure with existing GCoM ERP | C12: Technical | D12: 3 | E12: 3 | F12: =D12*E12 -> 9 | G12: API-first design; sandbox integration testing from Month 2 | H12: Maintain interim manual process | I12: Dev Lead / BA | J12: 45000

Sheet 🔧 Assumptions & FX
A1: GHANA CHAMBER OF MINES — KEY ASSUMPTIONS & FX REFERENCE
A3: FX & CURRENCY ASSUMPTIONS
A4: GHS / USD Exchange Rate (budget rate) | B4: 15.5 | C4: Editable Input | D4: Source: Bank of Ghana, May 2025 average
A5: GHS / EUR Exchange Rate (budget rate) | B5: 16.8 | C5: Editable Input | D5: Source: Bank of Ghana, May 2025 average
A6: GHS / GBP Exchange Rate (budget rate) | B6: 19.6 | C6: Editable Input | D6: Source: Bank of Ghana, May 2025 average
A7: Annual FX volatility buffer (%) | B7: 0.08 | C7: Editable Input | D7: 8% buffer applied to foreign-currency items
A9: INFLATION & ESCALATION
A10: Ghana CPI / annual inflation assumption | B10: 0.23 | C10: Editable Input | D10: Source: Ghana Statistical Service, 2025 forecast
A11: IT salary escalation (annual) | B11: 0.15 | C11: Editable Input | D11: Competitive tech market in Ghana & West Africa
A12: Cloud cost escalation (annual) | B12: 0.05 | C12: Editable Input | D12: AWS pricing trend; offset by reserved instances
A13: General cost contingency buffer | B13: 0.15 | C13: Editable Input | D13: Applied to all line items; see Budget Breakdown
A15: PROJECT PARAMETERS
A16: Total project duration (months) | B16: 36 | C16: Editable Input | D16: FY2025 – FY2027
A17: Total GCoM internal staff (end users) | B17: 45 | C17: Editable Input | D17: Accra HQ + regional offices
A18: Member company super-users | B18: 120 | C18: Editable Input | D18: Est. 3 super-users × 40 member companies
A19: Number of member companies (current) | B19: 40 | C19: Editable Input | D19: Source: GCoM Membership Register 2025
A20: Sprint duration (weeks) | B20: 2 | C20: Editable Input | D20: Agile/Scrum delivery methodology
A21: UAT sign-off period (weeks) | B21: 3 | C21: Editable Input | D21: Per major module; requires GCoM Director sign-off
A23: TECHNOLOGY ASSUMPTIONS
A24: Primary cloud provider | B24: AWS (af-south-1) | C24: Editable Input | D24: Cape Town region; lowest latency for Ghana
A25: Database technology | B25: PostgreSQL + MongoDB | C25: Editable Input | D25: Relational + document store for reports
A26: Frontend framework | B26: React 18 + TypeScript | C26: Editable Input | D26: Progressive Web App + mobile-responsive
A27: Backend framework | B27: Node.js / Django REST | C27: Editable Input | D27: Microservices architecture
A28: Authentication | B28: OAuth2 + MFA (Okta) | C28: Editable Input | D28: Single sign-on for GCoM and members
A29: Reporting layer | B29: Apache Superset / Power BI | C29: Editable Input | D29: Self-service BI for GCoM management
A30: CI/CD pipeline | B30: GitHub Actions + Terraform | C30: Editable Input | D30: Infrastructure as code
A31: Data backup frequency | B31: Daily + real-time replication | C31: Editable Input | D31: RPO < 1 hr; RTO < 4 hrs
