Workbook

Sheet Summary
A1: Insurer Products, Services, Revenue Contributions & Revenue Sources
A2: Prepared 6 Oct 2026 from company filings/results releases (mostly FY2025) and secondary sources. See 'Sources & Notes'.
A4: Sheet | B4: What it contains
A5: Company Profiles | B5: One row per insurer: products, services/channels, revenue sources, revenue contribution headline, caveats.
A6: Segment Data | B6: Reported segment figures in native currency/units, with % shares calculated by formula. Blue = hardcoded from a source; black = formula; yellow fill = derived by subtraction.
A7: Reconciliation | B7: Formula check that segment components sum to each reported total.
A8: Revenue Sources Matrix | B8: Which revenue source (premiums, investment income, fees, etc.) is primary or secondary for each company.
A9: Sources & Notes | B9: Document links and caveats.
A12: Important caveats
A13: 1. Companies report on different bases (net premiums written, gross written premiums, insurance revenue, operating profit, net income). Shares are only meaningful WITHIN a company/basis, not across companies.
A14: 2. Premium share is not profit share: e.g. Chubb North America Commercial is ~39% of premiums but ~53% of segment income (see Segment Data).
A15: 3. Guardian Life segment figures could not be retrieved; only products/sources are given.
A16: 4. Some figures come from secondary sites (flagged in the Source column). Verify against filings before relying on them.
A17: 5. Rows with yellow fill are derived by subtraction from reported totals (rounding differences possible).

Sheet Company Profiles
A1: Company profiles
A2: Revenue contribution figures are FY2025 unless stated; see Segment Data for numbers and shares.
A4: Company | B4: Type | C4: Products | D4: Services / channels | E4: Revenue sources | F4: Revenue contribution (headline) | G4: Caveats
A5: Progressive | B5: US P&C (auto-focused) | C5: Personal and commercial autos and trucks; motorcycles, boats, RVs (special lines); homeowners/renters. | D5: Direct (web, phone, app) and independent agents; Snapshot usage-based telematics program. | E5: Net premiums earned (~$81.7B); investment income ($3.58B); fees and service revenues. | F5: Net premiums written $83.2B: Personal Lines $72.6B (~87%), Commercial Lines $10.6B (~13%). | G5: Total revenue ~$87.6B comes from a secondary site. Commercial premiums fell 3% (rideshare non-renewals).
A6: Chubb | B6: Global P&C + life | C6: Commercial P&C, high-net-worth personal lines, agricultural, overseas general (commercial & consumer), global reinsurance, life insurance. | D6: Broker/agent distribution plus Chubb Digital ($1.4B premium, +27%). | E6: Underwriting income (P&C record $6.53B, combined ratio 85.7%); net investment income (~$7.0B across segments); life premiums/spread. | F6: NPW $54.8B: NA Commercial 39%, Overseas General 27%, Life 13%, NA Personal 13%, Agricultural 5%, Reinsurance 2%. | G6: Profit more concentrated than premium: NA Commercial ~53% of segment income.
A7: AIG | B7: Global commercial/specialty P&C | C7: North America Commercial, International Commercial (incl. Lloyd's/Talbot), Global Personal (high-net-worth); Lexington excess & surplus lines. | D7: Wholesale and retail brokers; third-party capital vehicles (e.g. Lloyd's Syndicate 2479, Amwins/Blackstone vehicle). | E7: Underwriting income (General Insurance $2.3B, combined ratio 90.1%); net investment income ($4.2B). | F7: General Insurance NPW $23.7B: NA Commercial 37%, International Commercial 37%, Global Personal 26%. | G7: Life & retirement is held separately (Corebridge) and excluded. Capital-vehicle fee income is not quantified in sources.
A8: Allianz | B8: Global diversified (P&C, life/health, asset mgmt) | C8: Retail and commercial P&C (motor, home, Allianz Partners travel/assistance/health); life and health; asset management. | D8: Agents, brokers, direct, partnerships; asset management for third-party investors. | E8: Insurance premiums; life/health investment margins; asset-management fees (operating revenues EUR 8.5B). | F8: Operating profit EUR 17.4B: P&C EUR 9.0B (~52%), Life/Health EUR 5.6B (~32%), remainder asset mgmt net of corporate (~EUR 2.8B, derived). | G8: Third-party AUM EUR 1.99T drives fee income. Asset mgmt operating profit not retrieved separately.
A9: Travelers | B9: US P&C | C9: Business Insurance (Select Accounts small commercial, Middle Market, National Property); Bond & Specialty (surety, management liability); Personal (auto, homeowners). | D9: Independent agents and brokers. | E9: Net written premiums ($44.4B); net investment income (just under $4B). | F9: NWP $44.4B: Business Insurance ~$22.6B (~51%, derived), Personal $17.5B (~39%), Bond & Specialty $4.3B (~10%). | G9: Most Canadian operations sold to Definity. Business Insurance NWP derived by subtraction.
A10: Allstate | B10: US personal lines + protection services | C10: Auto, homeowners and other personal lines; Protection Services: protection plans, roadside, dealer services, identity protection, Arity telematics analytics. | D10: Agents (exclusive and independent) and direct; business-to-business protection plans. | E10: Premiums; investment income; service and fee revenue (Protection Services). | F10: Total revenue $67.7B. Q4 earned premiums: auto $9.62B (~65%), homeowners $4.06B (~27%) of $14.8B Property-Liability. | G10: Protection Services = 4.8% of premiums written ($3.0B) but 81.6% of policies in force. Group health/benefits businesses being divested.
A11: Lemonade | B11: AI-native US/EU personal lines | C11: Renters, homeowners, pet, term life, car (incl. autonomous-vehicle car product). | D11: Direct digital (AI chatbot onboarding and claims). | E11: Net earned premium; ceding commission from reinsurers; net investment income; commissions and other income. | F11: Q2 2026 revenue $294.4M: net earned premium ~86%, ceding commission ~7%, investment income ~3%, commission/other ~4%. | G11: Still loss-making (H1 2026 net loss $79.2M). Revenue by product line not retrieved; only in-force premium ($1.43B).
A12: Ping An | B12: Chinese financial conglomerate | C12: Life & health, P&C, banking (Ping An Bank), asset management; four categories: protection, asset management, credit, service. | D12: Agents, bancassurance, auto-dealer channel, Auto Owner app (120M+ users), Good Doctor health services (AI Doctor). | E12: Insurance premiums; investment returns on very large insurance funds (RMB 6.61T); bank interest and fees; health services. | F12: 2025 operating profit RMB 134.4B. Q1 2025: Life & Health RMB 26.9B of RMB 37.9B (~71%). | G12: Full-year segment split not retrieved. Good Doctor revenue (RMB 2.48B in H1 2026) is small versus insurance and banking.
A13: AXA | B13: Global diversified insurer | C13: P&C (personal, commercial incl. AXA XL); life, savings, health, protection; 51% of Prima (Italian digital motor). | D13: Agents, brokers, direct, bancassurance. | E13: Premiums; health/protection margins; unit-linked fees; investment income. | F13: GWP & other revenues EUR 116B: P&C EUR 58.0B (~50%), Life & Health EUR 56.5B (~49%), Asset Mgmt EUR 0.9B (<1%). | G13: AXA IM sold July 2025. Underlying earnings EUR 8.4B after ~EUR 1.2B holding costs.
A14: Swiss Re | B14: Global reinsurer | C14: P&C Reinsurance; Life & Health Reinsurance; Corporate Solutions (direct large-corporate insurance). | D14: Reinsurance to insurers; insurance-linked securities; AI underwriting tools for clients. | E14: Reinsurance premiums and underwriting result; recurring investment income (4.2% yield). | F14: 2025 net income $4.8B: P&C Re $2.8B (~55% of segment total), L&H Re $1.3B (~25%), Corporate Solutions $0.99B (~19%). | G14: Segment net incomes sum above group total because group-level items are negative (see Segment Data).
A15: Munich Re | B15: Global reinsurer + primary insurer (ERGO) | C15: P&C reinsurance; life & health reinsurance; Global Specialty Insurance; ERGO primary insurance; AI insurance (aiSure). | D15: Reinsurance; ERGO via agents/brokers/direct; AI product-design platform for clients. | E15: Reinsurance and primary premiums; investment income (2026 target return above 3.5%). | F15: Net result EUR 6.12B: Reinsurance EUR 5.20B (~85%), ERGO EUR 0.92B (~15%). Group insurance revenue EUR 60.4B, ERGO EUR 21.7B (~36%). | G15: Reinsurance revenue derived by subtraction. ERGO is ~36% of revenue but ~15% of profit.
A16: Guardian Life | B16: US mutual life/benefits insurer | C16: Life, disability, dental, vision, retirement and annuity products; workplace group benefits. | D16: Group benefits sales offices, financial professionals; Park Avenue Securities (broker-dealer/investment adviser); ~12M people served. | E16: Premiums, fees and other income; annuity considerations and fund deposits; investment income (per financial statement line items). | F16: Not retrieved. | G16: Check Guardian's annual report for statutory financials.

Sheet Segment Data
A1: Segment data (native currency and units)
A2: Blue = sourced input; black = formula; yellow = derived by subtraction. % share computed within each Company + Basis over Component and Derived rows.
A4: Company | B4: Basis | C4: Segment / line item | D4: Value | E4: Unit | F4: Row type | G4: % of basis total | H4: Source / notes
A5: Progressive | B5: FY2025 net premiums written | C5: Personal Lines | D5: 72.6 | E5: $B | F5: Component | G5: =IF(OR(F5="Component",F5="Derived component"),D5/(SUMIFS($D$5:$D$200,$A$5:$A$200,A5,$B$5:$B$200,B5,$F$5:$F$200,"Component")+SUMIFS($D$5:$D$200,$A$5:$A$200,A5,$B$5:$B$200,B5,$F$5:$F$200,"Derived component")),"") -> 0.87259615 | H5: Progressive FY2025 10-K / Dec 2025 release; Fintool Q4 2025 summary (secondary) (87.5% share per source)
A6: Progressive | B6: FY2025 net premiums written | C6: Commercial Lines | D6: 10.6 | E6: $B | F6: Component | G6: =IF(OR(F6="Component",F6="Derived component"),D6/(SUMIFS($D$5:$D$200,$A$5:$A$200,A6,$B$5:$B$200,B6,$F$5:$F$200,"Component")+SUMIFS($D$5:$D$200,$A$5:$A$200,A6,$B$5:$B$200,B6,$F$5:$F$200,"Derived component")),"") -> 0.12740385 | H6: Progressive FY2025 10-K / Dec 2025 release; Fintool Q4 2025 summary (secondary)
A7: Progressive | B7: FY2025 net premiums written | C7: Total net premiums written | D7: 83.2 | E7: $B | F7: Reported total | G7: =IF(OR(F7="Component",F7="Derived component"),D7/(SUMIFS($D$5:$D$200,$A$5:$A$200,A7,$B$5:$B$200,B7,$F$5:$F$200,"Component")+SUMIFS($D$5:$D$200,$A$5:$A$200,A7,$B$5:$B$200,B7,$F$5:$F$200,"Derived component")),"") | H7: 10-K: $83.2B net premiums written
A8: Progressive | B8: FY2025 selected revenue lines | C8: Net premiums earned | D8: 81.66 | E8: $B | F8: Selected | G8: =IF(OR(F8="Component",F8="Derived component"),D8/(SUMIFS($D$5:$D$200,$A$5:$A$200,A8,$B$5:$B$200,B8,$F$5:$F$200,"Component")+SUMIFS($D$5:$D$200,$A$5:$A$200,A8,$B$5:$B$200,B8,$F$5:$F$200,"Derived component")),"") | H8: Progressive FY2025 10-K / Dec 2025 release; Fintool Q4 2025 summary (secondary)
A9: Progressive | B9: FY2025 selected revenue lines | C9: Investment income | D9: 3.58 | E9: $B | F9: Selected | G9: =IF(OR(F9="Component",F9="Derived component"),D9/(SUMIFS($D$5:$D$200,$A$5:$A$200,A9,$B$5:$B$200,B9,$F$5:$F$200,"Component")+SUMIFS($D$5:$D$200,$A$5:$A$200,A9,$B$5:$B$200,B9,$F$5:$F$200,"Derived component")),"") | H9: Progressive FY2025 10-K / Dec 2025 release; Fintool Q4 2025 summary (secondary) (up from $2.83B in 2024)
A10: Progressive | B10: FY2025 selected revenue lines | C10: Net income | D10: 11.31 | E10: $B | F10: Selected | G10: =IF(OR(F10="Component",F10="Derived component"),D10/(SUMIFS($D$5:$D$200,$A$5:$A$200,A10,$B$5:$B$200,B10,$F$5:$F$200,"Component")+SUMIFS($D$5:$D$200,$A$5:$A$200,A10,$B$5:$B$200,B10,$F$5:$F$200,"Derived component")),"") | H10: Progressive FY2025 10-K / Dec 2025 release; Fintool Q4 2025 summary (secondary)
A11: Chubb | B11: FY2025 net premiums written | C11: North America Commercial P&C | D11: 21280 | E11: $M | F11: Component | G11: =IF(OR(F11="Component",F11="Derived component"),D11/(SUMIFS($D$5:$D$200,$A$5:$A$200,A11,$B$5:$B$200,B11,$F$5:$F$200,"Component")+SUMIFS($D$5:$D$200,$A$5:$A$200,A11,$B$5:$B$200,B11,$F$5:$F$200,"Derived component")),"") -> 0.38802378 | H11: Chubb FY2025 10-K segment table (SEC EDGAR)
A12: Chubb | B12: FY2025 net premiums written | C12: North America Personal P&C | D12: 7024 | E12: $M | F12: Component | G12: =IF(OR(F12="Component",F12="Derived component"),D12/(SUMIFS($D$5:$D$200,$A$5:$A$200,A12,$B$5:$B$200,B12,$F$5:$F$200,"Component")+SUMIFS($D$5:$D$200,$A$5:$A$200,A12,$B$5:$B$200,B12,$F$5:$F$200,"Derived component")),"") -> 0.12807702 | H12: Chubb FY2025 10-K segment table (SEC EDGAR)
A13: Chubb | B13: FY2025 net premiums written | C13: North America Agricultural | D13: 2926 | E13: $M | F13: Component | G13: =IF(OR(F13="Component",F13="Derived component"),D13/(SUMIFS($D$5:$D$200,$A$5:$A$200,A13,$B$5:$B$200,B13,$F$5:$F$200,"Component")+SUMIFS($D$5:$D$200,$A$5:$A$200,A13,$B$5:$B$200,B13,$F$5:$F$200,"Derived component")),"") -> 0.053353269 | H13: Chubb FY2025 10-K segment table (SEC EDGAR)
A14: Chubb | B14: FY2025 net premiums written | C14: Overseas General | D14: 15024 | E14: $M | F14: Component | G14: =IF(OR(F14="Component",F14="Derived component"),D14/(SUMIFS($D$5:$D$200,$A$5:$A$200,A14,$B$5:$B$200,B14,$F$5:$F$200,"Component")+SUMIFS($D$5:$D$200,$A$5:$A$200,A14,$B$5:$B$200,B14,$F$5:$F$200,"Derived component")),"") -> 0.27395062 | H14: Chubb FY2025 10-K segment table (SEC EDGAR)
A15: Chubb | B15: FY2025 net premiums written | C15: Global Reinsurance | D15: 1309 | E15: $M | F15: Component | G15: =IF(OR(F15="Component",F15="Derived component"),D15/(SUMIFS($D$5:$D$200,$A$5:$A$200,A15,$B$5:$B$200,B15,$F$5:$F$200,"Component")+SUMIFS($D$5:$D$200,$A$5:$A$200,A15,$B$5:$B$200,B15,$F$5:$F$200,"Derived component")),"") -> 0.023868568 | H15: Chubb FY2025 10-K segment table (SEC EDGAR)
A16: Chubb | B16: FY2025 net premiums written | C16: Life Insurance | D16: 7279 | E16: $M | F16: Component | G16: =IF(OR(F16="Component",F16="Derived component"),D16/(SUMIFS($D$5:$D$200,$A$5:$A$200,A16,$B$5:$B$200,B16,$F$5:$F$200,"Component")+SUMIFS($D$5:$D$200,$A$5:$A$200,A16,$B$5:$B$200,B16,$F$5:$F$200,"Derived component")),"") -> 0.13272674 | H16: Chubb FY2025 10-K segment table (SEC EDGAR)
... A34: Allianz | B34: FY2025 operating profit | C34: Life/Health | D34: 5.6 | E34: EUR B | F34: Component | G34: =IF(OR(F34="Component",F34="Derived component"),D34/(SUMIFS($D$5:$D$200,$A$5:$A$200,A34,$B$5:$B$200,B34,$F$5:$F$200,"Component")+SUMIFS($D$5:$D$200,$A$5:$A$200,A34,$B$5:$B$200,B34,$F$5:$F$200,"Derived component")),"") -> 0.32183908 | H34: Allianz FY2025 results (Insurtech Digital; Reinsurance News)
A35: Allianz | B35: FY2025 operating profit | C35: Asset Management + Corporate & other (derived) | D35: =D36-D33-D34 -> 2.8 | E35: EUR B | F35: Derived component | G35: =IF(OR(F35="Component",F35="Derived component"),D35/(SUMIFS($D$5:$D$200,$A$5:$A$200,A35,$B$5:$B$200,B35,$F$5:$F$200,"Component")+SUMIFS($D$5:$D$200,$A$5:$A$200,A35,$B$5:$B$200,B35,$F$5:$F$200,"Derived component")),"") -> 0.16091954 | H35: Derived by subtraction; asset management profit not retrieved separately
A36: Allianz | B36: FY2025 operating profit | C36: Group operating profit | D36: 17.4 | E36: EUR B | F36: Reported total | G36: =IF(OR(F36="Component",F36="Derived component"),D36/(SUMIFS($D$5:$D$200,$A$5:$A$200,A36,$B$5:$B$200,B36,$F$5:$F$200,"Component")+SUMIFS($D$5:$D$200,$A$5:$A$200,A36,$B$5:$B$200,B36,$F$5:$F$200,"Derived component")),"") | H36: Allianz FY2025 results (Insurtech Digital; Reinsurance News)
A37: Allianz | B37: FY2025 selected volume lines | C37: Total business volume (group) | D37: 186.9 | E37: EUR B | F37: Selected | G37: =IF(OR(F37="Component",F37="Derived component"),D37/(SUMIFS($D$5:$D$200,$A$5:$A$200,A37,$B$5:$B$200,B37,$F$5:$F$200,"Component")+SUMIFS($D$5:$D$200,$A$5:$A$200,A37,$B$5:$B$200,B37,$F$5:$F$200,"Derived component")),"") | H37: Allianz FY2025 results (Insurtech Digital; Reinsurance News)
A38: Allianz | B38: FY2025 selected volume lines | C38: P&C total business volume | D38: 86.7 | E38: EUR B | F38: Selected | G38: =IF(OR(F38="Component",F38="Derived component"),D38/(SUMIFS($D$5:$D$200,$A$5:$A$200,A38,$B$5:$B$200,B38,$F$5:$F$200,"Component")+SUMIFS($D$5:$D$200,$A$5:$A$200,A38,$B$5:$B$200,B38,$F$5:$F$200,"Derived component")),"") | H38: Allianz FY2025 results (Insurtech Digital; Reinsurance News)
A39: Allianz | B39: FY2025 selected volume lines | C39: Asset management operating revenues | D39: 8.5 | E39: EUR B | F39: Selected | G39: =IF(OR(F39="Component",F39="Derived component"),D39/(SUMIFS($D$5:$D$200,$A$5:$A$200,A39,$B$5:$B$200,B39,$F$5:$F$200,"Component")+SUMIFS($D$5:$D$200,$A$5:$A$200,A39,$B$5:$B$200,B39,$F$5:$F$200,"Derived component")),"") | H39: Allianz FY2025 results (Insurtech Digital; Reinsurance News)
A40: Allianz | B40: FY2025 selected volume lines | C40: Third-party assets under management (EUR trillion) | D40: 1.99 | E40: EUR T | F40: Selected | G40: =IF(OR(F40="Component",F40="Derived component"),D40/(SUMIFS($D$5:$D$200,$A$5:$A$200,A40,$B$5:$B$200,B40,$F$5:$F$200,"Component")+SUMIFS($D$5:$D$200,$A$5:$A$200,A40,$B$5:$B$200,B40,$F$5:$F$200,"Derived component")),"") | H40: Unit is EUR trillion for this row
A41: Travelers | B41: FY2025 net written premiums | C41: Business Insurance (derived) | D41: =D44-D42-D43 -> 22.6 | E41: $B | F41: Derived component | G41: =IF(OR(F41="Component",F41="Derived component"),D41/(SUMIFS($D$5:$D$200,$A$5:$A$200,A41,$B$5:$B$200,B41,$F$5:$F$200,"Component")+SUMIFS($D$5:$D$200,$A$5:$A$200,A41,$B$5:$B$200,B41,$F$5:$F$200,"Derived component")),"") -> 0.50900901 | H41: Derived by subtraction
A42: Travelers | B42: FY2025 net written premiums | C42: Bond & Specialty Insurance | D42: 4.3 | E42: $B | F42: Component | G42: =IF(OR(F42="Component",F42="Derived component"),D42/(SUMIFS($D$5:$D$200,$A$5:$A$200,A42,$B$5:$B$200,B42,$F$5:$F$200,"Component")+SUMIFS($D$5:$D$200,$A$5:$A$200,A42,$B$5:$B$200,B42,$F$5:$F$200,"Derived component")),"") -> 0.096846847 | H42: Travelers Q4/FY2025 release (Reinsurance News; BusinessWire)
A43: Travelers | B43: FY2025 net written premiums | C43: Personal Insurance | D43: 17.5 | E43: $B | F43: Component | G43: =IF(OR(F43="Component",F43="Derived component"),D43/(SUMIFS($D$5:$D$200,$A$5:$A$200,A43,$B$5:$B$200,B43,$F$5:$F$200,"Component")+SUMIFS($D$5:$D$200,$A$5:$A$200,A43,$B$5:$B$200,B43,$F$5:$F$200,"Derived component")),"") -> 0.39414414 | H43: Travelers Q4/FY2025 release (Reinsurance News; BusinessWire)
A44: Travelers | B44: FY2025 net written premiums | C44: Total net written premiums | D44: 44.4 | E44: $B | F44: Reported total | G44: =IF(OR(F44="Component",F44="Derived component"),D44/(SUMIFS($D$5:$D$200,$A$5:$A$200,A44,$B$5:$B$200,B44,$F$5:$F$200,"Component")+SUMIFS($D$5:$D$200,$A$5:$A$200,A44,$B$5:$B$200,B44,$F$5:$F$200,"Derived component")),"") | H44: Travelers Q4/FY2025 release (Reinsurance News; BusinessWire)
A45: Travelers | B45: Q4 2025 segment income (after-tax) | C45: Business Insurance | D45: 1290 | E45: $M | F45: Component | G45: =IF(OR(F45="Component",F45="Derived component"),D45/(SUMIFS($D$5:$D$200,$A$5:$A$200,A45,$B$5:$B$200,B45,$F$5:$F$200,"Component")+SUMIFS($D$5:$D$200,$A$5:$A$200,A45,$B$5:$B$200,B45,$F$5:$F$200,"Derived component")),"") -> 0.49311927 | H45: Travelers Q4 2025 (Yahoo Finance summary: $1.29B)
A46: Travelers | B46: Q4 2025 segment income (after-tax) | C46: Bond & Specialty Insurance | D46: 236 | E46: $M | F46: Component | G46: =IF(OR(F46="Component",F46="Derived component"),D46/(SUMIFS($D$5:$D$200,$A$5:$A$200,A46,$B$5:$B$200,B46,$F$5:$F$200,"Component")+SUMIFS($D$5:$D$200,$A$5:$A$200,A46,$B$5:$B$200,B46,$F$5:$F$200,"Derived component")),"") -> 0.090214067 | H46: Travelers Q4 2025
A47: Travelers | B47: Q4 2025 segment income (after-tax) | C47: Personal Insurance | D47: 1090 | E47: $M | F47: Component | G47: =IF(OR(F47="Component",F47="Derived component"),D47/(SUMIFS($D$5:$D$200,$A$5:$A$200,A47,$B$5:$B$200,B47,$F$5:$F$200,"Component")+SUMIFS($D$5:$D$200,$A$5:$A$200,A47,$B$5:$B$200,B47,$F$5:$F$200,"Derived component")),"") -> 0.41666667 | H47: Travelers Q4 2025 (Yahoo Finance summary: $1.09B)
A48: Allstate | B48: Q4 2025 Property-Liability premiums earned | C48: Allstate Protection Auto | D48: 9.62 | E48: $B | F48: Component | G48: =IF(OR(F48="Component",F48="Derived component"),D48/(SUMIFS($D$5:$D$200,$A$5:$A$200,A48,$B$5:$B$200,B48,$F$5:$F$200,"Component")+SUMIFS($D$5:$D$200,$A$5:$A$200,A48,$B$5:$B$200,B48,$F$5:$F$200,"Derived component")),"") -> 0.65 | H48: Allstate FY2025 10-K and Q4 2025 release; Fintool (secondary) for Q4 split
A49: Allstate | B49: Q4 2025 Property-Liability premiums earned | C49: Allstate Protection Homeowners | D49: 4.06 | E49: $B | F49: Component | G49: =IF(OR(F49="Component",F49="Derived component"),D49/(SUMIFS($D$5:$D$200,$A$5:$A$200,A49,$B$5:$B$200,B49,$F$5:$F$200,"Component")+SUMIFS($D$5:$D$200,$A$5:$A$200,A49,$B$5:$B$200,B49,$F$5:$F$200,"Derived component")),"") -> 0.27432432 | H49: Allstate FY2025 10-K and Q4 2025 release; Fintool (secondary) for Q4 split
A50: Allstate | B50: Q4 2025 Property-Liability premiums earned | C50: Other Property-Liability (derived) | D50: =D51-D48-D49 -> 1.12 | E50: $B | F50: Derived component | G50: =IF(OR(F50="Component",F50="Derived component"),D50/(SUMIFS($D$5:$D$200,$A$5:$A$200,A50,$B$5:$B$200,B50,$F$5:$F$200,"Component")+SUMIFS($D$5:$D$200,$A$5:$A$200,A50,$B$5:$B$200,B50,$F$5:$F$200,"Derived component")),"") -> 0.075675676 | H50: Derived by subtraction; includes other personal, commercial, run-off
A51: Allstate | B51: Q4 2025 Property-Liability premiums earned | C51: Total Property-Liability earned premiums | D51: 14.8 | E51: $B | F51: Reported total | G51: =IF(OR(F51="Component",F51="Derived component"),D51/(SUMIFS($D$5:$D$200,$A$5:$A$200,A51,$B$5:$B$200,B51,$F$5:$F$200,"Component")+SUMIFS($D$5:$D$200,$A$5:$A$200,A51,$B$5:$B$200,B51,$F$5:$F$200,"Derived component")),"") | H51: Allstate FY2025 10-K and Q4 2025 release; Fintool (secondary) for Q4 split
A52: Allstate | B52: FY2025 selected lines | C52: Total revenues | D52: 67.7 | E52: $B | F52: Selected | G52: =IF(OR(F52="Component",F52="Derived component"),D52/(SUMIFS($D$5:$D$200,$A$5:$A$200,A52,$B$5:$B$200,B52,$F$5:$F$200,"Component")+SUMIFS($D$5:$D$200,$A$5:$A$200,A52,$B$5:$B$200,B52,$F$5:$F$200,"Derived component")),"") | H52: Allstate FY2025 10-K and Q4 2025 release; Fintool (secondary) for Q4 split
A53: Allstate | B53: FY2025 selected lines | C53: Net income | D53: 10.2 | E53: $B | F53: Selected | G53: =IF(OR(F53="Component",F53="Derived component"),D53/(SUMIFS($D$5:$D$200,$A$5:$A$200,A53,$B$5:$B$200,B53,$F$5:$F$200,"Component")+SUMIFS($D$5:$D$200,$A$5:$A$200,A53,$B$5:$B$200,B53,$F$5:$F$200,"Derived component")),"") | H53: Allstate FY2025 10-K and Q4 2025 release; Fintool (secondary) for Q4 split
A54: Allstate | B54: FY2025 selected lines | C54: Protection Services premiums written | D54: 3.006 | E54: $B | F54: Selected | G54: =IF(OR(F54="Component",F54="Derived component"),D54/(SUMIFS($D$5:$D$200,$A$5:$A$200,A54,$B$5:$B$200,B54,$F$5:$F$200,"Component")+SUMIFS($D$5:$D$200,$A$5:$A$200,A54,$B$5:$B$200,B54,$F$5:$F$200,"Derived component")),"") | H54: 10-K: 4.8% of premiums written; 81.6% of policies in force
A55: Lemonade | B55: Q2 2026 revenue | C55: Net earned premium | D55: 252 | E55: $M | F55: Component | G55: =IF(OR(F55="Component",F55="Derived component"),D55/(SUMIFS($D$5:$D$200,$A$5:$A$200,A55,$B$5:$B$200,B55,$F$5:$F$200,"Component")+SUMIFS($D$5:$D$200,$A$5:$A$200,A55,$B$5:$B$200,B55,$F$5:$F$200,"Derived component")),"") -> 0.85597826 | H55: Lemonade Q2 2026 shareholder letter (SEC 8-K)
A56: Lemonade | B56: Q2 2026 revenue | C56: Ceding commission income | D56: 20.4 | E56: $M | F56: Component | G56: =IF(OR(F56="Component",F56="Derived component"),D56/(SUMIFS($D$5:$D$200,$A$5:$A$200,A56,$B$5:$B$200,B56,$F$5:$F$200,"Component")+SUMIFS($D$5:$D$200,$A$5:$A$200,A56,$B$5:$B$200,B56,$F$5:$F$200,"Derived component")),"") -> 0.069293478 | H56: Lemonade Q2 2026 shareholder letter (SEC 8-K)
A57: Lemonade | B57: Q2 2026 revenue | C57: Net investment income | D57: 9.7 | E57: $M | F57: Component | G57: =IF(OR(F57="Component",F57="Derived component"),D57/(SUMIFS($D$5:$D$200,$A$5:$A$200,A57,$B$5:$B$200,B57,$F$5:$F$200,"Component")+SUMIFS($D$5:$D$200,$A$5:$A$200,A57,$B$5:$B$200,B57,$F$5:$F$200,"Derived component")),"") -> 0.03294837 | H57: Lemonade Q2 2026 shareholder letter (SEC 8-K)
A58: Lemonade | B58: Q2 2026 revenue | C58: Commission and other income | D58: 12.3 | E58: $M | F58: Component | G58: =IF(OR(F58="Component",F58="Derived component"),D58/(SUMIFS($D$5:$D$200,$A$5:$A$200,A58,$B$5:$B$200,B58,$F$5:$F$200,"Component")+SUMIFS($D$5:$D$200,$A$5:$A$200,A58,$B$5:$B$200,B58,$F$5:$F$200,"Derived component")),"") -> 0.041779891 | H58: Lemonade Q2 2026 shareholder letter (SEC 8-K)
...

Sheet Reconciliation
A1: Reconciliation: components vs reported totals
A2: Components + derived rows should equal the reported total. Reconciling items (Swiss Re group items) are shown separately.
A4: Company | B4: Basis | C4: Unit | D4: Sum of components | E4: Reported total | F4: Difference | G4: Status
A5: Progressive | B5: FY2025 net premiums written | C5: $B | D5: =SUMIFS('Segment Data'!$D$5:$D$200,'Segment Data'!$A$5:$A$200,A5,'Segment Data'!$B$5:$B$200,B5,'Segment Data'!$F$5:$F$200,"Component")+SUMIFS('Segment Data'!$D$5:$D$200,'Segment Data'!$A$5:$A$200,A5,'Segment Data'!$B$5:$B$200,B5,'Segment Data'!$F$5:$F$200,"Derived component") -> 83.2 | E5: ='Segment Data'!D7 -> 83.2 | F5: =D5-E5 -> 0 | G5: =IF(ABS(F5)<0.005,"OK",IF(COUNTIFS('Segment Data'!$A$5:$A$200,A5,'Segment Data'!$B$5:$B$200,B5,'Segment Data'!$F$5:$F$200,"Reconciling item")>0,"Group items explain gap","CHECK")) -> OK
A6: Chubb | B6: FY2025 net premiums written | C6: $M | D6: =SUMIFS('Segment Data'!$D$5:$D$200,'Segment Data'!$A$5:$A$200,A6,'Segment Data'!$B$5:$B$200,B6,'Segment Data'!$F$5:$F$200,"Component")+SUMIFS('Segment Data'!$D$5:$D$200,'Segment Data'!$A$5:$A$200,A6,'Segment Data'!$B$5:$B$200,B6,'Segment Data'!$F$5:$F$200,"Derived component") -> 54842 | E6: ='Segment Data'!D17 -> 54842 | F6: =D6-E6 -> 0 | G6: =IF(ABS(F6)<0.005,"OK",IF(COUNTIFS('Segment Data'!$A$5:$A$200,A6,'Segment Data'!$B$5:$B$200,B6,'Segment Data'!$F$5:$F$200,"Reconciling item")>0,"Group items explain gap","CHECK")) -> OK
A7: Chubb | B7: FY2025 segment income | C7: $M | D7: =SUMIFS('Segment Data'!$D$5:$D$200,'Segment Data'!$A$5:$A$200,A7,'Segment Data'!$B$5:$B$200,B7,'Segment Data'!$F$5:$F$200,"Component")+SUMIFS('Segment Data'!$D$5:$D$200,'Segment Data'!$A$5:$A$200,A7,'Segment Data'!$B$5:$B$200,B7,'Segment Data'!$F$5:$F$200,"Derived component") -> 14227 | E7: ='Segment Data'!D24 -> 14227 | F7: =D7-E7 -> 0 | G7: =IF(ABS(F7)<0.005,"OK",IF(COUNTIFS('Segment Data'!$A$5:$A$200,A7,'Segment Data'!$B$5:$B$200,B7,'Segment Data'!$F$5:$F$200,"Reconciling item")>0,"Group items explain gap","CHECK")) -> OK
A8: AIG | B8: FY2025 General Insurance net premiums written | C8: $M | D8: =SUMIFS('Segment Data'!$D$5:$D$200,'Segment Data'!$A$5:$A$200,A8,'Segment Data'!$B$5:$B$200,B8,'Segment Data'!$F$5:$F$200,"Component")+SUMIFS('Segment Data'!$D$5:$D$200,'Segment Data'!$A$5:$A$200,A8,'Segment Data'!$B$5:$B$200,B8,'Segment Data'!$F$5:$F$200,"Derived component") -> 23675 | E8: ='Segment Data'!D28 -> 23675 | F8: =D8-E8 -> 0 | G8: =IF(ABS(F8)<0.005,"OK",IF(COUNTIFS('Segment Data'!$A$5:$A$200,A8,'Segment Data'!$B$5:$B$200,B8,'Segment Data'!$F$5:$F$200,"Reconciling item")>0,"Group items explain gap","CHECK")) -> OK
A9: Allianz | B9: FY2025 operating profit | C9: EUR B | D9: =SUMIFS('Segment Data'!$D$5:$D$200,'Segment Data'!$A$5:$A$200,A9,'Segment Data'!$B$5:$B$200,B9,'Segment Data'!$F$5:$F$200,"Component")+SUMIFS('Segment Data'!$D$5:$D$200,'Segment Data'!$A$5:$A$200,A9,'Segment Data'!$B$5:$B$200,B9,'Segment Data'!$F$5:$F$200,"Derived component") -> 17.4 | E9: ='Segment Data'!D36 -> 17.4 | F9: =D9-E9 -> 0 | G9: =IF(ABS(F9)<0.005,"OK",IF(COUNTIFS('Segment Data'!$A$5:$A$200,A9,'Segment Data'!$B$5:$B$200,B9,'Segment Data'!$F$5:$F$200,"Reconciling item")>0,"Group items explain gap","CHECK")) -> OK
A10: Travelers | B10: FY2025 net written premiums | C10: $B | D10: =SUMIFS('Segment Data'!$D$5:$D$200,'Segment Data'!$A$5:$A$200,A10,'Segment Data'!$B$5:$B$200,B10,'Segment Data'!$F$5:$F$200,"Component")+SUMIFS('Segment Data'!$D$5:$D$200,'Segment Data'!$A$5:$A$200,A10,'Segment Data'!$B$5:$B$200,B10,'Segment Data'!$F$5:$F$200,"Derived component") -> 44.4 | E10: ='Segment Data'!D44 -> 44.4 | F10: =D10-E10 -> 0 | G10: =IF(ABS(F10)<0.005,"OK",IF(COUNTIFS('Segment Data'!$A$5:$A$200,A10,'Segment Data'!$B$5:$B$200,B10,'Segment Data'!$F$5:$F$200,"Reconciling item")>0,"Group items explain gap","CHECK")) -> OK
A11: Allstate | B11: Q4 2025 Property-Liability premiums earned | C11: $B | D11: =SUMIFS('Segment Data'!$D$5:$D$200,'Segment Data'!$A$5:$A$200,A11,'Segment Data'!$B$5:$B$200,B11,'Segment Data'!$F$5:$F$200,"Component")+SUMIFS('Segment Data'!$D$5:$D$200,'Segment Data'!$A$5:$A$200,A11,'Segment Data'!$B$5:$B$200,B11,'Segment Data'!$F$5:$F$200,"Derived component") -> 14.8 | E11: ='Segment Data'!D51 -> 14.8 | F11: =D11-E11 -> 0 | G11: =IF(ABS(F11)<0.005,"OK",IF(COUNTIFS('Segment Data'!$A$5:$A$200,A11,'Segment Data'!$B$5:$B$200,B11,'Segment Data'!$F$5:$F$200,"Reconciling item")>0,"Group items explain gap","CHECK")) -> OK
A12: Lemonade | B12: Q2 2026 revenue | C12: $M | D12: =SUMIFS('Segment Data'!$D$5:$D$200,'Segment Data'!$A$5:$A$200,A12,'Segment Data'!$B$5:$B$200,B12,'Segment Data'!$F$5:$F$200,"Component")+SUMIFS('Segment Data'!$D$5:$D$200,'Segment Data'!$A$5:$A$200,A12,'Segment Data'!$B$5:$B$200,B12,'Segment Data'!$F$5:$F$200,"Derived component") -> 294.4 | E12: ='Segment Data'!D59 -> 294.4 | F12: =D12-E12 -> 0 | G12: =IF(ABS(F12)<0.005,"OK",IF(COUNTIFS('Segment Data'!$A$5:$A$200,A12,'Segment Data'!$B$5:$B$200,B12,'Segment Data'!$F$5:$F$200,"Reconciling item")>0,"Group items explain gap","CHECK")) -> OK
A13: Lemonade | B13: H1 2026 revenue | C13: $M | D13: =SUMIFS('Segment Data'!$D$5:$D$200,'Segment Data'!$A$5:$A$200,A13,'Segment Data'!$B$5:$B$200,B13,'Segment Data'!$F$5:$F$200,"Component")+SUMIFS('Segment Data'!$D$5:$D$200,'Segment Data'!$A$5:$A$200,A13,'Segment Data'!$B$5:$B$200,B13,'Segment Data'!$F$5:$F$200,"Derived component") -> 552.4 | E13: ='Segment Data'!D64 -> 552.4 | F13: =D13-E13 -> 0 | G13: =IF(ABS(F13)<0.005,"OK",IF(COUNTIFS('Segment Data'!$A$5:$A$200,A13,'Segment Data'!$B$5:$B$200,B13,'Segment Data'!$F$5:$F$200,"Reconciling item")>0,"Group items explain gap","CHECK")) -> OK
A14: Ping An | B14: Q1 2025 operating profit attributable to shareholders | C14: RMB M | D14: =SUMIFS('Segment Data'!$D$5:$D$200,'Segment Data'!$A$5:$A$200,A14,'Segment Data'!$B$5:$B$200,B14,'Segment Data'!$F$5:$F$200,"Component")+SUMIFS('Segment Data'!$D$5:$D$200,'Segment Data'!$A$5:$A$200,A14,'Segment Data'!$B$5:$B$200,B14,'Segment Data'!$F$5:$F$200,"Derived component") -> 37907 | E14: ='Segment Data'!D67 -> 37907 | F14: =D14-E14 -> 0 | G14: =IF(ABS(F14)<0.005,"OK",IF(COUNTIFS('Segment Data'!$A$5:$A$200,A14,'Segment Data'!$B$5:$B$200,B14,'Segment Data'!$F$5:$F$200,"Reconciling item")>0,"Group items explain gap","CHECK")) -> OK
A15: AXA | B15: FY2025 gross written premiums & other revenues | C15: EUR M | D15: =SUMIFS('Segment Data'!$D$5:$D$200,'Segment Data'!$A$5:$A$200,A15,'Segment Data'!$B$5:$B$200,B15,'Segment Data'!$F$5:$F$200,"Component")+SUMIFS('Segment Data'!$D$5:$D$200,'Segment Data'!$A$5:$A$200,A15,'Segment Data'!$B$5:$B$200,B15,'Segment Data'!$F$5:$F$200,"Derived component") -> 116000 | E15: ='Segment Data'!D77 -> 116000 | F15: =D15-E15 -> 0 | G15: =IF(ABS(F15)<0.005,"OK",IF(COUNTIFS('Segment Data'!$A$5:$A$200,A15,'Segment Data'!$B$5:$B$200,B15,'Segment Data'!$F$5:$F$200,"Reconciling item")>0,"Group items explain gap","CHECK")) -> OK
A16: Swiss Re | B16: FY2025 segment net income | C16: $M | D16: =SUMIFS('Segment Data'!$D$5:$D$200,'Segment Data'!$A$5:$A$200,A16,'Segment Data'!$B$5:$B$200,B16,'Segment Data'!$F$5:$F$200,"Component")+SUMIFS('Segment Data'!$D$5:$D$200,'Segment Data'!$A$5:$A$200,A16,'Segment Data'!$B$5:$B$200,B16,'Segment Data'!$F$5:$F$200,"Derived component") -> 5088 | E16: ='Segment Data'!D82 -> 4800 | F16: =D16-E16 -> 288 | G16: =IF(ABS(F16)<0.005,"OK",IF(COUNTIFS('Segment Data'!$A$5:$A$200,A16,'Segment Data'!$B$5:$B$200,B16,'Segment Data'!$F$5:$F$200,"Reconciling item")>0,"Group items explain gap","CHECK")) -> Group items explain gap
A17: Munich Re | B17: FY2025 net result | C17: EUR M | D17: =SUMIFS('Segment Data'!$D$5:$D$200,'Segment Data'!$A$5:$A$200,A17,'Segment Data'!$B$5:$B$200,B17,'Segment Data'!$F$5:$F$200,"Component")+SUMIFS('Segment Data'!$D$5:$D$200,'Segment Data'!$A$5:$A$200,A17,'Segment Data'!$B$5:$B$200,B17,'Segment Data'!$F$5:$F$200,"Derived component") -> 6121 | E17: ='Segment Data'!D85 -> 6121 | F17: =D17-E17 -> 0 | G17: =IF(ABS(F17)<0.005,"OK",IF(COUNTIFS('Segment Data'!$A$5:$A$200,A17,'Segment Data'!$B$5:$B$200,B17,'Segment Data'!$F$5:$F$200,"Reconciling item")>0,"Group items explain gap","CHECK")) -> OK
A18: Munich Re | B18: FY2025 insurance revenue | C18: EUR M | D18: =SUMIFS('Segment Data'!$D$5:$D$200,'Segment Data'!$A$5:$A$200,A18,'Segment Data'!$B$5:$B$200,B18,'Segment Data'!$F$5:$F$200,"Component")+SUMIFS('Segment Data'!$D$5:$D$200,'Segment Data'!$A$5:$A$200,A18,'Segment Data'!$B$5:$B$200,B18,'Segment Data'!$F$5:$F$200,"Derived component") -> 60412 | E18: ='Segment Data'!D88 -> 60412 | F18: =D18-E18 -> 0 | G18: =IF(ABS(F18)<0.005,"OK",IF(COUNTIFS('Segment Data'!$A$5:$A$200,A18,'Segment Data'!$B$5:$B$200,B18,'Segment Data'!$F$5:$F$200,"Reconciling item")>0,"Group items explain gap","CHECK")) -> OK
A20: Green = link to another sheet; black = formula.

Sheet Revenue Sources Matrix
A1: Revenue sources matrix
A2: Classification is my judgement from the sources reviewed (Primary = dominant source; Secondary = material but smaller; blank = not material/not evidenced).
A4: Company | B4: Underwriting premiums | C4: Investment income | D4: Fees / service revenue | E4: Ceding & other commissions | F4: Banking income | G4: Asset-management fees | H4: Reinsurance / risk-transfer income | I4: Notes
A5: Progressive | B5: Primary | C5: Secondary | D5: Secondary | I5: Fees and service revenues are not quantified in sources.
A6: Chubb | B6: Primary | C6: Secondary | H6: Secondary | I6: Global Reinsurance segment is ~2% of premium.
A7: AIG | B7: Primary | C7: Secondary | D7: Secondary | I7: Fee income from AIG-managed capital vehicles is inferred, not quantified.
A8: Allianz | B8: Primary | C8: Secondary | G8: Secondary | I8: Asset-management operating revenues EUR 8.5B.
A9: Travelers | B9: Primary | C9: Secondary | I9: Net investment income just under $4B.
A10: Allstate | B10: Primary | C10: Secondary | D10: Secondary | I10: Protection Services (plans, roadside, Arity, identity).
A11: Lemonade | B11: Primary | C11: Secondary | E11: Secondary | I11: Ceding commission ~7% of Q2 2026 revenue.
A12: Ping An | B12: Primary | C12: Primary | D12: Secondary | F12: Primary | G12: Secondary | I12: Banking and insurance funds are very large; health services small.
A13: AXA | B13: Primary | C13: Secondary | D13: Secondary | G13: Secondary | I13: AXA IM disposed July 2025; unit-linked and health fees.
A14: Swiss Re | B14: Primary | C14: Secondary | H14: Primary | I14: Reinsurance is the core business.
A15: Munich Re | B15: Primary | C15: Secondary | H15: Primary | I15: Also primary insurance via ERGO.
A16: Guardian Life | B16: Primary | C16: Secondary | D16: Secondary | I16: Unverified: based on product description and line-item names only.

Sheet Sources & Notes
A1: Sources & notes
A3: Company | B3: Document | C3: URL / reference | D3: Type
A4: Progressive | B4: Form 10-K FY2025 | C4: https://www.sec.gov/Archives/edgar/data/80661/000008066126000086/pgr-20251231_d2.htm | D4: Primary
A5: Progressive | B5: Dec 2025 results release | C5: https://www.nasdaq.com/press-release/progressive-reports-december-2025-results-2026-01-28 | D5: Primary
A6: Progressive | B6: Q4 2025 summary (segment %, investment income) | C6: https://fintool.com/app/research/companies/PGR/earnings/Q4 2025 | D6: Secondary
A7: Chubb | B7: Form 10-K FY2025 (segment table) | C7: https://www.sec.gov/Archives/edgar/data/896159/000089615926000005/cb-20251231.htm | D7: Primary
A8: Chubb | B8: FY2025 results coverage | C8: https://www.reinsurancene.ws/chubb-sees-record-pc-underwriting-income-of-6-53bn-in-2025/ | D8: Secondary
A9: AIG | B9: 2025 Annual Report | C9: https://www.sec.gov/Archives/edgar/data/5272/000000527226000038/aig2025annualreport.pdf | D9: Primary
A10: AIG | B10: Q4/FY2025 results release | C10: https://www.businesswire.com/news/home/20260210634236/en | D10: Primary
A11: AIG | B11: Segment commentary | C11: https://www.carriermanagement.com/news/2026/02/12/284530.htm | D11: Secondary
A12: Allianz | B12: FY2025 results coverage | C12: https://insurtechdigital.com/news/allianz-achieves-record-17-4bn-profit-as-all-units-deliver | D12: Secondary
A13: Allianz | B13: Q4/FY2025 coverage | C13: https://www.reinsurancene.ws/allianzs-q425-operating-profit-rises-3-fy25-hits-record-e17-4bn/ | D13: Secondary
A14: Travelers | B14: Q4/FY2025 release | C14: https://www.businesswire.com/news/home/20260119567832/en/Travelers-Reports-Excellent-Fourth-Quarter-and-Full-Year-Results | D14: Primary
... A25: Guardian Life | B25: Financial highlights page | C25: https://www.guardianlife.com/financial-highlights | D25: Primary (no figures retrieved)
A27: Notes
A28: Percentages marked as derived/approximate in Company Profiles are my own calculations from the reported figures.
A29: A Ping An 2025 'operating revenue' figure in one secondary source looked misprinted (off by a factor of ten) and was not used.
A30: Progressive's two sources give slightly different Q1 2026 combined ratios (86.0 vs 86.4); not used in this workbook.
A31: Figures are as of the sources' publication dates; check for restatements.
