Workbook

Sheet Organisations
A1: Company Name | B1: Role at Event | C1: Sponsorship Tier (if any) | D1: Website | E1: Headquarters Country | F1: City | G1: Regions/Countries of Operation | H1: Business Type | I1: Commodities | J1: Business Size | K1: Listed/Private (ticker if listed) | L1: Brief Description | M1: Source URL | N1: Confidence | O1: Profile Source URL
A2: ABSA Bank | B2: Speaker organisation (1); Advisory Board organisation | C2: N/A | D2: https://www.absa.co.za | E2: South Africa | F2: Johannesburg | G2: N/A | H2: Financier | I2: N/A | J2: Large | K2: Listed (parent Absa Group Ltd, JSE: ABG) | L2: South African bank; its head of mining sits on the AMW advisory board and speaks on value-addition corridors. | M2: https://african-miningweek.com/attend/conference-speakers | N2: Confirmed | O2: https://www.absa.co.za
A3: ACE Geosynthetics | B3: Exhibitor | C3: Showcase Exhibitor | D3: N/A | E3: N/A | F3: N/A | G3: N/A | H3: Equipment/services supplier | I3: N/A | J3: N/A | K3: N/A | L3: Geosynthetics supplier (business type inferred from the company name); no profile detail on the event site. | M3: https://african-miningweek.com/sponsors/ace-geosynthetics | N3: Confirmed | O3: N/A
A4: AFG Bank Mali | B4: Speaker organisation (1) | C4: N/A | D4: N/A | E4: Mali | F4: N/A | G4: N/A | H4: Financier | I4: N/A | J4: N/A | K4: N/A | L4: Malian bank; its Deputy Managing Director speaks on ASGM formalisation. | M4: https://african-miningweek.com/attend/conference-speakers | N4: Confirmed | O4: N/A
A5: Africa Finance Corporation (AFC) | B5: Sponsor (sponsors 'Enabling Africa's Value Addition Corridors' session); Speaker organisation (2) | C5: Silver Sponsor | D5: https://www.africafc.org | E5: Nigeria | F5: Lagos | G5: Pan-Africa | H5: Financier | I5: N/A | J5: Large | K5: Unlisted (multilateral development finance institution) | L5: Pan-African infrastructure and project-finance institution; delegation focuses on mining finance and beneficiation. | M5: https://african-miningweek.com/sponsors/africaa-finance-corporation | https://african-miningweek.com/attend/conference-speakers | N5: Confirmed | O5: https://www.africafc.org
A6: Africa Minerals Strategy Group (AMSG) | B6: Partner; Host of closed-door Natural Resources Leaders Roundtable (15 Oct); Speaker organisation (2); Advisory Board organisation | C6: Partner | D6: N/A | E6: N/A | F6: N/A | G6: N/A | H6: Policy/intergovernmental body | I6: N/A | J6: N/A | K6: N/A | L6: Pan-African minerals strategy body and formal AMW 2026 partner; its Secretary General gives a keynote. | M6: https://african-miningweek.com/sponsors/africa-minerals-strategy-group | https://african-miningweek.com/attend/conference-speakers | N6: Confirmed | O6: N/A
A7: Africa50 | B7: Speaker organisation (1) | C7: N/A | D7: https://www.africa50.com | E7: Morocco | F7: Casablanca | G7: Pan-Africa | H7: Financier | I7: N/A | J7: N/A | K7: Unlisted (multilateral-backed) | L7: Pan-African infrastructure investment platform; its investment director speaks at the opening dialogue. | M7: https://african-miningweek.com/attend/conference-speakers | N7: Confirmed | O7: https://www.africa50.com
A8: Apeiron Investment Group | B8: Speaker organisation (1) | C8: N/A | D8: N/A | E8: N/A | F8: N/A | G8: N/A | H8: Financier | I8: N/A | J8: N/A | K8: N/A | L8: Investment group; its head of natural resources is listed as a speaker. | M8: https://african-miningweek.com/attend/conference-speakers | N8: Confirmed | O8: N/A
A9: Argentine Embassy in South Africa | B9: Speaker organisation (1) | C9: N/A | D9: N/A | E9: Argentina | F9: N/A | G9: South Africa (host country) | H9: Government agency | I9: N/A | J9: N/A | K9: N/A (diplomatic mission) | L9: Diplomatic mission; its Head of Mission speaks at the opening dialogue. | M9: https://african-miningweek.com/news/us-argentine-representatives-join-amw-2026-mineral-diplomacy-reshapes-supply-chains | https://african-miningweek.com/attend/conference-speakers | N9: Confirmed | O9: N/A
A10: ASAFO & CO. (U.S.) LLP | B10: Speaker organisation (1) | C10: N/A | D10: N/A | E10: N/A | F10: N/A | G10: N/A | H10: Professional services (legal/audit) | I10: N/A | J10: N/A | K10: N/A | L10: Firm (LLP) whose managing partner is listed as a speaker; no further profile on the event site. | M10: https://african-miningweek.com/attend/conference-speakers | N10: Confirmed | O10: N/A
A11: Buenassa | B11: Speaker organisation (1) | C11: N/A | D11: N/A | E11: Democratic Republic of the Congo | F11: N/A | G11: Democratic Republic of the Congo | H11: Refiner/processor | I11: Copper; Cobalt | J11: N/A | K11: N/A | L11: Company behind a copper-cobalt refinery project supporting DRC mineral beneficiation (per press-release headline). | M11: https://african-miningweek.com/news/drc-mineral-beneficiation-buenassa-highlights-need-smart-capital-strategic-partnerships | https://african-miningweek.com/attend/conference-speakers | N11: Confirmed | O11: N/A
A12: Chamber of Mines of Mali | B12: Partner; Showcase Exhibitor; Speaker organisation (1) | C12: Partner; Showcase Exhibitor | D12: N/A | E12: Mali | F12: N/A | G12: N/A | H12: Industry association | I12: N/A | J12: N/A | K12: N/A | L12: Mali's mining industry chamber; its President speaks on the Africa Gold Forum panel. | M12: https://african-miningweek.com/sponsors/chamber-mines-mali | https://african-miningweek.com/attend/conference-speakers | N12: Confirmed | O12: N/A
... A97: Valterra Platinum | B97: Global stakeholder (logo) | C97: N/A | D97: https://www.valterraplatinum.com | E97: South Africa | F97: Johannesburg | G97: South Africa; Zimbabwe | H97: Miner/producer | I97: PGMs | J97: Large | K97: Listed (JSE; ticker not verified) | L97: Platinum-group-metals miner (formerly Anglo American Platinum); shown among AMW 2026 'global stakeholders'. | M97: https://african-miningweek.com/sponsors/valt | N97: Likely | O97: https://www.valterraplatinum.com

Sheet People
A1: Full Name | B1: Job Title | C1: Organisation | D1: Role at Event | E1: Session/Panel Topic | F1: Country | G1: LinkedIn or public profile URL | H1: Source URL
A2: Daouda Diakite | B2: Minister's Senior Adviser | C2: Ministry of Mines and Geology, Guinea | D2: Keynote Speaker | E2: Keynote Address, 13:15 (14 Oct) | F2: Guinea | G2: https://african-miningweek.com/speakers/daouda-diakite | H2: https://african-miningweek.com/attend/conference-speakers | https://african-miningweek.com/attend/conference-program
A3: Hon. Losuba Ludoru Wongo | B3: Minister of Mining | C3: Ministry of Mining, South Sudan | D3: Keynote Speaker | E3: Ministerial Panel: Strategic Minerals: Developing a Value Chain that Works for Africa (14 Oct) | F3: South Sudan | G3: https://african-miningweek.com/speakers/hon-losuba-ludoru-wongo-wongo | H3: https://african-miningweek.com/attend/conference-speakers | https://african-miningweek.com/attend/conference-program
A4: H.E. Louis Watum Kabamba | B4: Minister of Mines | C4: Ministry of Mines, Democratic Republic of the Congo | D4: Keynote Speaker | E4: Opening Ceremony: keynote addresses (14 Oct) | Ministerial Panel: Strategic Minerals: Developing a Value Chain that Works for Africa (14 Oct) | F4: Democratic Republic of the Congo | G4: https://african-miningweek.com/speakers/louis-watum-kabamba | H4: https://african-miningweek.com/attend/conference-speakers | https://african-miningweek.com/attend/conference-program
A5: H.E. Moses Engadu | B5: Secretary General | C5: Africa Minerals Strategy Group (AMSG) | D5: Keynote Speaker | E5: Opening Ceremony: keynote addresses (14 Oct) | F5: N/A | G5: https://african-miningweek.com/speakers/moses-engadu | H5: https://african-miningweek.com/attend/conference-speakers | https://african-miningweek.com/attend/conference-program
A6: Hon. Dr. Polite Kambamura | B6: Minister of Mines and Mining Development | C6: Ministry of Mines and Mining Development, Zimbabwe | D6: Keynote Speaker | E6: Ministerial Panel: Strategic Minerals: Developing a Value Chain that Works for Africa (14 Oct) | F6: Zimbabwe | G6: https://african-miningweek.com/speakers/hon-dr-polite-kambamura | H6: https://african-miningweek.com/attend/conference-speakers | https://african-miningweek.com/attend/conference-program
A7: Hon. R. Matenokay Tingban | B7: Minister of Mines and Energy | C7: Ministry of Mines and Energy, Liberia | D7: Keynote Speaker | E7: Ministerial Panel: Strategic Minerals: Developing a Value Chain that Works for Africa (14 Oct) | F7: Liberia | G7: https://african-miningweek.com/speakers/hon-matenokay-tingban | H7: https://african-miningweek.com/attend/conference-speakers | https://african-miningweek.com/attend/conference-program
A8: Hon. Rufin Benam-Beltoungou | B8: Minister of Mines and Geology | C8: Ministry of Mines and Geology, Central African Republic | D8: Keynote Speaker | E8: Ministerial Panel: Strategic Minerals: Developing a Value Chain that Works for Africa (14 Oct) | F8: Central African Republic | G8: https://african-miningweek.com/speakers/rufin-benam-beltoungou | H8: https://african-miningweek.com/attend/conference-speakers | https://african-miningweek.com/attend/conference-program
A9: Yasser Ramadan | B9: Chairman | C9: Egyptian Mineral Resources and Mining Industries Authority (MRMIA) | D9: Keynote Speaker; Advisory Board Member (per press release) | E9: Keynote Address, 14:10 (14 Oct) | F9: Egypt | G9: https://african-miningweek.com/speakers/yasser-ramadan | H9: https://african-miningweek.com/attend/conference-speakers | https://african-miningweek.com/attend/conference-program
A10: Dr. Abdoul Karim Kabèlè-Camara | B10: Vice President in charge of Government and External Affairs, West Africa | C10: Fortuna Mining Corporation | D10: Speaker | E10: N/A (not yet assigned to a session in the published programme) | F10: Canada | G10: N/A | H10: https://african-miningweek.com/
A11: Abel Manumbu | B11: Founder and Managing Director | C11: UR Energy Limited (UR Xenergi Limited Tanzania) | D11: Speaker | E11: Enabling Africa's Value Addition Corridors (14 Oct) | F11: Tanzania | G11: https://african-miningweek.com/speakers/abel-manumbu | H11: https://african-miningweek.com/attend/conference-speakers | https://african-miningweek.com/attend/conference-program
A12: Ahmed Bello-Maccido | B12: Associate, Metals & Mining | C12: Africa Finance Corporation (AFC) | D12: Speaker | E12: Regional Connectivity: Financing Africa's Mineral Infrastructure (14 Oct) | F12: Nigeria | G12: https://african-miningweek.com/speakers/ahmed-bello-maccido | H12: https://african-miningweek.com/attend/conference-speakers | https://african-miningweek.com/attend/conference-program
... A77: William Mason | B77: Associate Director, Mining Economics & Emissions | C77: S&P Global Energy | D77: Speaker | E77: Bucking the Trend: Africa's Decade-High Exploration Surge and the Rising Cost of Production (Technical Track, 15 Oct) | Leveraging Advanced Technologies & AI to Transform Mining Practices for Sustainable Growth (15 Oct) | F77: United States | G77: https://african-miningweek.com/speakers/william-mason | H77: https://african-miningweek.com/attend/conference-speakers | https://african-miningweek.com/attend/conference-program

Sheet Summary
A1: African Mining Week 2026: Participants Workbook Summary
A3: Event | B3: African Mining Week 2026 (organiser: Energy Capital & Power)
A4: Dates / venue | B4: 14–16 October 2026, Cape Town International Convention Centre, Cape Town, South Africa
A5: Date data collected | B5: 20 September 2026 (lists are still changing; organiser was announcing speakers on 15 September)
A6: Primary source | B6: Official event website: african-miningweek.com (partners/exhibitors, speakers, programme, media partners, homepage, press releases)
A8: Totals
A9: Organisations (de-duplicated) | B9: =COUNTA(Organisations!$A$2:$A$97) -> 96
A10: People | B10: =COUNTA(People!$A$2:$A$77) -> 76
A11: Organisations rated Confirmed | B11: =COUNTIF(Organisations!$N$2:$N$97,"Confirmed") -> 70
A12: Organisations rated Likely | B12: =COUNTIF(Organisations!$N$2:$N$97,"Likely") -> 26
A13: Organisations rated Unverified | B13: =COUNTIF(Organisations!$N$2:$N$97,"Unverified") -> 0
A15: Organisations by business type
A16: Business type | B16: Organisations
A17: Energy/power | B17: =COUNTIF(Organisations!$H$2:$H$97,A17) -> 2
A18: Engineering/consulting | B18: =COUNTIF(Organisations!$H$2:$H$97,A18) -> 4
A19: Equipment/services supplier | B19: =COUNTIF(Organisations!$H$2:$H$97,A19) -> 2
A20: Financier | B20: =COUNTIF(Organisations!$H$2:$H$97,A20) -> 12
A21: Government agency | B21: =COUNTIF(Organisations!$H$2:$H$97,A21) -> 17
A22: Industry association | B22: =COUNTIF(Organisations!$H$2:$H$97,A22) -> 8
A23: Logistics/transport | B23: =COUNTIF(Organisations!$H$2:$H$97,A23) -> 2
A24: Media/communications | B24: =COUNTIF(Organisations!$H$2:$H$97,A24) -> 10
A25: Mine developer/explorer | B25: =COUNTIF(Organisations!$H$2:$H$97,A25) -> 2
A26: Miner/producer | B26: =COUNTIF(Organisations!$H$2:$H$97,A26) -> 4
A27: Policy/intergovernmental body | B27: =COUNTIF(Organisations!$H$2:$H$97,A27) -> 2
A28: Professional services (legal/audit) | B28: =COUNTIF(Organisations!$H$2:$H$97,A28) -> 7
... A32: N/A | B32: =COUNTIF(Organisations!$H$2:$H$97,A32) -> 16
A34: Total (check) | B34: =SUM(B17:B32) -> 96
A36: Organisations by headquarters country (as far as identifiable)
A37: Headquarters country | B37: Organisations
A38: Angola | B38: =COUNTIF(Organisations!$E$2:$E$97,A38) -> 1
A39: Argentina | B39: =COUNTIF(Organisations!$E$2:$E$97,A39) -> 1
A40: Belgium | B40: =COUNTIF(Organisations!$E$2:$E$97,A40) -> 1
A41: Botswana | B41: =COUNTIF(Organisations!$E$2:$E$97,A41) -> 1
A42: Canada | B42: =COUNTIF(Organisations!$E$2:$E$97,A42) -> 2
A43: Central African Republic | B43: =COUNTIF(Organisations!$E$2:$E$97,A43) -> 1
A44: Chad | B44: =COUNTIF(Organisations!$E$2:$E$97,A44) -> 1
A45: Democratic Republic of the Congo | B45: =COUNTIF(Organisations!$E$2:$E$97,A45) -> 2
A46: Egypt | B46: =COUNTIF(Organisations!$E$2:$E$97,A46) -> 1
A47: Ethiopia | B47: =COUNTIF(Organisations!$E$2:$E$97,A47) -> 1
A48: Ghana | B48: =COUNTIF(Organisations!$E$2:$E$97,A48) -> 1
...
