Workbook

Sheet Summary
A1: African Insurers: Products, Technology, Revenue Contributions & Financial Engineering
A2: Prepared 7 Oct 2026 from company results, trade press and regulator/industry sources. See 'Sources & Notes'.
A4: Sheet | B4: What it contains
A5: Company Profiles | B5: One row per insurer/group: products, channels, revenue sources, revenue contribution headline, technology and partnerships, caveats.
A6: Segment Data | B6: Reported segment and market figures in native currency/units with % shares by formula. Blue = sourced input; black = formula; yellow fill = derived by subtraction.
A7: Reconciliation | B7: Formula check that components sum to each reported total.
A8: Revenue Sources Matrix | B8: Primary/secondary revenue sources for each company (my classification from the sources).
A9: Vendor & Partnerships | B9: Named technology vendors, insurtechs, telcos, fintechs and joint-venture partners.
A10: Financial Engineering | B10: Capital, reinsurance, M&A and risk-transfer structures.
A11: Sources & Notes | B11: Links and caveats.
A14: Important caveats
A15: 1. Companies report on different bases (net result from financial services, results from operations, normalised headline earnings, gross written premium). Shares are meaningful only within a company and basis.
A16: 2. Africa-specific: most insurers outside South Africa disclose far less segment detail. Several Nigeria/Kenya/Ghana figures are partial, mixed-basis or from trade press.
A17: 3. Ghana market-share data (2018-2021) is dated; Hollard Ghana partnership details are from 2021-2022 announcements.
A18: 4. No announced partnerships between African insurers and frontier-AI labs (Anthropic, OpenAI) or Palantir were found; named technology partners are listed in 'Vendor & Partnerships'.
A19: 5. Some figures come from secondary sources (flagged in the Source column), including a Kenya microinsurance premium figure from a LinkedIn post.
A20: 6. Not researched in depth: Liberty, Hollard South Africa, AVBOB, Egyptian groups (Misr, Allianz Egypt), Leadway financials, Ghana's Enterprise Group and SIC (current figures).
A21: 7. Currency units: R = South African rand; NGN = Nigerian naira; MAD = Moroccan dirham; KSh = Kenyan shilling; USD thousands for Atlas market rankings.

Sheet Company Profiles
A1: Company profiles
A2: Revenue contribution is the latest full year available (shown in each row); see Segment Data for numbers and shares.
A4: Company | B4: Country / type | C4: Products | D4: Services / channels | E4: Revenue sources | F4: Revenue contribution (headline) | G4: Technology / partnerships | H4: Caveats
A5: Sanlam | B5: South Africa; pan-African and India financial services group | C5: Life and health insurance, general insurance (Santam, SanlamAllianz), investment management, credit and structuring. | D5: Agents and branches (Assupol integration), brokers, banking/rewards ecosystem planned in SA; present in 25 African countries. | E5: Insurance margins, asset-based fees, credit income (India), net investment return on capital. | F5: FY2025 net result from financial services R15.9B: life & health R9.26B (~58%), general insurance R3.58B (~22%), credit & structuring R2.27B (~14%), investment management R1.51B (~10%), corporate costs -R0.67B. | G5: Technology and AI named as a Vision 2030 enabler; client-system modernisation; GoTyme Bank for digital ecosystem; SanlamAllianz JV (Allianz 49%). | H5: Group-level only; no stated AI savings figures.
A6: Old Mutual | B6: South Africa; life, short-term, asset management, banking | C6: Life and savings (Mass & Foundation, Personal Finance, Wealth, Corporate), Old Mutual Insure, Old Mutual Investments, Africa Regions, OM Bank, Old Mutual Finance. | D6: Advisers, branch network (46% of OM Bank customers came via branches), brokers. | E6: Underwriting and fee income; asset-management fees; shareholder investment returns; lending margin. | F6: FY2025 results from operations R9.8B; Insure ~R2.06B (~21%), Africa Regions ~R1.7B (~17%), asset management ~R1.54B (~16%). | G6: Expanding AI and data analytics in underwriting/claims; OM Bank launched Aug 2025 (~284,000 customers); R2.5B cost programme. | H6: Segment figures are approximate (trade press). OM Bank carrying value cut by R3B.
A7: Discovery | B7: South Africa; health, life, motor, bank, wellness | C7: Discovery Health (medical scheme administration), Discovery Life, Discovery Insure, Discovery Bank, Vitality. | D7: Vitality rewards ecosystem; digital channels; Global Vitality Network licensing. | E7: Underwriting/administration margins, bank income, Vitality network earnings. | F7: FY to Jun 2026 normalised operating profit R17.75B: Discovery SA ~R13.87B (~78%), Vitality R3.88B (~22%). Bank first full-year profit R370M. | G7: Behavioural-incentive model exported to AIA, Ping An, Sumitomo, John Hancock, Manulife and Vitality UK; EasyEquities partnership. | H7: Per-unit FY2026 profit split not retrieved (only growth rates).
A8: Momentum | B8: South Africa; life, investments, short-term, health, specialty | C8: Momentum Retail, Momentum Investments, Metropolitan Life, Momentum Corporate, Momentum Insure, Momentum Health, Guardrisk, India health JV, Africa. | D8: Advisers, brokers, corporate and retail channels. | E8: Life margins, annuity profits, fees, underwriting, risk-transfer (Guardrisk). | F8: FY to Jun 2026 normalised headline earnings R7.06B: Investments R1.19B, Guardrisk R1.04B, Retail R1.01B, Insure R0.47B, Health R0.37B, India R0.02B. Insurance revenue R61.4B. | G8: Systems migration across Retail, Metropolitan and Africa (saves >R100M a year); Metropolitan turnaround using digital transformation. | H8: Remaining ~R2.96B is other units (Metropolitan, Corporate, Africa) net of costs - derived.
A9: Santam | B9: South Africa; Africa's largest general insurer (Sanlam subsidiary) | C9: Personal and commercial insurance via Broker, Client and Partner Solutions; MiWay (direct); Specialist Solutions; Santam Re; alternative risk transfer; Lloyd's Syndicate 1918. | D9: Brokers, partners (e.g. MultiChoice book), direct, Lloyd's. | E9: Premiums, investment return on insurance funds (~3% of NEP), ART investment margin. | F9: FY2025 GWP R43.96B; NEP R36.92B; net insurance result R5.26B; combined ratio 88.7%; SA = 81% of GWP. | G9: Live on Guidewire cloud platform (Jun 2026) with AI roadmap; Santam Syndicate 1918 launched Jan 2026. | H9: Weather volatility; 2025 margin above 5-10% target range.
A10: OUTsurance | B10: South Africa; multinational P&C and life (Australia, Ireland) | C10: Personal and business P&C (SA), Youi (Australia), OUTsurance Ireland, OUTsurance Life. | D10: Direct and digital; growing broker channel; call centres. | E10: Premiums; investment income; life earnings. | F10: FY to Jun 2026 insurance revenue R41.49B: Youi R25.24B (~61%), South Africa R14.36B (~35%), Ireland R0.52B (~1%). Profit R6.18B. | G10: Proprietary systems and AI-driven efficiency; CEO says human touch still preferred for complex claims. | H10: Ireland remains loss-making (operating loss R489M).
A11: AIICO Insurance | B11: Nigeria; composite | C11: Life and general insurance. | D11: Agents, brokers, corporate. | E11: Premiums and investment income. | F11: 2025 revenue N98.3B (up from N76.1B); total assets N440.2B. | G11: Not retrieved. | H11: Revenue basis may differ from peers' gross premium.
A12: AXA Mansard | B12: Nigeria; composite (AXA brand) | C12: Life and general insurance, health. | D12: Digital-first distribution, brokers. | E12: Premiums and investment income. | F12: 2025 revenue N71.8B; profit after tax fell 78.9% to N5.46B; H1 2026 PAT N7.8B (+14%). | G12: Uses Curacel AI claims platform; digital transformation named as growth driver. | H12: Profit volatility in 2025.
A13: NEM Insurance | B13: Nigeria; non-life | C13: General insurance. | D13: Brokers and direct. | E13: Premiums. | F13: 2025 gross premium income N96.4B (from N69.5B). | G13: Not retrieved. | H13: Gross premium, not revenue.
A14: Cornerstone Insurance | B14: Nigeria; composite | C14: General and life insurance. | D14: Retail base; microinsurance and digital distribution potential. | E14: Premiums. | F14: 2025 revenue N29.9B (from N20.6B); PAT N7.1B (from N15.7B). | G14: Not retrieved. | H14: Profit down sharply.
A15: Leadway Assurance | B15: Nigeria; largest composite by gross premium (per comparison site) | C15: Life and general insurance. | D15: Leadway Direct digital platform (quotes, policy management, claims tracking). | E15: Premiums. | F15: Not retrieved. | G15: Leadway Direct. | H15: Ranking claim is from a comparison site; verify.
... A22: African Risk Capacity (ARC Ltd) | B22: Pan-African mutual; sovereign parametric | C22: Sovereign drought, cyclone and flood insurance; inclusive insurance cells; Retakaful cell. | D22: Governments, WFP, development partners. | E22: Premiums (largely donor-supported); investment income. | F22: 2025 GWP USD 48.6M (+26%); profit USD 13.5M; gross claims paid USD 21.4M. | G22: JBA Risk Management (flood model); Gallagher Re (WFP parametric reinsurance); AfDB ADRiFi premium support. | H22: Not a commercial insurer; sovereign and humanitarian focus.

Sheet Segment Data
A1: Segment and market data (native currency and units)
A2: Blue = sourced input; black = formula; yellow = derived by subtraction. % share computed within each Company + Basis over Component and Derived rows.
A4: Company | B4: Basis | C4: Segment / line item | D4: Value | E4: Unit | F4: Row type | G4: % of basis total | H4: Source / notes
A5: Sanlam | B5: FY2025 net result from financial services | C5: Life insurance and health | D5: 9257 | E5: R M | F5: Component | G5: =IF(OR(F5="Component",F5="Derived component"),D5/(SUMIFS($D$5:$D$300,$A$5:$A$300,A5,$B$5:$B$300,B5,$F$5:$F$300,"Component")+SUMIFS($D$5:$D$300,$A$5:$A$300,A5,$B$5:$B$300,B5,$F$5:$F$300,"Derived component")),"") -> 0.58077671 | H5: Sanlam FY2025 annual results presentation (12 Mar 2026)
A6: Sanlam | B6: FY2025 net result from financial services | C6: General insurance | D6: 3577 | E6: R M | F6: Component | G6: =IF(OR(F6="Component",F6="Derived component"),D6/(SUMIFS($D$5:$D$300,$A$5:$A$300,A6,$B$5:$B$300,B6,$F$5:$F$300,"Component")+SUMIFS($D$5:$D$300,$A$5:$A$300,A6,$B$5:$B$300,B6,$F$5:$F$300,"Derived component")),"") -> 0.22441809 | H6: Sanlam FY2025 annual results presentation (12 Mar 2026)
A7: Sanlam | B7: FY2025 net result from financial services | C7: Investment management | D7: 1508 | E7: R M | F7: Component | G7: =IF(OR(F7="Component",F7="Derived component"),D7/(SUMIFS($D$5:$D$300,$A$5:$A$300,A7,$B$5:$B$300,B7,$F$5:$F$300,"Component")+SUMIFS($D$5:$D$300,$A$5:$A$300,A7,$B$5:$B$300,B7,$F$5:$F$300,"Derived component")),"") -> 0.094610703 | H7: Sanlam FY2025 annual results presentation (12 Mar 2026)
A8: Sanlam | B8: FY2025 net result from financial services | C8: Credit and structuring | D8: 2266 | E8: R M | F8: Component | G8: =IF(OR(F8="Component",F8="Derived component"),D8/(SUMIFS($D$5:$D$300,$A$5:$A$300,A8,$B$5:$B$300,B8,$F$5:$F$300,"Component")+SUMIFS($D$5:$D$300,$A$5:$A$300,A8,$B$5:$B$300,B8,$F$5:$F$300,"Derived component")),"") -> 0.14216701 | H8: Sanlam FY2025 annual results presentation (12 Mar 2026)
A9: Sanlam | B9: FY2025 net result from financial services | C9: Corporate expenses and other | D9: -669 | E9: R M | F9: Component | G9: =IF(OR(F9="Component",F9="Derived component"),D9/(SUMIFS($D$5:$D$300,$A$5:$A$300,A9,$B$5:$B$300,B9,$F$5:$F$300,"Component")+SUMIFS($D$5:$D$300,$A$5:$A$300,A9,$B$5:$B$300,B9,$F$5:$F$300,"Derived component")),"") -> -0.04197252 | H9: Sanlam FY2025 annual results presentation (12 Mar 2026)
A10: Sanlam | B10: FY2025 net result from financial services | C10: Net result from financial services (NRFFS) | D10: 15939 | E10: R M | F10: Reported total | G10: =IF(OR(F10="Component",F10="Derived component"),D10/(SUMIFS($D$5:$D$300,$A$5:$A$300,A10,$B$5:$B$300,B10,$F$5:$F$300,"Component")+SUMIFS($D$5:$D$300,$A$5:$A$300,A10,$B$5:$B$300,B10,$F$5:$F$300,"Derived component")),"") | H10: Sanlam FY2025 annual results presentation (12 Mar 2026)
A11: Sanlam | B11: FY2025 selected lines | C11: Net operational earnings | D11: 17154 | E11: R M | F11: Selected | G11: =IF(OR(F11="Component",F11="Derived component"),D11/(SUMIFS($D$5:$D$300,$A$5:$A$300,A11,$B$5:$B$300,B11,$F$5:$F$300,"Component")+SUMIFS($D$5:$D$300,$A$5:$A$300,A11,$B$5:$B$300,B11,$F$5:$F$300,"Derived component")),"") | H11: Sanlam FY2025 annual results presentation (12 Mar 2026)
A12: Sanlam | B12: FY2025 selected lines | C12: Net investment return | D12: 1962 | E12: R M | F12: Selected | G12: =IF(OR(F12="Component",F12="Derived component"),D12/(SUMIFS($D$5:$D$300,$A$5:$A$300,A12,$B$5:$B$300,B12,$F$5:$F$300,"Component")+SUMIFS($D$5:$D$300,$A$5:$A$300,A12,$B$5:$B$300,B12,$F$5:$F$300,"Derived component")),"") | H12: Sanlam FY2025 annual results presentation (12 Mar 2026)
A13: Sanlam | B13: FY2025 selected lines | C13: Group equity value | D13: 185559 | E13: R M | F13: Selected | G13: =IF(OR(F13="Component",F13="Derived component"),D13/(SUMIFS($D$5:$D$300,$A$5:$A$300,A13,$B$5:$B$300,B13,$F$5:$F$300,"Component")+SUMIFS($D$5:$D$300,$A$5:$A$300,A13,$B$5:$B$300,B13,$F$5:$F$300,"Derived component")),"") | H13: Sanlam FY2025 results
A14: Sanlam | B14: FY2025 selected lines | C14: New business volumes (R billion) | D14: 496 | E14: R M | F14: Selected | G14: =IF(OR(F14="Component",F14="Derived component"),D14/(SUMIFS($D$5:$D$300,$A$5:$A$300,A14,$B$5:$B$300,B14,$F$5:$F$300,"Component")+SUMIFS($D$5:$D$300,$A$5:$A$300,A14,$B$5:$B$300,B14,$F$5:$F$300,"Derived component")),"") | H14: Unit is R billion for this row
A15: Sanlam | B15: FY2025 selected lines | C15: Net client cash flows (R billion) | D15: 127 | E15: R M | F15: Selected | G15: =IF(OR(F15="Component",F15="Derived component"),D15/(SUMIFS($D$5:$D$300,$A$5:$A$300,A15,$B$5:$B$300,B15,$F$5:$F$300,"Component")+SUMIFS($D$5:$D$300,$A$5:$A$300,A15,$B$5:$B$300,B15,$F$5:$F$300,"Derived component")),"") | H15: Unit is R billion for this row
A16: Sanlam | B16: FY2025 selected lines | C16: Capital released by ALM change (approx.) | D16: 650 | E16: R M | F16: Selected | G16: =IF(OR(F16="Component",F16="Derived component"),D16/(SUMIFS($D$5:$D$300,$A$5:$A$300,A16,$B$5:$B$300,B16,$F$5:$F$300,"Component")+SUMIFS($D$5:$D$300,$A$5:$A$300,A16,$B$5:$B$300,B16,$F$5:$F$300,"Derived component")),"") | H16: Margin-backing assets moved from fixed to floating rates
... A19: Old Mutual | B19: FY2025 results from operations | C19: Old Mutual Investments (asset management) | D19: 1544 | E19: R M | F19: Component | G19: =IF(OR(F19="Component",F19="Derived component"),D19/(SUMIFS($D$5:$D$300,$A$5:$A$300,A19,$B$5:$B$300,B19,$F$5:$F$300,"Component")+SUMIFS($D$5:$D$300,$A$5:$A$300,A19,$B$5:$B$300,B19,$F$5:$F$300,"Derived component")),"") -> 0.15721413 | H19: Old Mutual FY2025 results (17 Mar 2026); Moonstone summary (approximate segment figures)
A20: Old Mutual | B20: FY2025 results from operations | C20: Life & Savings, banking, corporate and other (derived) | D20: =D21-D17-D18-D19 -> 4517 | E20: R M | F20: Derived component | G20: =IF(OR(F20="Component",F20="Derived component"),D20/(SUMIFS($D$5:$D$300,$A$5:$A$300,A20,$B$5:$B$300,B20,$F$5:$F$300,"Component")+SUMIFS($D$5:$D$300,$A$5:$A$300,A20,$B$5:$B$300,B20,$F$5:$F$300,"Derived component")),"") -> 0.4599328 | H20: Derived by subtraction
A21: Old Mutual | B21: FY2025 results from operations | C21: Group results from operations | D21: 9821 | E21: R M | F21: Reported total | G21: =IF(OR(F21="Component",F21="Derived component"),D21/(SUMIFS($D$5:$D$300,$A$5:$A$300,A21,$B$5:$B$300,B21,$F$5:$F$300,"Component")+SUMIFS($D$5:$D$300,$A$5:$A$300,A21,$B$5:$B$300,B21,$F$5:$F$300,"Derived component")),"") | H21: Old Mutual FY2025 SENS
A22: Old Mutual | B22: FY2025 selected lines | C22: Adjusted headline earnings | D22: 8263 | E22: R M | F22: Selected | G22: =IF(OR(F22="Component",F22="Derived component"),D22/(SUMIFS($D$5:$D$300,$A$5:$A$300,A22,$B$5:$B$300,B22,$F$5:$F$300,"Component")+SUMIFS($D$5:$D$300,$A$5:$A$300,A22,$B$5:$B$300,B22,$F$5:$F$300,"Derived component")),"") | H22: Old Mutual FY2025 results (17 Mar 2026); Moonstone summary (approximate segment figures)
A23: Old Mutual | B23: FY2025 selected lines | C23: Old Mutual Insure gross written premium (R million) | D23: 23400 | E23: R M | F23: Selected | G23: =IF(OR(F23="Component",F23="Derived component"),D23/(SUMIFS($D$5:$D$300,$A$5:$A$300,A23,$B$5:$B$300,B23,$F$5:$F$300,"Component")+SUMIFS($D$5:$D$300,$A$5:$A$300,A23,$B$5:$B$300,B23,$F$5:$F$300,"Derived component")),"") | H23: Old Mutual FY2025 results (17 Mar 2026); Moonstone summary (approximate segment figures)
A24: Old Mutual | B24: FY2025 selected lines | C24: Life APE sales (R million) | D24: 12300 | E24: R M | F24: Selected | G24: =IF(OR(F24="Component",F24="Derived component"),D24/(SUMIFS($D$5:$D$300,$A$5:$A$300,A24,$B$5:$B$300,B24,$F$5:$F$300,"Component")+SUMIFS($D$5:$D$300,$A$5:$A$300,A24,$B$5:$B$300,B24,$F$5:$F$300,"Derived component")),"") | H24: Old Mutual FY2025 results (17 Mar 2026); Moonstone summary (approximate segment figures)
A25: Old Mutual | B25: FY2025 selected lines | C25: Life and Savings funds under management (R million) | D25: 1100000 | E25: R M | F25: Selected | G25: =IF(OR(F25="Component",F25="Derived component"),D25/(SUMIFS($D$5:$D$300,$A$5:$A$300,A25,$B$5:$B$300,B25,$F$5:$F$300,"Component")+SUMIFS($D$5:$D$300,$A$5:$A$300,A25,$B$5:$B$300,B25,$F$5:$F$300,"Derived component")),"") | H25: About R1.1 trillion
A26: Old Mutual | B26: FY2025 selected lines | C26: OM Bank impairment | D26: 3000 | E26: R M | F26: Selected | G26: =IF(OR(F26="Component",F26="Derived component"),D26/(SUMIFS($D$5:$D$300,$A$5:$A$300,A26,$B$5:$B$300,B26,$F$5:$F$300,"Component")+SUMIFS($D$5:$D$300,$A$5:$A$300,A26,$B$5:$B$300,B26,$F$5:$F$300,"Derived component")),"") | H26: Carrying value cut from R6B to R3B
A27: Old Mutual | B27: FY2025 selected lines | C27: Targeted cost savings by 2027 | D27: 2500 | E27: R M | F27: Selected | G27: =IF(OR(F27="Component",F27="Derived component"),D27/(SUMIFS($D$5:$D$300,$A$5:$A$300,A27,$B$5:$B$300,B27,$F$5:$F$300,"Component")+SUMIFS($D$5:$D$300,$A$5:$A$300,A27,$B$5:$B$300,B27,$F$5:$F$300,"Derived component")),"") | H27: R450M achieved in 2025
A28: Discovery | B28: FY to Jun 2026 normalised profit from operations | C28: Discovery South Africa (derived) | D28: =D30-D29 -> 13868 | E28: R M | F28: Derived component | G28: =IF(OR(F28="Component",F28="Derived component"),D28/(SUMIFS($D$5:$D$300,$A$5:$A$300,A28,$B$5:$B$300,B28,$F$5:$F$300,"Component")+SUMIFS($D$5:$D$300,$A$5:$A$300,A28,$B$5:$B$300,B28,$F$5:$F$300,"Derived component")),"") -> 0.78129577 | H28: Reported as ~R13.87B; derived from total less Vitality
A29: Discovery | B29: FY to Jun 2026 normalised profit from operations | C29: Vitality | D29: 3882 | E29: R M | F29: Component | G29: =IF(OR(F29="Component",F29="Derived component"),D29/(SUMIFS($D$5:$D$300,$A$5:$A$300,A29,$B$5:$B$300,B29,$F$5:$F$300,"Component")+SUMIFS($D$5:$D$300,$A$5:$A$300,A29,$B$5:$B$300,B29,$F$5:$F$300,"Derived component")),"") -> 0.21870423 | H29: Discovery FY2026 results release (3 Sep 2026); EasyEquities blog summary
A30: Discovery | B30: FY to Jun 2026 normalised profit from operations | C30: Normalised profit from operations | D30: 17750 | E30: R M | F30: Reported total | G30: =IF(OR(F30="Component",F30="Derived component"),D30/(SUMIFS($D$5:$D$300,$A$5:$A$300,A30,$B$5:$B$300,B30,$F$5:$F$300,"Component")+SUMIFS($D$5:$D$300,$A$5:$A$300,A30,$B$5:$B$300,B30,$F$5:$F$300,"Derived component")),"") | H30: Discovery FY2026 results release (3 Sep 2026); EasyEquities blog summary
A31: Discovery | B31: FY to Jun 2026 selected lines | C31: Discovery Bank normalised profit | D31: 370 | E31: R M | F31: Selected | G31: =IF(OR(F31="Component",F31="Derived component"),D31/(SUMIFS($D$5:$D$300,$A$5:$A$300,A31,$B$5:$B$300,B31,$F$5:$F$300,"Component")+SUMIFS($D$5:$D$300,$A$5:$A$300,A31,$B$5:$B$300,B31,$F$5:$F$300,"Derived component")),"") | H31: Discovery FY2026 results release (3 Sep 2026); EasyEquities blog summary
A32: Discovery | B32: FY to Jun 2026 selected lines | C32: Discovery Bank profit before new-business acquisition costs | D32: 865 | E32: R M | F32: Selected | G32: =IF(OR(F32="Component",F32="Derived component"),D32/(SUMIFS($D$5:$D$300,$A$5:$A$300,A32,$B$5:$B$300,B32,$F$5:$F$300,"Component")+SUMIFS($D$5:$D$300,$A$5:$A$300,A32,$B$5:$B$300,B32,$F$5:$F$300,"Derived component")),"") | H32: Discovery FY2026 results release (3 Sep 2026); EasyEquities blog summary
A33: Discovery | B33: FY to Jun 2026 selected lines | C33: Headline earnings | D33: 12920 | E33: R M | F33: Selected | G33: =IF(OR(F33="Component",F33="Derived component"),D33/(SUMIFS($D$5:$D$300,$A$5:$A$300,A33,$B$5:$B$300,B33,$F$5:$F$300,"Component")+SUMIFS($D$5:$D$300,$A$5:$A$300,A33,$B$5:$B$300,B33,$F$5:$F$300,"Derived component")),"") | H33: Discovery FY2026 results release (3 Sep 2026); EasyEquities blog summary
A34: Discovery | B34: FY to Jun 2026 selected lines | C34: Normalised headline earnings | D34: 11800 | E34: R M | F34: Selected | G34: =IF(OR(F34="Component",F34="Derived component"),D34/(SUMIFS($D$5:$D$300,$A$5:$A$300,A34,$B$5:$B$300,B34,$F$5:$F$300,"Component")+SUMIFS($D$5:$D$300,$A$5:$A$300,A34,$B$5:$B$300,B34,$F$5:$F$300,"Derived component")),"") | H34: Discovery FY2026 results release (3 Sep 2026); EasyEquities blog summary
A35: Momentum | B35: FY to Jun 2026 normalised headline earnings | C35: Momentum Investments | D35: 1190 | E35: R M | F35: Component | G35: =IF(OR(F35="Component",F35="Derived component"),D35/(SUMIFS($D$5:$D$300,$A$5:$A$300,A35,$B$5:$B$300,B35,$F$5:$F$300,"Component")+SUMIFS($D$5:$D$300,$A$5:$A$300,A35,$B$5:$B$300,B35,$F$5:$F$300,"Derived component")),"") -> 0.16855524 | H35: Momentum FY2026 results (17 Sep 2026); BusinessTech/Moonstone/Daily Investor summaries
A36: Momentum | B36: FY to Jun 2026 normalised headline earnings | C36: Guardrisk | D36: 1040 | E36: R M | F36: Component | G36: =IF(OR(F36="Component",F36="Derived component"),D36/(SUMIFS($D$5:$D$300,$A$5:$A$300,A36,$B$5:$B$300,B36,$F$5:$F$300,"Component")+SUMIFS($D$5:$D$300,$A$5:$A$300,A36,$B$5:$B$300,B36,$F$5:$F$300,"Derived component")),"") -> 0.14730878 | H36: Momentum FY2026 results (17 Sep 2026); BusinessTech/Moonstone/Daily Investor summaries
A37: Momentum | B37: FY to Jun 2026 normalised headline earnings | C37: Momentum Retail | D37: 1010 | E37: R M | F37: Component | G37: =IF(OR(F37="Component",F37="Derived component"),D37/(SUMIFS($D$5:$D$300,$A$5:$A$300,A37,$B$5:$B$300,B37,$F$5:$F$300,"Component")+SUMIFS($D$5:$D$300,$A$5:$A$300,A37,$B$5:$B$300,B37,$F$5:$F$300,"Derived component")),"") -> 0.14305949 | H37: Momentum FY2026 results (17 Sep 2026); BusinessTech/Moonstone/Daily Investor summaries
A38: Momentum | B38: FY to Jun 2026 normalised headline earnings | C38: Momentum Insure | D38: 474 | E38: R M | F38: Component | G38: =IF(OR(F38="Component",F38="Derived component"),D38/(SUMIFS($D$5:$D$300,$A$5:$A$300,A38,$B$5:$B$300,B38,$F$5:$F$300,"Component")+SUMIFS($D$5:$D$300,$A$5:$A$300,A38,$B$5:$B$300,B38,$F$5:$F$300,"Derived component")),"") -> 0.06713881 | H38: Momentum FY2026 results (17 Sep 2026); BusinessTech/Moonstone/Daily Investor summaries
A39: Momentum | B39: FY to Jun 2026 normalised headline earnings | C39: Momentum Health | D39: 367 | E39: R M | F39: Component | G39: =IF(OR(F39="Component",F39="Derived component"),D39/(SUMIFS($D$5:$D$300,$A$5:$A$300,A39,$B$5:$B$300,B39,$F$5:$F$300,"Component")+SUMIFS($D$5:$D$300,$A$5:$A$300,A39,$B$5:$B$300,B39,$F$5:$F$300,"Derived component")),"") -> 0.051983003 | H39: Momentum FY2026 results (17 Sep 2026); BusinessTech/Moonstone/Daily Investor summaries
A40: Momentum | B40: FY to Jun 2026 normalised headline earnings | C40: India health JV (Aditya Birla Health) | D40: 22 | E40: R M | F40: Component | G40: =IF(OR(F40="Component",F40="Derived component"),D40/(SUMIFS($D$5:$D$300,$A$5:$A$300,A40,$B$5:$B$300,B40,$F$5:$F$300,"Component")+SUMIFS($D$5:$D$300,$A$5:$A$300,A40,$B$5:$B$300,B40,$F$5:$F$300,"Derived component")),"") -> 0.0031161473 | H40: Momentum FY2026 results (17 Sep 2026); BusinessTech/Moonstone/Daily Investor summaries
A41: Momentum | B41: FY to Jun 2026 normalised headline earnings | C41: Metropolitan, Corporate, Africa and group costs (derived) | D41: =D42-D35-D36-D37-D38-D39-D40 -> 2957 | E41: R M | F41: Derived component | G41: =IF(OR(F41="Component",F41="Derived component"),D41/(SUMIFS($D$5:$D$300,$A$5:$A$300,A41,$B$5:$B$300,B41,$F$5:$F$300,"Component")+SUMIFS($D$5:$D$300,$A$5:$A$300,A41,$B$5:$B$300,B41,$F$5:$F$300,"Derived component")),"") -> 0.41883853 | H41: Derived by subtraction
A42: Momentum | B42: FY to Jun 2026 normalised headline earnings | C42: Normalised headline earnings | D42: 7060 | E42: R M | F42: Reported total | G42: =IF(OR(F42="Component",F42="Derived component"),D42/(SUMIFS($D$5:$D$300,$A$5:$A$300,A42,$B$5:$B$300,B42,$F$5:$F$300,"Component")+SUMIFS($D$5:$D$300,$A$5:$A$300,A42,$B$5:$B$300,B42,$F$5:$F$300,"Derived component")),"") | H42: Momentum FY2026 results (17 Sep 2026); BusinessTech/Moonstone/Daily Investor summaries
A43: Momentum | B43: FY2026 selected lines | C43: Insurance revenue | D43: 61400 | E43: R M | F43: Selected | G43: =IF(OR(F43="Component",F43="Derived component"),D43/(SUMIFS($D$5:$D$300,$A$5:$A$300,A43,$B$5:$B$300,B43,$F$5:$F$300,"Component")+SUMIFS($D$5:$D$300,$A$5:$A$300,A43,$B$5:$B$300,B43,$F$5:$F$300,"Derived component")),"") | H43: Momentum FY2026 results (17 Sep 2026); BusinessTech/Moonstone/Daily Investor summaries
...

Sheet Reconciliation
A1: Reconciliation: components vs reported totals
A2: Components + derived rows should equal the reported total.
A4: Company | B4: Basis | C4: Unit | D4: Sum of components | E4: Reported total | F4: Difference | G4: Status
A5: Sanlam | B5: FY2025 net result from financial services | C5: R M | D5: =SUMIFS('Segment Data'!$D$5:$D$300,'Segment Data'!$A$5:$A$300,A5,'Segment Data'!$B$5:$B$300,B5,'Segment Data'!$F$5:$F$300,"Component")+SUMIFS('Segment Data'!$D$5:$D$300,'Segment Data'!$A$5:$A$300,A5,'Segment Data'!$B$5:$B$300,B5,'Segment Data'!$F$5:$F$300,"Derived component") -> 15939 | E5: ='Segment Data'!D10 -> 15939 | F5: =D5-E5 -> 0 | G5: =IF(ABS(F5)<0.005,"OK","CHECK") -> OK
A6: Old Mutual | B6: FY2025 results from operations | C6: R M | D6: =SUMIFS('Segment Data'!$D$5:$D$300,'Segment Data'!$A$5:$A$300,A6,'Segment Data'!$B$5:$B$300,B6,'Segment Data'!$F$5:$F$300,"Component")+SUMIFS('Segment Data'!$D$5:$D$300,'Segment Data'!$A$5:$A$300,A6,'Segment Data'!$B$5:$B$300,B6,'Segment Data'!$F$5:$F$300,"Derived component") -> 9821 | E6: ='Segment Data'!D21 -> 9821 | F6: =D6-E6 -> 0 | G6: =IF(ABS(F6)<0.005,"OK","CHECK") -> OK
A7: Discovery | B7: FY to Jun 2026 normalised profit from operations | C7: R M | D7: =SUMIFS('Segment Data'!$D$5:$D$300,'Segment Data'!$A$5:$A$300,A7,'Segment Data'!$B$5:$B$300,B7,'Segment Data'!$F$5:$F$300,"Component")+SUMIFS('Segment Data'!$D$5:$D$300,'Segment Data'!$A$5:$A$300,A7,'Segment Data'!$B$5:$B$300,B7,'Segment Data'!$F$5:$F$300,"Derived component") -> 17750 | E7: ='Segment Data'!D30 -> 17750 | F7: =D7-E7 -> 0 | G7: =IF(ABS(F7)<0.005,"OK","CHECK") -> OK
A8: Momentum | B8: FY to Jun 2026 normalised headline earnings | C8: R M | D8: =SUMIFS('Segment Data'!$D$5:$D$300,'Segment Data'!$A$5:$A$300,A8,'Segment Data'!$B$5:$B$300,B8,'Segment Data'!$F$5:$F$300,"Component")+SUMIFS('Segment Data'!$D$5:$D$300,'Segment Data'!$A$5:$A$300,A8,'Segment Data'!$B$5:$B$300,B8,'Segment Data'!$F$5:$F$300,"Derived component") -> 7060 | E8: ='Segment Data'!D42 -> 7060 | F8: =D8-E8 -> 0 | G8: =IF(ABS(F8)<0.005,"OK","CHECK") -> OK
A9: OUTsurance | B9: FY to Jun 2026 insurance revenue | C9: R M | D9: =SUMIFS('Segment Data'!$D$5:$D$300,'Segment Data'!$A$5:$A$300,A9,'Segment Data'!$B$5:$B$300,B9,'Segment Data'!$F$5:$F$300,"Component")+SUMIFS('Segment Data'!$D$5:$D$300,'Segment Data'!$A$5:$A$300,A9,'Segment Data'!$B$5:$B$300,B9,'Segment Data'!$F$5:$F$300,"Derived component") -> 41490 | E9: ='Segment Data'!D61 -> 41490 | F9: =D9-E9 -> 0 | G9: =IF(ABS(F9)<0.005,"OK","CHECK") -> OK
A10: Wafa Assurance | B10: H1 2025 premiums | C10: MAD M | D10: =SUMIFS('Segment Data'!$D$5:$D$300,'Segment Data'!$A$5:$A$300,A10,'Segment Data'!$B$5:$B$300,B10,'Segment Data'!$F$5:$F$300,"Component")+SUMIFS('Segment Data'!$D$5:$D$300,'Segment Data'!$A$5:$A$300,A10,'Segment Data'!$B$5:$B$300,B10,'Segment Data'!$F$5:$F$300,"Derived component") -> 7882 | E10: ='Segment Data'!D80 -> 7882 | F10: =D10-E10 -> 0 | G10: =IF(ABS(F10)<0.005,"OK","CHECK") -> OK
A11: Africa life market (Atlas 2024) | B11: 2024 life premiums - top 10 | C11: USD thousand | D11: =SUMIFS('Segment Data'!$D$5:$D$300,'Segment Data'!$A$5:$A$300,A11,'Segment Data'!$B$5:$B$300,B11,'Segment Data'!$F$5:$F$300,"Component")+SUMIFS('Segment Data'!$D$5:$D$300,'Segment Data'!$A$5:$A$300,A11,'Segment Data'!$B$5:$B$300,B11,'Segment Data'!$F$5:$F$300,"Derived component") -> 47099364 | E11: ='Segment Data'!D104 -> 47099364 | F11: =D11-E11 -> 0 | G11: =IF(ABS(F11)<0.005,"OK","CHECK") -> OK
A12: Africa non-life market (Atlas 2024) | B12: 2024 non-life premiums - top 10 | C12: USD thousand | D12: =SUMIFS('Segment Data'!$D$5:$D$300,'Segment Data'!$A$5:$A$300,A12,'Segment Data'!$B$5:$B$300,B12,'Segment Data'!$F$5:$F$300,"Component")+SUMIFS('Segment Data'!$D$5:$D$300,'Segment Data'!$A$5:$A$300,A12,'Segment Data'!$B$5:$B$300,B12,'Segment Data'!$F$5:$F$300,"Derived component") -> 26513193 | E12: ='Segment Data'!D116 -> 26513193 | F12: =D12-E12 -> 0 | G12: =IF(ABS(F12)<0.005,"OK","CHECK") -> OK
A14: Green = link to another sheet; black = formula. Derived rows reconcile by construction; sourced components (Sanlam, Momentum, Wafa, Atlas) are the real checks.

Sheet Revenue Sources Matrix
A1: Revenue sources matrix
A2: My classification from the sources reviewed. Primary = dominant; Secondary = material but smaller; blank = not evidenced in sources.
A4: Company | B4: Underwriting premiums | C4: Investment income | D4: Asset-management / admin fees | E4: Banking & credit income | F4: Reinsurance / risk-transfer income | G4: Platform / wellness income | H4: Notes
A5: Sanlam | B5: Primary | C5: Secondary | D5: Secondary | E5: Secondary | H5: Credit (India) ~14% of NRFFS; investment management ~10%.
A6: Old Mutual | B6: Primary | C6: Secondary | D6: Secondary | E6: Secondary | H6: OM Bank and Old Mutual Finance lending; bank still loss-making.
A7: Discovery | B7: Primary | C7: Secondary | E7: Secondary | G7: Secondary | H7: Vitality = ~22% of profit; Bank first profit FY2026.
A8: Momentum | B8: Primary | C8: Secondary | D8: Secondary | F8: Secondary | H8: Guardrisk (risk-transfer) earned R1.04B.
A9: Santam | B9: Primary | C9: Secondary | F9: Secondary | H9: Investment return on insurance funds ~3% of NEP; Santam Re and ART.
A10: OUTsurance | B10: Primary | C10: Secondary | H10: Life earnings secondary.
A11: AIICO Insurance | B11: Primary | H11: Investment income not retrieved.
A12: AXA Mansard | B12: Primary | H12: Investment income not retrieved.
A13: NEM Insurance | B13: Primary
A14: Cornerstone Insurance | B14: Primary
A15: Leadway Assurance | B15: Primary | H15: Financials not retrieved.
A16: Britam | B16: Primary | H16: Microinsurance fast-growing but small.
A17: Jubilee Holdings | B17: Primary
A18: CIC Group | B18: Primary
A19: Wafa Assurance | B19: Primary | C19: Primary | H19: Investments MAD 66B support income.
A20: Hollard Ghana | B20: Primary | H20: Digital micro-premiums; no financials retrieved.
A21: Enterprise / SIC (Ghana) | B21: Primary | H21: Dated information.
A22: African Risk Capacity | B22: Primary | C22: Secondary | F22: Primary | H22: Donor-supported sovereign parametric premiums.

Sheet Vendor & Partnerships
A1: Technology vendors and partnerships
A2: Only partnerships evidenced in the sources. 'In-house' means no named external vendor was found.
A4: Insurer | B4: Partner / vendor | C4: Partner type | D4: Solution / purpose | E4: Region | F4: Date / note
A5: Santam | B5: Guidewire | C5: Core-system vendor | D5: Cloud policy, claims and billing platform; foundation for AI in underwriting, claims and service | E5: South Africa | F5: Went live 9 Jun 2026
A6: AXA Mansard, Liberty Health, Old Mutual, Jubilee Health | B6: Curacel | C6: Insurtech (claims AI) | D6: AI-driven claims processing and fraud detection; vendor claims cycle cut of 70%+; pay-per-claim SaaS | E6: Nigeria, South Africa, Kenya | F6: 2023 announcement; claims are vendor-reported
A7: Jubilee Health (Kenya) | B7: bolttech (African unit) | C7: Insurtech / distribution | D7: Embedded health distribution via banks, petrol stations, retailers, marketplaces | E7: Kenya | F7: Business Daily, 2026
A8: CIC Group | B8: CARD MBA (Philippines) | C8: Microinsurance partner | D8: New and adapted products for informal-sector customers | E8: Kenya | F8: Business Daily, 2026
A9: Britam | B9: Britam Connect (in-house) | C9: In-house | D9: Embedded, pay-as-you-go microinsurance for gig workers and small businesses | E9: Kenya | F9: Business Daily, 2026
A10: Hollard Life Ghana | B10: Cassava Fintech + Vodafone | C10: Fintech + telco | D10: USSD micro-life product MeBanbo for mobile-money users | E10: Ghana | F10: Hollard press release (c. 2021-22)
A11: Hollard Ghana | B11: Jumia / JumiaPay | C11: E-commerce | D11: Digital sale of general and life insurance | E11: Ghana | F11: Launched Jun 2021
A12: Hollard Insurance Ghana | B12: ETAP | C12: Licensed insurtech | D12: ETAP-Hollard digital auto insurance with instant claims | E12: Ghana | F12: First NIC insurtech licence
A13: Hollard Ghana | B13: Araba Hollard chatbot (in-house) | C13: In-house AI | D13: Chatbot fronting Hollard ChatInsure | E13: Ghana | F13: Press release
A14: Sanlam | B14: Allianz | C14: Joint venture | D14: SanlamAllianz pan-African JV; Allianz 49%, Sanlam 51% | E14: Africa | F14: Allianz raised stake in Apr 2025
A15: Sanlam | B15: GoTyme Bank | C15: Digital bank partner | D15: Digital ecosystem for cross-sell, acquisition and retention in SA | E15: South Africa | F15: FY2025 results
... A27: Multiple insurers (15+) | B27: Lami | C27: Insurtech platform | D27: SaaS distribution platform connected to 15+ African insurers | E27: Africa | F27: Techpoint Africa, 2026

Sheet Financial Engineering
A1: Financial engineering, capital and risk-transfer structures
A2: 'Why it matters' is my interpretation; figures are from the cited sources.
A4: Entity | B4: Mechanism | C4: Description / figures | D4: Why it matters (interpretation) | E4: Source
A5: Sanlam / Allianz | B5: Joint-venture holding | C5: SanlamAllianz is held 51% Sanlam / 49% Allianz after Allianz bought another 8.59% for R4.5B initially; 10 of 11 country integrations complete. | D5: Shares capital needs and brings global reinsurance/expertise while keeping Sanlam's control. | E5: Business Report (Sep 2025); Sanlam FY2025
A6: Sanlam | B6: ALM / capital efficiency | C6: Margin-backing assets moved from fixed to floating rate under IFRS 17, releasing about R650M of capital and locking in prior investment variances. | D6: Cuts solvency capital needs without changing the insurance book. | E6: Sanlam FY2025 presentation
A7: Sanlam | B7: Strategic stakes / disposals | C7: Raised Shriram stakes above 50% in insurers; MUFG buying 20% of Shriram Finance; holds ~12.5% of Ninety One after active asset management disposals. | D7: Redeploys capital to higher-growth India and sheds lower-return units. | E7: Sanlam media release, 12 Mar 2026
A8: Santam | B8: Lloyd's syndicate | C8: Santam Syndicate 1918 began underwriting 1 Jan 2026; approved capacity above £300M; consortia and facility lines above USD 40M. | D8: Access to specialist London-market classes and capacity beyond local balance sheet. | E8: Sanlam FY2025 presentation; Santam
A9: Santam | B9: Reinsurance cost control | C9: Reinsurance cost fell about 4.6% as a share of gross earned premium from 2023 to 2025. | D9: Retains more margin from improved underwriting. | E9: FA News (11 Mar 2026)
A10: Old Mutual | B10: Capital return and cost programme | C10: R3B buyback (R682M done in H2 2025); discretionary capital R6.1B; R2.5B savings target by 2027 (R450M achieved). | D10: Returns excess capital while OM Bank investment is written down. | E10: Moonstone; Old Mutual results
A11: Momentum | B11: Buybacks and market exits | C11: R1B buyback completed; Ghana disposal concluded 9 Sep 2025; Mozambique held for sale; dividend policy revised. | D11: Refocuses on core South African businesses and India. | E11: Momentum media release; BusinessTech
A12: OUTsurance | B12: Subsidiary capital injections | C12: EUR 10M a year for five years plus an additional EUR 20M in late 2026 (EUR 70M total) for Ireland. | D12: Funds growth of a loss-making start-up to regulatory solvency. | E12: Daily Investor (Sep 2026)
A13: Nigerian insurers | B13: Regulatory recapitalisation | C13: NIIRA 2025 raised minimum capital to N10B (life), N15B (non-life), N35B (reinsurance); 43 insurers cleared by July 2026, 8 pending; composites must split within five years; eight insurers sought about N132.5B. | D13: Forces capital raising, mergers and portfolio transfers. | E13: BusinessDay; Ecofin
A14: NSIA Group | B14: Captive reinsurer | C14: CRCA approved Manzi Re as NSIA's captive reinsurer. | D14: Retains risk and reinsurance margin inside the group. | E14: MEIR
A15: African Risk Capacity | B15: Sovereign parametric pool | C15: Hybrid mutual insurer pooling sovereign risk with reinsurance; 300+ policies and over USD 250M paid since 2014; donor-funded premium support (e.g. Germany EUR 18M); first sovereign flood cover signed Jan 2026. | D15: Turns climate risk into pre-arranged payouts with donor-subsidised premiums. | E15: Reinsurance News; MEIR; Artemis
A16: Wafa Assurance / Sanlam Morocco / Allianz Morocco | B16: Cross-border M&A | C16: Wafa bought 63.39% of Delta Insurance (Egypt); Sanlam Morocco and Allianz Morocco agreed merger terms in March 2026. | D16: Scale and diversification in North Africa. | E16: MEIR

Sheet Sources & Notes
A1: Sources & notes
A3: Company / topic | B3: Document | C3: URL | D3: Type
A4: Market ranking | B4: Top 30 African insurance companies | C4: https://atlas-mag.net/en/articles/top-30-african-insurance-companies | D4: Secondary (industry magazine)
A5: Market ranking | B5: Top 10 non-life premiums 2024 | C5: https://atlas-mag.net/en/articles/top-10-african-companies-non-life-insurance-premiums-2024 | D5: Secondary
A6: Market ranking | B6: Top 10 life premiums 2024 | C6: https://atlas-mag.net/en/articles/top-10-african-companies-life-insurance-premiums-2024 | D6: Secondary
A7: Sanlam | B7: FY2025 annual results presentation | C7: https://www.sanlam.com/downloads/results-announcements/2025/annual-results-presentation-2025.pdf | D7: Primary
A8: Sanlam | B8: FY2025 media release | C8: https://www.sanlam.com/pdf/media-releases/2026/media-release-annual-results-2025.pdf | D8: Primary
A9: Sanlam | B9: SanlamAllianz stake change | C9: https://iol.co.za/business-report/companies/2025-09-04-sanlams-businesses-perform-well-in-the-first-half-and-return-on-equity-value-is-strong/ | D9: Secondary
A10: Old Mutual | B10: FY2025 results summary | C10: https://www.moonstone.co.za/old-mutual-earnings-rise-as-insurance-investments-and-africa-drive-results/ | D10: Secondary
A11: Old Mutual | B11: FY2025 SENS announcement | C11: https://sharedata.co.za/v2/scripts/SENS.aspx?id=542104 | D11: Primary
A12: Discovery | B12: FY2026 results release | C12: https://www.mynewsdesk.com/za/discovery-holdings-ltd/pressreleases/discovery-grows-operating-profit-17-percent-to-r17-dot-75bn-as-bank-drives-new-strategic-phase-3464509 | D12: Primary
A13: Discovery | B13: FY2026 summary | C13: https://blogs.easyequities.co.za/discovery-fy26-a-strong-year-and-a-shared-road-ahead | D13: Secondary
A14: Momentum | B14: FY2026 results summary | C14: https://www.moonstone.co.za/?p=61779 | D14: Secondary
... A36: ARC | B36: Sovereign flood cover | C36: https://meinsurancereview.com/News/ViewNewsLetterArticle/id/94331/Type/Africa | D36: Secondary
A38: Notes
A39: Derived figures (yellow rows in Segment Data) are my own subtraction from reported totals.
A40: Old Mutual segment figures are rounded 'about' values from trade press; Discovery's SA profit is derived from the group total less Vitality.
A41: Momentum's FY2026 'other' line (~R2.96B) combines Metropolitan, Corporate, Africa and group costs; the sources I found did not give each separately.
A42: A Kenya insurance penetration range of 2.1% to 2.43% appears in different sources; 2.1% is used here.
